File: data/InventWood/Superwood-ID34s-07302025.csv
Time (sec),Force (N),Position (mm),Stress (Pa),Strain (m/m)
3.54,23.5,0.0180,222000,0.000368
3.69,29.3,0.0298,276000,0.000609
3.84,34.7,0.0420,327000,0.000860
3.99,39.7,0.0543,374000,0.00111
4.14,44.8,0.0665,422000,0.00136
4.29,51.4,0.0787,484000,0.00161
4.44,60.3,0.0909,568000,0.00186
4.59,69.4,0.103,653000,0.00211
4.74,78.0,0.115,735000,0.00236
4.89,87.5,0.128,824000,0.00261
5.04,97.1,0.140,914000,0.00286
5.19,107,0.152,1010000,0.00311
5.34,118,0.164,1110000,0.00336
5.49,129,0.177,1220000,0.00361
5.64,141,0.189,1330000,0.00386
5.79,153,0.201,1440000,0.00411
5.94,165,0.213,1560000,0.00436
6.09,178,0.225,1680000,0.00461
6.24,191,0.238,1800000,0.00486
6.39,205,0.250,1930000,0.00511
6.54,219,0.262,2060000,0.00536
6.69,234,0.274,2200000,0.00561
6.84,248,0.286,2340000,0.00585
6.99,264,0.299,2490000,0.00610
7.14,279,0.311,2630000,0.00635
7.29,295,0.323,2780000,0.00660
7.44,311,0.335,2930000,0.00685
7.59,328,0.347,3090000,0.00710
7.74,344,0.359,3240000,0.00735
7.89,361,0.372,3400000,0.00760
8.04,379,0.384,3560000,0.00785
8.19,396,0.396,3730000,0.00810
8.34,414,0.408,3900000,0.00835
8.48,432,0.420,4070000,0.00860
8.63,451,0.433,4240000,0.00885
8.78,469,0.445,4420000,0.00910
8.93,489,0.457,4610000,0.00935
9.08,509,0.470,4790000,0.00960
9.23,530,0.482,4990000,0.00985
9.38,550,0.494,5180000,0.0101
9.53,570,0.506,5360000,0.0104
9.68,591,0.519,5570000,0.0106
9.83,615,0.531,5790000,0.0109
9.98,638,0.543,6010000,0.0111
10.1,661,0.555,6230000,0.0113
10.3,684,0.567,6440000,0.0116
10.4,708,0.579,6670000,0.0118
10.6,732,0.592,6890000,0.0121
10.7,756,0.604,7120000,0.0123
10.9,780,0.616,7350000,0.0126
11.0,805,0.628,7580000,0.0128
11.2,835,0.641,7860000,0.0131
11.3,870,0.653,8190000,0.0133
11.5,905,0.665,8520000,0.0136
11.6,939,0.677,8850000,0.0138
11.8,975,0.689,9180000,0.0141
11.9,1010,0.702,9560000,0.0143
12.1,1060,0.714,9960000,0.0146
12.2,1100,0.726,10400000,0.0148
12.4,1140,0.738,10800000,0.0151
12.5,1190,0.750,11200000,0.0153
12.7,1240,0.763,11600000,0.0156
12.8,1280,0.775,12100000,0.0158
13.0,1330,0.787,12600000,0.0161
13.1,1380,0.799,13000000,0.0163
13.3,1440,0.811,13500000,0.0166
13.4,1490,0.824,14000000,0.0168
13.6,1540,0.836,14500000,0.0171
13.7,1600,0.848,15100000,0.0173
13.9,1660,0.860,15600000,0.0176
14.0,1720,0.872,16200000,0.0178
14.2,1780,0.885,16700000,0.0181
14.3,1840,0.897,17300000,0.0183
14.5,1900,0.909,17900000,0.0186
14.6,1970,0.921,18500000,0.0188
14.8,2030,0.933,19100000,0.0191
14.9,2100,0.946,19800000,0.0193
15.1,2160,0.958,20400000,0.0196
15.2,2230,0.970,21000000,0.0198
15.4,2290,0.982,21600000,0.0201
15.5,2350,0.994,22200000,0.0203
15.7,2420,1.01,22800000,0.0206
15.8,2480,1.02,23400000,0.0208
16.0,2550,1.03,24000000,0.0211
16.1,2610,1.04,24600000,0.0213
16.3,2680,1.06,25200000,0.0216
16.4,2750,1.07,25900000,0.0218
16.6,2810,1.08,26500000,0.0221
16.7,2880,1.09,27200000,0.0223
16.9,2950,1.10,27800000,0.0226
17.0,3020,1.12,28500000,0.0228
17.2,3090,1.13,29100000,0.0231
17.3,3160,1.14,29800000,0.0233
17.5,3230,1.15,30400000,0.0236
17.6,3300,1.17,31000000,0.0238
17.8,3360,1.18,31700000,0.0241
17.9,3430,1.19,32300000,0.0243
18.1,3510,1.20,33000000,0.0246
18.2,3580,1.21,33700000,0.0248
18.4,3600,1.23,33900000,0.0251
18.5,3670,1.24,34500000,0.0253
18.7,3710,1.25,35000000,0.0256
18.8,3780,1.26,35600000,0.0258
19.0,3850,1.28,36200000,0.0261
19.1,3900,1.29,36800000,0.0263
19.3,3970,1.30,37400000,0.0266
19.4,4040,1.31,38000000,0.0268
19.6,4100,1.32,38600000,0.0271
19.7,4120,1.34,38800000,0.0273
19.9,4130,1.35,38900000,0.0276
20.0,3990,1.36,37600000,0.0278
20.2,3080,1.37,29000000,0.0281
20.3,3180,1.39,29900000,0.0283
20.5,3290,1.40,31000000,0.0286
20.6,3410,1.41,32100000,0.0288
20.8,3520,1.42,33200000,0.0291
20.9,3640,1.43,34300000,0.0293
21.1,3750,1.45,35300000,0.0296
21.2,3860,1.46,36400000,0.0298
21.4,3970,1.47,37400000,0.0301
21.5,4080,1.48,38400000,0.0303
21.7,4190,1.49,39400000,0.0306
21.8,4300,1.51,40400000,0.0308
22.0,4400,1.52,41500000,0.0311
22.1,4510,1.53,42500000,0.0313
22.3,4620,1.54,43500000,0.0316
22.4,4730,1.56,44500000,0.0318
22.6,4840,1.57,45600000,0.0321
22.7,4960,1.58,46700000,0.0323
22.9,5080,1.59,47800000,0.0326
23.0,5200,1.60,48900000,0.0328
23.2,5320,1.62,50100000,0.0331
23.3,5450,1.63,51300000,0.0333
23.5,5570,1.64,52500000,0.0336
23.6,5700,1.65,53700000,0.0338
23.8,5830,1.67,54900000,0.0341
23.9,5960,1.68,56100000,0.0343
24.1,6080,1.69,57300000,0.0346
24.2,6200,1.70,58400000,0.0348
24.4,6320,1.71,59500000,0.0351
24.5,6440,1.73,60600000,0.0353
24.7,6550,1.74,61700000,0.0356
24.8,6660,1.75,62700000,0.0358
25.0,6760,1.76,63700000,0.0361
25.1,6880,1.78,64800000,0.0363
25.3,7000,1.79,65900000,0.0366
25.4,7120,1.80,67100000,0.0368
25.6,7240,1.81,68200000,0.0371
25.7,7360,1.82,69300000,0.0373
25.9,7480,1.84,70500000,0.0376
26.0,7600,1.85,71600000,0.0378
26.2,7720,1.86,72700000,0.0381
26.3,7830,1.87,73700000,0.0383
26.5,7940,1.89,74700000,0.0386
26.6,8040,1.90,75700000,0.0388
26.8,8140,1.91,76700000,0.0391
26.9,8240,1.92,77600000,0.0393
27.1,8330,1.93,78500000,0.0396
27.2,8430,1.95,79400000,0.0398
27.3,8530,1.96,80300000,0.0401
27.5,8640,1.97,81400000,0.0403
27.6,8750,1.98,82400000,0.0406
27.8,8870,2.00,83500000,0.0408
27.9,8980,2.01,84600000,0.0411
28.1,9090,2.02,85600000,0.0413
28.2,9200,2.03,86700000,0.0416
28.4,9310,2.04,87700000,0.0418
28.5,9410,2.06,88600000,0.0421
28.7,9500,2.07,89500000,0.0423
28.8,9590,2.08,90300000,0.0426
29.0,9680,2.09,91100000,0.0428
29.1,9770,2.11,92000000,0.0431
29.3,9860,2.12,92900000,0.0433
29.4,9960,2.13,93800000,0.0435
29.6,10100,2.14,94800000,0.0438
29.7,10200,2.15,95800000,0.0440
29.9,10300,2.17,96800000,0.0443
30.0,10400,2.18,97800000,0.0445
30.2,10500,2.19,98800000,0.0448
30.3,10600,2.20,99800000,0.0450
30.5,10700,2.22,101000000,0.0453
30.6,10800,2.23,102000000,0.0455
30.8,10900,2.24,103000000,0.0458
30.9,11000,2.25,103000000,0.0460
31.1,11100,2.26,104000000,0.0463
31.2,11200,2.28,105000000,0.0465
31.4,11300,2.29,106000000,0.0468
31.5,11400,2.30,107000000,0.0470
31.7,11500,2.31,108000000,0.0473
31.8,11500,2.33,109000000,0.0475
32.0,11600,2.34,109000000,0.0478
32.1,11600,2.35,110000000,0.0480
32.3,11700,2.36,110000000,0.0483
32.4,11700,2.37,110000000,0.0485
32.6,11700,2.39,110000000,0.0488
32.7,11800,2.40,111000000,0.0490
32.9,11800,2.41,111000000,0.0493
33.0,11900,2.42,112000000,0.0495
33.2,11900,2.44,112000000,0.0498
33.3,12000,2.45,113000000,0.0500
33.5,12000,2.46,113000000,0.0503
33.6,12100,2.47,113000000,0.0505
33.8,12100,2.48,114000000,0.0508
33.9,12000,2.50,113000000,0.0510
34.1,12000,2.51,113000000,0.0513
34.2,11900,2.52,112000000,0.0515
34.4,11900,2.53,112000000,0.0518
34.5,11900,2.55,112000000,0.0520
34.7,11900,2.56,112000000,0.0523
34.8,12000,2.57,113000000,0.0525
35.0,12000,2.58,113000000,0.0528
35.1,12100,2.59,114000000,0.0530
35.3,12100,2.61,114000000,0.0533
35.4,12200,2.62,115000000,0.0535
35.6,12200,2.63,115000000,0.0538
35.7,12300,2.64,116000000,0.0540
35.9,12300,2.65,116000000,0.0543
36.0,12400,2.67,117000000,0.0545
36.2,12400,2.68,117000000,0.0548
36.3,12500,2.69,117000000,0.0550
36.5,12500,2.70,118000000,0.0553
36.6,12500,2.72,118000000,0.0555
36.8,12500,2.73,117000000,0.0558
36.9,12300,2.74,116000000,0.0560
37.1,11900,2.75,112000000,0.0563
37.2,11100,2.77,104000000,0.0565
37.4,10600,2.78,99900000,0.0568
37.5,10300,2.79,97300000,0.0570
37.7,10200,2.80,96300000,0.0573
37.8,10200,2.81,96000000,0.0575
38.0,10200,2.83,96200000,0.0578
38.1,10300,2.84,96600000,0.0580
38.3,10300,2.85,97100000,0.0583
38.4,10400,2.86,97600000,0.0585
38.6,10400,2.87,98000000,0.0588
38.7,10500,2.89,98500000,0.0590
38.9,10500,2.90,99000000,0.0593
39.0,10600,2.91,99400000,0.0595
39.2,10600,2.92,100000000,0.0598
39.3,10700,2.94,100000000,0.0600
39.5,10700,2.95,101000000,0.0603
39.6,10800,2.96,102000000,0.0605
39.8,10900,2.97,102000000,0.0608
39.9,10900,2.98,103000000,0.0610
40.1,11000,3.00,104000000,0.0613
40.2,11100,3.01,104000000,0.0615
40.4,11200,3.02,105000000,0.0618
40.5,11200,3.03,106000000,0.0620
40.7,11300,3.05,107000000,0.0623
40.8,11400,3.06,107000000,0.0625
41.0,11500,3.07,108000000,0.0628
41.1,11500,3.08,109000000,0.0630
41.3,11600,3.09,109000000,0.0633
41.4,11700,3.11,110000000,0.0635
41.6,11800,3.12,111000000,0.0638
41.7,11800,3.13,111000000,0.0640
41.9,11900,3.14,112000000,0.0643
42.0,12000,3.16,113000000,0.0645
42.2,12100,3.17,114000000,0.0648
42.3,12100,3.18,114000000,0.0650
42.5,12200,3.19,115000000,0.0653
42.6,12300,3.20,116000000,0.0655
42.8,12300,3.22,116000000,0.0658
42.9,12400,3.23,117000000,0.0660
43.1,12500,3.24,118000000,0.0663
43.2,12500,3.25,118000000,0.0665
43.4,12600,3.27,119000000,0.0668
43.5,12700,3.28,119000000,0.0670
43.7,12700,3.29,120000000,0.0673
43.8,12800,3.30,120000000,0.0675
44.0,12800,3.31,121000000,0.0678
44.1,12800,3.33,121000000,0.0680
44.3,12800,3.34,120000000,0.0683
44.4,12700,3.35,120000000,0.0685
44.6,12700,3.36,120000000,0.0688
44.7,12700,3.38,119000000,0.0690
44.9,12700,3.39,119000000,0.0693
45.0,12600,3.40,119000000,0.0695
45.2,12600,3.41,119000000,0.0698
45.3,12600,3.42,119000000,0.0700
45.5,12600,3.44,119000000,0.0703
45.6,12700,3.45,119000000,0.0705
45.8,12700,3.46,120000000,0.0708
45.9,12800,3.47,120000000,0.0710
46.1,12800,3.49,121000000,0.0713
46.2,12900,3.50,121000000,0.0715
46.4,12900,3.51,122000000,0.0718
46.5,13000,3.52,122000000,0.0720
46.7,13000,3.53,123000000,0.0723
46.8,13100,3.55,123000000,0.0725
47.0,13100,3.56,124000000,0.0728
47.1,13200,3.57,124000000,0.0730
47.3,13200,3.58,124000000,0.0733
47.4,13200,3.60,125000000,0.0735
47.6,13300,3.61,125000000,0.0738
47.7,13300,3.62,125000000,0.0740
47.9,13300,3.63,125000000,0.0743
48.0,13300,3.64,125000000,0.0745
48.2,13300,3.66,125000000,0.0748
48.3,13200,3.67,125000000,0.0750
48.5,13200,3.68,125000000,0.0753
48.6,13200,3.69,125000000,0.0755
48.8,13200,3.71,125000000,0.0758
48.9,13300,3.72,125000000,0.0760
49.1,13300,3.73,125000000,0.0763
49.2,13400,3.74,126000000,0.0765
49.4,13400,3.75,126000000,0.0768
49.5,13500,3.77,127000000,0.0770
49.7,13500,3.78,127000000,0.0772
49.8,13600,3.79,128000000,0.0775
50.0,13600,3.80,128000000,0.0777
50.1,13700,3.81,129000000,0.0780
50.3,13700,3.83,129000000,0.0782
50.4,13700,3.84,129000000,0.0785
50.6,13800,3.85,130000000,0.0787
50.7,13800,3.86,130000000,0.0790
50.9,13800,3.88,130000000,0.0792
51.0,13700,3.89,129000000,0.0795
51.2,13700,3.90,129000000,0.0797
51.3,13600,3.91,128000000,0.0800
51.5,13400,3.92,127000000,0.0802
51.6,13100,3.94,124000000,0.0805
51.8,12100,3.95,114000000,0.0808
51.9,11100,3.96,105000000,0.0810
52.1,10500,3.97,99300000,0.0813
52.2,10400,3.99,98200000,0.0815
52.4,10400,4.00,98100000,0.0817
52.5,10500,4.01,98400000,0.0820
52.7,10500,4.02,98900000,0.0822
52.8,10600,4.03,99500000,0.0825
53.0,10600,4.05,100000000,0.0827
53.1,10700,4.06,101000000,0.0830
53.3,10800,4.07,101000000,0.0832
53.4,10800,4.08,102000000,0.0835
53.6,10900,4.10,102000000,0.0837
53.7,10900,4.11,103000000,0.0840
53.9,10900,4.12,103000000,0.0842
54.0,10900,4.13,103000000,0.0845
54.1,10900,4.14,103000000,0.0847
54.3,10500,4.16,98900000,0.0850
54.4,10300,4.17,96600000,0.0852
54.6,10200,4.18,95700000,0.0855
54.7,10100,4.19,95500000,0.0857
54.9,10100,4.21,95600000,0.0860
55.0,10200,4.22,95800000,0.0862
55.2,10200,4.23,96200000,0.0865
55.3,10300,4.24,96600000,0.0867
55.5,10300,4.25,97100000,0.0870
55.6,10400,4.27,97600000,0.0872
55.8,10400,4.28,98000000,0.0875
55.9,10500,4.29,98500000,0.0877
56.1,10500,4.30,98900000,0.0880
56.2,10500,4.32,99200000,0.0882
56.4,10600,4.33,99600000,0.0885
56.5,10600,4.34,100000000,0.0887
56.7,10700,4.35,100000000,0.0890
56.8,10700,4.36,101000000,0.0892
57.0,10700,4.38,101000000,0.0895
57.1,10800,4.39,102000000,0.0897
57.3,10800,4.40,102000000,0.0900
57.4,10900,4.41,102000000,0.0902
57.6,10900,4.43,103000000,0.0905
57.7,11000,4.44,103000000,0.0907
57.9,11000,4.45,104000000,0.0910
58.0,11000,4.46,104000000,0.0912
58.2,11100,4.47,104000000,0.0915
58.3,11100,4.49,105000000,0.0917
58.5,11200,4.50,105000000,0.0920
58.6,11200,4.51,105000000,0.0922
58.8,11200,4.52,106000000,0.0925
58.9,11300,4.54,106000000,0.0927
59.1,11300,4.55,106000000,0.0930
59.2,11400,4.56,107000000,0.0932
59.4,11400,4.57,107000000,0.0935
59.5,11500,4.58,108000000,0.0937
59.7,11500,4.60,108000000,0.0940
59.8,11500,4.61,109000000,0.0942
60.0,11600,4.62,109000000,0.0945
60.1,11500,4.63,108000000,0.0947
60.3,11300,4.65,107000000,0.0950
60.4,11200,4.66,106000000,0.0952
60.6,11200,4.67,105000000,0.0955
60.7,11200,4.68,106000000,0.0957
60.9,11200,4.69,106000000,0.0960
61.0,11200,4.71,106000000,0.0962
61.2,11300,4.72,106000000,0.0965
61.3,11300,4.73,106000000,0.0967
61.5,11400,4.74,107000000,0.0970
61.6,11400,4.76,108000000,0.0972
61.8,11500,4.77,108000000,0.0975
61.9,11600,4.78,109000000,0.0977
62.1,11700,4.79,110000000,0.0980
62.2,11700,4.80,111000000,0.0982
62.4,11800,4.82,111000000,0.0985
62.5,11900,4.83,112000000,0.0987
62.7,12000,4.84,113000000,0.0990
62.8,12100,4.85,114000000,0.0992
63.0,12200,4.86,115000000,0.0995
63.1,12300,4.88,115000000,0.0997
63.3,12300,4.89,116000000,0.100
63.4,12400,4.90,117000000,0.100
63.6,12500,4.91,118000000,0.100
63.7,12600,4.93,118000000,0.101
63.9,12600,4.94,119000000,0.101
64.0,12700,4.95,119000000,0.101
64.2,12800,4.96,120000000,0.101
64.3,12800,4.97,121000000,0.102
64.5,12900,4.99,121000000,0.102
64.6,12900,5.00,122000000,0.102
64.8,13000,5.01,122000000,0.102
64.9,13000,5.02,123000000,0.103
65.1,13100,5.04,123000000,0.103
65.2,13100,5.05,124000000,0.103
65.4,13200,5.06,124000000,0.103
65.5,13200,5.07,125000000,0.104
65.7,13300,5.08,125000000,0.104
65.8,13300,5.10,125000000,0.104
66.0,13300,5.11,126000000,0.104
66.1,13400,5.12,126000000,0.105
66.3,13400,5.13,126000000,0.105
66.4,13400,5.15,126000000,0.105
66.6,13400,5.16,126000000,0.105
66.7,13400,5.17,126000000,0.106
66.9,13300,5.18,126000000,0.106
67.0,13300,5.19,126000000,0.106
67.2,13300,5.21,126000000,0.106
67.3,13300,5.22,125000000,0.107
67.5,13300,5.23,125000000,0.107
67.6,13300,5.24,125000000,0.107
67.8,13300,5.26,125000000,0.107
67.9,13200,5.27,125000000,0.108
68.1,13200,5.28,124000000,0.108
68.2,13200,5.29,124000000,0.108
68.4,13100,5.30,123000000,0.108
68.5,13000,5.32,123000000,0.109
68.7,13000,5.33,122000000,0.109
68.8,12800,5.34,121000000,0.109
69.0,12600,5.35,119000000,0.109
69.1,12300,5.37,116000000,0.110
69.3,12000,5.38,113000000,0.110
69.4,11900,5.39,112000000,0.110
69.6,11800,5.40,111000000,0.110
69.7,11800,5.41,111000000,0.111
69.9,11900,5.43,112000000,0.111
70.0,11900,5.44,112000000,0.111
70.2,11900,5.45,112000000,0.111
70.3,12000,5.46,113000000,0.112
70.5,12100,5.48,114000000,0.112
70.6,12100,5.49,114000000,0.112
70.8,12200,5.50,115000000,0.112
70.9,12300,5.51,115000000,0.113
71.1,12300,5.52,116000000,0.113
71.2,12400,5.54,117000000,0.113
71.4,12500,5.55,117000000,0.113
71.5,12500,5.56,118000000,0.114
71.7,12600,5.57,118000000,0.114
71.8,12600,5.59,119000000,0.114
72.0,12700,5.60,119000000,0.114
72.1,12700,5.61,120000000,0.115
72.3,12800,5.62,120000000,0.115
72.4,12800,5.63,121000000,0.115
72.6,12800,5.65,121000000,0.115
72.7,12900,5.66,121000000,0.116
72.9,12900,5.67,122000000,0.116
73.0,12900,5.68,122000000,0.116
73.2,12900,5.70,122000000,0.116
73.3,13000,5.71,122000000,0.117
73.5,13000,5.72,122000000,0.117
73.6,13000,5.73,122000000,0.117
73.8,13000,5.74,122000000,0.117
73.9,13000,5.76,122000000,0.118
74.1,13000,5.77,122000000,0.118
74.2,13000,5.78,122000000,0.118
74.4,12900,5.79,122000000,0.118
74.5,12900,5.81,121000000,0.119
74.7,12800,5.82,121000000,0.119
74.8,12800,5.83,121000000,0.119
75.0,12800,5.84,120000000,0.119
75.1,12700,5.85,120000000,0.120
75.3,12600,5.87,119000000,0.120
75.4,12400,5.88,117000000,0.120
75.6,12200,5.89,115000000,0.120
75.7,12100,5.90,114000000,0.121
75.9,12000,5.92,113000000,0.121
76.0,11600,5.93,110000000,0.121
76.2,11500,5.94,108000000,0.121
76.3,11400,5.95,108000000,0.122
76.5,11400,5.96,107000000,0.122
76.6,11400,5.98,107000000,0.122
76.8,11400,5.99,108000000,0.122
76.9,11400,6.00,108000000,0.123
77.1,11400,6.01,108000000,0.123
77.2,11500,6.02,108000000,0.123
77.4,11500,6.04,108000000,0.123
77.5,11500,6.05,108000000,0.124
77.7,11500,6.06,108000000,0.124
77.8,11500,6.07,108000000,0.124
78.0,11500,6.09,108000000,0.124
78.1,11500,6.10,108000000,0.125
78.3,11500,6.11,108000000,0.125
78.4,11400,6.12,108000000,0.125
78.6,11400,6.14,107000000,0.125
78.7,11300,6.15,107000000,0.126
78.9,11300,6.16,106000000,0.126
79.0,11300,6.17,106000000,0.126
79.2,11300,6.18,106000000,0.126
79.3,11300,6.20,106000000,0.127
79.5,11300,6.21,106000000,0.127
79.6,11300,6.22,107000000,0.127
79.8,11300,6.23,107000000,0.127
79.9,11400,6.24,107000000,0.128
80.1,11400,6.26,107000000,0.128
80.2,11300,6.27,107000000,0.128
80.4,11300,6.28,107000000,0.128
80.5,11300,6.29,106000000,0.129
80.7,11300,6.31,106000000,0.129
80.8,11200,6.32,106000000,0.129
80.9,11200,6.33,105000000,0.129
81.1,11100,6.34,105000000,0.130
81.2,11100,6.35,104000000,0.130
81.4,11000,6.37,104000000,0.130
81.5,11000,6.38,103000000,0.130
81.7,10900,6.39,103000000,0.131
81.8,10900,6.40,103000000,0.131
82.0,10800,6.42,102000000,0.131
82.1,10800,6.43,101000000,0.131
82.3,10700,6.44,101000000,0.132
82.4,10700,6.45,100000000,0.132
82.6,10600,6.46,100000000,0.132
82.7,10600,6.48,99600000,0.132
82.9,10500,6.49,98900000,0.133
83.0,10400,6.50,97800000,0.133
83.2,10300,6.51,97100000,0.133
83.3,10300,6.53,96700000,0.133
83.5,10300,6.54,96600000,0.134
83.6,10200,6.55,96500000,0.134
83.8,10300,6.56,96500000,0.134
83.9,10300,6.57,96600000,0.134
84.1,10300,6.59,96700000,0.135
84.2,10300,6.60,96800000,0.135
84.4,10300,6.61,96900000,0.135
84.5,10300,6.62,97000000,0.135
84.7,10300,6.64,97200000,0.136
84.8,10300,6.65,97300000,0.136
85.0,10300,6.66,97400000,0.136
85.1,10400,6.67,97600000,0.136
85.3,10400,6.68,97800000,0.137
85.4,10400,6.70,98000000,0.137
85.6,10400,6.71,98200000,0.137
85.7,10400,6.72,98400000,0.137
85.9,10500,6.73,98600000,0.138
86.0,10500,6.75,98900000,0.138
86.2,10500,6.76,99200000,0.138
86.3,10600,6.77,99600000,0.138
86.5,10600,6.78,100000000,0.139
86.6,10700,6.79,100000000,0.139
86.8,10700,6.81,101000000,0.139
86.9,10800,6.82,101000000,0.139
87.1,10800,6.83,102000000,0.140
87.2,10800,6.84,102000000,0.140
87.4,10900,6.86,103000000,0.140
87.5,10900,6.87,103000000,0.140
87.7,11000,6.88,103000000,0.141
87.8,11000,6.89,103000000,0.141
88.0,11000,6.90,104000000,0.141
88.1,11000,6.92,104000000,0.141
88.3,11000,6.93,104000000,0.142
88.4,11000,6.94,104000000,0.142
88.6,11100,6.95,104000000,0.142
88.7,11100,6.97,104000000,0.142
88.9,11100,6.98,104000000,0.143
89.0,11100,6.99,105000000,0.143
89.2,11100,7.00,105000000,0.143
89.3,11100,7.01,105000000,0.143
89.5,11200,7.03,105000000,0.144
89.6,11200,7.04,105000000,0.144
89.8,11200,7.05,105000000,0.144
89.9,11200,7.06,106000000,0.144
90.1,11200,7.08,106000000,0.145
90.2,11300,7.09,106000000,0.145
90.4,11300,7.10,106000000,0.145
90.5,11300,7.11,106000000,0.145
90.7,11300,7.12,106000000,0.146
90.8,11300,7.14,106000000,0.146
91.0,11300,7.15,106000000,0.146
91.1,11300,7.16,106000000,0.146
91.3,11300,7.17,106000000,0.147
91.4,11200,7.19,106000000,0.147
91.6,11200,7.20,106000000,0.147
91.7,11200,7.21,106000000,0.147
91.9,11200,7.22,106000000,0.148
92.0,11200,7.23,106000000,0.148
92.2,11300,7.25,106000000,0.148
92.3,11200,7.26,106000000,0.148
92.5,11200,7.27,105000000,0.149
92.6,11200,7.28,105000000,0.149
92.8,11100,7.29,105000000,0.149
92.9,11000,7.31,104000000,0.149
93.1,11000,7.32,103000000,0.150
93.2,11000,7.33,103000000,0.150
93.4,10900,7.34,103000000,0.150
93.5,10800,7.36,102000000,0.150
93.7,10100,7.37,95400000,0.151
93.8,9620,7.38,90600000,0.151
94.0,9460,7.39,89000000,0.151
94.1,9330,7.41,87900000,0.151
94.3,9260,7.42,87200000,0.152
94.4,9230,7.43,86900000,0.152
94.6,9220,7.44,86800000,0.152
94.7,9200,7.45,86600000,0.152
94.9,9160,7.47,86200000,0.153
95.0,9120,7.48,85900000,0.153
95.2,9110,7.49,85800000,0.153
95.3,9120,7.50,85900000,0.153
95.5,9140,7.51,86100000,0.154
95.6,9170,7.53,86400000,0.154
95.8,9210,7.54,86700000,0.154
95.9,9260,7.55,87200000,0.154
96.1,9300,7.56,87600000,0.155
96.2,9350,7.58,88100000,0.155
96.4,9400,7.59,88500000,0.155
96.5,9460,7.60,89000000,0.155
96.7,9510,7.61,89600000,0.156
96.8,9570,7.62,90100000,0.156
97.0,9630,7.64,90700000,0.156
97.1,9690,7.65,91200000,0.156
97.3,9750,7.66,91800000,0.157
97.4,9810,7.67,92300000,0.157
97.6,9860,7.69,92900000,0.157
97.7,9920,7.70,93400000,0.157
97.9,9970,7.71,93900000,0.158
98.0,10000,7.72,94400000,0.158
98.2,10100,7.73,94900000,0.158
98.3,10100,7.75,95400000,0.158
98.5,10200,7.76,95800000,0.159
98.6,10200,7.77,96100000,0.159
98.8,10200,7.78,96400000,0.159
98.9,10300,7.80,96700000,0.159
99.1,10300,7.81,96800000,0.160
99.2,10200,7.82,96300000,0.160
99.4,10200,7.83,95700000,0.160
99.5,10100,7.84,95100000,0.160
99.7,10000,7.86,94500000,0.161
99.8,9980,7.87,94000000,0.161
100,9910,7.88,93300000,0.161
100,9810,7.89,92300000,0.161
100,9650,7.91,90900000,0.162
100,9500,7.92,89500000,0.162
101,9380,7.93,88300000,0.162
101,9280,7.94,87400000,0.162
101,9220,7.95,86800000,0.163
101,9190,7.97,86600000,0.163
101,9190,7.98,86500000,0.163
101,9200,7.99,86600000,0.163
101,9230,8.00,86900000,0.164
102,9250,8.02,87100000,0.164
102,9280,8.03,87400000,0.164
102,9310,8.04,87700000,0.164
102,9340,8.05,87900000,0.165
102,9350,8.06,88100000,0.165
102,9360,8.08,88200000,0.165
103,9380,8.09,88400000,0.165
103,9410,8.10,88600000,0.166
103,9440,8.11,88900000,0.166
103,9470,8.13,89100000,0.166
103,9500,8.14,89500000,0.166
103,9540,8.15,89800000,0.167
103,9570,8.16,90100000,0.167
104,9610,8.17,90500000,0.167
104,9640,8.19,90800000,0.167
104,9660,8.20,91000000,0.168
104,9680,8.21,91100000,0.168
104,9690,8.22,91300000,0.168
104,9710,8.24,91400000,0.168
104,9740,8.25,91700000,0.169
105,9770,8.26,92000000,0.169
105,9800,8.27,92300000,0.169
105,9830,8.28,92600000,0.169
105,9870,8.30,92900000,0.170
105,9910,8.31,93300000,0.170
105,9950,8.32,93600000,0.170
106,9990,8.33,94000000,0.170
106,10000,8.35,94400000,0.171
106,10100,8.36,94700000,0.171
106,10100,8.37,95100000,0.171
106,10100,8.38,95500000,0.171
106,10200,8.39,95900000,0.172
106,10200,8.41,96200000,0.172
107,10300,8.42,96600000,0.172
107,10300,8.43,96900000,0.172
107,10300,8.44,97400000,0.173
107,10400,8.45,97800000,0.173
107,10400,8.47,98200000,0.173
107,10500,8.48,98500000,0.173
107,10500,8.49,98900000,0.174
108,10500,8.50,99200000,0.174
108,10600,8.52,99500000,0.174
108,10600,8.53,99700000,0.174
108,10600,8.54,99800000,0.175
108,10600,8.55,100000000,0.175
108,10600,8.57,100000000,0.175
108,10700,8.58,100000000,0.175
109,10700,8.59,100000000,0.176
109,10700,8.60,100000000,0.176
109,10700,8.61,100000000,0.176
109,10100,8.63,94700000,0.176
109,9550,8.64,89900000,0.177
109,9410,8.65,88600000,0.177
110,9380,8.66,88300000,0.177
110,9390,8.68,88400000,0.177
110,9410,8.69,88600000,0.178
110,9440,8.70,88900000,0.178
110,9460,8.71,89100000,0.178
110,9480,8.72,89300000,0.178
110,9490,8.74,89400000,0.179
111,9500,8.75,89400000,0.179
111,9500,8.76,89500000,0.179
111,9500,8.77,89500000,0.179
111,9520,8.78,89600000,0.180
111,9540,8.80,89800000,0.180
111,9550,8.81,90000000,0.180
111,9580,8.82,90200000,0.180
112,9600,8.83,90400000,0.181
112,9630,8.85,90700000,0.181
112,9660,8.86,91000000,0.181
112,9690,8.87,91200000,0.181
112,9720,8.88,91500000,0.182
112,9750,8.89,91900000,0.182
113,9790,8.91,92100000,0.182
113,9820,8.92,92500000,0.182
113,9860,8.93,92800000,0.183
113,9890,8.94,93100000,0.183
113,9920,8.96,93500000,0.183
113,9960,8.97,93800000,0.183
113,9990,8.98,94100000,0.184
114,10000,8.99,94400000,0.184
114,10100,9.00,94700000,0.184
114,10100,9.02,94900000,0.184
114,10100,9.03,95200000,0.185
114,10100,9.04,95400000,0.185
114,10200,9.05,95700000,0.185
114,10200,9.07,95900000,0.185
115,10200,9.08,96100000,0.186
115,10200,9.09,96300000,0.186
115,10200,9.10,96400000,0.186
115,10300,9.11,96600000,0.186
115,10300,9.13,96800000,0.187
115,10300,9.14,96900000,0.187
116,10300,9.15,97000000,0.187
116,10300,9.16,97200000,0.187
116,10300,9.18,97300000,0.188
116,10300,9.19,97400000,0.188
116,10400,9.20,97500000,0.188
116,10400,9.21,97600000,0.188
116,10400,9.22,97700000,0.189
117,10400,9.24,97800000,0.189
117,10400,9.25,97900000,0.189
117,10400,9.26,98100000,0.189
117,10400,9.27,98200000,0.190
117,10400,9.29,98300000,0.190
117,10500,9.30,98400000,0.190
117,10500,9.31,98600000,0.190
118,10500,9.32,98700000,0.191
118,10500,9.33,98900000,0.191
118,10500,9.35,99000000,0.191
118,10500,9.36,99200000,0.191
118,10600,9.37,99400000,0.192
118,10600,9.38,99500000,0.192
119,10600,9.40,99700000,0.192
119,10600,9.41,99900000,0.192
119,10600,9.42,100000000,0.193
119,10700,9.43,100000000,0.193
119,10700,9.44,101000000,0.193
119,10700,9.46,101000000,0.193
119,10700,9.47,101000000,0.194
120,10700,9.48,101000000,0.194
120,10800,9.49,101000000,0.194
120,10800,9.51,102000000,0.194
120,10800,9.52,102000000,0.195
120,10800,9.53,102000000,0.195
120,10900,9.54,102000000,0.195
120,10900,9.55,102000000,0.195
121,10900,9.57,103000000,0.196
121,10900,9.58,103000000,0.196
121,11000,9.59,103000000,0.196
121,11000,9.60,103000000,0.196
121,11000,9.61,104000000,0.197
121,11000,9.63,104000000,0.197
122,11100,9.64,104000000,0.197
122,11100,9.65,104000000,0.197
122,11100,9.66,104000000,0.198
122,11100,9.68,105000000,0.198
122,11100,9.69,105000000,0.198
122,11100,9.70,105000000,0.198
122,11200,9.71,105000000,0.199
123,11200,9.73,105000000,0.199
123,11200,9.74,105000000,0.199
123,11200,9.75,106000000,0.199
123,11200,9.76,106000000,0.200
123,11200,9.77,106000000,0.200
123,11200,9.79,106000000,0.200
123,11300,9.80,106000000,0.200
124,11300,9.81,106000000,0.201
124,11300,9.82,106000000,0.201
124,11300,9.84,106000000,0.201
124,11300,9.85,106000000,0.201
124,11300,9.86,106000000,0.202
124,11300,9.87,106000000,0.202
125,11200,9.88,106000000,0.202
125,11200,9.90,106000000,0.202
125,11200,9.91,106000000,0.203
125,11200,9.92,106000000,0.203
125,11200,9.93,106000000,0.203
125,11200,9.94,106000000,0.203
125,11200,9.96,106000000,0.204
126,11200,9.97,106000000,0.204
126,11200,9.98,106000000,0.204
126,11200,9.99,106000000,0.204
126,11200,10.0,106000000,0.205
126,11200,10.0,106000000,0.205
126,11200,10.0,106000000,0.205
126,11200,10.0,106000000,0.205
127,11200,10.1,106000000,0.206
127,11200,10.1,106000000,0.206
127,11200,10.1,106000000,0.206
127,11200,10.1,106000000,0.206
127,11200,10.1,106000000,0.207
127,11300,10.1,106000000,0.207
128,11300,10.1,106000000,0.207
128,11300,10.1,106000000,0.207
128,11300,10.2,106000000,0.208
128,11300,10.2,106000000,0.208
128,11300,10.2,106000000,0.208
128,11300,10.2,107000000,0.208
128,11300,10.2,107000000,0.209
129,11300,10.2,107000000,0.209
129,11300,10.2,107000000,0.209
129,11300,10.2,107000000,0.209
129,11400,10.3,107000000,0.210
129,11400,10.3,107000000,0.210
129,11400,10.3,107000000,0.210
129,11400,10.3,107000000,0.210
130,11400,10.3,107000000,0.211
130,11400,10.3,107000000,0.211
130,11400,10.3,107000000,0.211
130,11400,10.3,107000000,0.211
130,11400,10.3,108000000,0.212
130,11400,10.4,108000000,0.212
131,11400,10.4,108000000,0.212
131,11400,10.4,108000000,0.212
131,11400,10.4,108000000,0.213
131,11400,10.4,108000000,0.213
131,11400,10.4,108000000,0.213
131,11400,10.4,108000000,0.213
131,11400,10.4,108000000,0.214
132,11400,10.5,107000000,0.214
132,11300,10.5,107000000,0.214
132,11300,10.5,106000000,0.214
132,11200,10.5,106000000,0.215
132,11200,10.5,105000000,0.215
132,11100,10.5,105000000,0.215
132,11100,10.5,104000000,0.215
133,11000,10.5,104000000,0.216
133,11000,10.6,103000000,0.216
133,10900,10.6,103000000,0.216
133,10900,10.6,103000000,0.216
133,10900,10.6,102000000,0.217
133,10900,10.6,102000000,0.217
134,10900,10.6,102000000,0.217
134,10800,10.6,102000000,0.217
134,10700,10.6,101000000,0.218
134,10500,10.7,98900000,0.218
134,10400,10.7,98300000,0.218
134,10400,10.7,98200000,0.218
134,10500,10.7,98500000,0.219
135,10500,10.7,98900000,0.219
135,10600,10.7,99400000,0.219
135,10600,10.7,99900000,0.219
135,10700,10.7,100000000,0.220
135,10700,10.8,101000000,0.220
135,10800,10.8,101000000,0.220
135,10800,10.8,102000000,0.220
136,10800,10.8,102000000,0.221
136,10900,10.8,102000000,0.221
136,10900,10.8,103000000,0.221
136,10900,10.8,103000000,0.221
136,11000,10.8,103000000,0.222
136,11000,10.8,103000000,0.222
136,11000,10.9,104000000,0.222
137,11000,10.9,104000000,0.222
137,11000,10.9,104000000,0.223
137,11100,10.9,104000000,0.223
137,11100,10.9,104000000,0.223
137,11100,10.9,104000000,0.223
137,11000,10.9,104000000,0.224
138,10900,10.9,102000000,0.224
138,10300,11.0,97400000,0.224
138,9860,11.0,92800000,0.224
138,9700,11.0,91400000,0.225
138,9660,11.0,91000000,0.225
138,9660,11.0,91000000,0.225
138,9690,11.0,91300000,0.225
139,9730,11.0,91600000,0.226
139,9770,11.0,92000000,0.226
139,9820,11.1,92400000,0.226
139,9860,11.1,92800000,0.226
139,9900,11.1,93300000,0.227
139,9950,11.1,93700000,0.227
139,10000,11.1,94100000,0.227
140,10000,11.1,94600000,0.227
140,10100,11.1,95000000,0.228
140,10100,11.1,95500000,0.228
140,10200,11.2,96000000,0.228
140,10200,11.2,96400000,0.228
140,10300,11.2,96900000,0.229
141,10300,11.2,97300000,0.229
141,10400,11.2,97700000,0.229
141,10400,11.2,98100000,0.229
141,10500,11.2,98500000,0.230
141,10500,11.2,98900000,0.230
141,10500,11.3,99200000,0.230
141,10600,11.3,99500000,0.230
142,10600,11.3,99900000,0.231
142,10600,11.3,100000000,0.231
142,10700,11.3,100000000,0.231
142,10700,11.3,101000000,0.231
142,10700,11.3,101000000,0.232
142,10800,11.3,101000000,0.232
142,10800,11.3,101000000,0.232
143,10800,11.4,102000000,0.232
143,10800,11.4,102000000,0.233
143,10800,11.4,102000000,0.233
143,10900,11.4,102000000,0.233
143,10900,11.4,103000000,0.233
143,10900,11.4,103000000,0.234
144,10900,11.4,103000000,0.234
144,11000,11.4,103000000,0.234
144,11000,11.5,103000000,0.234
144,11000,11.5,103000000,0.235
144,11000,11.5,104000000,0.235
144,11000,11.5,104000000,0.235
144,11000,11.5,104000000,0.235
145,11000,11.5,104000000,0.236
145,11000,11.5,104000000,0.236
145,11000,11.5,103000000,0.236
145,10900,11.6,103000000,0.236
145,10800,11.6,102000000,0.237
145,10700,11.6,101000000,0.237
145,10600,11.6,99900000,0.237
146,10500,11.6,99100000,0.237
146,10500,11.6,98600000,0.238
146,10400,11.6,98100000,0.238
146,10400,11.6,97800000,0.238
146,10400,11.7,97500000,0.238
146,10300,11.7,97200000,0.239
147,10300,11.7,96900000,0.239
147,10300,11.7,96700000,0.239
147,10200,11.7,96300000,0.239
147,10200,11.7,95900000,0.240
147,10100,11.7,95500000,0.240
147,10100,11.7,94800000,0.240
147,9970,11.8,93900000,0.240
148,9860,11.8,92800000,0.241
148,9810,11.8,92300000,0.241
148,9800,11.8,92200000,0.241
148,9810,11.8,92400000,0.241
148,9840,11.8,92600000,0.242
148,9880,11.8,93000000,0.242
148,9920,11.8,93400000,0.242
149,9970,11.8,93900000,0.242
149,10000,11.9,94400000,0.243
149,10100,11.9,94800000,0.243
149,10100,11.9,95300000,0.243
149,10200,11.9,95800000,0.243
149,10200,11.9,96300000,0.244
150,10300,11.9,96800000,0.244
150,10300,11.9,97200000,0.244
150,10400,11.9,97700000,0.244
150,10400,12.0,98100000,0.245
150,10500,12.0,98600000,0.245
150,10500,12.0,99000000,0.245
150,10600,12.0,99400000,0.245
151,10600,12.0,99800000,0.246
151,10600,12.0,100000000,0.246
151,10700,12.0,101000000,0.246
151,10700,12.0,101000000,0.246
151,10800,12.1,101000000,0.247
151,10800,12.1,102000000,0.247
151,10800,12.1,102000000,0.247
152,10900,12.1,102000000,0.247
152,10900,12.1,103000000,0.248
152,10900,12.1,103000000,0.248
152,10900,12.1,103000000,0.248
152,11000,12.1,103000000,0.248
152,11000,12.2,103000000,0.249
153,11000,12.2,103000000,0.249
153,11000,12.2,104000000,0.249
153,11000,12.2,104000000,0.249
153,11000,12.2,104000000,0.250
153,11000,12.2,103000000,0.250