File: data/InventWood/Superwood-ID22s-07302025.csv
Time (sec),Force (N),Position (mm),Stress (Pa),Strain (m/m)
25.4,52.2,0.0204,464000,0.000410
25.5,64.8,0.0354,576000,0.000712
25.7,78.3,0.0503,696000,0.00101
25.9,93.4,0.0651,830000,0.00131
26.1,110,0.0800,981000,0.00161
26.3,129,0.0949,1150000,0.00191
26.4,150,0.110,1330000,0.00221
26.6,173,0.125,1530000,0.00251
26.8,198,0.140,1760000,0.00281
27.0,225,0.155,2000000,0.00311
27.2,257,0.169,2280000,0.00341
27.3,290,0.184,2580000,0.00371
27.5,326,0.199,2890000,0.00401
27.7,365,0.214,3240000,0.00431
27.9,405,0.229,3600000,0.00461
28.1,446,0.244,3960000,0.00490
28.2,486,0.259,4320000,0.00520
28.4,532,0.274,4730000,0.00551
28.6,579,0.289,5140000,0.00581
28.8,626,0.304,5560000,0.00611
29.0,673,0.318,5980000,0.00640
29.1,721,0.333,6400000,0.00670
29.3,769,0.348,6830000,0.00700
29.5,816,0.363,7250000,0.00730
29.7,865,0.378,7680000,0.00760
29.9,914,0.393,8120000,0.00790
30.0,964,0.408,8570000,0.00820
30.2,1020,0.423,9040000,0.00850
30.4,1070,0.438,9530000,0.00880
30.6,1130,0.453,10100000,0.00911
30.8,1200,0.468,10600000,0.00940
30.9,1260,0.482,11200000,0.00970
31.1,1330,0.497,11800000,0.0100
31.3,1400,0.512,12400000,0.0103
31.5,1470,0.527,13000000,0.0106
31.7,1540,0.542,13700000,0.0109
31.8,1620,0.557,14400000,0.0112
32.0,1710,0.572,15200000,0.0115
32.2,1820,0.587,16200000,0.0118
32.4,1940,0.601,17200000,0.0121
32.6,2060,0.616,18300000,0.0124
32.7,2170,0.631,19300000,0.0127
32.9,2280,0.646,20200000,0.0130
33.1,2380,0.661,21200000,0.0133
33.3,2500,0.676,22200000,0.0136
33.5,2610,0.691,23200000,0.0139
33.6,2730,0.706,24200000,0.0142
33.8,2850,0.721,25300000,0.0145
34.0,2960,0.736,26300000,0.0148
34.2,3080,0.750,27300000,0.0151
34.4,3200,0.765,28400000,0.0154
34.5,3320,0.780,29500000,0.0157
34.7,3450,0.795,30700000,0.0160
34.9,3580,0.810,31800000,0.0163
35.1,3710,0.825,33000000,0.0166
35.2,3840,0.840,34100000,0.0169
35.4,3950,0.855,35100000,0.0172
35.6,4060,0.869,36000000,0.0175
35.8,4160,0.884,37000000,0.0178
36.0,4270,0.899,38000000,0.0181
36.1,4390,0.914,39000000,0.0184
36.3,4510,0.929,40000000,0.0187
36.5,4620,0.944,41100000,0.0190
36.7,4750,0.959,42200000,0.0193
36.9,4890,0.974,43400000,0.0196
37.0,5020,0.989,44600000,0.0199
37.2,5160,1.00,45800000,0.0202
37.4,5300,1.02,47100000,0.0205
37.6,5440,1.03,48300000,0.0208
37.8,5570,1.05,49500000,0.0211
37.9,5700,1.06,50700000,0.0214
38.1,5820,1.08,51700000,0.0217
38.3,5940,1.09,52800000,0.0220
38.5,6060,1.11,53800000,0.0223
38.7,6180,1.12,54900000,0.0226
38.8,6300,1.14,56000000,0.0229
39.0,6430,1.15,57100000,0.0232
39.2,6560,1.17,58300000,0.0235
39.4,6700,1.18,59500000,0.0238
39.6,6850,1.20,60800000,0.0241
39.7,7000,1.21,62200000,0.0244
39.9,7150,1.23,63500000,0.0247
40.1,7300,1.24,64800000,0.0250
40.3,7440,1.26,66100000,0.0253
40.5,7580,1.27,67300000,0.0256
40.6,7720,1.29,68600000,0.0259
40.8,7870,1.30,69900000,0.0262
41.0,8010,1.32,71200000,0.0265
41.2,8160,1.33,72500000,0.0268
41.4,8300,1.35,73800000,0.0271
41.5,8440,1.36,75000000,0.0274
41.7,8590,1.38,76300000,0.0277
41.9,8730,1.39,77500000,0.0280
42.1,8860,1.41,78700000,0.0283
42.3,9000,1.42,80000000,0.0286
42.4,9130,1.44,81100000,0.0289
42.6,9260,1.45,82300000,0.0292
42.8,9380,1.47,83300000,0.0295
43.0,9440,1.48,83900000,0.0298
43.2,9480,1.49,84200000,0.0301
43.3,9550,1.51,84900000,0.0304
43.5,9660,1.52,85800000,0.0307
43.7,9800,1.54,87100000,0.0310
43.9,9950,1.55,88400000,0.0313
44.1,10100,1.57,89700000,0.0316
44.2,10300,1.58,91100000,0.0319
44.4,10400,1.60,92500000,0.0322
44.6,10600,1.61,93900000,0.0325
44.8,10700,1.63,95400000,0.0328
45.0,10900,1.64,96800000,0.0331
45.1,11000,1.66,98100000,0.0334
45.3,11200,1.67,99500000,0.0337
45.5,11400,1.69,101000000,0.0340
45.7,11500,1.70,102000000,0.0343
45.8,11700,1.72,104000000,0.0346
46.0,11800,1.73,105000000,0.0349
46.2,12000,1.75,106000000,0.0352
46.4,12100,1.76,108000000,0.0355
46.6,12300,1.78,109000000,0.0358
46.7,12400,1.79,110000000,0.0361
46.9,12600,1.81,112000000,0.0364
47.1,12700,1.82,113000000,0.0367
47.3,12900,1.84,114000000,0.0370
47.5,13000,1.85,115000000,0.0373
47.6,13100,1.87,117000000,0.0376
47.8,13300,1.88,118000000,0.0379
48.0,13400,1.90,119000000,0.0382
48.2,13500,1.91,120000000,0.0385
48.4,13600,1.93,121000000,0.0387
48.5,13700,1.94,122000000,0.0391
48.7,13800,1.96,122000000,0.0394
48.9,13800,1.97,122000000,0.0397
49.1,13600,1.99,121000000,0.0400
49.3,10100,2.00,90100000,0.0403
49.4,10200,2.02,90700000,0.0406
49.6,10400,2.03,92100000,0.0409
49.8,10500,2.05,93600000,0.0412
50.0,10700,2.06,95200000,0.0415
50.2,10900,2.08,96600000,0.0418
50.3,11000,2.09,98000000,0.0420
50.5,11200,2.11,99300000,0.0423
50.7,11300,2.12,101000000,0.0427
50.9,11500,2.14,102000000,0.0429
51.1,11600,2.15,103000000,0.0432
51.2,11800,2.17,104000000,0.0435
51.4,11900,2.18,106000000,0.0438
51.6,12000,2.20,107000000,0.0441
51.8,12200,2.21,108000000,0.0444
52.0,12300,2.22,109000000,0.0447
52.1,12500,2.24,111000000,0.0450
52.3,12600,2.25,112000000,0.0453
52.5,12700,2.27,113000000,0.0457
52.7,12900,2.28,114000000,0.0460
52.9,13000,2.30,116000000,0.0462
53.0,13100,2.31,117000000,0.0465
53.2,13300,2.33,118000000,0.0468
53.4,13400,2.34,119000000,0.0471
53.6,13500,2.36,120000000,0.0474
53.8,13700,2.37,121000000,0.0477
53.9,13800,2.39,122000000,0.0480
54.1,13800,2.40,123000000,0.0483
54.3,13900,2.42,124000000,0.0486
54.5,14000,2.43,124000000,0.0489
54.7,14000,2.45,125000000,0.0492
54.8,14100,2.46,125000000,0.0495
55.0,14100,2.48,125000000,0.0498
55.2,14100,2.49,125000000,0.0501
55.4,14100,2.51,126000000,0.0504
55.6,14200,2.52,126000000,0.0507
55.7,14200,2.54,126000000,0.0510
55.9,14200,2.55,126000000,0.0513
56.1,14200,2.57,126000000,0.0516
56.3,14200,2.58,126000000,0.0519
56.5,14200,2.60,127000000,0.0522
56.6,14300,2.61,127000000,0.0525
56.8,14300,2.63,127000000,0.0528
57.0,14300,2.64,127000000,0.0531
57.2,14300,2.66,127000000,0.0534
57.3,14300,2.67,127000000,0.0537
57.5,14300,2.69,127000000,0.0540
57.7,14400,2.70,128000000,0.0543
57.9,14400,2.72,128000000,0.0546
58.1,14400,2.73,128000000,0.0549
58.2,14500,2.75,128000000,0.0552
58.4,14500,2.76,129000000,0.0555
58.6,14500,2.78,129000000,0.0558
58.8,14600,2.79,130000000,0.0561
59.0,14600,2.81,130000000,0.0564
59.1,14700,2.82,130000000,0.0567
59.3,14700,2.84,131000000,0.0570
59.5,14800,2.85,131000000,0.0573
59.7,14800,2.87,132000000,0.0576
59.9,14800,2.88,132000000,0.0579
60.0,14900,2.90,132000000,0.0582
60.2,14900,2.91,132000000,0.0585
60.4,14900,2.92,132000000,0.0588
60.6,14900,2.94,133000000,0.0591
60.8,14900,2.95,133000000,0.0594
60.9,15000,2.97,133000000,0.0597
61.1,15000,2.98,133000000,0.0600
61.3,15000,3.00,133000000,0.0603
61.5,15000,3.01,133000000,0.0606
61.7,15000,3.03,133000000,0.0609
61.8,15000,3.04,133000000,0.0612
62.0,15000,3.06,133000000,0.0615
62.2,15000,3.07,133000000,0.0618
62.4,14900,3.09,133000000,0.0621
62.6,14800,3.10,132000000,0.0624
62.7,14800,3.12,131000000,0.0627
62.9,14800,3.13,131000000,0.0630
63.1,14700,3.15,131000000,0.0633
63.3,14700,3.16,131000000,0.0636
63.5,14700,3.18,130000000,0.0639
63.6,14600,3.19,130000000,0.0642
63.8,14500,3.21,129000000,0.0645
64.0,14200,3.22,126000000,0.0648
64.2,12200,3.24,108000000,0.0651
64.4,11700,3.25,104000000,0.0654
64.5,11500,3.27,102000000,0.0657
64.7,11500,3.28,102000000,0.0660
64.9,11500,3.30,103000000,0.0663
65.1,11600,3.31,103000000,0.0666
65.3,11700,3.33,104000000,0.0669
65.4,11700,3.34,104000000,0.0672
65.6,11800,3.36,105000000,0.0675
65.8,11900,3.37,106000000,0.0678
66.0,12000,3.39,107000000,0.0681
66.2,12100,3.40,108000000,0.0684
66.3,12200,3.42,109000000,0.0687
66.5,12400,3.43,110000000,0.0690
66.7,12500,3.45,111000000,0.0693
66.9,12600,3.46,112000000,0.0696
67.1,12800,3.48,113000000,0.0699
67.2,12900,3.49,114000000,0.0702
67.4,13000,3.51,116000000,0.0705
67.6,13200,3.52,117000000,0.0708
67.8,13300,3.54,118000000,0.0711
67.9,13400,3.55,119000000,0.0714
68.1,13500,3.57,120000000,0.0717
68.3,13600,3.58,121000000,0.0720
68.5,13700,3.60,122000000,0.0723
68.7,13800,3.61,123000000,0.0726
68.8,13900,3.63,123000000,0.0729
69.0,13900,3.64,124000000,0.0732
69.2,14000,3.66,124000000,0.0735
69.4,13900,3.67,124000000,0.0738
69.6,13900,3.68,123000000,0.0741
69.7,13700,3.70,122000000,0.0744
69.9,13500,3.71,120000000,0.0747
70.1,13200,3.73,117000000,0.0750
70.3,13000,3.74,115000000,0.0753
70.5,12900,3.76,114000000,0.0756
70.6,12800,3.77,114000000,0.0759
70.8,12700,3.79,113000000,0.0762
71.0,12700,3.80,113000000,0.0765
71.2,12700,3.82,113000000,0.0768
71.4,12800,3.83,113000000,0.0771
71.5,12800,3.85,114000000,0.0774
71.7,12900,3.86,115000000,0.0777
71.9,13000,3.88,116000000,0.0780
72.1,13100,3.89,117000000,0.0783
72.3,13200,3.91,117000000,0.0786
72.4,13300,3.92,118000000,0.0789
72.6,13400,3.94,119000000,0.0792
72.8,13500,3.95,120000000,0.0795
73.0,13500,3.97,120000000,0.0798
73.2,13600,3.98,120000000,0.0801
73.3,13600,4.00,121000000,0.0804
73.5,13600,4.01,121000000,0.0807
73.7,13600,4.03,121000000,0.0810
73.9,13600,4.04,120000000,0.0813
74.1,13500,4.06,120000000,0.0816
74.2,13500,4.07,120000000,0.0819
74.4,13400,4.09,119000000,0.0822
74.6,13400,4.10,119000000,0.0825
74.8,13400,4.12,119000000,0.0828
75.0,13300,4.13,119000000,0.0831
75.1,13300,4.15,118000000,0.0834
75.3,13300,4.16,118000000,0.0837
75.5,13300,4.18,118000000,0.0840
75.7,13200,4.19,117000000,0.0843
75.9,13100,4.21,117000000,0.0846
76.0,13100,4.22,116000000,0.0849
76.2,13100,4.24,116000000,0.0852
76.4,13100,4.25,116000000,0.0855
76.6,13200,4.27,117000000,0.0858
76.8,13200,4.28,117000000,0.0861
76.9,13300,4.30,118000000,0.0864
77.1,13400,4.31,119000000,0.0867
77.3,13400,4.33,119000000,0.0870
77.5,13500,4.34,120000000,0.0873
77.7,13500,4.36,120000000,0.0876
77.8,13600,4.37,121000000,0.0879
78.0,13600,4.38,121000000,0.0882
78.2,13600,4.40,121000000,0.0885
78.4,13700,4.42,122000000,0.0888
78.5,13700,4.43,122000000,0.0891
78.7,13700,4.44,122000000,0.0894
78.9,13800,4.46,122000000,0.0897
79.1,13800,4.47,122000000,0.0900
79.3,13800,4.49,123000000,0.0903
79.4,13800,4.50,123000000,0.0906
79.6,13800,4.52,123000000,0.0909
79.8,13900,4.53,123000000,0.0912
80.0,13900,4.55,124000000,0.0915
80.2,14000,4.56,124000000,0.0918
80.3,14100,4.58,125000000,0.0921
80.5,14200,4.59,126000000,0.0924
80.7,14300,4.61,127000000,0.0927
80.9,14400,4.62,128000000,0.0930
81.1,14600,4.64,129000000,0.0933
81.2,14700,4.65,131000000,0.0936
81.4,14800,4.67,132000000,0.0939
81.6,14900,4.68,133000000,0.0942
81.8,15100,4.70,134000000,0.0945
82.0,15200,4.71,135000000,0.0948
82.1,15300,4.73,136000000,0.0951
82.3,15400,4.74,137000000,0.0954
82.5,15500,4.76,137000000,0.0957
82.7,15600,4.77,138000000,0.0960
82.9,15600,4.79,139000000,0.0963
83.0,15700,4.80,140000000,0.0966
83.2,15800,4.82,140000000,0.0969
83.4,15900,4.83,141000000,0.0972
83.6,15900,4.85,141000000,0.0975
83.8,16000,4.86,142000000,0.0978
83.9,16000,4.88,142000000,0.0981
84.1,16100,4.89,143000000,0.0984
84.3,16100,4.91,143000000,0.0987
84.5,16100,4.92,143000000,0.0990
84.7,16100,4.94,143000000,0.0993
84.8,16100,4.95,143000000,0.0996
85.0,16100,4.97,143000000,0.0999
85.2,16100,4.98,143000000,0.100
85.4,16100,5.00,143000000,0.100
85.6,16100,5.01,143000000,0.101
85.7,16100,5.03,143000000,0.101
85.9,16100,5.04,143000000,0.101
86.1,16200,5.06,143000000,0.102
86.3,16100,5.07,143000000,0.102
86.5,16100,5.09,143000000,0.102
86.6,16100,5.10,143000000,0.103
86.8,16100,5.11,143000000,0.103
87.0,16100,5.13,143000000,0.103
87.2,16100,5.14,143000000,0.103
87.4,16000,5.16,142000000,0.104
87.5,15900,5.17,141000000,0.104
87.7,15800,5.19,140000000,0.104
87.9,15700,5.20,139000000,0.105
88.1,15600,5.22,138000000,0.105
88.3,15500,5.23,138000000,0.105
88.4,15400,5.25,137000000,0.106
88.6,15300,5.26,136000000,0.106
88.8,15100,5.28,134000000,0.106
89.0,14900,5.29,133000000,0.106
89.1,14600,5.31,130000000,0.107
89.3,14000,5.32,124000000,0.107
89.5,13300,5.34,118000000,0.107
89.7,13100,5.35,116000000,0.108
89.9,12900,5.37,115000000,0.108
90.0,12900,5.38,115000000,0.108
90.2,12900,5.40,115000000,0.109
90.4,13000,5.41,116000000,0.109
90.6,13100,5.43,116000000,0.109
90.8,13200,5.44,117000000,0.109
90.9,13300,5.46,118000000,0.110
91.1,13400,5.47,119000000,0.110
91.3,13500,5.49,120000000,0.110
91.5,13600,5.50,121000000,0.111
91.7,13700,5.52,122000000,0.111
91.8,13800,5.53,122000000,0.111
92.0,13900,5.55,123000000,0.112
92.2,13900,5.56,124000000,0.112
92.4,14000,5.58,124000000,0.112
92.6,14100,5.59,125000000,0.112
92.7,14200,5.61,126000000,0.113
92.9,14200,5.62,126000000,0.113
93.1,14300,5.64,127000000,0.113
93.3,14300,5.65,127000000,0.114
93.5,14300,5.67,127000000,0.114
93.6,8670,5.68,77000000,0.114
93.8,8720,5.70,77500000,0.115
94.0,8860,5.71,78700000,0.115
94.2,9000,5.73,80000000,0.115
94.4,9130,5.74,81100000,0.115
94.5,9240,5.76,82100000,0.116
94.7,9350,5.77,83000000,0.116
94.9,9440,5.79,83900000,0.116
95.1,9530,5.80,84700000,0.117
95.3,9620,5.82,85500000,0.117
95.4,9710,5.83,86300000,0.117
95.6,9790,5.84,87000000,0.118
95.8,9880,5.86,87800000,0.118
96.0,9970,5.87,88600000,0.118
96.2,10100,5.89,89400000,0.118
96.3,10200,5.90,90200000,0.119
96.5,10200,5.92,91000000,0.119
96.7,10300,5.93,91800000,0.119
96.9,10400,5.95,92500000,0.120
97.1,10500,5.96,93200000,0.120
97.2,10600,5.98,94000000,0.120
97.4,10700,5.99,94700000,0.121
97.6,10700,6.01,95400000,0.121
97.8,10800,6.02,96100000,0.121
98.0,10900,6.04,96800000,0.121
98.1,11000,6.05,97500000,0.122
98.3,11000,6.07,98000000,0.122
98.5,11100,6.08,98600000,0.122
98.7,11200,6.10,99100000,0.123
98.9,11200,6.11,99700000,0.123
99.0,11300,6.13,100000000,0.123
99.2,11300,6.14,101000000,0.124
99.4,11400,6.16,101000000,0.124
99.6,11400,6.17,102000000,0.124
99.7,11500,6.19,102000000,0.124
99.9,11500,6.20,103000000,0.125
100,11600,6.22,103000000,0.125
100,11600,6.23,103000000,0.125
100,11700,6.25,104000000,0.126
101,11700,6.26,104000000,0.126
101,11800,6.28,105000000,0.126
101,11800,6.29,105000000,0.127
101,11900,6.31,105000000,0.127
101,11900,6.32,106000000,0.127
102,11900,6.34,106000000,0.127
102,12000,6.35,106000000,0.128
102,12000,6.37,107000000,0.128
102,12100,6.38,107000000,0.128
102,12100,6.40,107000000,0.129
102,12100,6.41,108000000,0.129
103,12200,6.43,108000000,0.129
103,12200,6.44,109000000,0.130
103,12300,6.46,109000000,0.130
103,12300,6.47,109000000,0.130
103,12400,6.49,110000000,0.130
104,12400,6.50,110000000,0.131
104,12500,6.51,111000000,0.131
104,12600,6.53,112000000,0.131
104,12600,6.55,112000000,0.132
104,12700,6.56,113000000,0.132
104,12700,6.57,113000000,0.132
105,12800,6.59,114000000,0.133
105,12900,6.60,115000000,0.133
105,13000,6.62,115000000,0.133
105,13000,6.63,116000000,0.133
105,13100,6.65,116000000,0.134
105,13200,6.66,117000000,0.134
106,13300,6.68,118000000,0.134
106,13300,6.69,119000000,0.135
106,13400,6.71,119000000,0.135
106,13500,6.72,120000000,0.135
106,13600,6.74,121000000,0.136
107,13700,6.75,121000000,0.136
107,13800,6.77,122000000,0.136
107,13800,6.78,123000000,0.136
107,13900,6.80,124000000,0.137
107,14000,6.81,124000000,0.137
107,14100,6.83,125000000,0.137
108,14100,6.84,126000000,0.138
108,14200,6.86,126000000,0.138
108,14300,6.87,127000000,0.138
108,14300,6.89,127000000,0.139
108,14400,6.90,128000000,0.139
109,14400,6.92,128000000,0.139
109,14500,6.93,129000000,0.139
109,14500,6.95,129000000,0.140
109,14600,6.96,129000000,0.140
109,14600,6.98,130000000,0.140
109,14600,6.99,130000000,0.141
110,14700,7.01,130000000,0.141
110,14700,7.02,131000000,0.141
110,14800,7.04,131000000,0.142
110,14800,7.05,131000000,0.142
110,14800,7.07,132000000,0.142
111,14900,7.08,132000000,0.142
111,14900,7.10,133000000,0.143
111,15000,7.11,133000000,0.143
111,15000,7.13,133000000,0.143
111,15000,7.14,133000000,0.144
111,15000,7.16,133000000,0.144
112,15000,7.17,133000000,0.144
112,14900,7.19,132000000,0.145
112,14800,7.20,132000000,0.145
112,14800,7.22,131000000,0.145
112,14800,7.23,131000000,0.145
113,14800,7.24,131000000,0.146
113,14800,7.26,132000000,0.146
113,14900,7.27,132000000,0.146
113,14900,7.29,132000000,0.147
113,14900,7.30,133000000,0.147
113,15000,7.32,133000000,0.147
114,15100,7.33,134000000,0.148
114,15100,7.35,134000000,0.148
114,15100,7.36,135000000,0.148
114,15200,7.38,135000000,0.148
114,15200,7.39,135000000,0.149
114,15200,7.41,135000000,0.149
115,15300,7.42,136000000,0.149
115,15300,7.44,136000000,0.150
115,15300,7.45,136000000,0.150
115,15200,7.47,135000000,0.150
115,15100,7.48,135000000,0.151
116,15100,7.50,134000000,0.151
116,15100,7.51,134000000,0.151
116,15100,7.53,134000000,0.151
116,15200,7.54,135000000,0.152
116,15200,7.56,135000000,0.152
116,15200,7.57,135000000,0.152
117,15300,7.59,136000000,0.153
117,15300,7.60,136000000,0.153
117,15300,7.62,136000000,0.153
117,15300,7.63,136000000,0.154
117,15400,7.65,136000000,0.154
118,15400,7.66,137000000,0.154
118,15400,7.68,137000000,0.154
118,15400,7.69,137000000,0.155
118,15400,7.71,137000000,0.155
118,15400,7.72,137000000,0.155
118,15400,7.74,137000000,0.156
119,15400,7.75,137000000,0.156
119,15400,7.77,137000000,0.156
119,15400,7.78,137000000,0.156
119,15400,7.80,137000000,0.157
119,15400,7.81,137000000,0.157
120,15300,7.83,136000000,0.157
120,15200,7.84,135000000,0.158
120,14900,7.86,132000000,0.158
120,14600,7.87,129000000,0.158
120,14300,7.89,127000000,0.159
120,14300,7.90,127000000,0.159
121,14300,7.92,127000000,0.159
121,14300,7.93,127000000,0.160
121,14400,7.95,128000000,0.160
121,14400,7.96,128000000,0.160
121,14500,7.97,129000000,0.160
121,14500,7.99,129000000,0.161
122,14600,8.00,130000000,0.161
122,14600,8.02,130000000,0.161
122,14600,8.03,130000000,0.162
122,14600,8.05,130000000,0.162
122,14600,8.06,130000000,0.162
123,14600,8.08,130000000,0.162
123,14600,8.09,130000000,0.163
123,14500,8.11,129000000,0.163
123,14400,8.12,128000000,0.163
123,14200,8.14,127000000,0.164
123,13900,8.15,124000000,0.164
124,13500,8.17,120000000,0.164
124,13200,8.18,117000000,0.165
124,13000,8.20,116000000,0.165
124,12800,8.21,114000000,0.165
124,11900,8.23,106000000,0.165
125,11500,8.24,103000000,0.166
125,11500,8.26,102000000,0.166
125,11500,8.27,102000000,0.166
125,11500,8.29,102000000,0.167
125,11600,8.30,103000000,0.167
125,11700,8.32,104000000,0.167
126,11800,8.33,104000000,0.168
126,11800,8.35,105000000,0.168
126,11900,8.36,106000000,0.168
126,12000,8.38,107000000,0.168
126,12100,8.39,107000000,0.169
127,12200,8.41,108000000,0.169
127,12200,8.42,109000000,0.169
127,12300,8.44,109000000,0.170
127,12400,8.45,110000000,0.170
127,12400,8.47,111000000,0.170
127,12500,8.48,111000000,0.171
128,12600,8.50,112000000,0.171
128,12600,8.51,112000000,0.171
128,12700,8.53,113000000,0.171
128,12700,8.54,113000000,0.172
128,12800,8.56,113000000,0.172
128,12800,8.57,114000000,0.172
129,12900,8.59,114000000,0.173
129,12900,8.60,115000000,0.173
129,13000,8.62,115000000,0.173
129,13000,8.63,116000000,0.174
129,13100,8.65,116000000,0.174
130,13100,8.66,117000000,0.174
130,13200,8.68,117000000,0.174
130,13200,8.69,117000000,0.175
130,13200,8.71,118000000,0.175
130,13300,8.72,118000000,0.175
130,13300,8.73,118000000,0.176
131,13300,8.75,118000000,0.176
131,13300,8.76,118000000,0.176
131,13300,8.78,119000000,0.177
131,13400,8.79,119000000,0.177
131,13400,8.81,119000000,0.177
132,13400,8.82,119000000,0.177
132,13400,8.84,119000000,0.178
132,13500,8.85,120000000,0.178
132,13500,8.87,120000000,0.178
132,13500,8.88,120000000,0.179
132,13600,8.90,121000000,0.179
133,13600,8.91,121000000,0.179
133,13600,8.93,121000000,0.180
133,13700,8.94,121000000,0.180
133,13600,8.96,121000000,0.180
133,13600,8.97,121000000,0.180
134,13700,8.99,121000000,0.181
134,13700,9.00,122000000,0.181
134,13700,9.02,122000000,0.181
134,13800,9.03,122000000,0.182
134,13800,9.05,123000000,0.182
134,13900,9.06,123000000,0.182
135,13900,9.08,123000000,0.183
135,13800,9.09,123000000,0.183
135,13600,9.11,121000000,0.183
135,13200,9.12,117000000,0.183
135,13100,9.14,116000000,0.184
136,13000,9.15,116000000,0.184
136,13100,9.17,116000000,0.184
136,13200,9.18,117000000,0.185
136,13200,9.20,118000000,0.185
136,13300,9.21,118000000,0.185
136,13400,9.23,119000000,0.186
137,13500,9.24,120000000,0.186
137,13600,9.26,121000000,0.186
137,13700,9.27,122000000,0.186
137,13800,9.29,123000000,0.187
137,13900,9.30,123000000,0.187
137,14000,9.32,124000000,0.187
138,14000,9.33,125000000,0.188
138,14100,9.35,125000000,0.188
138,14200,9.36,126000000,0.188
138,14200,9.38,126000000,0.189
138,14300,9.39,127000000,0.189
139,14300,9.41,127000000,0.189
139,14400,9.42,128000000,0.189
139,14400,9.44,128000000,0.190
139,14500,9.45,129000000,0.190
139,14500,9.46,129000000,0.190
139,14500,9.48,129000000,0.191
140,14600,9.49,130000000,0.191
140,14600,9.51,130000000,0.191
140,14600,9.52,130000000,0.192
140,14600,9.54,130000000,0.192
140,14700,9.55,130000000,0.192
141,14700,9.57,130000000,0.192
141,14700,9.58,130000000,0.193
141,14700,9.60,130000000,0.193
141,14700,9.61,130000000,0.193
141,14700,9.63,130000000,0.194
141,14700,9.64,130000000,0.194
142,14700,9.66,130000000,0.194
142,14700,9.67,130000000,0.195
142,14700,9.69,130000000,0.195
142,14600,9.70,130000000,0.195
142,14600,9.72,130000000,0.195
143,14600,9.73,130000000,0.196
143,14600,9.75,129000000,0.196
143,14500,9.76,129000000,0.196
143,14500,9.78,128000000,0.197
143,14400,9.79,128000000,0.197
143,14300,9.81,127000000,0.197
144,14200,9.82,126000000,0.198
144,14000,9.84,125000000,0.198
144,13900,9.85,124000000,0.198
144,13800,9.87,123000000,0.198
144,13800,9.88,122000000,0.199
144,13700,9.90,122000000,0.199
145,13700,9.91,121000000,0.199
145,13600,9.93,121000000,0.200
145,13600,9.94,121000000,0.200
145,13600,9.96,121000000,0.200
145,13600,9.97,121000000,0.201
146,13600,9.99,121000000,0.201
146,13600,10.0,121000000,0.201
146,13600,10.0,121000000,0.201
146,13600,10.0,121000000,0.202
146,13600,10.0,121000000,0.202
146,13600,10.1,120000000,0.202
147,13500,10.1,120000000,0.203
147,13500,10.1,120000000,0.203
147,13500,10.1,120000000,0.203
147,13500,10.1,120000000,0.204
147,13400,10.1,119000000,0.204
148,13400,10.2,119000000,0.204
148,13300,10.2,118000000,0.204
148,13300,10.2,118000000,0.205
148,13200,10.2,118000000,0.205
148,13200,10.2,117000000,0.205
148,13200,10.2,117000000,0.206
149,13200,10.2,117000000,0.206
149,13200,10.3,117000000,0.206
149,13200,10.3,118000000,0.207
149,13200,10.3,118000000,0.207
149,13200,10.3,118000000,0.207
150,13300,10.3,118000000,0.207
150,13300,10.3,118000000,0.208
150,13300,10.3,118000000,0.208
150,13300,10.4,118000000,0.208
150,13400,10.4,119000000,0.209
150,13400,10.4,119000000,0.209
151,13400,10.4,119000000,0.209
151,13500,10.4,120000000,0.210
151,13500,10.4,120000000,0.210
151,13600,10.4,121000000,0.210
151,13600,10.5,121000000,0.210
151,13700,10.5,121000000,0.211
152,13700,10.5,122000000,0.211
152,13700,10.5,122000000,0.211
152,13800,10.5,122000000,0.212
152,13800,10.5,122000000,0.212
152,13800,10.6,123000000,0.212
153,13800,10.6,123000000,0.213
153,13900,10.6,123000000,0.213
153,13900,10.6,124000000,0.213
153,13900,10.6,124000000,0.213
153,14000,10.6,124000000,0.214
153,14000,10.6,124000000,0.214
154,14000,10.7,124000000,0.214
154,14000,10.7,125000000,0.215
154,14000,10.7,125000000,0.215
154,14000,10.7,125000000,0.215
154,14100,10.7,125000000,0.216
155,14100,10.7,125000000,0.216
155,14000,10.7,125000000,0.216
155,12500,10.8,111000000,0.216
155,11900,10.8,105000000,0.217
155,11700,10.8,104000000,0.217
155,11600,10.8,103000000,0.217
156,11000,10.8,97600000,0.218
156,10300,10.8,91100000,0.218
156,10100,10.9,89900000,0.218
156,10100,10.9,89500000,0.219
156,10100,10.9,89700000,0.219
157,10100,10.9,90100000,0.219
157,10200,10.9,90600000,0.219
157,10200,10.9,90900000,0.220
157,10300,10.9,91300000,0.220
157,10300,11.0,91700000,0.220
157,10400,11.0,92100000,0.221
158,10400,11.0,92600000,0.221
158,10500,11.0,93000000,0.221
158,10500,11.0,93600000,0.222
158,10600,11.0,94100000,0.222
158,10700,11.0,94700000,0.222
158,10700,11.1,95300000,0.222
159,10800,11.1,95900000,0.223
159,10900,11.1,96400000,0.223
159,10900,11.1,97000000,0.223
159,11000,11.1,97600000,0.224
159,11100,11.1,98300000,0.224
160,11100,11.1,98900000,0.224
160,11200,11.2,99400000,0.225
160,11300,11.2,100000000,0.225
160,11300,11.2,100000000,0.225
160,11400,11.2,101000000,0.225
160,11400,11.2,102000000,0.226
161,11500,11.2,102000000,0.226
161,11500,11.3,103000000,0.226
161,11600,11.3,103000000,0.227
161,11600,11.3,103000000,0.227
161,11700,11.3,104000000,0.227
162,11700,11.3,104000000,0.228
162,11800,11.3,105000000,0.228
162,11800,11.3,105000000,0.228
162,11800,11.4,105000000,0.228
162,11800,11.4,105000000,0.229
162,11800,11.4,105000000,0.229
163,11800,11.4,105000000,0.229
163,11800,11.4,105000000,0.230
163,11800,11.4,105000000,0.230
163,11900,11.4,105000000,0.230
163,11900,11.5,106000000,0.231
164,11900,11.5,106000000,0.231
164,11900,11.5,106000000,0.231
164,11900,11.5,106000000,0.231
164,11900,11.5,106000000,0.232
164,11900,11.5,106000000,0.232
164,11900,11.6,106000000,0.232
165,11900,11.6,106000000,0.233
165,12000,11.6,106000000,0.233
165,12000,11.6,106000000,0.233
165,12000,11.6,106000000,0.234
165,12000,11.6,106000000,0.234
166,12000,11.6,106000000,0.234
166,12000,11.7,106000000,0.234
166,11900,11.7,106000000,0.235
166,11800,11.7,105000000,0.235
166,11700,11.7,104000000,0.235
166,11600,11.7,103000000,0.236
167,11600,11.7,103000000,0.236
167,11600,11.7,103000000,0.236
167,11500,11.8,103000000,0.237
167,11500,11.8,103000000,0.237
167,11600,11.8,103000000,0.237
167,11600,11.8,103000000,0.237
168,11600,11.8,103000000,0.238
168,11600,11.8,103000000,0.238
168,11600,11.8,103000000,0.238
168,11600,11.9,103000000,0.239
168,11500,11.9,103000000,0.239
169,11500,11.9,103000000,0.239
169,11500,11.9,102000000,0.240
169,11500,11.9,102000000,0.240
169,11500,11.9,102000000,0.240
169,11500,12.0,102000000,0.240
169,11500,12.0,102000000,0.241
170,11500,12.0,102000000,0.241
170,11500,12.0,102000000,0.241
170,11500,12.0,102000000,0.242
170,11400,12.0,102000000,0.242
170,11400,12.0,101000000,0.242
171,11300,12.1,101000000,0.243
171,11200,12.1,99900000,0.243
171,11200,12.1,99400000,0.243
171,11100,12.1,98900000,0.243
171,11100,12.1,98500000,0.244
171,11100,12.1,98200000,0.244
172,11000,12.1,98000000,0.244
172,11000,12.2,97800000,0.245
172,11000,12.2,97800000,0.245
172,11000,12.2,97800000,0.245
172,11000,12.2,97800000,0.246
173,11000,12.2,97900000,0.246
173,11000,12.2,98000000,0.246
173,11000,12.3,98100000,0.246
173,11000,12.3,98200000,0.247
173,11100,12.3,98300000,0.247
173,11100,12.3,98500000,0.247
174,11100,12.3,98600000,0.248
174,11100,12.3,98700000,0.248
174,11100,12.3,98900000,0.248
174,11100,12.4,99000000,0.249
174,11200,12.4,99200000,0.249
174,11200,12.4,99300000,0.249
175,11200,12.4,99400000,0.249
175,11200,12.4,99500000,0.250
175,11200,12.4,99600000,0.250
175,11200,12.4,99800000,0.250
175,11200,12.5,99900000,0.251
176,11300,12.5,100000000,0.251
176,11300,12.5,100000000,0.251
176,11300,12.5,100000000,0.251
176,11300,12.5,100000000,0.252
176,11300,12.5,100000000,0.252
176,11300,12.5,100000000,0.252
177,11300,12.6,100000000,0.253
177,11300,12.6,100000000,0.253
177,11300,12.6,100000000,0.253
177,11300,12.6,101000000,0.254
177,11300,12.6,101000000,0.254
178,11300,12.6,101000000,0.254
178,11300,12.7,101000000,0.254
178,11300,12.7,101000000,0.255
178,11300,12.7,101000000,0.255
178,11300,12.7,101000000,0.255
178,11300,12.7,101000000,0.256
179,11300,12.7,101000000,0.256
179,11300,12.7,101000000,0.256
179,11300,12.8,101000000,0.257
179,11300,12.8,101000000,0.257
179,11400,12.8,101000000,0.257
180,11300,12.8,101000000,0.257
180,11400,12.8,101000000,0.258
180,11400,12.8,101000000,0.258
180,11400,12.8,101000000,0.258
180,11400,12.9,101000000,0.259
180,11400,12.9,101000000,0.259
181,11400,12.9,101000000,0.259
181,11400,12.9,101000000,0.260
181,11400,12.9,101000000,0.260
181,11400,12.9,101000000,0.260
181,11400,13.0,102000000,0.260
181,11400,13.0,102000000,0.261
182,11400,13.0,102000000,0.261
182,11400,13.0,102000000,0.261
182,11500,13.0,102000000,0.262
182,11500,13.0,102000000,0.262
182,11500,13.0,102000000,0.262
183,11500,13.1,102000000,0.263
183,11500,13.1,102000000,0.263
183,11500,13.1,102000000,0.263
183,11500,13.1,102000000,0.263
183,11600,13.1,103000000,0.264
183,11600,13.1,103000000,0.264
184,11600,13.1,103000000,0.264
184,11600,13.2,103000000,0.265
184,11700,13.2,104000000,0.265
184,11700,13.2,104000000,0.265
184,11700,13.2,104000000,0.266
185,11700,13.2,104000000,0.266
185,11800,13.2,105000000,0.266
185,11800,13.2,105000000,0.266
185,11800,13.3,105000000,0.267
185,11900,13.3,105000000,0.267
185,11900,13.3,106000000,0.267
186,11900,13.3,106000000,0.268
186,12000,13.3,106000000,0.268
186,12000,13.3,106000000,0.268
186,12000,13.4,107000000,0.269
186,12000,13.4,107000000,0.269
187,12100,13.4,107000000,0.269
187,12100,13.4,108000000,0.269
187,12100,13.4,108000000,0.270
187,12200,13.4,108000000,0.270
187,12200,13.4,108000000,0.270
187,12200,13.5,109000000,0.271
188,12300,13.5,109000000,0.271
188,12300,13.5,109000000,0.271
188,12300,13.5,110000000,0.272
188,12400,13.5,110000000,0.272
188,12400,13.5,110000000,0.272
189,12500,13.5,111000000,0.272
189,12500,13.6,111000000,0.273
189,12500,13.6,111000000,0.273
189,12600,13.6,112000000,0.273
189,12600,13.6,112000000,0.274
189,12700,13.6,112000000,0.274
190,12700,13.6,113000000,0.274
190,12700,13.7,113000000,0.275
190,12800,13.7,113000000,0.275
190,12800,13.7,114000000,0.275
190,12800,13.7,114000000,0.275
190,12900,13.7,114000000,0.276
191,12900,13.7,115000000,0.276
191,12900,13.7,115000000,0.276
191,13000,13.8,115000000,0.277
191,13000,13.8,116000000,0.277
191,13000,13.8,116000000,0.277
192,13100,13.8,116000000,0.278
192,13100,13.8,116000000,0.278
192,13100,13.8,117000000,0.278
192,13200,13.8,117000000,0.278
192,13200,13.9,117000000,0.279
192,13200,13.9,117000000,0.279
193,13200,13.9,118000000,0.279
193,13300,13.9,118000000,0.280
193,13300,13.9,118000000,0.280
193,13300,13.9,119000000,0.280
193,13400,13.9,119000000,0.281
194,13400,14.0,119000000,0.281
194,13400,14.0,119000000,0.281
194,13500,14.0,120000000,0.281
194,13500,14.0,120000000,0.282
194,13500,14.0,120000000,0.282
194,13600,14.0,121000000,0.282
195,13600,14.1,121000000,0.283
195,13700,14.1,121000000,0.283
195,13700,14.1,122000000,0.283
195,13700,14.1,122000000,0.284
195,13800,14.1,123000000,0.284
196,13800,14.1,123000000,0.284
196,13900,14.1,123000000,0.284
196,13900,14.2,124000000,0.285
196,14000,14.2,124000000,0.285
196,14100,14.2,125000000,0.285
196,14100,14.2,125000000,0.286
197,14200,14.2,126000000,0.286
197,14200,14.2,126000000,0.286
197,14300,14.2,127000000,0.287
197,14300,14.3,127000000,0.287
197,14400,14.3,128000000,0.287
197,14500,14.3,128000000,0.287
198,14500,14.3,129000000,0.288
198,14600,14.3,130000000,0.288
198,14700,14.3,130000000,0.288
198,14700,14.4,131000000,0.289
198,14800,14.4,132000000,0.289
199,14900,14.4,132000000,0.289
199,14900,14.4,133000000,0.290
199,15000,14.4,133000000,0.290
199,15100,14.4,134000000,0.290
199,15200,14.4,135000000,0.290
199,15300,14.5,136000000,0.291
200,15300,14.5,136000000,0.291
200,15400,14.5,137000000,0.291
200,15500,14.5,138000000,0.292
200,15600,14.5,139000000,0.292
200,15700,14.5,139000000,0.292
201,15800,14.5,140000000,0.293
201,15900,14.6,141000000,0.293
201,15900,14.6,142000000,0.293
201,16000,14.6,143000000,0.293
201,16100,14.6,143000000,0.294
201,16200,14.6,144000000,0.294
202,16300,14.6,145000000,0.294
202,16400,14.6,146000000,0.295
202,16500,14.7,147000000,0.295
202,16600,14.7,147000000,0.295
202,16700,14.7,148000000,0.296
203,16800,14.7,149000000,0.296
203,16900,14.7,150000000,0.296
203,17000,14.7,151000000,0.296
203,17100,14.8,152000000,0.297
203,17100,14.8,152000000,0.297
203,17200,14.8,153000000,0.297
204,17300,14.8,154000000,0.298
204,17400,14.8,155000000,0.298
204,17500,14.8,156000000,0.298
204,17600,14.8,157000000,0.299
204,17700,14.9,157000000,0.299
204,17800,14.9,158000000,0.299
205,17900,14.9,159000000,0.299
205,18100,14.9,161000000,0.300