File: data/InventWood/Superwood-ID9-23 Jul, 2025.csv
Time (sec),Force (N),Position (mm),Stress (Pa),Strain (%)
3.60,40.4,0.0283,318000,0.0281
3.64,42.9,0.0353,338000,0.0351
3.68,45.3,0.0422,357000,0.0419
3.72,48.4,0.0491,381000,0.0488
3.76,50.8,0.0559,400000,0.0555
3.80,53.6,0.0628,422000,0.0624
3.84,56.1,0.0696,442000,0.0691
3.89,58.6,0.0765,462000,0.0760
3.93,60.9,0.0835,479000,0.0830
3.97,63.7,0.0902,501000,0.0896
4.01,66.7,0.0972,525000,0.0966
4.05,69.0,0.104,543000,0.103
4.09,72.0,0.111,567000,0.110
4.13,74.6,0.118,587000,0.117
4.17,77.8,0.125,612000,0.124
4.21,80.9,0.132,637000,0.131
4.25,84.0,0.138,661000,0.137
4.30,86.4,0.145,680000,0.144
4.34,89.3,0.152,703000,0.151
4.38,92.8,0.159,730000,0.158
4.42,96.2,0.166,757000,0.165
4.46,99.3,0.173,782000,0.172
4.50,102,0.180,800000,0.179
4.54,105,0.187,824000,0.186
4.58,107,0.193,843000,0.192
4.62,110,0.200,867000,0.199
4.66,113,0.207,890000,0.206
4.71,116,0.214,914000,0.213
4.75,120,0.221,942000,0.219
4.79,125,0.228,987000,0.226
4.83,134,0.235,1050000,0.233
4.87,143,0.241,1130000,0.240
4.91,153,0.248,1210000,0.247
4.95,163,0.255,1280000,0.254
4.99,173,0.262,1370000,0.260
5.03,183,0.269,1440000,0.267
5.07,194,0.276,1520000,0.274
5.12,203,0.283,1600000,0.281
5.16,213,0.290,1680000,0.288
5.20,225,0.297,1770000,0.295
5.24,243,0.304,1910000,0.302
5.28,261,0.311,2050000,0.308
5.32,279,0.317,2190000,0.315
5.36,294,0.324,2320000,0.322
5.40,311,0.331,2440000,0.329
5.44,327,0.338,2570000,0.336
5.48,350,0.345,2750000,0.343
5.53,387,0.352,3050000,0.350
5.57,424,0.359,3340000,0.356
5.61,461,0.366,3630000,0.363
5.65,499,0.372,3930000,0.370
5.69,544,0.379,4280000,0.377
5.73,589,0.386,4630000,0.384
5.77,640,0.393,5040000,0.390
5.81,692,0.400,5440000,0.397
5.85,744,0.407,5860000,0.404
5.89,797,0.414,6280000,0.411
5.94,852,0.420,6710000,0.418
5.98,909,0.427,7150000,0.425
6.02,965,0.434,7600000,0.431
6.06,1020,0.441,8070000,0.438
6.10,1080,0.448,8510000,0.445
6.14,1140,0.455,9000000,0.452
6.18,1200,0.462,9480000,0.459
6.22,1270,0.469,9990000,0.466
6.26,1330,0.476,10500000,0.472
6.30,1400,0.482,11000000,0.479
6.35,1460,0.489,11500000,0.486
6.39,1530,0.496,12000000,0.493
6.43,1600,0.503,12600000,0.500
6.47,1660,0.510,13100000,0.506
6.51,1740,0.517,13700000,0.513
6.55,1800,0.524,14200000,0.520
6.59,1880,0.531,14800000,0.527
6.63,1950,0.538,15300000,0.534
6.67,2020,0.544,15900000,0.541
6.71,2100,0.551,16500000,0.548
6.76,2170,0.558,17100000,0.554
6.80,2250,0.565,17700000,0.561
6.84,2320,0.572,18300000,0.568
6.88,2400,0.579,18900000,0.575
6.92,2480,0.586,19500000,0.582
6.96,2560,0.593,20100000,0.589
7.00,2640,0.600,20800000,0.596
7.04,2720,0.607,21400000,0.603
7.08,2800,0.613,22100000,0.609
7.12,2890,0.620,22700000,0.616
7.17,2970,0.627,23400000,0.623
7.21,3050,0.634,24000000,0.630
7.25,3140,0.641,24700000,0.636
7.29,3230,0.647,25400000,0.643
7.33,3310,0.655,26100000,0.650
7.37,3400,0.661,26700000,0.657
7.41,3490,0.668,27500000,0.664
7.45,3570,0.675,28100000,0.671
7.49,3670,0.682,28900000,0.677
7.53,3750,0.689,29600000,0.684
7.58,3850,0.696,30300000,0.691
7.62,3940,0.703,31000000,0.698
7.66,4030,0.709,31700000,0.705
7.70,4130,0.716,32500000,0.712
7.74,4220,0.723,33200000,0.718
7.78,4320,0.730,34000000,0.725
7.82,4420,0.737,34800000,0.732
7.86,4520,0.744,35600000,0.739
7.90,4620,0.750,36300000,0.745
7.94,4720,0.757,37200000,0.752
7.99,4820,0.765,38000000,0.759
8.03,4930,0.771,38800000,0.766
8.07,5030,0.778,39600000,0.773
8.11,5140,0.785,40400000,0.780
8.15,5240,0.792,41300000,0.787
8.19,5350,0.799,42100000,0.794
8.23,5460,0.806,43000000,0.801
8.27,5560,0.813,43800000,0.807
8.31,5670,0.820,44600000,0.814
8.35,5770,0.827,45400000,0.821
8.40,5880,0.834,46300000,0.828
8.44,5990,0.841,47100000,0.835
8.48,6100,0.847,48000000,0.842
8.52,6210,0.854,48900000,0.848
8.56,6320,0.861,49700000,0.855
8.60,6430,0.868,50600000,0.862
8.64,6540,0.875,51500000,0.869
8.68,6650,0.882,52400000,0.876
8.72,6760,0.888,53200000,0.882
8.76,6880,0.895,54100000,0.889
8.81,6980,0.902,55000000,0.896
8.85,7100,0.909,55900000,0.903
8.89,7210,0.916,56700000,0.910
8.93,7320,0.923,57600000,0.917
8.97,7430,0.930,58500000,0.924
9.01,7540,0.936,59300000,0.930
9.05,7650,0.943,60200000,0.937
9.09,7760,0.950,61100000,0.944
9.13,7880,0.957,62000000,0.951
9.17,7980,0.964,62900000,0.957
9.22,8100,0.971,63800000,0.964
9.26,8210,0.978,64600000,0.971
9.30,8320,0.985,65500000,0.978
9.34,8430,0.992,66400000,0.985
9.38,8540,0.999,67200000,0.992
9.42,8650,1.01,68100000,0.999
9.46,8760,1.01,68900000,1.01
9.50,8870,1.02,69800000,1.01
9.54,8970,1.03,70600000,1.02
9.58,9080,1.03,71500000,1.03
9.63,9190,1.04,72300000,1.03
9.67,9300,1.05,73200000,1.04
9.71,9400,1.05,74000000,1.05
9.75,9500,1.06,74800000,1.05
9.79,9610,1.07,75600000,1.06
9.83,9710,1.07,76400000,1.07
9.87,9810,1.08,77200000,1.07
9.91,9910,1.09,78000000,1.08
9.95,10000,1.09,78800000,1.09
9.99,10100,1.10,79600000,1.09
10.0,10200,1.11,80300000,1.10
10.1,10300,1.12,81000000,1.11
10.1,10400,1.12,81800000,1.12
10.2,10500,1.13,82400000,1.12
10.2,10600,1.14,83200000,1.13
10.2,10700,1.14,83900000,1.14
10.3,10700,1.15,84600000,1.14
10.3,10800,1.16,85300000,1.15
10.4,10900,1.16,85900000,1.16
10.4,11000,1.17,86600000,1.16
10.4,11100,1.18,87200000,1.17
10.5,11200,1.18,87900000,1.18
10.5,11200,1.19,88400000,1.18
10.6,11300,1.20,89000000,1.19
10.6,11400,1.20,89600000,1.20
10.7,11400,1.21,90100000,1.20
10.7,11500,1.22,90600000,1.21
10.7,11500,1.23,90900000,1.22
10.8,11600,1.23,91000000,1.22
10.8,11500,1.24,90400000,1.23
10.9,11300,1.25,89100000,1.24
10.9,11100,1.25,87300000,1.24
10.9,11000,1.26,86600000,1.25
11.0,11000,1.27,86700000,1.26
11.0,11100,1.27,87100000,1.27
11.1,11100,1.28,87700000,1.27
11.1,11200,1.29,88200000,1.28
11.1,11300,1.29,88900000,1.29
11.2,11400,1.30,89500000,1.29
11.2,11500,1.31,90100000,1.30
11.3,11500,1.32,90800000,1.31
11.3,11600,1.32,91500000,1.31
11.3,11700,1.33,92200000,1.32
11.4,11800,1.34,92900000,1.33
11.4,11900,1.34,93500000,1.33
11.5,12000,1.35,94300000,1.34
11.5,12100,1.36,95000000,1.35
11.6,12200,1.36,95700000,1.35
11.6,12300,1.37,96500000,1.36
11.6,12400,1.38,97300000,1.37
11.7,12500,1.38,98000000,1.38
11.7,12500,1.39,98800000,1.38
11.8,12600,1.40,99600000,1.39
11.8,12700,1.41,100000000,1.40
11.8,12800,1.41,101000000,1.40
11.9,12900,1.42,102000000,1.41
11.9,13000,1.43,102000000,1.42
12.0,13100,1.43,103000000,1.42
12.0,13200,1.44,104000000,1.43
12.0,13300,1.45,105000000,1.44
12.1,13400,1.45,105000000,1.44
12.1,13500,1.46,106000000,1.45
12.2,13600,1.47,107000000,1.46
12.2,13700,1.47,107000000,1.46
12.2,13700,1.48,108000000,1.47
12.3,13800,1.49,109000000,1.48
12.3,13900,1.49,110000000,1.48
12.4,14000,1.50,110000000,1.49
12.4,14100,1.51,111000000,1.50
12.5,14200,1.51,112000000,1.50
12.5,14300,1.52,112000000,1.51
12.5,14400,1.53,113000000,1.52
12.6,14500,1.54,114000000,1.53
12.6,14600,1.54,115000000,1.53
12.7,14700,1.55,115000000,1.54
12.7,14700,1.56,116000000,1.55
12.7,14800,1.56,117000000,1.55
12.8,14900,1.57,117000000,1.56
12.8,15000,1.58,118000000,1.57
12.9,15100,1.58,119000000,1.57
12.9,15200,1.59,120000000,1.58
12.9,15300,1.60,120000000,1.59
13.0,15400,1.60,121000000,1.59
13.0,15500,1.61,122000000,1.60
13.1,15500,1.62,122000000,1.61
13.1,15600,1.62,123000000,1.61
13.2,15700,1.63,124000000,1.62
13.2,15800,1.64,124000000,1.63
13.2,15900,1.65,125000000,1.63
13.3,15900,1.65,126000000,1.64
13.3,16000,1.66,126000000,1.65
13.4,16100,1.67,127000000,1.66
13.4,16200,1.67,127000000,1.66
13.4,16200,1.68,128000000,1.67
13.5,16300,1.69,128000000,1.68
13.5,16400,1.69,129000000,1.68
13.6,16400,1.70,129000000,1.69
13.6,16500,1.71,130000000,1.70
13.6,16600,1.71,130000000,1.70
13.7,16600,1.72,131000000,1.71
13.7,16700,1.73,131000000,1.72
13.8,16700,1.73,132000000,1.72
13.8,16800,1.74,132000000,1.73
13.8,16800,1.75,132000000,1.74
13.9,16900,1.76,133000000,1.74
13.9,16900,1.76,133000000,1.75
14.0,16900,1.77,133000000,1.76
14.0,17000,1.78,134000000,1.76
14.1,17000,1.78,134000000,1.77
14.1,17000,1.79,134000000,1.78
14.1,17000,1.80,134000000,1.79
14.2,17100,1.80,134000000,1.79
14.2,17100,1.81,135000000,1.80
14.3,17100,1.82,135000000,1.81
14.3,17200,1.82,135000000,1.81
14.3,17200,1.83,135000000,1.82
14.4,17200,1.84,135000000,1.83
14.4,17200,1.85,136000000,1.83
14.5,17300,1.85,136000000,1.84
14.5,17300,1.86,136000000,1.85
14.5,17300,1.87,136000000,1.85
14.6,17300,1.87,137000000,1.86
14.6,17400,1.88,137000000,1.87
14.7,17400,1.89,137000000,1.87
14.7,17400,1.89,137000000,1.88
14.8,17400,1.90,137000000,1.89
14.8,17500,1.91,137000000,1.89
14.8,17500,1.91,138000000,1.90
14.9,17500,1.92,138000000,1.91
14.9,17500,1.93,138000000,1.92
15.0,17500,1.93,138000000,1.92
15.0,17500,1.94,138000000,1.93
15.0,17500,1.95,138000000,1.94
15.1,17600,1.96,138000000,1.94
15.1,17600,1.96,138000000,1.95
15.2,17600,1.97,138000000,1.96
15.2,17600,1.98,138000000,1.96
15.2,17600,1.98,138000000,1.97
15.3,17600,1.99,138000000,1.98
15.3,17600,2.00,138000000,1.98
15.4,17600,2.00,138000000,1.99
15.4,17600,2.01,139000000,2.00
15.4,17600,2.02,139000000,2.00
15.5,17600,2.02,139000000,2.01
15.5,17600,2.03,139000000,2.02
15.6,17600,2.04,139000000,2.02
15.6,17600,2.05,138000000,2.03
15.7,17600,2.05,138000000,2.04
15.7,17600,2.06,138000000,2.05
15.7,17600,2.07,138000000,2.05
15.8,17600,2.07,138000000,2.06
15.8,17600,2.08,138000000,2.07
15.9,17600,2.09,138000000,2.07
15.9,17600,2.09,138000000,2.08
15.9,17600,2.10,138000000,2.09
16.0,17600,2.11,138000000,2.09
16.0,17600,2.11,138000000,2.10
16.1,17600,2.12,138000000,2.11
16.1,17600,2.13,138000000,2.11
16.1,17600,2.13,138000000,2.12
16.2,17600,2.14,138000000,2.13
16.2,17600,2.15,138000000,2.13
16.3,17600,2.16,138000000,2.14
16.3,17600,2.16,138000000,2.15
16.3,17600,2.17,138000000,2.15
16.4,17600,2.18,138000000,2.16
16.4,17600,2.18,138000000,2.17
16.5,17500,2.19,138000000,2.18
16.5,17500,2.20,138000000,2.18
16.6,17500,2.20,138000000,2.19
16.6,17500,2.21,138000000,2.20
16.6,17500,2.22,138000000,2.20
16.7,17500,2.22,138000000,2.21
16.7,17500,2.23,138000000,2.22
16.8,17500,2.24,137000000,2.22
16.8,17400,2.24,137000000,2.23
16.8,17400,2.25,137000000,2.24
16.9,17400,2.26,137000000,2.24
16.9,17400,2.27,137000000,2.25
17.0,17400,2.27,137000000,2.26
17.0,17300,2.28,137000000,2.26
17.0,17300,2.29,136000000,2.27
17.1,17300,2.29,136000000,2.28
17.1,17300,2.30,136000000,2.28
17.2,17200,2.31,136000000,2.29
17.2,17200,2.31,135000000,2.30
17.3,17200,2.32,135000000,2.31
17.3,17100,2.33,135000000,2.31
17.3,17100,2.33,134000000,2.32
17.4,17000,2.34,134000000,2.33
17.4,16900,2.35,133000000,2.33
17.5,16800,2.36,132000000,2.34
17.5,15300,2.37,120000000,2.35
17.5,5990,2.38,47200000,2.36
17.6,6030,2.38,47400000,2.36
17.6,6080,2.39,47900000,2.37
17.7,6150,2.39,48400000,2.38
17.7,6200,2.40,48800000,2.38
17.7,6260,2.41,49300000,2.39
17.8,6320,2.41,49800000,2.40
17.8,6380,2.42,50300000,2.40
17.9,6440,2.43,50700000,2.41
17.9,6500,2.43,51100000,2.42
17.9,6550,2.44,51600000,2.42
18.0,6610,2.45,52000000,2.43
18.0,6660,2.45,52400000,2.44
18.1,6710,2.46,52800000,2.44
18.1,6750,2.47,53100000,2.45
18.2,6790,2.47,53500000,2.46
18.2,6840,2.48,53800000,2.46
18.2,6880,2.49,54100000,2.47
18.3,6920,2.49,54500000,2.48
18.3,6950,2.50,54700000,2.48
18.4,6990,2.51,55000000,2.49
18.4,7020,2.51,55300000,2.50
18.4,7060,2.52,55600000,2.50
18.5,7090,2.53,55800000,2.51
18.5,7120,2.53,56000000,2.52
18.6,7150,2.54,56300000,2.52
18.6,7180,2.55,56500000,2.53
18.6,7210,2.55,56700000,2.54
18.7,7230,2.56,56900000,2.54
18.7,7260,2.57,57200000,2.55
18.8,7290,2.58,57400000,2.56
18.8,7320,2.58,57600000,2.57
18.9,7340,2.59,57800000,2.57
18.9,7360,2.60,58000000,2.58
18.9,7380,2.60,58100000,2.59
19.0,7410,2.61,58300000,2.59
19.0,7430,2.62,58500000,2.60
19.1,7450,2.62,58600000,2.61
19.1,7470,2.63,58800000,2.61
19.1,7490,2.64,59000000,2.62
19.2,7520,2.64,59200000,2.63
19.2,7530,2.65,59300000,2.63
19.3,7560,2.66,59500000,2.64
19.3,7570,2.66,59600000,2.65
19.3,7600,2.67,59800000,2.65
19.4,7610,2.68,59900000,2.66
19.4,7630,2.69,60100000,2.67
19.5,7650,2.69,60200000,2.67
19.5,7670,2.70,60400000,2.68
19.5,7690,2.71,60500000,2.69
19.6,7700,2.71,60600000,2.69
19.6,7730,2.72,60800000,2.70
19.7,7740,2.73,60900000,2.71
19.7,7760,2.73,61100000,2.72
19.8,7770,2.74,61200000,2.72
19.8,7790,2.75,61300000,2.73
19.8,7810,2.75,61400000,2.74
19.9,7820,2.76,61600000,2.74
19.9,7840,2.77,61700000,2.75
20.0,7850,2.77,61800000,2.76
20.0,7870,2.78,61900000,2.76
20.0,7880,2.79,62000000,2.77
20.1,7900,2.80,62200000,2.78
20.1,7910,2.80,62300000,2.78
20.2,7930,2.81,62400000,2.79
20.2,7940,2.82,62500000,2.80
20.2,7950,2.82,62600000,2.80
20.3,7960,2.83,62700000,2.81
20.3,7980,2.84,62800000,2.82
20.4,7990,2.84,62900000,2.82
20.4,8000,2.85,63000000,2.83
20.4,8020,2.86,63100000,2.84
20.5,8030,2.86,63200000,2.85
20.5,8040,2.87,63300000,2.85
20.6,8050,2.88,63400000,2.86
20.6,8060,2.88,63500000,2.87
20.7,8070,2.89,63500000,2.87
20.7,8080,2.90,63600000,2.88
20.7,8090,2.91,63700000,2.89
20.8,8100,2.91,63800000,2.89
20.8,8110,2.92,63800000,2.90
20.9,8120,2.93,63900000,2.91
20.9,8130,2.93,64000000,2.91
20.9,8140,2.94,64100000,2.92
21.0,8150,2.95,64200000,2.93
21.0,8160,2.95,64200000,2.93
21.1,8170,2.96,64300000,2.94
21.1,8170,2.97,64300000,2.95
21.1,8180,2.97,64400000,2.95
21.2,8180,2.98,64400000,2.96
21.2,8190,2.99,64500000,2.97
21.3,8200,2.99,64500000,2.98
21.3,8200,3.00,64600000,2.98
21.4,8210,3.01,64600000,2.99
21.4,8220,3.02,64700000,3.00
21.4,8230,3.02,64700000,3.00
21.5,8230,3.03,64800000,3.01
21.5,8240,3.04,64800000,3.02
21.6,8240,3.04,64900000,3.02
21.6,8250,3.05,65000000,3.03
21.6,8260,3.06,65000000,3.04
21.7,8270,3.06,65100000,3.04
21.7,8280,3.07,65200000,3.05
21.8,8290,3.08,65200000,3.06
21.8,8290,3.08,65300000,3.06
21.8,8300,3.09,65300000,3.07
21.9,8310,3.10,65400000,3.08
21.9,8310,3.10,65500000,3.08
22.0,8330,3.11,65500000,3.09
22.0,8330,3.12,65600000,3.10
22.0,8340,3.13,65600000,3.10
22.1,8340,3.13,65700000,3.11
22.1,8350,3.14,65800000,3.12
22.2,8360,3.15,65800000,3.13
22.2,8370,3.15,65900000,3.13
22.3,8370,3.16,65900000,3.14
22.3,8380,3.17,66000000,3.15
22.3,8390,3.17,66000000,3.15
22.4,8390,3.18,66100000,3.16
22.4,8400,3.19,66200000,3.17
22.5,8410,3.19,66200000,3.17
22.5,8420,3.20,66300000,3.18
22.5,8420,3.21,66300000,3.19
22.6,8430,3.21,66300000,3.19
22.6,8430,3.22,66400000,3.20
22.7,8440,3.23,66400000,3.21
22.7,8450,3.24,66500000,3.21
22.7,8460,3.24,66600000,3.22
22.8,8470,3.25,66600000,3.23
22.8,8470,3.26,66700000,3.23
22.9,8480,3.26,66800000,3.24
22.9,8490,3.27,66800000,3.25
23.0,8500,3.28,66900000,3.26
23.0,8500,3.28,66900000,3.26
23.0,8510,3.29,67000000,3.27
23.1,8520,3.30,67100000,3.28
23.1,8530,3.30,67100000,3.28
23.2,8540,3.31,67200000,3.29
23.2,8540,3.32,67300000,3.30
23.2,8550,3.32,67300000,3.30
23.3,8560,3.33,67400000,3.31
23.3,8570,3.34,67400000,3.32
23.4,8570,3.35,67500000,3.32
23.4,8580,3.35,67500000,3.33
23.4,8580,3.36,67600000,3.34
23.5,8590,3.37,67600000,3.34
23.5,8600,3.37,67700000,3.35
23.6,8600,3.38,67700000,3.36
23.6,8610,3.39,67700000,3.36
23.6,8610,3.39,67800000,3.37
23.7,8620,3.40,67800000,3.38
23.7,8620,3.41,67800000,3.39
23.8,8630,3.41,67900000,3.39
23.8,8630,3.42,67900000,3.40
23.9,8640,3.43,68000000,3.41
23.9,8640,3.44,68000000,3.41
23.9,8640,3.44,68000000,3.42
24.0,8640,3.45,68000000,3.43
24.0,8640,3.46,68000000,3.43
24.1,8650,3.46,68100000,3.44
24.1,8650,3.47,68100000,3.45
24.1,8660,3.48,68100000,3.45
24.2,8660,3.48,68100000,3.46
24.2,8670,3.49,68200000,3.47
24.3,8670,3.50,68200000,3.47
24.3,8670,3.50,68300000,3.48
24.3,8680,3.51,68300000,3.49
24.4,8690,3.52,68400000,3.49
24.4,8690,3.52,68400000,3.50
24.5,8690,3.53,68400000,3.51
24.5,8700,3.54,68500000,3.52
24.5,8700,3.55,68500000,3.52
24.6,8710,3.55,68600000,3.53
24.6,8710,3.56,68600000,3.54
24.7,8720,3.57,68600000,3.54
24.7,8720,3.57,68700000,3.55
24.8,8730,3.58,68700000,3.56
24.8,8730,3.59,68700000,3.56
24.8,8740,3.59,68800000,3.57
24.9,8740,3.60,68800000,3.58
24.9,8750,3.61,68800000,3.58
25.0,8750,3.61,68900000,3.59
25.0,8750,3.62,68900000,3.60
25.0,8760,3.63,68900000,3.60
25.1,8760,3.63,69000000,3.61
25.1,8770,3.64,69000000,3.62
25.2,8770,3.65,69000000,3.62
25.2,8770,3.66,69100000,3.63
25.2,8770,3.66,69100000,3.64
25.3,8780,3.67,69100000,3.64
25.3,8780,3.68,69100000,3.65
25.4,8780,3.68,69100000,3.66
25.4,8790,3.69,69200000,3.67
25.5,8790,3.70,69200000,3.67
25.5,8790,3.70,69200000,3.68
25.5,8800,3.71,69200000,3.69
25.6,8800,3.72,69300000,3.69
25.6,8800,3.72,69300000,3.70
25.7,8810,3.73,69300000,3.71
25.7,8800,3.74,69300000,3.71
25.7,8810,3.74,69300000,3.72
25.8,8810,3.75,69300000,3.73
25.8,8810,3.76,69300000,3.73
25.9,8810,3.77,69300000,3.74
25.9,8810,3.77,69400000,3.75
25.9,8810,3.78,69400000,3.75
26.0,8810,3.79,69400000,3.76
26.0,8820,3.79,69400000,3.77
26.1,8810,3.80,69400000,3.77
26.1,8820,3.81,69400000,3.78
26.1,8820,3.81,69400000,3.79
26.2,8820,3.82,69400000,3.80
26.2,8820,3.83,69400000,3.80
26.3,8820,3.83,69400000,3.81
26.3,8820,3.84,69400000,3.82
26.4,8820,3.85,69400000,3.82
26.4,8820,3.85,69400000,3.83
26.4,8820,3.86,69400000,3.84
26.5,8820,3.87,69400000,3.84
26.5,8820,3.88,69500000,3.85
26.6,8830,3.88,69500000,3.86
26.6,8830,3.89,69500000,3.86
26.6,8830,3.90,69500000,3.87
26.7,8830,3.90,69500000,3.88
26.7,8840,3.91,69600000,3.88
26.8,8840,3.92,69600000,3.89
26.8,8850,3.92,69600000,3.90
26.8,8850,3.93,69700000,3.90
26.9,8850,3.94,69700000,3.91
26.9,8860,3.94,69700000,3.92
27.0,8850,3.95,69700000,3.93
27.0,8860,3.96,69700000,3.93
27.1,8860,3.97,69700000,3.94
27.1,8860,3.97,69700000,3.95
27.1,8860,3.98,69700000,3.95
27.2,8860,3.99,69800000,3.96
27.2,8870,3.99,69800000,3.97
27.3,8870,4.00,69800000,3.97
27.3,8870,4.01,69800000,3.98
27.3,8870,4.01,69800000,3.99
27.4,8880,4.02,69900000,3.99
27.4,8880,4.03,69900000,4.00
27.5,8890,4.03,69900000,4.01
27.5,8890,4.04,70000000,4.01
27.5,8890,4.05,70000000,4.02
27.6,8900,4.05,70000000,4.03
27.6,8900,4.06,70100000,4.03
27.7,8900,4.07,70100000,4.04
27.7,8900,4.07,70100000,4.05
27.7,8910,4.08,70100000,4.06
27.8,8910,4.09,70100000,4.06
27.8,8910,4.10,70200000,4.07
27.9,8910,4.10,70200000,4.08
27.9,8920,4.11,70200000,4.08
28.0,8910,4.12,70200000,4.09
28.0,8920,4.12,70200000,4.10
28.0,8910,4.13,70200000,4.10
28.1,8920,4.14,70200000,4.11
28.1,8920,4.14,70200000,4.12
28.2,8920,4.15,70200000,4.12
28.2,8920,4.16,70200000,4.13
28.2,8920,4.16,70200000,4.14
28.3,8920,4.17,70200000,4.14
28.3,8920,4.18,70200000,4.15
28.4,8930,4.19,70300000,4.16
28.4,8930,4.19,70300000,4.16
28.4,8930,4.20,70300000,4.17
28.5,8930,4.21,70300000,4.18
28.5,8940,4.21,70300000,4.19
28.6,8940,4.22,70400000,4.19
28.6,8940,4.23,70400000,4.20
28.6,8950,4.23,70400000,4.21
28.7,8950,4.24,70400000,4.21
28.7,8950,4.25,70500000,4.22
28.8,8960,4.25,70500000,4.23
28.8,8960,4.26,70500000,4.23
28.9,8960,4.27,70500000,4.24
28.9,8970,4.27,70600000,4.25
28.9,8970,4.28,70600000,4.25
29.0,8970,4.29,70600000,4.26
29.0,8970,4.30,70600000,4.27
29.1,8970,4.30,70600000,4.27
29.1,8970,4.31,70600000,4.28
29.1,8970,4.32,70600000,4.29
29.2,8980,4.32,70700000,4.29
29.2,8980,4.33,70600000,4.30
29.3,8980,4.34,70700000,4.31
29.3,8980,4.34,70700000,4.31
29.3,8980,4.35,70700000,4.32
29.4,8980,4.36,70700000,4.33
29.4,8980,4.36,70700000,4.34
29.5,8980,4.37,70700000,4.34
29.5,8980,4.38,70700000,4.35
29.6,8970,4.38,70600000,4.36
29.6,8970,4.39,70600000,4.36
29.6,8970,4.40,70600000,4.37
29.7,8960,4.41,70500000,4.38
29.7,8960,4.41,70500000,4.38
29.8,8950,4.42,70500000,4.39
29.8,8950,4.43,70500000,4.40
29.8,8950,4.43,70400000,4.40
29.9,8950,4.44,70500000,4.41
29.9,8950,4.45,70400000,4.42
30.0,8950,4.45,70400000,4.42
30.0,8950,4.46,70500000,4.43
30.0,8950,4.47,70500000,4.44
30.1,8960,4.47,70500000,4.44
30.1,8960,4.48,70500000,4.45
30.2,8960,4.49,70600000,4.46
30.2,8970,4.49,70600000,4.47
30.2,8980,4.50,70700000,4.47
30.3,8980,4.51,70700000,4.48
30.3,8990,4.52,70700000,4.49
30.4,8990,4.52,70800000,4.49
30.4,9000,4.53,70800000,4.50
30.5,9000,4.54,70900000,4.51
30.5,9010,4.54,70900000,4.51
30.5,9020,4.55,71000000,4.52
30.6,9020,4.56,71000000,4.53
30.6,9030,4.56,71100000,4.53
30.7,9030,4.57,71100000,4.54
30.7,9040,4.58,71200000,4.55
30.7,9050,4.58,71200000,4.55
30.8,9050,4.59,71300000,4.56
30.8,9050,4.60,71300000,4.57
30.9,9060,4.60,71300000,4.57
30.9,9070,4.61,71400000,4.58
30.9,9070,4.62,71400000,4.59
31.0,9080,4.63,71400000,4.60
31.0,9080,4.63,71500000,4.60
31.1,9090,4.64,71500000,4.61
31.1,9090,4.65,71600000,4.62
31.2,9100,4.65,71600000,4.62
31.2,9100,4.66,71600000,4.63
31.2,9110,4.67,71700000,4.64
31.3,9110,4.67,71700000,4.64
31.3,9120,4.68,71800000,4.65
31.4,9120,4.69,71800000,4.66
31.4,9130,4.69,71900000,4.66
31.4,9140,4.70,71900000,4.67
31.5,9140,4.71,72000000,4.68
31.5,9150,4.72,72000000,4.68
31.6,9160,4.72,72100000,4.69
31.6,9170,4.73,72100000,4.70
31.6,9170,4.74,72200000,4.70
31.7,9180,4.74,72200000,4.71
31.7,9180,4.75,72300000,4.72
31.8,9190,4.76,72300000,4.73
31.8,9190,4.76,72400000,4.73
31.8,9200,4.77,72400000,4.74
31.9,9210,4.78,72500000,4.75
31.9,9210,4.78,72500000,4.75
32.0,9220,4.79,72600000,4.76
32.0,9220,4.80,72600000,4.77
32.1,9230,4.80,72700000,4.77
32.1,9240,4.81,72700000,4.78
32.1,9250,4.82,72800000,4.79
32.2,9250,4.83,72800000,4.79
32.2,9260,4.83,72900000,4.80
32.3,9260,4.84,72900000,4.81
32.3,9270,4.85,73000000,4.81
32.3,9270,4.85,73000000,4.82
32.4,9280,4.86,73000000,4.83
32.4,9290,4.87,73100000,4.83
32.5,9290,4.87,73100000,4.84
32.5,9290,4.88,73200000,4.85
32.5,9290,4.89,73200000,4.85
32.6,9300,4.89,73200000,4.86
32.6,9300,4.90,73200000,4.87
32.7,9310,4.91,73300000,4.88
32.7,9310,4.91,73300000,4.88
32.7,9320,4.92,73300000,4.89
32.8,9320,4.93,73400000,4.90
32.8,9320,4.94,73400000,4.90
32.9,9330,4.94,73400000,4.91
32.9,9330,4.95,73400000,4.92
33.0,9330,4.96,73500000,4.92
33.0,9330,4.96,73500000,4.93
33.0,9340,4.97,73500000,4.94
33.1,9340,4.98,73500000,4.94
33.1,9340,4.98,73500000,4.95
33.2,9350,4.99,73600000,4.96
33.2,9350,5.00,73600000,4.96
33.2,9350,5.00,73600000,4.97
33.3,9350,5.01,73600000,4.98
33.3,9360,5.02,73600000,4.99
33.4,9360,5.03,73600000,4.99
33.4,9360,5.03,73700000,5.00
33.4,9360,5.04,73700000,5.01
33.5,9360,5.05,73700000,5.01
33.5,9360,5.05,73700000,5.02
33.6,9370,5.06,73700000,5.03
33.6,9370,5.07,73700000,5.03
33.7,9370,5.07,73700000,5.04
33.7,9370,5.08,73800000,5.05
33.7,9370,5.09,73800000,5.05
33.8,9370,5.09,73800000,5.06
33.8,9370,5.10,73800000,5.07
33.9,9380,5.11,73800000,5.07
33.9,9380,5.11,73800000,5.08
33.9,9380,5.12,73800000,5.09
34.0,9380,5.13,73800000,5.09
34.0,9380,5.14,73900000,5.10
34.1,9380,5.14,73900000,5.11
34.1,9390,5.15,73900000,5.11
34.1,9390,5.16,73900000,5.12
34.2,9390,5.16,73900000,5.13
34.2,9390,5.17,73900000,5.14
34.3,9390,5.18,73900000,5.14
34.3,9400,5.18,74000000,5.15
34.3,9400,5.19,74000000,5.16
34.4,9400,5.20,74000000,5.16
34.4,9400,5.20,74000000,5.17
34.5,9410,5.21,74100000,5.18
34.5,9410,5.22,74100000,5.18
34.6,9420,5.22,74100000,5.19
34.6,9420,5.23,74200000,5.20
34.6,9430,5.24,74200000,5.20
34.7,9430,5.25,74200000,5.21
34.7,9430,5.25,74300000,5.22
34.8,9440,5.26,74300000,5.22
34.8,9440,5.27,74300000,5.23
34.8,9450,5.27,74400000,5.24
34.9,9450,5.28,74400000,5.25
34.9,9460,5.29,74400000,5.25
35.0,9460,5.29,74500000,5.26
35.0,9460,5.30,74500000,5.27
35.0,9470,5.31,74500000,5.27
35.1,9470,5.31,74500000,5.28
35.1,9470,5.32,74600000,5.29
35.2,9470,5.33,74600000,5.29
35.2,9480,5.33,74600000,5.30
35.3,9480,5.34,74600000,5.31
35.3,9480,5.35,74600000,5.31
35.3,9480,5.36,74700000,5.32
35.4,9490,5.36,74700000,5.33
35.4,9490,5.37,74700000,5.33
35.5,9500,5.38,74700000,5.34
35.5,9500,5.38,74800000,5.35
35.5,9500,5.39,74800000,5.35
35.6,9510,5.40,74900000,5.36
35.6,9510,5.40,74900000,5.37
35.7,9520,5.41,74900000,5.37
35.7,9520,5.42,74900000,5.38
35.7,9530,5.42,75000000,5.39
35.8,9530,5.43,75000000,5.40
35.8,9530,5.44,75000000,5.40
35.9,9530,5.44,75100000,5.41
35.9,9540,5.45,75100000,5.42
35.9,9540,5.46,75100000,5.42
36.0,9550,5.47,75100000,5.43
36.0,9550,5.47,75200000,5.44
36.1,9550,5.48,75200000,5.44
36.1,9560,5.49,75200000,5.45
36.2,9560,5.49,75200000,5.46
36.2,9570,5.50,75300000,5.46
36.2,9570,5.51,75300000,5.47
36.3,9570,5.51,75300000,5.48
36.3,9570,5.52,75400000,5.48
36.4,9580,5.53,75400000,5.49
36.4,9580,5.53,75400000,5.50
36.4,9580,5.54,75400000,5.50
36.5,9580,5.55,75400000,5.51
36.5,9580,5.55,75400000,5.52
36.6,9590,5.56,75500000,5.53
36.6,9580,5.57,75400000,5.53
36.6,9590,5.58,75500000,5.54
36.7,9590,5.58,75500000,5.55
36.7,9590,5.59,75500000,5.55
36.8,9590,5.60,75500000,5.56
36.8,9600,5.60,75500000,5.57
36.8,9600,5.61,75600000,5.57
36.9,9600,5.62,75600000,5.58
36.9,9600,5.62,75600000,5.59
37.0,9600,5.63,75500000,5.59
37.0,9600,5.64,75600000,5.60
37.1,9600,5.64,75600000,5.61
37.1,9600,5.65,75600000,5.61
37.1,9600,5.66,75600000,5.62
37.2,9600,5.66,75600000,5.63
37.2,9600,5.67,75600000,5.63
37.3,9600,5.68,75600000,5.64
37.3,9600,5.69,75600000,5.65
37.3,9600,5.69,75600000,5.65
37.4,9600,5.70,75600000,5.66
37.4,9600,5.71,75600000,5.67
37.5,9610,5.71,75600000,5.68
37.5,9600,5.72,75600000,5.68
37.5,9600,5.73,75600000,5.69
37.6,9600,5.73,75500000,5.70
37.6,9600,5.74,75500000,5.70
37.7,9590,5.75,75500000,5.71
37.7,9590,5.75,75500000,5.72
37.8,9590,5.76,75500000,5.72
37.8,9590,5.77,75500000,5.73
37.8,9590,5.77,75500000,5.74
37.9,9590,5.78,75500000,5.74
37.9,9600,5.79,75500000,5.75
38.0,9590,5.80,75500000,5.76
38.0,9600,5.80,75500000,5.76
38.0,9590,5.81,75500000,5.77
38.1,9600,5.82,75500000,5.78
38.1,9590,5.82,75500000,5.79
38.2,9590,5.83,75500000,5.79
38.2,9590,5.84,75500000,5.80
38.2,9600,5.84,75500000,5.81
38.3,9600,5.85,75600000,5.81
38.3,9600,5.86,75500000,5.82
38.4,9600,5.86,75500000,5.83
38.4,9590,5.87,75500000,5.83
38.4,9600,5.88,75500000,5.84
38.5,9590,5.89,75500000,5.85
38.5,9600,5.89,75600000,5.85
38.6,9600,5.90,75600000,5.86
38.6,9610,5.91,75600000,5.87
38.7,9610,5.91,75600000,5.87
38.7,9610,5.92,75600000,5.88
38.7,9620,5.93,75700000,5.89
38.8,9620,5.93,75700000,5.89
38.8,9630,5.94,75800000,5.90
38.9,9630,5.95,75800000,5.91
38.9,9640,5.95,75900000,5.91
38.9,9640,5.96,75900000,5.92
39.0,9650,5.97,76000000,5.93
39.0,9650,5.97,76000000,5.94
39.1,9660,5.98,76000000,5.94
39.1,9660,5.99,76100000,5.95
39.1,9670,6.00,76100000,5.96
39.2,9670,6.00,76100000,5.96
39.2,9670,6.01,76200000,5.97
39.3,9680,6.02,76200000,5.98
39.3,9680,6.02,76200000,5.98
39.4,9690,6.03,76300000,5.99
39.4,9690,6.04,76300000,6.00
39.4,9700,6.04,76300000,6.00
39.5,9700,6.05,76400000,6.01
39.5,9710,6.06,76400000,6.02
39.6,9710,6.06,76400000,6.02
39.6,9710,6.07,76400000,6.03
39.6,9710,6.08,76500000,6.04
39.7,9710,6.08,76500000,6.04
39.7,9720,6.09,76500000,6.05
39.8,9720,6.10,76500000,6.06
39.8,9720,6.11,76500000,6.07
39.8,9720,6.11,76500000,6.07
39.9,9720,6.12,76500000,6.08
39.9,9720,6.13,76500000,6.09
40.0,9710,6.13,76500000,6.09
40.0,9710,6.14,76400000,6.10
40.0,9700,6.15,76400000,6.11
40.1,9700,6.15,76300000,6.11
40.1,9690,6.16,76300000,6.12
40.2,9690,6.17,76200000,6.13
40.2,9680,6.17,76200000,6.13
40.3,9670,6.18,76100000,6.14
40.3,9660,6.19,76100000,6.15
40.3,9660,6.20,76000000,6.15
40.4,9650,6.20,76000000,6.16
40.4,9640,6.21,75900000,6.17
40.5,9630,6.22,75800000,6.17
40.5,9630,6.22,75800000,6.18
40.5,9630,6.23,75800000,6.19
40.6,9620,6.24,75700000,6.20
40.6,9620,6.24,75700000,6.20
40.7,9610,6.25,75600000,6.21
40.7,9600,6.26,75600000,6.22
40.7,9590,6.26,75500000,6.22
40.8,9580,6.27,75400000,6.23
40.8,9570,6.28,75400000,6.24
40.9,9570,6.28,75300000,6.24
40.9,9560,6.29,75200000,6.25
40.9,9550,6.30,75200000,6.26
41.0,9550,6.30,75100000,6.26
41.0,9540,6.31,75100000,6.27
41.1,9530,6.32,75000000,6.28
41.1,9530,6.33,75000000,6.28
41.2,9530,6.33,75000000,6.29
41.2,9520,6.34,74900000,6.30
41.2,9520,6.35,74900000,6.30
41.3,9520,6.35,74900000,6.31
41.3,9520,6.36,74900000,6.32
41.4,9510,6.37,74900000,6.33
41.4,9510,6.37,74800000,6.33
41.4,9510,6.38,74800000,6.34
41.5,9500,6.39,74800000,6.35
41.5,9500,6.39,74800000,6.35
41.6,9490,6.40,74700000,6.36
41.6,9490,6.41,74700000,6.37
41.6,9480,6.42,74700000,6.37
41.7,9480,6.42,74600000,6.38
41.7,9480,6.43,74600000,6.39
41.8,9470,6.44,74600000,6.39
41.8,9470,6.44,74500000,6.40
41.9,9470,6.45,74500000,6.41
41.9,9470,6.46,74500000,6.41
41.9,9460,6.46,74500000,6.42
42.0,9460,6.47,74500000,6.43
42.0,9460,6.48,74400000,6.43
42.1,9460,6.48,74500000,6.44
42.1,9460,6.49,74400000,6.45
42.1,9460,6.50,74400000,6.46
42.2,9450,6.50,74400000,6.46
42.2,9450,6.51,74400000,6.47
42.3,9450,6.52,74400000,6.48
42.3,9450,6.53,74400000,6.48
42.3,9450,6.53,74400000,6.49
42.4,9450,6.54,74400000,6.50
42.4,9450,6.55,74400000,6.50
42.5,9440,6.55,74300000,6.51
42.5,9440,6.56,74300000,6.52
42.5,9430,6.57,74300000,6.52
42.6,9430,6.57,74200000,6.53
42.6,9430,6.58,74200000,6.54
42.7,9420,6.59,74100000,6.54
42.7,9410,6.59,74100000,6.55
42.8,9400,6.60,74000000,6.56
42.8,9400,6.61,74000000,6.56
42.8,9390,6.61,73900000,6.57
42.9,9380,6.62,73800000,6.58
42.9,9360,6.63,73700000,6.59
43.0,9360,6.64,73700000,6.59
43.0,9340,6.64,73500000,6.60
43.0,9330,6.65,73500000,6.61
43.1,9320,6.66,73400000,6.61
43.1,9310,6.66,73300000,6.62
43.2,9300,6.67,73200000,6.63
43.2,9290,6.68,73100000,6.63
43.2,9280,6.68,73000000,6.64
43.3,9270,6.69,73000000,6.65
43.3,9270,6.70,72900000,6.65
43.4,9260,6.70,72900000,6.66
43.4,9250,6.71,72800000,6.67
43.5,9240,6.72,72800000,6.67
43.5,9240,6.72,72700000,6.68
43.5,9230,6.73,72700000,6.69
43.6,9230,6.74,72600000,6.69
43.6,9220,6.75,72600000,6.70
43.7,9220,6.75,72500000,6.71
43.7,9210,6.76,72500000,6.71
43.7,9200,6.77,72400000,6.72
43.8,9200,6.77,72400000,6.73
43.8,9190,6.78,72300000,6.74
43.9,9190,6.79,72300000,6.74
43.9,9180,6.79,72200000,6.75
43.9,9170,6.80,72200000,6.76
44.0,9160,6.81,72100000,6.76
44.0,9160,6.81,72100000,6.77
44.1,9150,6.82,72000000,6.78
44.1,9140,6.83,72000000,6.78
44.1,9140,6.83,71900000,6.79
44.2,9130,6.84,71900000,6.80
44.2,9130,6.85,71800000,6.80
44.3,9120,6.86,71800000,6.81
44.3,9110,6.86,71700000,6.82
44.4,9100,6.87,71700000,6.82
44.4,9100,6.88,71600000,6.83
44.4,9090,6.88,71500000,6.84
44.5,9080,6.89,71500000,6.84
44.5,9070,6.90,71400000,6.85
44.6,9060,6.90,71400000,6.86
44.6,9060,6.91,71300000,6.87
44.6,9050,6.92,71200000,6.87
44.7,9040,6.92,71200000,6.88
44.7,9030,6.93,71100000,6.89
44.8,9020,6.94,71000000,6.89
44.8,9010,6.94,71000000,6.90
44.8,9010,6.95,70900000,6.91
44.9,9000,6.96,70800000,6.91
44.9,9000,6.97,70800000,6.92
45.0,8990,6.97,70700000,6.93
45.0,8980,6.98,70700000,6.93
45.0,8970,6.99,70600000,6.94
45.1,8960,6.99,70600000,6.95
45.1,8960,7.00,70500000,6.95
45.2,8940,7.01,70400000,6.96
45.2,8940,7.01,70300000,6.97
45.3,8920,7.02,70300000,6.97
45.3,8920,7.03,70200000,6.98
45.3,8900,7.03,70100000,6.99
45.4,8890,7.04,70000000,6.99
45.4,8870,7.05,69800000,7.00
45.5,8860,7.05,69800000,7.01
45.5,8850,7.06,69700000,7.02
45.5,8840,7.07,69600000,7.02
45.6,8830,7.08,69500000,7.03
45.6,8810,7.08,69400000,7.04
45.7,8800,7.09,69300000,7.04
45.7,8790,7.10,69200000,7.05
45.7,8780,7.10,69100000,7.06
45.8,8760,7.11,69000000,7.06
45.8,8750,7.12,68900000,7.07
45.9,8740,7.12,68800000,7.08
45.9,8730,7.13,68700000,7.08
46.0,8710,7.14,68600000,7.09
46.0,8700,7.14,68500000,7.10
46.0,8680,7.15,68300000,7.10
46.1,8670,7.16,68200000,7.11
46.1,8650,7.17,68100000,7.12
46.2,8640,7.17,68000000,7.12
46.2,8630,7.18,67900000,7.13
46.2,8610,7.19,67800000,7.14
46.3,8600,7.19,67700000,7.15
46.3,8580,7.20,67500000,7.15
46.4,8570,7.21,67400000,7.16
46.4,8550,7.21,67300000,7.17
46.4,8540,7.22,67200000,7.17
46.5,8530,7.23,67100000,7.18
46.5,8520,7.23,67000000,7.19
46.6,8510,7.24,67000000,7.19
46.6,8490,7.25,66800000,7.20
46.6,8480,7.25,66800000,7.21
46.7,8470,7.26,66600000,7.21
46.7,8460,7.27,66600000,7.22
46.8,8440,7.28,66400000,7.23
46.8,8430,7.28,66400000,7.23
46.9,8420,7.29,66300000,7.24
46.9,8410,7.30,66200000,7.25
46.9,8400,7.30,66100000,7.25
47.0,8390,7.31,66000000,7.26
47.0,8380,7.32,66000000,7.27
47.1,8370,7.32,65900000,7.28
47.1,8360,7.33,65800000,7.28
47.1,8350,7.34,65700000,7.29
47.2,8340,7.34,65600000,7.30
47.2,8330,7.35,65600000,7.30
47.3,8320,7.36,65500000,7.31
47.3,8310,7.36,65400000,7.32
47.3,8310,7.37,65400000,7.32
47.4,8300,7.38,65300000,7.33
47.4,8290,7.39,65300000,7.34
47.5,8290,7.39,65200000,7.34
47.5,8280,7.40,65200000,7.35
47.6,8280,7.41,65200000,7.36
47.6,8270,7.41,65100000,7.36
47.6,8270,7.42,65100000,7.37
47.7,8270,7.43,65100000,7.38
47.7,8260,7.43,65100000,7.39
47.8,8260,7.44,65000000,7.39
47.8,8260,7.45,65000000,7.40
47.8,8250,7.45,65000000,7.41
47.9,8250,7.46,64900000,7.41
47.9,8250,7.47,64900000,7.42
48.0,8240,7.47,64900000,7.43
48.0,8240,7.48,64900000,7.43
48.0,8230,7.49,64800000,7.44
48.1,8230,7.50,64800000,7.45
48.1,8230,7.50,64700000,7.45
48.2,8220,7.51,64700000,7.46
48.2,8220,7.52,64700000,7.47
48.2,8210,7.52,64600000,7.47
48.3,8200,7.53,64600000,7.48
48.3,8190,7.54,64500000,7.49
48.4,8190,7.54,64500000,7.49
48.4,8180,7.55,64400000,7.50
48.5,8170,7.56,64300000,7.51
48.5,8160,7.56,64200000,7.51
48.5,8150,7.57,64200000,7.52
48.6,8140,7.58,64100000,7.53
48.6,8140,7.59,64000000,7.54
48.7,8120,7.59,64000000,7.54
48.7,8120,7.60,63900000,7.55
48.7,8110,7.61,63800000,7.56
48.8,8100,7.61,63800000,7.56
48.8,8090,7.62,63700000,7.57
48.9,8080,7.63,63600000,7.58
48.9,8080,7.63,63600000,7.58
48.9,8070,7.64,63500000,7.59
49.0,8070,7.65,63500000,7.60
49.0,8060,7.65,63400000,7.60
49.1,8050,7.66,63400000,7.61
49.1,8040,7.67,63300000,7.62
49.1,8040,7.67,63300000,7.62
49.2,8030,7.68,63200000,7.63
49.2,8020,7.69,63200000,7.64
49.3,8020,7.70,63100000,7.64
49.3,8010,7.70,63000000,7.65
49.4,8000,7.71,63000000,7.66
49.4,7990,7.72,62900000,7.67
49.4,7980,7.72,62800000,7.67
49.5,7970,7.73,62700000,7.68
49.5,7960,7.74,62700000,7.69
49.6,7950,7.74,62600000,7.69
49.6,7940,7.75,62500000,7.70
49.6,7930,7.76,62400000,7.71
49.7,7920,7.76,62300000,7.71
49.7,7910,7.77,62300000,7.72
49.8,7900,7.78,62200000,7.73
49.8,7890,7.78,62100000,7.73
49.8,7880,7.79,62000000,7.74
49.9,7870,7.80,62000000,7.75
49.9,7860,7.81,61900000,7.75
50.0,7860,7.81,61900000,7.76
50.0,7850,7.82,61800000,7.77
50.1,7850,7.83,61800000,7.77
50.1,7840,7.83,61700000,7.78
50.1,7840,7.84,61700000,7.79
50.2,7840,7.85,61700000,7.80
50.2,7830,7.85,61700000,7.80
50.3,7830,7.86,61700000,7.81
50.3,7830,7.87,61600000,7.82
50.3,7830,7.87,61600000,7.82
50.4,7830,7.88,61600000,7.83
50.4,7830,7.89,61600000,7.84
50.5,7830,7.89,61600000,7.84
50.5,7830,7.90,61600000,7.85
50.5,7830,7.91,61600000,7.86
50.6,7830,7.92,61600000,7.86
50.6,7830,7.92,61600000,7.87
50.7,7830,7.93,61600000,7.88
50.7,7830,7.94,61600000,7.88
50.7,7830,7.94,61600000,7.89
50.8,7830,7.95,61600000,7.90
50.8,7830,7.96,61600000,7.90
50.9,7830,7.96,61600000,7.91
50.9,7830,7.97,61600000,7.92
51.0,7830,7.98,61600000,7.93
51.0,7830,7.98,61600000,7.93
51.0,7830,7.99,61600000,7.94
51.1,7830,8.00,61600000,7.95
51.1,7830,8.00,61600000,7.95
51.2,7830,8.01,61600000,7.96
51.2,7830,8.02,61600000,7.97
51.2,7830,8.03,61600000,7.97
51.3,7830,8.03,61600000,7.98
51.3,7830,8.04,61600000,7.99
51.4,7820,8.05,61600000,7.99
51.4,7820,8.05,61600000,8.00
51.4,7820,8.06,61600000,8.01
51.5,7820,8.07,61600000,8.01
51.5,7820,8.07,61500000,8.02
51.6,7820,8.08,61500000,8.03
51.6,7820,8.09,61500000,8.03
51.7,7810,8.09,61500000,8.04
51.7,7810,8.10,61500000,8.05
51.7,7810,8.11,61500000,8.05
51.8,7810,8.12,61500000,8.06
51.8,7810,8.12,61500000,8.07
51.9,7810,8.13,61500000,8.08
51.9,7810,8.14,61500000,8.08
51.9,7810,8.14,61500000,8.09
52.0,7810,8.15,61500000,8.10
52.0,7810,8.16,61500000,8.10
52.1,7810,8.16,61500000,8.11
52.1,7800,8.17,61400000,8.12
52.1,7800,8.18,61400000,8.12
52.2,7800,8.18,61400000,8.13
52.2,7790,8.19,61400000,8.14
52.3,7790,8.20,61300000,8.14
52.3,7780,8.20,61300000,8.15
52.3,7780,8.21,61200000,8.16
52.4,7770,8.22,61200000,8.16
52.4,7770,8.23,61200000,8.17
52.5,7760,8.23,61100000,8.18
52.5,7760,8.24,61100000,8.19
52.6,7750,8.25,61000000,8.19
52.6,7740,8.25,60900000,8.20
52.6,7730,8.26,60900000,8.21
52.7,7730,8.27,60800000,8.21
52.7,7720,8.27,60700000,8.22
52.8,7710,8.28,60700000,8.23
52.8,7700,8.29,60600000,8.23
52.8,7700,8.29,60600000,8.24
52.9,7690,8.30,60600000,8.25
52.9,7690,8.31,60500000,8.25
53.0,7680,8.31,60500000,8.26
53.0,7680,8.32,60400000,8.27
53.0,7670,8.33,60400000,8.27
53.1,7670,8.34,60300000,8.28
53.1,7660,8.34,60300000,8.29
53.2,7650,8.35,60300000,8.29
53.2,7650,8.36,60200000,8.30
53.2,7640,8.36,60100000,8.31
53.3,7640,8.37,60100000,8.32
53.3,7630,8.38,60100000,8.32
53.4,7620,8.38,60000000,8.33
53.4,7620,8.39,60000000,8.34
53.5,7610,8.40,59900000,8.34
53.5,7610,8.40,59900000,8.35
53.5,7600,8.41,59800000,8.36
53.6,7600,8.42,59800000,8.36
53.6,7590,8.42,59700000,8.37
53.7,7590,8.43,59700000,8.38
53.7,7580,8.44,59700000,8.38
53.7,7570,8.45,59600000,8.39
53.8,7570,8.45,59600000,8.40
53.8,7560,8.46,59500000,8.40
53.9,7560,8.47,59500000,8.41
53.9,7550,8.47,59400000,8.42
53.9,7550,8.48,59400000,8.42
54.0,7540,8.49,59400000,8.43
54.0,7540,8.49,59300000,8.44
54.1,7530,8.50,59300000,8.44
54.1,7530,8.51,59300000,8.45
54.2,7530,8.51,59300000,8.46
54.2,7530,8.52,59200000,8.47
54.2,7520,8.53,59200000,8.47
54.3,7520,8.53,59200000,8.48
54.3,7520,8.54,59200000,8.49
54.4,7520,8.55,59200000,8.49
54.4,7530,8.56,59300000,8.50
54.4,7530,8.56,59200000,8.51
54.5,7530,8.57,59300000,8.51
54.5,7530,8.58,59200000,8.52
54.6,7530,8.58,59300000,8.53
54.6,7530,8.59,59300000,8.53
54.6,7530,8.60,59300000,8.54
54.7,7530,8.60,59300000,8.55
54.7,7540,8.61,59300000,8.55
54.8,7540,8.62,59300000,8.56
54.8,7540,8.62,59300000,8.57
54.8,7540,8.63,59400000,8.57
54.9,7540,8.64,59400000,8.58
54.9,7550,8.65,59400000,8.59
55.0,7550,8.65,59400000,8.60
55.0,7550,8.66,59500000,8.60
55.1,7550,8.67,59400000,8.61
55.1,7550,8.67,59500000,8.62
55.1,7550,8.68,59400000,8.62
55.2,7550,8.69,59400000,8.63
55.2,7550,8.69,59400000,8.64
55.3,7550,8.70,59400000,8.64
55.3,7550,8.71,59400000,8.65
55.3,7550,8.71,59400000,8.66
55.4,7550,8.72,59400000,8.66
55.4,7540,8.73,59400000,8.67
55.5,7540,8.73,59400000,8.68
55.5,7540,8.74,59400000,8.68
55.5,7540,8.75,59400000,8.69
55.6,7540,8.75,59400000,8.70
55.6,7540,8.76,59400000,8.70
55.7,7540,8.77,59400000,8.71
55.7,7540,8.78,59400000,8.72
55.8,7540,8.78,59400000,8.73
55.8,7540,8.79,59300000,8.73
55.8,7540,8.80,59300000,8.74
55.9,7530,8.80,59300000,8.75
55.9,7530,8.81,59300000,8.75
56.0,7530,8.82,59200000,8.76
56.0,7520,8.82,59200000,8.77
56.0,7520,8.83,59200000,8.77
56.1,7510,8.84,59200000,8.78
56.1,7510,8.84,59100000,8.79
56.2,7510,8.85,59100000,8.79
56.2,7510,8.86,59100000,8.80
56.2,7500,8.87,59100000,8.81
56.3,7500,8.87,59000000,8.81
56.3,7500,8.88,59000000,8.82
56.4,7490,8.89,59000000,8.83
56.4,7490,8.89,58900000,8.83
56.4,7490,8.90,58900000,8.84
56.5,7480,8.91,58900000,8.85
56.5,7480,8.91,58900000,8.86
56.6,7470,8.92,58800000,8.86
56.6,7470,8.93,58800000,8.87
56.7,7470,8.93,58800000,8.88
56.7,7460,8.94,58700000,8.88
56.7,7460,8.95,58700000,8.89
56.8,7450,8.95,58600000,8.90
56.8,7440,8.96,58600000,8.90
56.9,7440,8.97,58500000,8.91
56.9,7440,8.98,58500000,8.92
56.9,7430,8.98,58500000,8.92
57.0,7430,8.99,58500000,8.93
57.0,7430,9.00,58500000,8.94
57.1,7420,9.00,58400000,8.94
57.1,7420,9.01,58400000,8.95
57.1,7420,9.02,58400000,8.96
57.2,7410,9.02,58400000,8.96
57.2,7410,9.03,58300000,8.97
57.3,7410,9.04,58300000,8.98
57.3,7400,9.04,58200000,8.99
57.3,7390,9.05,58200000,8.99
57.4,7390,9.06,58200000,9.00
57.4,7380,9.07,58100000,9.01
57.5,7380,9.07,58100000,9.01
57.5,7370,9.08,58000000,9.02
57.6,7370,9.09,58000000,9.03
57.6,7370,9.09,58000000,9.03
57.6,7370,9.10,58000000,9.04
57.7,7360,9.11,58000000,9.05
57.7,7360,9.11,57900000,9.05
57.8,7350,9.12,57900000,9.06
57.8,7350,9.13,57900000,9.07
57.8,7350,9.13,57800000,9.07
57.9,7340,9.14,57800000,9.08
57.9,7340,9.15,57800000,9.09
58.0,7340,9.15,57700000,9.09
58.0,7340,9.16,57700000,9.10
58.0,7330,9.17,57700000,9.11
58.1,7330,9.18,57700000,9.11
58.1,7320,9.18,57600000,9.12
58.2,7320,9.19,57600000,9.13
58.2,7320,9.20,57600000,9.14
58.3,7320,9.20,57600000,9.14
58.3,7310,9.21,57600000,9.15
58.3,7310,9.22,57600000,9.16
58.4,7310,9.22,57600000,9.16
58.4,7310,9.23,57600000,9.17
58.5,7310,9.24,57600000,9.18
58.5,7310,9.24,57600000,9.18
58.5,7310,9.25,57600000,9.19
58.6,7310,9.26,57600000,9.20
58.6,7320,9.26,57600000,9.20
58.7,7320,9.27,57600000,9.21
58.7,7320,9.28,57600000,9.22
58.7,7320,9.29,57600000,9.22
58.8,7320,9.29,57600000,9.23
58.8,7320,9.30,57600000,9.24
58.9,7320,9.31,57600000,9.24
58.9,7320,9.31,57600000,9.25
58.9,7320,9.32,57600000,9.26
59.0,7320,9.33,57600000,9.27
59.0,7320,9.33,57600000,9.27
59.1,7330,9.34,57700000,9.28
59.1,7320,9.35,57600000,9.29
59.2,7330,9.35,57700000,9.29
59.2,7330,9.36,57700000,9.30
59.2,7330,9.37,57700000,9.31
59.3,7330,9.37,57700000,9.31
59.3,7330,9.38,57700000,9.32
59.4,7340,9.39,57800000,9.33
59.4,7340,9.40,57800000,9.33
59.4,7340,9.40,57800000,9.34
59.5,7340,9.41,57800000,9.35
59.5,7350,9.42,57800000,9.35
59.6,7350,9.42,57800000,9.36
59.6,7350,9.43,57900000,9.37
59.6,7350,9.44,57900000,9.37
59.7,7350,9.44,57900000,9.38
59.7,7350,9.45,57900000,9.39
59.8,7350,9.46,57900000,9.39
59.8,7360,9.46,57900000,9.40
59.9,7360,9.47,57900000,9.41
59.9,7360,9.48,57900000,9.42
59.9,7360,9.48,57900000,9.42
60.0,7360,9.49,58000000,9.43
60.0,7360,9.50,57900000,9.44
60.1,7360,9.51,58000000,9.44
60.1,7360,9.51,58000000,9.45
60.1,7360,9.52,58000000,9.46
60.2,7360,9.53,58000000,9.46
60.2,7360,9.53,57900000,9.47
60.3,7360,9.54,58000000,9.48
60.3,7360,9.55,57900000,9.48
60.3,7360,9.55,57900000,9.49
60.4,7360,9.56,57900000,9.50
60.4,7360,9.57,57900000,9.50
60.5,7350,9.57,57900000,9.51
60.5,7350,9.58,57900000,9.52
60.5,7350,9.59,57800000,9.53
60.6,7350,9.59,57800000,9.53
60.6,7350,9.60,57800000,9.54
60.7,7340,9.61,57800000,9.55
60.7,7340,9.62,57800000,9.55
60.8,7340,9.62,57800000,9.56
60.8,7340,9.63,57800000,9.57
60.8,7340,9.64,57800000,9.57
60.9,7340,9.64,57800000,9.58
60.9,7330,9.65,57700000,9.59
61.0,7330,9.66,57700000,9.59
61.0,7330,9.66,57700000,9.60
61.0,7330,9.67,57700000,9.61
61.1,7320,9.68,57600000,9.61
61.1,7320,9.68,57600000,9.62
61.2,7320,9.69,57600000,9.63
61.2,7320,9.70,57600000,9.63
61.2,7320,9.71,57600000,9.64
61.3,7310,9.71,57600000,9.65
61.3,7310,9.72,57600000,9.65
61.4,7310,9.73,57500000,9.66
61.4,7310,9.73,57500000,9.67
61.4,7300,9.74,57500000,9.68
61.5,7300,9.75,57500000,9.68
61.5,7300,9.75,57500000,9.69
61.6,7300,9.76,57500000,9.70
61.6,7300,9.77,57400000,9.70
61.7,7300,9.77,57400000,9.71
61.7,7300,9.78,57400000,9.72
61.7,7290,9.79,57400000,9.72
61.8,7290,9.79,57400000,9.73
61.8,7280,9.80,57300000,9.74
61.9,7280,9.81,57300000,9.74
61.9,7280,9.82,57300000,9.75
61.9,7280,9.82,57300000,9.76
62.0,7270,9.83,57300000,9.76
62.0,7270,9.84,57200000,9.77
62.1,7270,9.84,57200000,9.78
62.1,7270,9.85,57200000,9.78
62.1,7260,9.86,57200000,9.79
62.2,7260,9.86,57100000,9.80
62.2,7260,9.87,57100000,9.81
62.3,7250,9.88,57100000,9.81
62.3,7250,9.88,57100000,9.82
62.4,7250,9.89,57100000,9.83
62.4,7250,9.90,57100000,9.83
62.4,7250,9.90,57000000,9.84
62.5,7240,9.91,57000000,9.85
62.5,7240,9.92,57000000,9.85
62.6,7240,9.92,57000000,9.86
62.6,7240,9.93,57000000,9.87
62.6,7240,9.94,57000000,9.87
62.7,7240,9.95,57000000,9.88
62.7,7230,9.95,56900000,9.89
62.8,7240,9.96,57000000,9.89
62.8,7230,9.97,56900000,9.90
62.8,7230,9.97,56900000,9.91
62.9,7230,9.98,56900000,9.91
62.9,7230,9.99,56900000,9.92
63.0,7230,9.99,56900000,9.93
63.0,7230,10.0,56900000,9.94
63.0,7230,10.0,56900000,9.94
63.1,7230,10.0,56900000,9.95
63.1,7230,10.0,56900000,9.96
63.2,7230,10.0,56900000,9.96
63.2,7240,10.0,57000000,9.97
63.3,7230,10.0,56900000,9.98
63.3,7240,10.0,57000000,9.98
63.3,7240,10.1,57000000,9.99
63.4,7240,10.1,57000000,10.0
63.4,7240,10.1,57000000,10.0
63.5,7240,10.1,57000000,10.0
63.5,7240,10.1,57000000,10.0
63.5,7240,10.1,57000000,10.0
63.6,7240,10.1,57000000,10.0
63.6,7240,10.1,57000000,10.0
63.7,7240,10.1,57000000,10.0
63.7,7240,10.1,57000000,10.1
63.7,7240,10.1,57000000,10.1
63.8,7240,10.1,57000000,10.1
63.8,7240,10.1,57000000,10.1
7.46,56.9,0.0810,462000,0.0800
8.06,110,0.184,892000,0.182
8.67,168,0.286,1360000,0.283
9.28,283,0.389,2300000,0.384
9.89,514,0.491,4170000,0.486
10.5,1070,0.594,8700000,0.587
11.1,2050,0.696,16600000,0.688
11.7,3320,0.798,26900000,0.789
12.3,4850,0.901,39400000,0.891
12.9,6530,1.00,53000000,0.992
13.5,8240,1.11,66900000,1.09
14.1,9950,1.21,80800000,1.19
14.8,11600,1.31,94400000,1.30
15.4,13200,1.41,107000000,1.40
16.0,14700,1.52,119000000,1.50
16.6,15800,1.62,128000000,1.60
17.2,16300,1.72,132000000,1.70
17.8,15800,1.82,128000000,1.80
18.4,16300,1.93,132000000,1.90
19.0,16600,2.03,135000000,2.01
19.6,16800,2.13,136000000,2.11
20.2,16100,2.23,130000000,2.21
20.8,15300,2.34,124000000,2.31
21.4,14600,2.44,119000000,2.41
21.9,5000,2.52,40600000,2.49