File: data/InventWood/Superwood-ID24s-07302025.csv
Time (sec),Force (N),Position (mm),Stress (Pa),Strain (m/m)
13.2,18.3,0.0186,170000,0.000373
13.3,19.2,0.0263,178000,0.000528
13.4,20.3,0.0344,188000,0.000692
13.5,21.8,0.0423,202000,0.000850
13.6,23.2,0.0505,215000,0.00101
13.7,24.8,0.0585,230000,0.00117
13.8,26.6,0.0664,246000,0.00133
13.9,28.8,0.0745,267000,0.00150
14.0,31.1,0.0824,289000,0.00165
14.1,33.7,0.0904,312000,0.00182
14.2,35.9,0.0985,333000,0.00198
14.3,38.1,0.106,353000,0.00214
14.4,40.6,0.115,376000,0.00230
14.5,43.6,0.123,404000,0.00246
14.6,46.4,0.130,430000,0.00262
14.7,49.4,0.139,458000,0.00278
14.8,52.6,0.147,487000,0.00294
14.9,56.7,0.155,525000,0.00310
15.0,61.3,0.163,568000,0.00327
15.1,65.9,0.171,611000,0.00343
15.1,71.2,0.179,660000,0.00359
15.2,76.6,0.187,710000,0.00375
15.3,82.6,0.195,766000,0.00391
15.4,89.3,0.203,828000,0.00407
15.5,96.2,0.211,892000,0.00423
15.6,103,0.219,958000,0.00439
15.7,111,0.227,1030000,0.00456
15.8,118,0.235,1100000,0.00472
15.9,127,0.243,1170000,0.00488
16.0,136,0.251,1260000,0.00504
16.1,145,0.259,1340000,0.00520
16.2,154,0.267,1430000,0.00536
16.3,163,0.275,1510000,0.00553
16.4,171,0.283,1590000,0.00569
16.5,180,0.291,1670000,0.00585
16.6,189,0.299,1750000,0.00601
16.7,198,0.307,1840000,0.00617
16.8,207,0.315,1920000,0.00633
16.9,217,0.323,2010000,0.00649
17.0,227,0.331,2100000,0.00665
17.1,237,0.339,2200000,0.00682
17.2,248,0.347,2300000,0.00697
17.3,259,0.355,2400000,0.00714
17.4,269,0.363,2500000,0.00730
17.5,280,0.371,2590000,0.00746
17.6,291,0.379,2700000,0.00762
17.7,301,0.387,2790000,0.00778
17.8,312,0.395,2890000,0.00794
17.9,323,0.404,2990000,0.00810
18.0,333,0.412,3090000,0.00826
18.1,344,0.420,3190000,0.00843
18.1,356,0.428,3300000,0.00859
18.2,367,0.436,3400000,0.00875
18.3,379,0.444,3520000,0.00892
18.4,391,0.452,3630000,0.00908
18.5,404,0.460,3740000,0.00923
18.6,416,0.468,3860000,0.00940
18.7,429,0.476,3970000,0.00955
18.8,442,0.484,4090000,0.00972
18.9,455,0.492,4220000,0.00988
19.0,468,0.500,4340000,0.0100
19.1,482,0.508,4470000,0.0102
19.2,496,0.516,4600000,0.0104
19.3,510,0.524,4730000,0.0105
19.4,525,0.532,4860000,0.0107
19.5,539,0.540,5000000,0.0108
19.6,554,0.548,5130000,0.0110
19.7,569,0.556,5270000,0.0112
19.8,584,0.564,5410000,0.0113
19.9,600,0.572,5560000,0.0115
20.0,617,0.581,5720000,0.0117
20.1,634,0.588,5880000,0.0118
20.2,657,0.596,6090000,0.0120
20.3,689,0.605,6390000,0.0121
20.4,719,0.612,6670000,0.0123
20.5,751,0.621,6960000,0.0125
20.6,780,0.629,7230000,0.0126
20.7,811,0.637,7510000,0.0128
20.8,842,0.645,7800000,0.0129
20.9,872,0.653,8090000,0.0131
21.0,905,0.661,8390000,0.0133
21.0,937,0.669,8690000,0.0134
21.1,969,0.677,8990000,0.0136
21.2,1010,0.685,9330000,0.0138
21.3,1050,0.693,9700000,0.0139
21.4,1090,0.701,10100000,0.0141
21.5,1130,0.709,10400000,0.0142
21.6,1170,0.717,10800000,0.0144
21.7,1210,0.725,11200000,0.0146
21.8,1250,0.733,11600000,0.0147
21.9,1290,0.741,11900000,0.0149
22.0,1330,0.749,12300000,0.0150
22.1,1370,0.757,12700000,0.0152
22.2,1410,0.765,13100000,0.0154
22.3,1460,0.773,13500000,0.0155
22.4,1500,0.781,13900000,0.0157
22.5,1550,0.789,14400000,0.0158
22.6,1600,0.797,14800000,0.0160
22.7,1640,0.805,15200000,0.0162
22.8,1690,0.813,15700000,0.0163
22.9,1740,0.821,16100000,0.0165
23.0,1780,0.829,16500000,0.0167
23.1,1830,0.837,17000000,0.0168
23.2,1880,0.846,17500000,0.0170
23.3,1930,0.853,17900000,0.0171
23.4,1980,0.862,18400000,0.0173
23.5,2030,0.870,18800000,0.0175
23.6,2080,0.878,19300000,0.0176
23.7,2130,0.886,19700000,0.0178
23.8,2180,0.893,20200000,0.0179
23.9,2230,0.902,20700000,0.0181
23.9,2280,0.910,21200000,0.0183
24.0,2330,0.917,21600000,0.0184
24.1,2390,0.926,22200000,0.0186
24.2,2450,0.934,22700000,0.0187
24.3,2500,0.942,23200000,0.0189
24.4,2560,0.950,23800000,0.0191
24.5,2620,0.958,24300000,0.0192
24.6,2680,0.966,24900000,0.0194
24.7,2740,0.974,25400000,0.0196
24.8,2800,0.982,26000000,0.0197
24.9,2870,0.990,26600000,0.0199
25.0,2940,0.998,27200000,0.0200
25.1,3000,1.01,27800000,0.0202
25.2,3070,1.01,28400000,0.0204
25.3,3130,1.02,29000000,0.0205
25.4,3200,1.03,29700000,0.0207
25.5,3270,1.04,30300000,0.0208
25.6,3330,1.05,30900000,0.0210
25.7,3400,1.05,31500000,0.0212
25.8,3470,1.06,32200000,0.0213
25.9,3540,1.07,32800000,0.0215
26.0,3600,1.08,33400000,0.0217
26.1,3670,1.09,34000000,0.0218
26.2,3740,1.09,34600000,0.0220
26.3,3800,1.10,35200000,0.0221
26.4,3870,1.11,35800000,0.0223
26.5,3930,1.12,36400000,0.0225
26.6,4000,1.13,37100000,0.0226
26.7,4060,1.13,37700000,0.0228
26.8,4130,1.14,38300000,0.0229
26.8,4200,1.15,38900000,0.0231
26.9,4260,1.16,39500000,0.0233
27.0,4330,1.17,40100000,0.0234
27.1,4400,1.17,40800000,0.0236
27.2,4460,1.18,41400000,0.0237
27.3,4530,1.19,42000000,0.0239
27.4,4600,1.20,42600000,0.0241
27.5,4670,1.21,43200000,0.0242
27.6,4730,1.21,43900000,0.0244
27.7,4800,1.22,44500000,0.0246
27.8,4870,1.23,45100000,0.0247
27.9,4930,1.24,45700000,0.0249
28.0,5000,1.25,46300000,0.0250
28.1,5070,1.26,47000000,0.0252
28.2,5130,1.26,47600000,0.0254
28.3,5200,1.27,48200000,0.0255
28.4,5260,1.28,48800000,0.0257
28.5,5320,1.29,49400000,0.0258
28.6,5390,1.30,50000000,0.0260
28.7,5460,1.30,50600000,0.0262
28.8,5520,1.31,51200000,0.0263
28.9,5590,1.32,51800000,0.0265
29.0,5670,1.33,52500000,0.0267
29.1,5740,1.34,53200000,0.0268
29.2,5820,1.34,53900000,0.0270
29.3,5900,1.35,54700000,0.0271
29.4,5980,1.36,55400000,0.0273
29.5,6060,1.37,56200000,0.0275
29.6,6090,1.38,56500000,0.0276
29.7,6180,1.38,57300000,0.0278
29.8,6270,1.39,58100000,0.0279
29.8,6360,1.40,58900000,0.0281
29.9,6450,1.41,59800000,0.0283
30.0,6540,1.42,60600000,0.0284
30.1,6630,1.42,61500000,0.0286
30.2,6730,1.43,62400000,0.0288
30.3,6830,1.44,63300000,0.0289
30.4,6920,1.45,64200000,0.0291
30.5,7020,1.46,65100000,0.0292
30.6,7120,1.46,66000000,0.0294
30.7,7200,1.47,66800000,0.0296
30.8,7300,1.48,67600000,0.0297
30.9,7390,1.49,68500000,0.0299
31.0,7480,1.50,69300000,0.0300
31.1,7580,1.50,70200000,0.0302
31.2,7670,1.51,71100000,0.0304
31.3,7750,1.52,71800000,0.0305
31.4,7840,1.53,72700000,0.0307
31.5,7940,1.54,73600000,0.0308
31.6,8050,1.54,74600000,0.0310
31.7,8120,1.55,75200000,0.0312
31.8,8200,1.56,76000000,0.0313
31.9,8310,1.57,77100000,0.0315
32.0,8420,1.58,78100000,0.0317
32.1,8540,1.58,79200000,0.0318
32.2,8660,1.59,80200000,0.0320
32.3,8770,1.60,81300000,0.0321
32.4,8880,1.61,82300000,0.0323
32.5,9000,1.62,83400000,0.0325
32.6,9120,1.62,84600000,0.0326
32.7,9250,1.63,85800000,0.0328
32.7,9380,1.64,86900000,0.0329
32.8,9500,1.65,88100000,0.0331
32.9,9630,1.66,89300000,0.0333
33.0,9760,1.66,90400000,0.0334
33.1,9880,1.67,91600000,0.0336
33.2,10000,1.68,92700000,0.0338
33.3,10100,1.69,93800000,0.0339
33.4,10200,1.70,94900000,0.0341
33.5,10400,1.70,96000000,0.0342
33.6,10500,1.71,96900000,0.0344
33.7,10600,1.72,98000000,0.0345
33.8,10700,1.73,98900000,0.0347
33.9,10800,1.74,99900000,0.0349
34.0,10900,1.74,101000000,0.0350
34.1,11000,1.75,102000000,0.0352
34.2,11100,1.76,103000000,0.0354
34.3,11200,1.77,104000000,0.0355
34.4,11300,1.78,104000000,0.0357
34.5,11400,1.78,105000000,0.0358
34.6,11400,1.79,106000000,0.0360
34.7,11500,1.80,107000000,0.0362
34.8,11600,1.81,108000000,0.0363
34.9,11700,1.82,108000000,0.0365
35.0,11800,1.83,109000000,0.0367
35.1,11900,1.83,110000000,0.0368
35.2,11900,1.84,110000000,0.0370
35.3,12000,1.85,111000000,0.0371
35.4,12100,1.86,112000000,0.0373
35.5,12100,1.87,112000000,0.0375
35.6,12200,1.87,113000000,0.0376
35.6,12200,1.88,114000000,0.0378
35.7,12300,1.89,114000000,0.0379
35.8,12400,1.90,115000000,0.0381
35.9,12400,1.91,115000000,0.0383
36.0,12500,1.91,116000000,0.0384
36.1,12500,1.92,116000000,0.0386
36.2,12600,1.93,116000000,0.0387
36.3,12600,1.94,117000000,0.0389
36.4,12600,1.95,117000000,0.0391
36.5,12600,1.95,117000000,0.0392
36.6,12600,1.96,117000000,0.0394
36.7,12600,1.97,117000000,0.0396
36.8,12600,1.98,117000000,0.0397
36.9,12500,1.99,116000000,0.0399
37.0,12500,1.99,115000000,0.0400
37.1,12300,2.00,114000000,0.0402
37.2,12200,2.01,113000000,0.0404
37.3,12100,2.02,112000000,0.0405
37.4,12000,2.03,111000000,0.0407
37.5,11900,2.03,111000000,0.0408
37.6,11800,2.04,110000000,0.0410
37.7,11800,2.05,109000000,0.0412
37.8,11700,2.06,108000000,0.0413
37.9,11400,2.07,106000000,0.0415
38.0,9690,2.08,89800000,0.0417
38.1,9070,2.08,84000000,0.0418
38.2,9000,2.09,83400000,0.0420
38.3,9010,2.10,83500000,0.0421
38.4,9050,2.11,83900000,0.0423
38.5,9110,2.11,84400000,0.0425
38.6,9170,2.12,85000000,0.0426
38.6,9230,2.13,85500000,0.0428
38.7,9290,2.14,86100000,0.0429
38.8,9350,2.15,86700000,0.0431
38.9,9400,2.15,87100000,0.0433
39.0,9460,2.16,87700000,0.0434
39.1,9510,2.17,88100000,0.0436
39.2,9550,2.18,88600000,0.0437
39.3,9600,2.19,89000000,0.0439
39.4,9640,2.19,89400000,0.0441
39.5,9680,2.20,89700000,0.0442
39.6,9720,2.21,90100000,0.0444
39.7,9750,2.22,90300000,0.0445
39.8,9780,2.23,90600000,0.0447
39.9,9810,2.23,90900000,0.0449
40.0,9830,2.24,91100000,0.0450
40.1,9860,2.25,91400000,0.0452
40.2,9880,2.26,91600000,0.0454
40.3,9900,2.27,91800000,0.0455
40.4,9930,2.27,92000000,0.0457
40.5,9950,2.28,92200000,0.0458
40.6,9980,2.29,92500000,0.0460
40.7,10000,2.30,92800000,0.0462
40.8,10000,2.31,93100000,0.0463
40.9,10100,2.32,93400000,0.0465
41.0,10100,2.32,93700000,0.0467
41.1,10100,2.33,94000000,0.0468
41.2,10200,2.34,94300000,0.0470
41.3,10200,2.35,94400000,0.0471
41.4,10200,2.36,94400000,0.0473
41.5,10200,2.36,94400000,0.0475
41.5,10200,2.37,94500000,0.0476
41.6,10200,2.38,94800000,0.0478
41.7,10300,2.39,95100000,0.0479
41.8,10300,2.40,95400000,0.0481
41.9,10300,2.40,95800000,0.0483
42.0,10400,2.41,96200000,0.0484
42.1,10400,2.42,96600000,0.0486
42.2,10500,2.43,97000000,0.0487
42.3,10500,2.44,97300000,0.0489
42.4,10500,2.44,97700000,0.0491
42.5,10600,2.45,98000000,0.0492
42.6,10600,2.46,98300000,0.0494
42.7,10600,2.47,98600000,0.0496
42.8,10700,2.48,98800000,0.0497
42.9,10700,2.48,99000000,0.0499
43.0,10700,2.49,99300000,0.0500
43.1,10700,2.50,99500000,0.0502
43.2,10800,2.51,99700000,0.0504
43.3,10800,2.52,100000000,0.0505
43.4,10800,2.52,100000000,0.0507
43.5,10800,2.53,100000000,0.0508
43.6,10800,2.54,101000000,0.0510
43.7,10900,2.55,101000000,0.0512
43.8,10900,2.56,101000000,0.0513
43.9,10900,2.56,101000000,0.0515
44.0,10900,2.57,101000000,0.0516
44.1,10900,2.58,101000000,0.0518
44.2,11000,2.59,102000000,0.0520
44.3,11000,2.60,102000000,0.0521
44.4,11000,2.60,102000000,0.0523
44.4,11000,2.61,102000000,0.0525
44.5,11000,2.62,102000000,0.0526
44.6,11000,2.63,102000000,0.0528
44.7,11000,2.64,102000000,0.0529
44.8,10900,2.64,101000000,0.0531
44.9,10900,2.65,101000000,0.0533
45.0,10900,2.66,101000000,0.0534
45.1,10900,2.67,101000000,0.0536
45.2,10800,2.68,100000000,0.0538
45.3,10800,2.68,100000000,0.0539
45.4,10800,2.69,99800000,0.0541
45.5,10700,2.70,99600000,0.0542
45.6,10700,2.71,99400000,0.0544
45.7,10700,2.72,99200000,0.0546
45.8,10700,2.72,99100000,0.0547
45.9,10700,2.73,99000000,0.0549
46.0,10700,2.74,99100000,0.0550
46.1,10700,2.75,99100000,0.0552
46.2,10700,2.76,99200000,0.0554
46.3,10700,2.77,99400000,0.0555
46.4,10700,2.77,99500000,0.0557
46.5,10800,2.78,99800000,0.0558
46.6,10800,2.79,100000000,0.0560
46.7,10800,2.80,100000000,0.0562
46.8,10800,2.81,100000000,0.0563
46.9,10900,2.81,101000000,0.0565
47.0,10900,2.82,101000000,0.0567
47.1,10900,2.83,101000000,0.0568
47.2,10900,2.84,101000000,0.0570
47.3,11000,2.85,102000000,0.0571
47.4,11000,2.85,102000000,0.0573
47.4,11000,2.86,102000000,0.0575
47.5,11000,2.87,102000000,0.0576
47.6,11000,2.88,102000000,0.0578
47.7,11000,2.89,102000000,0.0579
47.8,11000,2.89,102000000,0.0581
47.9,11000,2.90,102000000,0.0583
48.0,11000,2.91,102000000,0.0584
48.1,11000,2.92,102000000,0.0586
48.2,11000,2.93,102000000,0.0587
48.3,10900,2.93,101000000,0.0589
48.4,10900,2.94,101000000,0.0591
48.5,10900,2.95,101000000,0.0592
48.6,10900,2.96,101000000,0.0594
48.7,10900,2.97,101000000,0.0596
48.8,10900,2.97,101000000,0.0597
48.9,10900,2.98,101000000,0.0599
49.0,10800,2.99,100000000,0.0600
49.1,10800,3.00,99900000,0.0602
49.2,10700,3.01,99200000,0.0604
49.3,10600,3.01,98300000,0.0605
49.4,10500,3.02,97600000,0.0607
49.5,10400,3.03,96700000,0.0608
49.6,10300,3.04,95600000,0.0610
49.7,10200,3.05,94600000,0.0612
49.8,10200,3.05,94200000,0.0613
49.9,10100,3.06,94000000,0.0615
50.0,10200,3.07,94200000,0.0617
50.1,10200,3.08,94300000,0.0618
50.2,10200,3.09,94700000,0.0620
50.3,10300,3.09,95100000,0.0621
50.3,10300,3.10,95400000,0.0623
50.4,10300,3.11,95900000,0.0625
50.5,10400,3.12,96300000,0.0626
50.6,10400,3.13,96600000,0.0628
50.7,10500,3.13,97100000,0.0629
50.8,10500,3.14,97400000,0.0631
50.9,10600,3.15,97800000,0.0633
51.0,10600,3.16,98200000,0.0634
51.1,10600,3.17,98600000,0.0636
51.2,10700,3.17,99100000,0.0637
51.3,10700,3.18,99500000,0.0639
51.4,10800,3.19,100000000,0.0641
51.5,10800,3.20,100000000,0.0642
51.6,10900,3.21,101000000,0.0644
51.7,10900,3.21,101000000,0.0646
51.8,11000,3.22,102000000,0.0647
51.9,11000,3.23,102000000,0.0649
52.0,11100,3.24,103000000,0.0650
52.1,11100,3.25,103000000,0.0652
52.2,11200,3.25,104000000,0.0654
52.3,11200,3.26,104000000,0.0655
52.4,11300,3.27,104000000,0.0657
52.5,11300,3.28,105000000,0.0658
52.6,11400,3.29,105000000,0.0660
52.7,11400,3.30,106000000,0.0662
52.8,11400,3.30,106000000,0.0663
52.9,11500,3.31,106000000,0.0665
53.0,11500,3.32,107000000,0.0666
53.1,11500,3.33,107000000,0.0668
53.2,11600,3.34,107000000,0.0670
53.2,11600,3.34,107000000,0.0671
53.3,11600,3.35,108000000,0.0673
53.4,11600,3.36,108000000,0.0675
53.5,11600,3.37,107000000,0.0676
53.6,11600,3.38,107000000,0.0678
53.7,11500,3.38,107000000,0.0679
53.8,11500,3.39,107000000,0.0681
53.9,11500,3.40,107000000,0.0683
54.0,11500,3.41,106000000,0.0684
54.1,11500,3.42,106000000,0.0686
54.2,11400,3.42,106000000,0.0687
54.3,11400,3.43,106000000,0.0689
54.4,11400,3.44,105000000,0.0691
54.5,11400,3.45,105000000,0.0692
54.6,11300,3.46,105000000,0.0694
54.7,11300,3.46,105000000,0.0696
54.8,11300,3.47,105000000,0.0697
54.9,11300,3.48,105000000,0.0699
55.0,11300,3.49,105000000,0.0700
55.1,11300,3.50,105000000,0.0702
55.2,11200,3.50,104000000,0.0704
55.3,11100,3.51,103000000,0.0705
55.4,10900,3.52,101000000,0.0707
55.5,10700,3.53,98900000,0.0708
55.6,10600,3.54,97900000,0.0710
55.7,10500,3.54,97400000,0.0712
55.8,10500,3.55,97100000,0.0713
55.9,10400,3.56,96400000,0.0715
56.0,10300,3.57,95100000,0.0716
56.1,10200,3.58,94300000,0.0718
56.2,10100,3.58,93700000,0.0720
56.2,10100,3.59,93300000,0.0721
56.3,10000,3.60,92700000,0.0723
56.4,9910,3.61,91900000,0.0725
56.5,9820,3.62,91000000,0.0726
56.6,9730,3.62,90200000,0.0728
56.7,9650,3.63,89400000,0.0729
56.8,9510,3.64,88200000,0.0731
56.9,9290,3.65,86100000,0.0733
57.0,8950,3.66,83000000,0.0734
57.1,8830,3.66,81900000,0.0736
57.2,8780,3.67,81400000,0.0738
57.3,8760,3.68,81200000,0.0739
57.4,8770,3.69,81300000,0.0741
57.5,8780,3.70,81300000,0.0742
57.6,8800,3.70,81500000,0.0744
57.7,8820,3.71,81800000,0.0746
57.8,8850,3.72,82000000,0.0747
57.9,8880,3.73,82300000,0.0749
58.0,8910,3.74,82600000,0.0750
58.1,8940,3.74,82900000,0.0752
58.2,8970,3.75,83200000,0.0754
58.3,9000,3.76,83500000,0.0755
58.4,9030,3.77,83700000,0.0757
58.5,9070,3.78,84000000,0.0758
58.6,9090,3.78,84300000,0.0760
58.7,9120,3.79,84500000,0.0762
58.8,9150,3.80,84800000,0.0763
58.9,9170,3.81,85000000,0.0765
59.0,9200,3.82,85300000,0.0766
59.1,9230,3.83,85600000,0.0768
59.1,9250,3.83,85800000,0.0770
59.2,9280,3.84,86100000,0.0771
59.3,9310,3.85,86300000,0.0773
59.4,9330,3.86,86500000,0.0775
59.5,9360,3.87,86700000,0.0776
59.6,9370,3.87,86900000,0.0778
59.7,9400,3.88,87100000,0.0779
59.8,9420,3.89,87400000,0.0781
59.9,9440,3.90,87500000,0.0783
60.0,9470,3.91,87800000,0.0784
60.1,9490,3.91,88000000,0.0786
60.2,9510,3.92,88200000,0.0787
60.3,9530,3.93,88400000,0.0789
60.4,9550,3.94,88500000,0.0791
60.5,9570,3.95,88700000,0.0792
60.6,9590,3.95,88900000,0.0794
60.7,9610,3.96,89100000,0.0795
60.8,9630,3.97,89200000,0.0797
60.9,9640,3.98,89400000,0.0799
61.0,9660,3.99,89500000,0.0800
61.1,9670,3.99,89700000,0.0802
61.2,9690,4.00,89800000,0.0804
61.3,9700,4.01,89900000,0.0805
61.4,9710,4.02,90000000,0.0807
61.5,9720,4.03,90100000,0.0808
61.6,9730,4.03,90200000,0.0810
61.7,9740,4.04,90300000,0.0812
61.8,9750,4.05,90400000,0.0813
61.9,9760,4.06,90500000,0.0815
62.0,9770,4.07,90600000,0.0816
62.0,9770,4.07,90600000,0.0818
62.1,9780,4.08,90700000,0.0820
62.2,9790,4.09,90700000,0.0821
62.3,9790,4.10,90800000,0.0823
62.4,9800,4.11,90900000,0.0825
62.5,9800,4.11,90900000,0.0826
62.6,9810,4.12,90900000,0.0828
62.7,9820,4.13,91000000,0.0829
62.8,9820,4.14,91000000,0.0831
62.9,9830,4.15,91100000,0.0833
63.0,9840,4.15,91200000,0.0834
63.1,9840,4.16,91200000,0.0836
63.2,9850,4.17,91300000,0.0837
63.3,9870,4.18,91500000,0.0839
63.4,9880,4.19,91600000,0.0841
63.5,9890,4.19,91700000,0.0842
63.6,9910,4.20,91800000,0.0844
63.7,9920,4.21,92000000,0.0845
63.8,9930,4.22,92100000,0.0847
63.9,9940,4.23,92100000,0.0849
64.0,9950,4.23,92200000,0.0850
64.1,9950,4.24,92300000,0.0852
64.2,9950,4.25,92300000,0.0854
64.3,9950,4.26,92200000,0.0855
64.4,9950,4.27,92200000,0.0857
64.5,9930,4.27,92100000,0.0858
64.6,9920,4.28,92000000,0.0860
64.7,9900,4.29,91800000,0.0862
64.8,9870,4.30,91500000,0.0863
64.9,9840,4.31,91200000,0.0865
65.0,9810,4.31,90900000,0.0866
65.0,9780,4.32,90700000,0.0868
65.1,9760,4.33,90500000,0.0870
65.2,9740,4.34,90200000,0.0871
65.3,9710,4.35,90000000,0.0873
65.4,9680,4.36,89700000,0.0875
65.5,9650,4.36,89500000,0.0876
65.6,9630,4.37,89300000,0.0878
65.7,9610,4.38,89100000,0.0879
65.8,9600,4.39,89000000,0.0881
65.9,9590,4.40,88900000,0.0883
66.0,9580,4.40,88800000,0.0884
66.1,9570,4.41,88700000,0.0886
66.2,9560,4.42,88600000,0.0887
66.3,9550,4.43,88500000,0.0889
66.4,9540,4.44,88400000,0.0891
66.5,9530,4.44,88400000,0.0892
66.6,9520,4.45,88300000,0.0894
66.7,9520,4.46,88200000,0.0896
66.8,9510,4.47,88100000,0.0897
66.9,9500,4.48,88000000,0.0899
67.0,9490,4.48,87900000,0.0900
67.1,9470,4.49,87800000,0.0902
67.2,9460,4.50,87700000,0.0904
67.3,9450,4.51,87600000,0.0905
67.4,9430,4.52,87400000,0.0907
67.5,9420,4.52,87300000,0.0908
67.6,9410,4.53,87200000,0.0910
67.7,9390,4.54,87100000,0.0912
67.8,9390,4.55,87000000,0.0913
67.9,9370,4.56,86900000,0.0915
67.9,9360,4.56,86800000,0.0916
68.0,9350,4.57,86700000,0.0918
68.1,9340,4.58,86600000,0.0920
68.2,9340,4.59,86600000,0.0921
68.3,9340,4.60,86600000,0.0923
68.4,9330,4.60,86500000,0.0925
68.5,9330,4.61,86500000,0.0926
68.6,9330,4.62,86500000,0.0928
68.7,9330,4.63,86500000,0.0929
68.8,9330,4.64,86500000,0.0931
68.9,9330,4.64,86500000,0.0933
69.0,9330,4.65,86500000,0.0934
69.1,9330,4.66,86500000,0.0936
69.2,9330,4.67,86500000,0.0937
69.3,9330,4.68,86500000,0.0939
69.4,9340,4.68,86500000,0.0941
69.5,9340,4.69,86500000,0.0942
69.6,9340,4.70,86600000,0.0944
69.7,9350,4.71,86700000,0.0946
69.8,9360,4.72,86800000,0.0947
69.9,9370,4.72,86900000,0.0949
70.0,9380,4.73,87000000,0.0950
70.1,9400,4.74,87100000,0.0952
70.2,9410,4.75,87300000,0.0954
70.3,9420,4.76,87400000,0.0955
70.4,9440,4.76,87500000,0.0957
70.5,9460,4.77,87700000,0.0958
70.6,9470,4.78,87800000,0.0960
70.7,9490,4.79,87900000,0.0962
70.8,9500,4.80,88100000,0.0963
70.8,9520,4.80,88200000,0.0965
70.9,9540,4.81,88400000,0.0966
71.0,9550,4.82,88500000,0.0968
71.1,9570,4.83,88700000,0.0970
71.2,9590,4.84,88900000,0.0971
71.3,9600,4.84,89000000,0.0973
71.4,9620,4.85,89100000,0.0975
71.5,9640,4.86,89300000,0.0976
71.6,9650,4.87,89400000,0.0978
71.7,9670,4.88,89600000,0.0979
71.8,9670,4.89,89700000,0.0981
71.9,9680,4.89,89700000,0.0983
72.0,9690,4.90,89800000,0.0984
72.1,9700,4.91,89900000,0.0986
72.2,9710,4.92,90000000,0.0987
72.3,9720,4.93,90100000,0.0989
72.4,9730,4.93,90200000,0.0991
72.5,9740,4.94,90300000,0.0992
72.6,9750,4.95,90300000,0.0994
72.7,9750,4.96,90400000,0.0995
72.8,9760,4.97,90400000,0.0997
72.9,9760,4.97,90500000,0.0999
73.0,9760,4.98,90500000,0.100
73.1,9770,4.99,90600000,0.100
73.2,9770,5.00,90600000,0.100
73.3,9780,5.01,90700000,0.101
73.4,9780,5.01,90700000,0.101
73.5,9780,5.02,90600000,0.101
73.6,9780,5.03,90600000,0.101
73.7,9780,5.04,90700000,0.101
73.8,9780,5.05,90700000,0.101
73.8,9790,5.05,90700000,0.101
73.9,9790,5.06,90800000,0.102
74.0,9800,5.07,90800000,0.102
74.1,9810,5.08,90900000,0.102
74.2,9820,5.09,91000000,0.102
74.3,9840,5.09,91200000,0.102
74.4,9850,5.10,91300000,0.102
74.5,9860,5.11,91400000,0.103
74.6,9880,5.12,91600000,0.103
74.7,9910,5.13,91800000,0.103
74.8,9920,5.13,91900000,0.103
74.9,9940,5.14,92100000,0.103
75.0,9950,5.15,92200000,0.103
75.1,9960,5.16,92300000,0.104
75.2,9970,5.17,92400000,0.104
75.3,9980,5.17,92500000,0.104
75.4,9990,5.18,92600000,0.104
75.5,10000,5.19,92800000,0.104
75.6,10000,5.20,92900000,0.104
75.7,10000,5.21,93100000,0.105
75.8,10100,5.21,93300000,0.105
75.9,10100,5.22,93400000,0.105
76.0,10100,5.23,93600000,0.105
76.1,10100,5.24,93800000,0.105
76.2,10100,5.25,94000000,0.105
76.3,10200,5.25,94200000,0.106
76.4,10200,5.26,94400000,0.106
76.5,10200,5.27,94600000,0.106
76.6,10200,5.28,94800000,0.106
76.7,10200,5.29,95000000,0.106
76.7,10300,5.29,95200000,0.106
76.8,10300,5.30,95400000,0.106
76.9,10300,5.31,95500000,0.107
77.0,10300,5.32,95700000,0.107
77.1,10400,5.33,95900000,0.107
77.2,10400,5.33,96100000,0.107
77.3,10400,5.34,96300000,0.107
77.4,10400,5.35,96500000,0.107
77.5,10400,5.36,96700000,0.108
77.6,10500,5.37,96900000,0.108
77.7,10500,5.38,97000000,0.108
77.8,10500,5.38,97200000,0.108
77.9,10500,5.39,97400000,0.108
78.0,10500,5.40,97500000,0.108
78.1,10500,5.41,97700000,0.109
78.2,10600,5.42,97800000,0.109
78.3,10600,5.42,97900000,0.109
78.4,10600,5.43,98000000,0.109
78.5,10600,5.44,98000000,0.109
78.6,10600,5.45,98100000,0.109
78.7,10600,5.46,98100000,0.110
78.8,10600,5.46,98100000,0.110
78.9,10600,5.47,98100000,0.110
79.0,10600,5.48,98100000,0.110
79.1,10600,5.49,98000000,0.110
79.2,10600,5.50,98000000,0.110
79.3,10600,5.50,98100000,0.111
79.4,10600,5.51,98100000,0.111
79.5,10600,5.52,98100000,0.111
79.6,10600,5.53,98100000,0.111
79.6,10600,5.54,98200000,0.111
79.7,10600,5.54,98300000,0.111
79.8,10600,5.55,98300000,0.111
79.9,10600,5.56,98400000,0.112
80.0,10600,5.57,98500000,0.112
80.1,10600,5.58,98500000,0.112
80.2,10600,5.58,98600000,0.112
80.3,10600,5.59,98700000,0.112
80.4,10700,5.60,98700000,0.112
80.5,10700,5.61,98800000,0.113
80.6,10700,5.62,98900000,0.113
80.7,10700,5.62,98900000,0.113
80.8,10700,5.63,99000000,0.113
80.9,10700,5.64,99000000,0.113
81.0,10700,5.65,99000000,0.113
81.1,10700,5.66,99000000,0.114
81.2,10700,5.66,98900000,0.114
81.3,10700,5.67,98800000,0.114
81.4,10600,5.68,98700000,0.114
81.5,10600,5.69,98600000,0.114
81.6,10600,5.70,98500000,0.114
81.7,10600,5.70,98300000,0.115
81.8,10600,5.71,98100000,0.115
81.9,10600,5.72,98000000,0.115
82.0,10500,5.73,97700000,0.115
82.1,10500,5.74,97500000,0.115
82.2,10500,5.74,97200000,0.115
82.3,10400,5.75,96800000,0.116
82.4,10400,5.76,96300000,0.116
82.5,10300,5.77,95400000,0.116
82.6,9930,5.78,92000000,0.116
82.6,9550,5.79,88500000,0.116
82.7,9290,5.79,86100000,0.116
82.8,9050,5.80,83900000,0.116
82.9,8770,5.81,81300000,0.117
83.0,8610,5.82,79800000,0.117
83.1,8520,5.83,79000000,0.117
83.2,8470,5.83,78500000,0.117
83.3,8430,5.84,78200000,0.117
83.4,8420,5.85,78000000,0.117
83.5,8410,5.86,78000000,0.118
83.6,8400,5.87,77900000,0.118
83.7,8400,5.87,77900000,0.118
83.8,8400,5.88,77800000,0.118
83.9,8390,5.89,77800000,0.118
84.0,8400,5.90,77800000,0.118
84.1,8390,5.91,77800000,0.119
84.2,8400,5.91,77800000,0.119
84.3,8410,5.92,77900000,0.119
84.4,8410,5.93,77900000,0.119
84.5,8410,5.94,78000000,0.119
84.6,8420,5.95,78100000,0.119
84.7,8430,5.95,78100000,0.120
84.8,8440,5.96,78300000,0.120
84.9,8450,5.97,78300000,0.120
85.0,8460,5.98,78400000,0.120
85.1,8470,5.99,78500000,0.120
85.2,8470,5.99,78500000,0.120
85.3,8480,6.00,78600000,0.121
85.4,8490,6.01,78700000,0.121
85.5,8490,6.02,78700000,0.121
85.5,8490,6.03,78700000,0.121
85.6,8500,6.03,78800000,0.121
85.7,8510,6.04,78900000,0.121
85.8,8510,6.05,78900000,0.121
85.9,8510,6.06,78900000,0.122
86.0,8520,6.07,79000000,0.122
86.1,8530,6.07,79100000,0.122
86.2,8540,6.08,79100000,0.122
86.3,8540,6.09,79200000,0.122
86.4,8540,6.10,79200000,0.122
86.5,8540,6.11,79100000,0.123
86.6,8540,6.11,79100000,0.123
86.7,8540,6.12,79100000,0.123
86.8,8530,6.13,79100000,0.123
86.9,8530,6.14,79100000,0.123
87.0,8530,6.15,79100000,0.123
87.1,8530,6.15,79100000,0.124
87.2,8530,6.16,79100000,0.124
87.3,8530,6.17,79100000,0.124
87.4,8540,6.18,79200000,0.124
87.5,8550,6.19,79200000,0.124
87.6,8550,6.19,79300000,0.124
87.7,8560,6.20,79400000,0.125
87.8,8570,6.21,79400000,0.125
87.9,8570,6.22,79500000,0.125
88.0,8580,6.23,79600000,0.125
88.1,8590,6.23,79600000,0.125
88.2,8610,6.24,79800000,0.125
88.3,8620,6.25,79900000,0.126
88.4,8620,6.26,79900000,0.126
88.4,8640,6.27,80100000,0.126
88.5,8650,6.28,80200000,0.126
88.6,8660,6.28,80300000,0.126
88.7,8670,6.29,80400000,0.126
88.8,8680,6.30,80500000,0.126
88.9,8690,6.31,80600000,0.127
89.0,8710,6.32,80700000,0.127
89.1,8710,6.32,80800000,0.127
89.2,8730,6.33,80900000,0.127
89.3,8740,6.34,81000000,0.127
89.4,8750,6.35,81100000,0.127
89.5,8760,6.36,81200000,0.128
89.6,8770,6.36,81300000,0.128
89.7,8780,6.37,81400000,0.128
89.8,8790,6.38,81500000,0.128
89.9,8800,6.39,81600000,0.128
90.0,8810,6.40,81700000,0.128
90.1,8830,6.40,81800000,0.129
90.2,8840,6.41,81900000,0.129
90.3,8850,6.42,82000000,0.129
90.4,8860,6.43,82100000,0.129
90.5,8860,6.44,82200000,0.129
90.6,8870,6.44,82300000,0.129
90.7,8880,6.45,82400000,0.130
90.8,8890,6.46,82400000,0.130
90.9,8900,6.47,82500000,0.130
91.0,8890,6.48,82400000,0.130
91.1,8880,6.48,82300000,0.130
91.2,8860,6.49,82100000,0.130
91.3,8820,6.50,81700000,0.131
91.4,8770,6.51,81300000,0.131
91.4,8700,6.52,80600000,0.131
91.5,8610,6.52,79800000,0.131
91.6,8480,6.53,78600000,0.131
91.7,8300,6.54,76900000,0.131
91.8,8110,6.55,75200000,0.131
91.9,7950,6.56,73700000,0.132
92.0,7830,6.56,72600000,0.132
92.1,7740,6.57,71700000,0.132
92.2,7670,6.58,71100000,0.132
92.3,7620,6.59,70700000,0.132
92.4,7590,6.60,70400000,0.132
92.5,7570,6.60,70200000,0.133
92.6,7550,6.61,70000000,0.133
92.7,7550,6.62,70000000,0.133
92.8,7550,6.63,70000000,0.133
92.9,7540,6.64,69900000,0.133
93.0,7540,6.64,69900000,0.133
93.1,7550,6.65,69900000,0.134
93.2,7550,6.66,70000000,0.134
93.3,7550,6.67,70000000,0.134
93.4,7550,6.68,70000000,0.134
93.5,7560,6.69,70100000,0.134
93.6,7570,6.69,70100000,0.134
93.7,7570,6.70,70100000,0.135
93.8,7580,6.71,70200000,0.135
93.9,7580,6.72,70300000,0.135
94.0,7590,6.72,70300000,0.135
94.1,7590,6.73,70300000,0.135
94.2,7590,6.74,70400000,0.135
94.3,7600,6.75,70400000,0.136
94.3,7600,6.76,70500000,0.136
94.4,7610,6.77,70500000,0.136
94.5,7620,6.77,70600000,0.136
94.6,7630,6.78,70700000,0.136
94.7,7630,6.79,70800000,0.136
94.8,7640,6.80,70900000,0.136
94.9,7650,6.81,70900000,0.137
95.0,7650,6.81,71000000,0.137
95.1,7660,6.82,71000000,0.137
95.2,7660,6.83,71000000,0.137
95.3,7660,6.84,71000000,0.137
95.4,7670,6.85,71100000,0.137
95.5,7670,6.85,71100000,0.138
95.6,7670,6.86,71100000,0.138
95.7,7680,6.87,71200000,0.138
95.8,7680,6.88,71200000,0.138
95.9,7680,6.89,71200000,0.138
96.0,7670,6.89,71100000,0.138
96.1,7650,6.90,70900000,0.139
96.2,7640,6.91,70800000,0.139
96.3,7630,6.92,70800000,0.139
96.4,7630,6.93,70700000,0.139
96.5,7630,6.93,70700000,0.139
96.6,7630,6.94,70700000,0.139
96.7,7640,6.95,70800000,0.140
96.8,7650,6.96,70900000,0.140
96.9,7650,6.97,70900000,0.140
97.0,7660,6.97,71000000,0.140
97.1,7670,6.98,71100000,0.140
97.2,7680,6.99,71200000,0.140
97.2,7700,7.00,71400000,0.141
97.3,7720,7.01,71500000,0.141
97.4,7730,7.01,71700000,0.141
97.5,7750,7.02,71800000,0.141
97.6,7760,7.03,71900000,0.141
97.7,7780,7.04,72100000,0.141
97.8,7800,7.05,72300000,0.141
97.9,7810,7.05,72400000,0.142
98.0,7830,7.06,72600000,0.142
98.1,7850,7.07,72800000,0.142
98.2,7870,7.08,72900000,0.142
98.3,7890,7.09,73100000,0.142
98.4,7900,7.09,73300000,0.142
98.5,7920,7.10,73400000,0.143
98.6,7940,7.11,73600000,0.143
98.7,7940,7.12,73600000,0.143
98.8,7960,7.13,73800000,0.143
98.9,7980,7.13,73900000,0.143
99.0,7980,7.14,74000000,0.143
99.1,8000,7.15,74100000,0.144
99.2,8010,7.16,74300000,0.144
99.3,8020,7.17,74300000,0.144
99.4,8040,7.17,74500000,0.144
99.5,8050,7.18,74600000,0.144
99.6,8060,7.19,74700000,0.144
99.7,8070,7.20,74800000,0.145
99.8,8080,7.21,74900000,0.145
99.9,8100,7.22,75000000,0.145
100,8110,7.22,75200000,0.145
100,8120,7.23,75300000,0.145
100,8130,7.24,75400000,0.145
100,8150,7.25,75500000,0.146
100,8160,7.26,75600000,0.146
100,8170,7.26,75700000,0.146
101,8180,7.27,75800000,0.146
101,8190,7.28,75900000,0.146
101,8200,7.29,76000000,0.146
101,8210,7.30,76100000,0.146
101,8220,7.30,76200000,0.147
101,8230,7.31,76300000,0.147
101,8240,7.32,76400000,0.147
101,8250,7.33,76500000,0.147
101,8260,7.34,76600000,0.147
101,8270,7.34,76700000,0.147
102,8280,7.35,76800000,0.148
102,8280,7.36,76800000,0.148
102,8290,7.37,76900000,0.148
102,8300,7.38,77000000,0.148
102,8300,7.38,77000000,0.148
102,8310,7.39,77000000,0.148
102,8320,7.40,77100000,0.149
102,8310,7.41,77100000,0.149
102,8320,7.42,77100000,0.149
102,8310,7.42,77100000,0.149
102,8310,7.43,77000000,0.149
103,8300,7.44,77000000,0.149
103,8300,7.45,76900000,0.150
103,8290,7.46,76900000,0.150
103,8300,7.46,76900000,0.150
103,8290,7.47,76800000,0.150
103,8290,7.48,76800000,0.150
103,8290,7.49,76900000,0.150
103,8290,7.50,76900000,0.151
103,8300,7.50,76900000,0.151
103,8300,7.51,76900000,0.151
104,8300,7.52,76900000,0.151
104,8300,7.53,76900000,0.151
104,8300,7.54,76900000,0.151
104,8300,7.54,77000000,0.151
104,8310,7.55,77000000,0.152
104,8300,7.56,77000000,0.152
104,8310,7.57,77000000,0.152
104,8310,7.58,77000000,0.152
104,8300,7.58,77000000,0.152
104,8310,7.59,77000000,0.152
105,8300,7.60,77000000,0.153
105,8300,7.61,77000000,0.153
105,8310,7.62,77000000,0.153
105,8300,7.62,77000000,0.153
105,8310,7.63,77000000,0.153
105,8320,7.64,77100000,0.153
105,8320,7.65,77100000,0.154
105,8330,7.66,77200000,0.154
105,8330,7.66,77200000,0.154
105,8330,7.67,77200000,0.154
105,8340,7.68,77300000,0.154
106,8340,7.69,77300000,0.154
106,8340,7.70,77300000,0.155
106,8350,7.70,77400000,0.155
106,8340,7.71,77300000,0.155
106,8340,7.72,77300000,0.155
106,8340,7.73,77300000,0.155
106,8340,7.74,77300000,0.155
106,8330,7.74,77200000,0.156
106,8330,7.75,77200000,0.156
106,8320,7.76,77100000,0.156
107,8320,7.77,77100000,0.156
107,8310,7.78,77000000,0.156
107,8300,7.78,76900000,0.156
107,8300,7.79,76900000,0.156
107,8280,7.80,76800000,0.157
107,8280,7.81,76800000,0.157
107,8280,7.82,76700000,0.157
107,8270,7.83,76600000,0.157
107,8260,7.83,76600000,0.157
107,8260,7.84,76600000,0.157
107,8250,7.85,76500000,0.158
108,8250,7.86,76500000,0.158
108,8240,7.87,76400000,0.158
108,8240,7.87,76300000,0.158
108,8230,7.88,76300000,0.158
108,8220,7.89,76200000,0.158
108,8220,7.90,76200000,0.159
108,8220,7.91,76200000,0.159
108,8220,7.91,76200000,0.159
108,8210,7.92,76100000,0.159
108,8220,7.93,76200000,0.159
109,8210,7.94,76100000,0.159
109,8210,7.95,76100000,0.160
109,8210,7.95,76100000,0.160
109,8210,7.96,76100000,0.160
109,8200,7.97,76100000,0.160
109,8200,7.98,76000000,0.160
109,8200,7.99,76000000,0.160
109,8200,7.99,76000000,0.161
109,8190,8.00,75900000,0.161
109,8190,8.01,75900000,0.161
110,8190,8.02,75900000,0.161
110,8190,8.03,75900000,0.161
110,8190,8.03,75900000,0.161
110,8190,8.05,75900000,0.162