File: data/InventWood/Superwood-ID23s-07302025.csv
Time (sec),Force (N),Position (mm),Stress (Pa),Strain (m/m)
15.3,19.2,0.0176,173000,0.000343
15.4,20.7,0.0277,187000,0.000539
15.5,22.1,0.0380,199000,0.000740
15.6,23.3,0.0483,210000,0.000942
15.8,25.6,0.0585,230000,0.00114
15.9,27.9,0.0686,251000,0.00134
16.0,30.3,0.0788,273000,0.00154
16.1,32.7,0.0889,295000,0.00173
16.2,35.3,0.0993,318000,0.00194
16.4,38.2,0.110,344000,0.00214
16.5,41.4,0.120,373000,0.00234
16.6,43.8,0.130,395000,0.00254
16.7,46.6,0.140,420000,0.00274
16.8,50.1,0.151,451000,0.00294
17.0,54.3,0.161,489000,0.00314
17.1,58.3,0.171,525000,0.00334
17.2,62.1,0.181,560000,0.00354
17.3,65.9,0.192,594000,0.00374
17.4,68.9,0.202,621000,0.00394
17.6,72.2,0.212,651000,0.00414
17.7,74.8,0.222,674000,0.00433
17.8,78.4,0.233,706000,0.00453
17.9,83.7,0.243,754000,0.00473
18.0,89.8,0.253,809000,0.00493
18.2,95.9,0.263,864000,0.00513
18.3,102,0.274,922000,0.00533
18.4,109,0.284,978000,0.00553
18.5,115,0.294,1030000,0.00573
18.6,121,0.304,1090000,0.00593
18.8,129,0.315,1160000,0.00613
18.9,136,0.325,1220000,0.00633
19.0,145,0.335,1300000,0.00653
19.1,156,0.345,1410000,0.00673
19.2,173,0.355,1560000,0.00693
19.4,192,0.366,1730000,0.00713
19.5,211,0.376,1900000,0.00733
19.6,230,0.386,2070000,0.00753
19.7,250,0.396,2250000,0.00773
19.8,268,0.407,2410000,0.00793
20.0,287,0.417,2580000,0.00813
20.1,304,0.427,2740000,0.00833
20.2,321,0.437,2900000,0.00852
20.3,338,0.448,3050000,0.00872
20.4,354,0.458,3190000,0.00892
20.6,371,0.468,3340000,0.00912
20.7,387,0.478,3490000,0.00932
20.8,404,0.488,3640000,0.00952
20.9,422,0.499,3800000,0.00972
21.0,440,0.509,3960000,0.00992
21.2,456,0.519,4110000,0.0101
21.3,472,0.530,4260000,0.0103
21.4,489,0.540,4400000,0.0105
21.5,507,0.550,4570000,0.0107
21.6,525,0.560,4730000,0.0109
21.8,543,0.571,4890000,0.0111
21.9,561,0.581,5050000,0.0113
22.0,581,0.591,5230000,0.0115
22.1,603,0.601,5430000,0.0117
22.2,625,0.612,5630000,0.0119
22.4,650,0.622,5850000,0.0121
22.5,676,0.632,6090000,0.0123
22.6,702,0.642,6330000,0.0125
22.7,730,0.653,6580000,0.0127
22.8,761,0.663,6860000,0.0129
23.0,793,0.673,7150000,0.0131
23.1,826,0.683,7440000,0.0133
23.2,859,0.693,7740000,0.0135
23.3,892,0.704,8040000,0.0137
23.4,930,0.714,8380000,0.0139
23.6,977,0.724,8810000,0.0141
23.7,1040,0.734,9390000,0.0143
23.8,1100,0.744,9950000,0.0145
23.9,1160,0.755,10500000,0.0147
24.0,1220,0.765,11000000,0.0149
24.2,1280,0.775,11600000,0.0151
24.3,1350,0.786,12100000,0.0153
24.4,1410,0.796,12700000,0.0155
24.5,1470,0.806,13300000,0.0157
24.6,1530,0.816,13800000,0.0159
24.8,1600,0.827,14400000,0.0161
24.9,1670,0.837,15100000,0.0163
25.0,1750,0.847,15700000,0.0165
25.1,1820,0.857,16400000,0.0167
25.2,1900,0.867,17100000,0.0169
25.4,1980,0.878,17800000,0.0171
25.5,2060,0.888,18600000,0.0173
25.6,2140,0.898,19300000,0.0175
25.7,2220,0.909,20000000,0.0177
25.8,2290,0.919,20700000,0.0179
25.9,2370,0.929,21400000,0.0181
26.1,2450,0.939,22100000,0.0183
26.2,2530,0.950,22800000,0.0185
26.3,2610,0.960,23500000,0.0187
26.4,2680,0.970,24200000,0.0189
26.5,2760,0.980,24900000,0.0191
26.7,2840,0.990,25600000,0.0193
26.8,2920,1.00,26300000,0.0195
26.9,3010,1.01,27100000,0.0197
27.0,3090,1.02,27800000,0.0199
27.1,3170,1.03,28500000,0.0201
27.3,3250,1.04,29300000,0.0203
27.4,3340,1.05,30100000,0.0205
27.5,3420,1.06,30800000,0.0207
27.6,3510,1.07,31600000,0.0209
27.7,3590,1.08,32400000,0.0211
27.9,3680,1.09,33100000,0.0213
28.0,3770,1.10,33900000,0.0215
28.1,3850,1.11,34700000,0.0217
28.2,3940,1.12,35500000,0.0219
28.3,4010,1.13,36100000,0.0221
28.5,4090,1.14,36900000,0.0223
28.6,4160,1.15,37500000,0.0225
28.7,4230,1.16,38100000,0.0227
28.8,4300,1.17,38700000,0.0229
28.9,4360,1.19,39200000,0.0231
29.1,4420,1.20,39800000,0.0233
29.2,4470,1.21,40300000,0.0235
29.3,4530,1.22,40900000,0.0237
29.4,4600,1.23,41400000,0.0239
29.5,4650,1.24,41900000,0.0241
29.7,4710,1.25,42400000,0.0243
29.8,4770,1.26,43000000,0.0245
29.9,4830,1.27,43500000,0.0247
30.0,4890,1.28,44000000,0.0249
30.1,4950,1.29,44600000,0.0251
30.3,5010,1.30,45200000,0.0253
30.4,5080,1.31,45800000,0.0255
30.5,5150,1.32,46400000,0.0257
30.6,5220,1.33,47000000,0.0259
30.7,5280,1.34,47600000,0.0261
30.9,5340,1.35,48100000,0.0263
31.0,5400,1.36,48600000,0.0265
31.1,5450,1.37,49100000,0.0267
31.2,5510,1.38,49600000,0.0269
31.3,5570,1.39,50200000,0.0271
31.5,5620,1.40,50700000,0.0273
31.6,5690,1.41,51200000,0.0275
31.7,5750,1.42,51800000,0.0277
31.8,5810,1.43,52400000,0.0279
31.9,5880,1.44,53000000,0.0281
32.1,5950,1.45,53600000,0.0283
32.2,6020,1.46,54300000,0.0285
32.3,6090,1.47,54900000,0.0287
32.4,6170,1.48,55600000,0.0289
32.5,6250,1.49,56300000,0.0291
32.7,6330,1.50,57000000,0.0293
32.8,6400,1.51,57700000,0.0295
32.9,6480,1.52,58400000,0.0297
33.0,6550,1.53,59000000,0.0299
33.1,6630,1.54,59700000,0.0301
33.3,6710,1.55,60400000,0.0303
33.4,6780,1.56,61100000,0.0305
33.5,6850,1.57,61800000,0.0307
33.6,6930,1.58,62400000,0.0309
33.7,7000,1.60,63100000,0.0311
33.9,7070,1.61,63700000,0.0313
34.0,7130,1.62,64200000,0.0315
34.1,7190,1.63,64800000,0.0317
34.2,7240,1.64,65300000,0.0319
34.3,7300,1.65,65700000,0.0321
34.5,7340,1.66,66100000,0.0323
34.6,7380,1.67,66500000,0.0325
34.7,7430,1.68,66900000,0.0327
34.8,7480,1.69,67400000,0.0329
34.9,7540,1.70,67900000,0.0331
35.1,7600,1.71,68500000,0.0333
35.2,7660,1.72,69000000,0.0335
35.3,7720,1.73,69500000,0.0337
35.4,7790,1.74,70200000,0.0339
35.5,7860,1.75,70800000,0.0341
35.6,7930,1.76,71500000,0.0343
35.8,8000,1.77,72100000,0.0345
35.9,8080,1.78,72800000,0.0347
36.0,8160,1.79,73500000,0.0349
36.1,8230,1.80,74200000,0.0351
36.2,8320,1.81,74900000,0.0353
36.4,8400,1.82,75700000,0.0355
36.5,8470,1.83,76300000,0.0357
36.6,8550,1.84,77100000,0.0359
36.7,8630,1.85,77800000,0.0361
36.8,8710,1.86,78400000,0.0363
37.0,8780,1.87,79100000,0.0365
37.1,8840,1.88,79600000,0.0367
37.2,8900,1.89,80200000,0.0369
37.3,8960,1.90,80700000,0.0371
37.4,9010,1.91,81200000,0.0373
37.6,9070,1.92,81700000,0.0375
37.7,9120,1.93,82200000,0.0377
37.8,9180,1.94,82700000,0.0379
37.9,9250,1.95,83300000,0.0381
38.0,9310,1.96,83900000,0.0383
38.2,9380,1.97,84500000,0.0385
38.3,9450,1.98,85100000,0.0387
38.4,9510,1.99,85700000,0.0389
38.5,9570,2.00,86200000,0.0391
38.6,9640,2.02,86900000,0.0393
38.8,9710,2.03,87500000,0.0395
38.9,9770,2.04,88100000,0.0397
39.0,9840,2.05,88700000,0.0399
39.1,9910,2.06,89300000,0.0401
39.2,9980,2.07,89900000,0.0403
39.4,10100,2.08,90600000,0.0405
39.5,10100,2.09,91300000,0.0407
39.6,10200,2.10,91900000,0.0409
39.7,10300,2.11,92500000,0.0411
39.8,10300,2.12,93200000,0.0413
40.0,10400,2.13,93900000,0.0415
40.1,10500,2.14,94600000,0.0417
40.2,10600,2.15,95300000,0.0419
40.3,10600,2.16,95900000,0.0421
40.4,10700,2.17,96500000,0.0423
40.6,10800,2.18,97200000,0.0425
40.7,10900,2.19,97800000,0.0427
40.8,10900,2.20,98500000,0.0429
40.9,11000,2.21,99100000,0.0431
41.0,11100,2.22,99600000,0.0433
41.2,11100,2.23,100000000,0.0435
41.3,11200,2.24,101000000,0.0437
41.4,11200,2.25,101000000,0.0439
41.5,11300,2.26,102000000,0.0441
41.6,11300,2.27,102000000,0.0443
41.8,11400,2.28,103000000,0.0445
41.9,11400,2.29,103000000,0.0447
42.0,11500,2.30,103000000,0.0449
42.1,11500,2.31,104000000,0.0451
42.2,11500,2.32,104000000,0.0453
42.4,11600,2.33,104000000,0.0455
42.5,11600,2.34,105000000,0.0457
42.6,11600,2.35,105000000,0.0459
42.7,11700,2.36,105000000,0.0461
42.8,11700,2.37,105000000,0.0463
43.0,11700,2.38,105000000,0.0465
43.1,11700,2.39,106000000,0.0467
43.2,11800,2.40,106000000,0.0469
43.3,11800,2.41,106000000,0.0471
43.4,11900,2.43,107000000,0.0473
43.6,11900,2.44,107000000,0.0475
43.7,12000,2.45,108000000,0.0477
43.8,12000,2.46,108000000,0.0479
43.9,12100,2.47,109000000,0.0481
44.0,12100,2.48,109000000,0.0483
44.2,12200,2.49,110000000,0.0485
44.3,12200,2.50,110000000,0.0487
44.4,12200,2.51,110000000,0.0489
44.5,12200,2.52,110000000,0.0491
44.6,12200,2.53,110000000,0.0493
44.8,12100,2.54,109000000,0.0495
44.9,11900,2.55,107000000,0.0497
45.0,11600,2.56,105000000,0.0499
45.1,11500,2.57,104000000,0.0501
45.2,11500,2.58,104000000,0.0503
45.4,11500,2.59,104000000,0.0505
45.5,11500,2.60,104000000,0.0507
45.6,11600,2.61,104000000,0.0509
45.7,11700,2.62,105000000,0.0511
45.8,11700,2.63,106000000,0.0513
45.9,11800,2.64,106000000,0.0515
46.1,11800,2.65,107000000,0.0517
46.2,11900,2.66,107000000,0.0519
46.3,12000,2.67,108000000,0.0521
46.4,12000,2.68,108000000,0.0523
46.5,12100,2.69,109000000,0.0525
46.7,12100,2.70,109000000,0.0527
46.8,12100,2.71,109000000,0.0529
46.9,12200,2.72,110000000,0.0531
47.0,12200,2.73,110000000,0.0533
47.1,12300,2.74,110000000,0.0535
47.3,12300,2.75,111000000,0.0537
47.4,12300,2.76,111000000,0.0539
47.5,12300,2.77,111000000,0.0541
47.6,12300,2.78,111000000,0.0543
47.7,12300,2.79,111000000,0.0545
47.9,12300,2.80,111000000,0.0547
48.0,12300,2.81,111000000,0.0549
48.1,12400,2.82,111000000,0.0551
48.2,12400,2.83,112000000,0.0553
48.3,12400,2.85,112000000,0.0555
48.5,12400,2.86,112000000,0.0557
48.6,12500,2.87,112000000,0.0559
48.7,12500,2.88,113000000,0.0561
48.8,12600,2.89,113000000,0.0563
48.9,12600,2.90,114000000,0.0565
49.1,12600,2.91,114000000,0.0567
49.2,12700,2.92,114000000,0.0569
49.3,12700,2.93,115000000,0.0571
49.4,12800,2.94,115000000,0.0573
49.5,12800,2.95,115000000,0.0575
49.7,12800,2.96,116000000,0.0577
49.8,12900,2.97,116000000,0.0579
49.9,12900,2.98,116000000,0.0581
50.0,12900,2.99,116000000,0.0583
50.1,13000,3.00,117000000,0.0585
50.3,13000,3.01,117000000,0.0587
50.4,13000,3.02,117000000,0.0589
50.5,13000,3.03,118000000,0.0591
50.6,13100,3.04,118000000,0.0593
50.7,13100,3.05,118000000,0.0595
50.9,13100,3.06,118000000,0.0597
51.0,13200,3.07,118000000,0.0599
51.1,13200,3.08,119000000,0.0601
51.2,13200,3.09,119000000,0.0603
51.3,13200,3.10,119000000,0.0605
51.5,13200,3.11,119000000,0.0606
51.6,13200,3.12,119000000,0.0608
51.7,13300,3.13,119000000,0.0610
51.8,13300,3.14,120000000,0.0612
51.9,13300,3.15,120000000,0.0614
52.1,13300,3.16,120000000,0.0616
52.2,13300,3.17,120000000,0.0618
52.3,13300,3.18,120000000,0.0621
52.4,13300,3.19,120000000,0.0623
52.5,13300,3.20,120000000,0.0625
52.7,13200,3.21,119000000,0.0627
52.8,13200,3.22,118000000,0.0629
52.9,13000,3.23,117000000,0.0631
53.0,12700,3.25,115000000,0.0633
53.1,11900,3.26,107000000,0.0635
53.3,11100,3.27,99700000,0.0637
53.4,10900,3.28,98600000,0.0639
53.5,10900,3.29,98600000,0.0640
53.6,11000,3.30,99100000,0.0643
53.7,11100,3.31,99800000,0.0645
53.9,11200,3.32,100000000,0.0646
54.0,11200,3.33,101000000,0.0648
54.1,11300,3.34,102000000,0.0650
54.2,11400,3.35,103000000,0.0652
54.3,11500,3.36,104000000,0.0654
54.5,11600,3.37,104000000,0.0656
54.6,11700,3.38,105000000,0.0658
54.7,11700,3.39,106000000,0.0660
54.8,11800,3.40,106000000,0.0662
54.9,11900,3.41,107000000,0.0664
55.1,12000,3.42,108000000,0.0666
55.2,12000,3.43,108000000,0.0668
55.3,12100,3.44,109000000,0.0670
55.4,12200,3.45,110000000,0.0672
55.5,12200,3.46,110000000,0.0674
55.7,12300,3.47,111000000,0.0676
55.8,12300,3.48,111000000,0.0678
55.9,12400,3.49,112000000,0.0680
56.0,12400,3.50,112000000,0.0682
56.1,12500,3.51,113000000,0.0684
56.2,12600,3.52,113000000,0.0686
56.4,12600,3.53,113000000,0.0688
56.5,12600,3.54,114000000,0.0690
56.6,12700,3.55,114000000,0.0692
56.7,12700,3.56,115000000,0.0694
56.8,12800,3.57,115000000,0.0696
57.0,12800,3.58,116000000,0.0698
57.1,12900,3.59,116000000,0.0700
57.2,12900,3.60,116000000,0.0702
57.3,12900,3.61,116000000,0.0704
57.4,12900,3.62,117000000,0.0706
57.6,13000,3.63,117000000,0.0708
57.7,12900,3.64,117000000,0.0710
57.8,12900,3.65,116000000,0.0712
57.9,12800,3.66,116000000,0.0714
58.0,12800,3.68,116000000,0.0716
58.2,12800,3.69,116000000,0.0718
58.3,12800,3.70,115000000,0.0720
58.4,12800,3.71,115000000,0.0722
58.5,12800,3.72,116000000,0.0724
58.6,12800,3.73,116000000,0.0726
58.8,12800,3.74,116000000,0.0728
58.9,12800,3.75,115000000,0.0730
59.0,12800,3.76,115000000,0.0732
59.1,12800,3.77,115000000,0.0734
59.2,12800,3.78,115000000,0.0736
59.4,12800,3.79,115000000,0.0738
59.5,12800,3.80,115000000,0.0740
59.6,12800,3.81,115000000,0.0742
59.7,12800,3.82,115000000,0.0744
59.8,12800,3.83,115000000,0.0746
60.0,12800,3.84,115000000,0.0748
60.1,12800,3.85,115000000,0.0750
60.2,12800,3.86,116000000,0.0752
60.3,12800,3.87,116000000,0.0754
60.4,12900,3.88,116000000,0.0756
60.6,12900,3.89,116000000,0.0758
60.7,12900,3.90,116000000,0.0760
60.8,12900,3.91,116000000,0.0762
60.9,12900,3.92,117000000,0.0764
61.0,13000,3.93,117000000,0.0766
61.2,13000,3.94,117000000,0.0768
61.3,13000,3.95,117000000,0.0770
61.4,13000,3.96,117000000,0.0772
61.5,13000,3.97,117000000,0.0774
61.6,13100,3.98,118000000,0.0776
61.8,13100,3.99,118000000,0.0778
61.9,13100,4.00,118000000,0.0780
62.0,13100,4.01,118000000,0.0782
62.1,13100,4.02,118000000,0.0784
62.2,13200,4.03,119000000,0.0786
62.4,13200,4.04,119000000,0.0788
62.5,13200,4.05,119000000,0.0790
62.6,13200,4.06,119000000,0.0792
62.7,13300,4.07,119000000,0.0794
62.8,13300,4.08,120000000,0.0796
63.0,13300,4.10,120000000,0.0798
63.1,13300,4.11,120000000,0.0800
63.2,13400,4.12,120000000,0.0802
63.3,13400,4.13,121000000,0.0804
63.4,13400,4.14,121000000,0.0806
63.6,13400,4.15,121000000,0.0808
63.7,13500,4.16,121000000,0.0810
63.8,13500,4.17,121000000,0.0812
63.9,13500,4.18,122000000,0.0814
64.0,13500,4.19,122000000,0.0816
64.2,13500,4.20,122000000,0.0818
64.3,13600,4.21,122000000,0.0820
64.4,13600,4.22,122000000,0.0822
64.5,13600,4.23,122000000,0.0824
64.6,13600,4.24,123000000,0.0826
64.8,13600,4.25,123000000,0.0828
64.9,13600,4.26,123000000,0.0830
65.0,13600,4.27,123000000,0.0832
65.1,13700,4.28,123000000,0.0834
65.2,13700,4.29,123000000,0.0836
65.4,13700,4.30,123000000,0.0838
65.5,13700,4.31,123000000,0.0840
65.6,13700,4.32,124000000,0.0842
65.7,13700,4.33,124000000,0.0844
65.8,13800,4.34,124000000,0.0846
65.9,13800,4.35,124000000,0.0848
66.1,13800,4.36,124000000,0.0850
66.2,13800,4.37,125000000,0.0852
66.3,13900,4.38,125000000,0.0854
66.4,13900,4.39,125000000,0.0856
66.5,13900,4.40,125000000,0.0858
66.7,13900,4.41,125000000,0.0860
66.8,13900,4.42,126000000,0.0862
66.9,14000,4.43,126000000,0.0864
67.0,14000,4.44,126000000,0.0866
67.1,14000,4.45,126000000,0.0868
67.3,14100,4.46,127000000,0.0870
67.4,14100,4.47,127000000,0.0872
67.5,14200,4.48,128000000,0.0874
67.6,14200,4.49,128000000,0.0876
67.7,14200,4.50,128000000,0.0878
67.9,14300,4.51,129000000,0.0880
68.0,14300,4.52,129000000,0.0882
68.1,14400,4.54,130000000,0.0884
68.2,14400,4.55,130000000,0.0886
68.3,14500,4.56,130000000,0.0888
68.5,14500,4.57,131000000,0.0890
68.6,14500,4.58,131000000,0.0892
68.7,14600,4.59,131000000,0.0894
68.8,14600,4.60,132000000,0.0896
68.9,14600,4.61,132000000,0.0898
69.1,14600,4.62,132000000,0.0900
69.2,14600,4.63,132000000,0.0902
69.3,14600,4.64,131000000,0.0904
69.4,14600,4.65,131000000,0.0906
69.5,14500,4.66,131000000,0.0908
69.7,14400,4.67,130000000,0.0910
69.8,14300,4.68,128000000,0.0912
69.9,14100,4.69,127000000,0.0914
70.0,14000,4.70,126000000,0.0916
70.1,13900,4.71,125000000,0.0918
70.3,13900,4.72,125000000,0.0920
70.4,13800,4.73,124000000,0.0922
70.5,13800,4.74,124000000,0.0924
70.6,13700,4.75,124000000,0.0926
70.7,13700,4.76,123000000,0.0928
70.9,13700,4.77,123000000,0.0930
71.0,13700,4.78,123000000,0.0932
71.1,13700,4.79,123000000,0.0934
71.2,13700,4.80,123000000,0.0936
71.3,13700,4.81,123000000,0.0938
71.5,13700,4.82,123000000,0.0940
71.6,13700,4.83,124000000,0.0942
71.7,13700,4.84,124000000,0.0944
71.8,13800,4.85,124000000,0.0946
71.9,13800,4.86,124000000,0.0948
72.1,13800,4.87,124000000,0.0950
72.2,13800,4.88,125000000,0.0952
72.3,13900,4.89,125000000,0.0954
72.4,13900,4.90,125000000,0.0956
72.5,13900,4.91,125000000,0.0958
72.7,13900,4.92,126000000,0.0960
72.8,14000,4.93,126000000,0.0962
72.9,14000,4.95,126000000,0.0964
73.0,14000,4.96,126000000,0.0966
73.1,14000,4.97,126000000,0.0968
73.3,14000,4.98,126000000,0.0970
73.4,14000,4.99,126000000,0.0972
73.5,13900,5.00,126000000,0.0974
73.6,13900,5.01,125000000,0.0976
73.7,13800,5.02,125000000,0.0978
73.9,13800,5.03,124000000,0.0980
74.0,13700,5.04,123000000,0.0982
74.1,13600,5.05,123000000,0.0984
74.2,13600,5.06,122000000,0.0986
74.3,13500,5.07,122000000,0.0988
74.5,13400,5.08,121000000,0.0990
74.6,13400,5.09,121000000,0.0992
74.7,13300,5.10,120000000,0.0994
74.8,13300,5.11,120000000,0.0996
74.9,13200,5.12,119000000,0.0998
75.1,13200,5.13,119000000,0.100
75.2,13100,5.14,118000000,0.100
75.3,13100,5.15,118000000,0.100
75.4,13000,5.16,117000000,0.101
75.5,13000,5.17,117000000,0.101
75.7,12900,5.18,116000000,0.101
75.8,12900,5.19,116000000,0.101
75.9,12800,5.20,115000000,0.101
76.0,12700,5.21,115000000,0.102
76.1,12700,5.22,114000000,0.102
76.2,12500,5.23,113000000,0.102
76.4,12400,5.24,112000000,0.102
76.5,12300,5.25,111000000,0.102
76.6,12300,5.26,111000000,0.103
76.7,12200,5.27,110000000,0.103
76.8,12200,5.28,110000000,0.103
77.0,12200,5.29,110000000,0.103
77.1,12200,5.30,110000000,0.103
77.2,12300,5.31,110000000,0.104
77.3,12300,5.32,111000000,0.104
77.4,12300,5.33,111000000,0.104
77.6,12400,5.34,112000000,0.104
77.7,12400,5.35,112000000,0.104
77.8,12500,5.36,113000000,0.105
77.9,12600,5.38,113000000,0.105
78.0,12700,5.39,114000000,0.105
78.2,12700,5.40,115000000,0.105
78.3,12800,5.41,115000000,0.105
78.4,12900,5.42,116000000,0.106
78.5,12900,5.43,117000000,0.106
78.6,13000,5.44,117000000,0.106
78.8,13100,5.45,118000000,0.106
78.9,13100,5.46,118000000,0.106
79.0,13200,5.47,119000000,0.107
79.1,13200,5.48,119000000,0.107
79.2,13300,5.49,120000000,0.107
79.4,13400,5.50,120000000,0.107
79.5,13400,5.51,121000000,0.107
79.6,13500,5.52,121000000,0.108
79.7,13500,5.53,122000000,0.108
79.8,13600,5.54,123000000,0.108
80.0,13700,5.55,123000000,0.108
80.1,13700,5.56,124000000,0.108
80.2,13800,5.57,124000000,0.109
80.3,13900,5.58,125000000,0.109
80.4,14000,5.59,126000000,0.109
80.6,14000,5.60,126000000,0.109
80.7,14100,5.61,127000000,0.109
80.8,14100,5.62,127000000,0.110
80.9,14200,5.63,128000000,0.110
81.0,14200,5.64,128000000,0.110
81.2,14300,5.65,129000000,0.110
81.3,14300,5.66,129000000,0.110
81.4,14400,5.67,129000000,0.111
81.5,14400,5.68,130000000,0.111
81.6,14500,5.69,130000000,0.111
81.8,14500,5.70,131000000,0.111
81.9,14500,5.71,131000000,0.111
82.0,14500,5.72,131000000,0.112
82.1,14500,5.73,131000000,0.112
82.2,14400,5.74,130000000,0.112
82.4,14300,5.75,129000000,0.112
82.5,14200,5.76,128000000,0.112
82.6,14100,5.77,127000000,0.113
82.7,14000,5.79,126000000,0.113
82.8,13900,5.80,125000000,0.113
83.0,13900,5.81,125000000,0.113
83.1,13900,5.82,125000000,0.113
83.2,13800,5.83,125000000,0.114
83.3,13800,5.84,125000000,0.114
83.4,13800,5.85,125000000,0.114
83.6,13900,5.86,125000000,0.114
83.7,13900,5.87,125000000,0.114
83.8,13900,5.88,126000000,0.115
83.9,14000,5.89,126000000,0.115
84.0,14000,5.90,126000000,0.115
84.2,14100,5.91,127000000,0.115
84.3,14100,5.92,127000000,0.115
84.4,14200,5.93,128000000,0.116
84.5,14200,5.94,128000000,0.116
84.6,14300,5.95,128000000,0.116
84.8,14300,5.96,129000000,0.116
84.9,14300,5.97,128000000,0.116
85.0,14100,5.98,127000000,0.117
85.1,14100,5.99,127000000,0.117
85.2,14000,6.00,126000000,0.117
85.4,14000,6.01,126000000,0.117
85.5,14000,6.02,126000000,0.117
85.6,14000,6.03,126000000,0.118
85.7,14000,6.04,127000000,0.118
85.8,14100,6.05,127000000,0.118
86.0,14100,6.06,127000000,0.118
86.1,14100,6.07,127000000,0.118
86.2,14200,6.08,128000000,0.119
86.3,14200,6.09,128000000,0.119
86.4,14300,6.10,128000000,0.119
86.5,14300,6.11,129000000,0.119
86.7,14300,6.12,129000000,0.119
86.8,14400,6.13,129000000,0.120
86.9,14400,6.14,130000000,0.120
87.0,14400,6.15,130000000,0.120
87.1,14400,6.16,130000000,0.120
87.3,14400,6.17,130000000,0.120
87.4,14400,6.18,130000000,0.121
87.5,14400,6.19,130000000,0.121
87.6,14400,6.21,130000000,0.121
87.7,14400,6.22,130000000,0.121
87.9,14300,6.23,129000000,0.121
88.0,14100,6.24,127000000,0.122
88.1,13900,6.25,126000000,0.122
88.2,13800,6.26,124000000,0.122
88.3,13700,6.27,123000000,0.122
88.5,13600,6.28,123000000,0.122
88.6,13600,6.29,123000000,0.123
88.7,13600,6.30,122000000,0.123
88.8,13600,6.31,122000000,0.123
88.9,13600,6.32,122000000,0.123
89.1,13600,6.33,122000000,0.123
89.2,13600,6.34,123000000,0.124
89.3,13600,6.35,123000000,0.124
89.4,13600,6.36,123000000,0.124
89.5,13600,6.37,123000000,0.124
89.7,13700,6.38,123000000,0.124
89.8,13700,6.39,123000000,0.125
89.9,13700,6.40,123000000,0.125
90.0,13700,6.41,124000000,0.125
90.1,13800,6.42,124000000,0.125
90.3,13800,6.43,124000000,0.125
90.4,13800,6.44,124000000,0.126
90.5,13800,6.45,125000000,0.126
90.6,13900,6.46,125000000,0.126
90.7,13900,6.47,125000000,0.126
90.9,13900,6.48,125000000,0.126
91.0,13900,6.49,125000000,0.127
91.1,13900,6.50,126000000,0.127
91.2,14000,6.51,126000000,0.127
91.3,14000,6.52,126000000,0.127
91.5,14000,6.53,126000000,0.127
91.6,14000,6.54,126000000,0.128
91.7,14000,6.55,126000000,0.128
91.8,14000,6.56,126000000,0.128
91.9,14000,6.57,126000000,0.128
92.1,14000,6.58,126000000,0.128
92.2,13900,6.59,126000000,0.129
92.3,13900,6.60,126000000,0.129
92.4,13900,6.61,125000000,0.129
92.5,13900,6.63,125000000,0.129
92.7,13900,6.64,125000000,0.129
92.8,13800,6.65,125000000,0.130
92.9,13800,6.66,124000000,0.130
93.0,13700,6.67,124000000,0.130
93.1,13700,6.68,123000000,0.130
93.3,13600,6.69,122000000,0.130
93.4,13500,6.70,122000000,0.131
93.5,13400,6.71,121000000,0.131
93.6,13300,6.72,120000000,0.131
93.7,13200,6.73,119000000,0.131
93.9,13100,6.74,118000000,0.131
94.0,13000,6.75,117000000,0.132
94.1,12900,6.76,116000000,0.132
94.2,12700,6.77,115000000,0.132
94.3,12600,6.78,114000000,0.132
94.5,12500,6.79,113000000,0.132
94.6,12400,6.80,112000000,0.133
94.7,12300,6.81,111000000,0.133
94.8,12300,6.82,111000000,0.133
94.9,12300,6.83,110000000,0.133
95.1,12200,6.84,110000000,0.133
95.2,12200,6.85,110000000,0.134
95.3,12200,6.86,110000000,0.134
95.4,12300,6.87,110000000,0.134
95.5,12300,6.88,111000000,0.134
95.7,12300,6.89,111000000,0.134
95.8,12400,6.90,111000000,0.135
95.9,12400,6.91,112000000,0.135
96.0,12400,6.92,112000000,0.135
96.1,12500,6.93,112000000,0.135
96.2,12500,6.94,113000000,0.135
96.4,12500,6.95,113000000,0.136
96.5,12600,6.96,113000000,0.136
96.6,12600,6.97,113000000,0.136
96.7,12600,6.98,113000000,0.136
96.8,12600,6.99,113000000,0.136
97.0,12500,7.00,113000000,0.137
97.1,12500,7.01,113000000,0.137
97.2,12500,7.02,113000000,0.137
97.3,12500,7.03,113000000,0.137
97.4,12500,7.05,113000000,0.137
97.6,12600,7.06,113000000,0.138
97.7,12600,7.07,113000000,0.138
97.8,12600,7.08,114000000,0.138
97.9,12700,7.09,114000000,0.138
98.0,12700,7.10,114000000,0.138
98.2,12700,7.11,115000000,0.139
98.3,12800,7.12,115000000,0.139
98.4,12800,7.13,115000000,0.139
98.5,12900,7.14,116000000,0.139
98.6,12900,7.15,116000000,0.139
98.8,12900,7.16,116000000,0.140
98.9,13000,7.17,117000000,0.140
99.0,13000,7.18,117000000,0.140
99.1,13000,7.19,117000000,0.140
99.2,13000,7.20,117000000,0.140
99.4,13100,7.21,118000000,0.141
99.5,13100,7.22,118000000,0.141
99.6,13100,7.23,118000000,0.141
99.7,13100,7.24,118000000,0.141
99.8,13200,7.25,119000000,0.141
100,13200,7.26,119000000,0.142
100,13200,7.27,119000000,0.142
100,13200,7.28,119000000,0.142
100,13200,7.29,119000000,0.142
100,13300,7.30,119000000,0.142
101,13300,7.31,120000000,0.143
101,13300,7.32,120000000,0.143
101,13300,7.33,120000000,0.143
101,13300,7.34,120000000,0.143
101,13400,7.35,121000000,0.143
101,13400,7.36,121000000,0.144
101,13400,7.37,121000000,0.144
101,13500,7.38,121000000,0.144
102,13500,7.39,122000000,0.144
102,13500,7.40,122000000,0.144
102,13600,7.41,122000000,0.145
102,13600,7.42,122000000,0.145
102,13600,7.43,123000000,0.145
102,13700,7.44,123000000,0.145
102,13700,7.45,123000000,0.145
102,13700,7.47,124000000,0.146
102,13700,7.48,124000000,0.146
103,13800,7.49,124000000,0.146
103,13800,7.50,124000000,0.146
103,13800,7.51,124000000,0.146
103,13800,7.52,124000000,0.147
103,13700,7.53,124000000,0.147
103,13700,7.54,123000000,0.147
103,13700,7.55,123000000,0.147
103,13700,7.56,123000000,0.147
104,13700,7.57,123000000,0.148
104,13700,7.58,123000000,0.148
104,13600,7.59,123000000,0.148
104,13600,7.60,123000000,0.148
104,13600,7.61,122000000,0.148
104,13500,7.62,122000000,0.149
104,13400,7.63,121000000,0.149
104,13300,7.64,120000000,0.149
105,13200,7.65,119000000,0.149
105,12900,7.66,116000000,0.149
105,12300,7.67,111000000,0.150
105,11800,7.68,107000000,0.150
105,11600,7.69,105000000,0.150
105,11500,7.70,104000000,0.150
105,11500,7.71,103000000,0.150
105,11500,7.72,103000000,0.151
105,11500,7.73,103000000,0.151
106,11500,7.74,103000000,0.151
106,11500,7.75,103000000,0.151
106,11500,7.76,104000000,0.151
106,11500,7.77,104000000,0.152
106,11600,7.78,104000000,0.152
106,11600,7.79,104000000,0.152
106,11600,7.80,105000000,0.152
106,11700,7.81,105000000,0.152
107,11700,7.82,105000000,0.153
107,11700,7.83,106000000,0.153
107,11800,7.84,106000000,0.153
107,11800,7.86,106000000,0.153
107,11800,7.87,107000000,0.153
107,11900,7.88,107000000,0.154
107,11900,7.89,107000000,0.154
107,12000,7.90,108000000,0.154
108,12000,7.91,108000000,0.154
108,12000,7.92,108000000,0.154
108,12100,7.93,109000000,0.155
108,12100,7.94,109000000,0.155
108,12200,7.95,109000000,0.155
108,12200,7.96,110000000,0.155
108,12200,7.97,110000000,0.155
108,12200,7.98,110000000,0.156
108,12300,7.99,110000000,0.156
109,12200,8.00,110000000,0.156
109,12100,8.01,109000000,0.156
109,12100,8.02,109000000,0.156
109,12100,8.03,109000000,0.157
109,12100,8.04,109000000,0.157
109,12100,8.05,109000000,0.157
109,12200,8.06,110000000,0.157
109,12200,8.07,110000000,0.157
110,12300,8.08,111000000,0.158
110,12300,8.09,111000000,0.158
110,12400,8.10,112000000,0.158
110,12400,8.11,112000000,0.158
110,12500,8.12,113000000,0.158
110,12600,8.13,113000000,0.159
110,12600,8.14,114000000,0.159
110,12700,8.15,114000000,0.159
111,12700,8.16,115000000,0.159
111,12800,8.17,115000000,0.159
111,12800,8.18,116000000,0.160
111,12900,8.19,116000000,0.160
111,12900,8.20,117000000,0.160
111,13000,8.21,117000000,0.160
111,13000,8.22,117000000,0.160
111,13100,8.23,118000000,0.161
111,13100,8.24,118000000,0.161
112,13200,8.25,119000000,0.161
112,13200,8.26,119000000,0.161
112,13200,8.27,119000000,0.161
112,13200,8.29,119000000,0.162
112,13200,8.30,119000000,0.162
112,13200,8.31,119000000,0.162
112,13200,8.32,119000000,0.162
112,13200,8.33,119000000,0.162
113,13200,8.34,119000000,0.163
113,13300,8.35,119000000,0.163
113,13300,8.36,120000000,0.163
113,13300,8.37,120000000,0.163
113,13300,8.38,120000000,0.163
113,13300,8.39,120000000,0.164
113,13300,8.40,120000000,0.164
113,13400,8.41,120000000,0.164
113,13400,8.42,121000000,0.164
114,13400,8.43,121000000,0.164
114,13400,8.44,121000000,0.164
114,13500,8.45,121000000,0.165
114,13500,8.46,122000000,0.165
114,13600,8.47,122000000,0.165
114,13600,8.48,122000000,0.165
114,13600,8.49,123000000,0.165
114,13700,8.50,123000000,0.166
115,13800,8.51,124000000,0.166
115,13800,8.52,124000000,0.166
115,13900,8.53,125000000,0.166
115,13900,8.54,125000000,0.166
115,14000,8.55,126000000,0.167
115,14000,8.56,126000000,0.167
115,14100,8.57,127000000,0.167
115,14100,8.58,127000000,0.167
116,14200,8.59,128000000,0.167
116,14200,8.60,128000000,0.168
116,14200,8.61,128000000,0.168
116,14300,8.62,129000000,0.168
116,14300,8.63,129000000,0.168
116,14300,8.64,129000000,0.168
116,14400,8.65,129000000,0.169
116,14400,8.66,130000000,0.169
116,14400,8.67,130000000,0.169
117,14400,8.68,130000000,0.169
117,14400,8.70,130000000,0.169
117,14400,8.71,130000000,0.170
117,14400,8.72,129000000,0.170
117,14300,8.73,129000000,0.170
117,14300,8.74,129000000,0.170
117,14300,8.75,129000000,0.170
117,14200,8.76,128000000,0.171
118,13800,8.77,125000000,0.171
118,13400,8.78,121000000,0.171
118,13000,8.79,117000000,0.171
118,12700,8.80,115000000,0.172
118,12600,8.81,113000000,0.172
118,12500,8.82,112000000,0.172
118,12400,8.83,112000000,0.172
118,12400,8.84,112000000,0.172
119,12400,8.85,112000000,0.172
119,12400,8.86,112000000,0.173
119,12400,8.87,112000000,0.173
119,12400,8.88,112000000,0.173
119,12500,8.89,112000000,0.173
119,12500,8.90,112000000,0.173
119,12500,8.91,113000000,0.174
119,12500,8.92,113000000,0.174
119,12500,8.93,113000000,0.174
120,12600,8.94,113000000,0.174
120,12600,8.95,113000000,0.174
120,12600,8.96,114000000,0.175
120,12600,8.97,114000000,0.175
120,12700,8.98,114000000,0.175
120,12700,8.99,114000000,0.175
120,12700,9.00,115000000,0.175
120,12800,9.01,115000000,0.176
121,12800,9.02,115000000,0.176
121,12800,9.03,115000000,0.176
121,12800,9.04,116000000,0.176
121,12900,9.05,116000000,0.176
121,12900,9.06,116000000,0.177
121,12900,9.07,116000000,0.177
121,12900,9.08,117000000,0.177
121,13000,9.09,117000000,0.177
122,13000,9.10,117000000,0.177
122,13000,9.12,117000000,0.178
122,13000,9.13,117000000,0.178
122,13000,9.14,117000000,0.178
122,13000,9.15,117000000,0.178
122,13100,9.16,118000000,0.178
122,13100,9.17,118000000,0.179
122,13100,9.18,118000000,0.179
122,13100,9.19,118000000,0.179
123,13100,9.20,118000000,0.179
123,13200,9.21,119000000,0.179
123,13200,9.22,119000000,0.180
123,13200,9.23,119000000,0.180
123,13200,9.24,119000000,0.180
123,13200,9.25,119000000,0.180
123,13200,9.26,119000000,0.180
123,13200,9.27,119000000,0.181
124,13200,9.28,119000000,0.181
124,13200,9.29,119000000,0.181
124,13200,9.30,119000000,0.181
124,13200,9.31,119000000,0.181
124,13100,9.32,118000000,0.182
124,13100,9.33,118000000,0.182
124,13000,9.34,118000000,0.182
124,13000,9.35,117000000,0.182
125,12900,9.36,117000000,0.182
125,12900,9.37,116000000,0.183
125,12900,9.38,116000000,0.183
125,12800,9.39,116000000,0.183
125,12800,9.40,115000000,0.183
125,12800,9.41,115000000,0.183
125,12800,9.42,115000000,0.184
125,12800,9.43,115000000,0.184
125,12800,9.44,115000000,0.184
126,12700,9.45,115000000,0.184
126,12700,9.46,115000000,0.184
126,12700,9.47,115000000,0.185
126,12700,9.48,115000000,0.185
126,12700,9.49,115000000,0.185
126,12700,9.50,115000000,0.185
126,12700,9.51,115000000,0.185
126,12700,9.52,115000000,0.186
127,12800,9.53,115000000,0.186
127,12800,9.55,115000000,0.186
127,12800,9.56,115000000,0.186
127,12800,9.57,115000000,0.186
127,12800,9.58,115000000,0.187
127,12800,9.59,115000000,0.187
127,12800,9.60,116000000,0.187
127,12800,9.61,116000000,0.187
128,12900,9.62,116000000,0.187
128,12900,9.63,116000000,0.188
128,12900,9.64,116000000,0.188
128,12900,9.65,116000000,0.188
128,12900,9.66,116000000,0.188
128,12900,9.67,117000000,0.188
128,13000,9.68,117000000,0.189
128,13000,9.69,117000000,0.189
128,13000,9.70,117000000,0.189
129,13000,9.71,117000000,0.189
129,13000,9.72,117000000,0.189
129,13100,9.73,118000000,0.190
129,13100,9.74,118000000,0.190
129,13100,9.75,118000000,0.190
129,13100,9.76,118000000,0.190
129,13100,9.77,118000000,0.190
129,13200,9.78,119000000,0.191
130,13200,9.79,119000000,0.191
130,13200,9.80,119000000,0.191
130,13200,9.81,119000000,0.191
130,13200,9.82,119000000,0.191
130,13300,9.83,119000000,0.192
130,13300,9.84,120000000,0.192
130,13300,9.85,120000000,0.192
130,13300,9.86,120000000,0.192
131,13300,9.87,120000000,0.192
131,13400,9.88,120000000,0.193
131,13400,9.89,120000000,0.193
131,13400,9.90,121000000,0.193
131,13400,9.91,121000000,0.193
131,13400,9.92,121000000,0.193
131,13400,9.93,121000000,0.194
131,13400,9.95,121000000,0.194
131,13400,9.96,121000000,0.194
132,13500,9.97,121000000,0.194
132,13500,9.98,121000000,0.194
132,13500,9.99,122000000,0.195
132,13500,10.0,122000000,0.195
132,13500,10.0,122000000,0.195
132,13500,10.0,122000000,0.195
132,13500,10.0,122000000,0.195
132,13600,10.0,122000000,0.196
133,13600,10.0,122000000,0.196
133,13600,10.1,122000000,0.196
133,13600,10.1,122000000,0.196
133,13600,10.1,123000000,0.196
133,13600,10.1,123000000,0.197
133,13600,10.1,123000000,0.197
133,13600,10.1,123000000,0.197
133,13600,10.1,123000000,0.197
133,13600,10.1,122000000,0.197
134,13600,10.1,122000000,0.198
134,13500,10.1,122000000,0.198
134,13500,10.2,122000000,0.198
134,13500,10.2,122000000,0.198
134,13500,10.2,121000000,0.198
134,13400,10.2,121000000,0.199
134,13400,10.2,120000000,0.199
134,13000,10.2,117000000,0.199
135,12700,10.2,114000000,0.199
135,12500,10.2,113000000,0.199
135,12500,10.2,112000000,0.200
135,12400,10.3,112000000,0.200