File: data/InventWood/Superwood-ID26s-07302025.csv
Time (sec),Force (N),Position (mm),Stress (Pa),Strain (m/m)
12.3,20.7,0.0236,194000,0.000478
12.4,22.1,0.0289,207000,0.000586
12.5,23.4,0.0341,219000,0.000690
12.5,24.9,0.0395,233000,0.000800
12.6,26.2,0.0448,245000,0.000907
12.6,27.9,0.0501,261000,0.00101
12.7,29.8,0.0555,279000,0.00112
12.8,31.6,0.0607,296000,0.00123
12.8,33.8,0.0661,316000,0.00134
12.9,35.5,0.0714,332000,0.00145
13.0,37.5,0.0768,350000,0.00155
13.0,39.4,0.0821,369000,0.00166
13.1,41.3,0.0873,386000,0.00177
13.2,43.2,0.0928,404000,0.00188
13.2,44.8,0.0979,419000,0.00198
13.3,46.6,0.103,436000,0.00209
13.4,48.1,0.109,450000,0.00220
13.4,49.6,0.114,464000,0.00231
13.5,51.5,0.119,482000,0.00241
13.6,53.5,0.125,500000,0.00252
13.6,55.4,0.130,518000,0.00263
13.7,57.6,0.135,539000,0.00274
13.7,60.4,0.141,565000,0.00285
13.8,62.7,0.146,586000,0.00295
13.9,64.9,0.151,607000,0.00306
13.9,68.0,0.157,636000,0.00317
14.0,75.8,0.162,709000,0.00327
14.1,83.5,0.167,781000,0.00338
14.1,90.0,0.172,841000,0.00349
14.2,96.3,0.178,900000,0.00359
14.3,102,0.183,957000,0.00370
14.3,108,0.188,1010000,0.00381
14.4,114,0.193,1070000,0.00392
14.5,119,0.199,1110000,0.00402
14.5,125,0.204,1170000,0.00413
14.6,130,0.209,1220000,0.00424
14.6,136,0.214,1270000,0.00434
14.7,142,0.220,1320000,0.00445
14.8,147,0.225,1380000,0.00456
14.8,153,0.230,1430000,0.00467
14.9,159,0.236,1490000,0.00477
15.0,166,0.241,1550000,0.00488
15.0,172,0.246,1610000,0.00499
15.1,178,0.252,1660000,0.00510
15.2,184,0.257,1720000,0.00521
15.2,191,0.262,1780000,0.00531
15.3,197,0.268,1840000,0.00542
15.4,203,0.273,1900000,0.00553
15.4,210,0.278,1960000,0.00564
15.5,217,0.284,2030000,0.00574
15.5,223,0.289,2090000,0.00585
15.6,231,0.294,2160000,0.00596
15.7,238,0.300,2230000,0.00606
15.7,246,0.305,2300000,0.00618
15.8,253,0.310,2370000,0.00628
15.9,261,0.315,2440000,0.00639
15.9,269,0.321,2520000,0.00650
16.0,277,0.326,2590000,0.00660
16.1,285,0.331,2670000,0.00671
16.1,293,0.337,2740000,0.00682
16.2,301,0.342,2820000,0.00692
16.3,310,0.347,2900000,0.00703
16.3,318,0.353,2970000,0.00714
16.4,326,0.358,3050000,0.00725
16.5,334,0.363,3130000,0.00736
16.5,342,0.369,3200000,0.00747
16.6,350,0.374,3270000,0.00757
16.6,358,0.379,3350000,0.00768
16.7,367,0.385,3430000,0.00779
16.8,377,0.390,3520000,0.00789
16.8,387,0.395,3620000,0.00800
16.9,396,0.400,3710000,0.00811
17.0,406,0.406,3800000,0.00821
17.0,417,0.411,3900000,0.00832
17.1,427,0.416,4000000,0.00843
17.2,439,0.422,4110000,0.00854
17.2,450,0.427,4210000,0.00864
17.3,462,0.432,4320000,0.00875
17.4,474,0.437,4440000,0.00886
17.4,487,0.443,4550000,0.00896
17.5,501,0.448,4680000,0.00907
17.5,514,0.453,4800000,0.00918
17.6,528,0.459,4940000,0.00929
17.7,541,0.464,5060000,0.00939
17.7,556,0.469,5200000,0.00950
17.8,571,0.475,5340000,0.00961
17.9,585,0.480,5470000,0.00971
17.9,601,0.485,5620000,0.00982
18.0,616,0.490,5760000,0.00993
18.1,632,0.496,5910000,0.0100
18.1,649,0.501,6070000,0.0101
18.2,665,0.506,6220000,0.0103
18.3,682,0.512,6380000,0.0104
18.3,699,0.517,6540000,0.0105
18.4,717,0.522,6710000,0.0106
18.4,735,0.528,6870000,0.0107
18.5,753,0.533,7040000,0.0108
18.6,771,0.538,7220000,0.0109
18.6,790,0.544,7390000,0.0110
18.7,810,0.549,7580000,0.0111
18.8,830,0.554,7760000,0.0112
18.8,850,0.560,7950000,0.0113
18.9,872,0.565,8150000,0.0114
19.0,895,0.570,8380000,0.0115
19.0,922,0.575,8630000,0.0117
19.1,949,0.581,8880000,0.0118
19.2,978,0.586,9150000,0.0119
19.2,1010,0.591,9400000,0.0120
19.3,1030,0.597,9670000,0.0121
19.3,1060,0.602,9950000,0.0122
19.4,1090,0.607,10200000,0.0123
19.5,1120,0.613,10500000,0.0124
19.5,1150,0.618,10800000,0.0125
19.6,1180,0.623,11100000,0.0126
19.7,1210,0.629,11300000,0.0127
19.7,1240,0.634,11600000,0.0128
19.8,1280,0.639,11900000,0.0129
19.9,1310,0.644,12200000,0.0130
19.9,1340,0.650,12500000,0.0132
20.0,1370,0.655,12800000,0.0133
20.1,1400,0.660,13100000,0.0134
20.1,1440,0.666,13400000,0.0135
20.2,1470,0.671,13800000,0.0136
20.3,1510,0.676,14100000,0.0137
20.3,1540,0.682,14400000,0.0138
20.4,1580,0.687,14800000,0.0139
20.4,1610,0.692,15100000,0.0140
20.5,1650,0.698,15400000,0.0141
20.6,1690,0.703,15800000,0.0142
20.6,1730,0.708,16200000,0.0143
20.7,1770,0.714,16500000,0.0144
20.8,1810,0.719,16900000,0.0146
20.8,1850,0.724,17300000,0.0147
20.9,1890,0.729,17700000,0.0148
21.0,1930,0.735,18000000,0.0149
21.0,1970,0.740,18400000,0.0150
21.1,2010,0.745,18800000,0.0151
21.2,2050,0.751,19200000,0.0152
21.2,2090,0.756,19600000,0.0153
21.3,2140,0.761,20000000,0.0154
21.3,2180,0.767,20400000,0.0155
21.4,2220,0.772,20800000,0.0156
21.5,2260,0.777,21200000,0.0157
21.5,2300,0.783,21600000,0.0158
21.6,2350,0.788,22000000,0.0160
21.7,2390,0.793,22400000,0.0161
21.7,2430,0.798,22700000,0.0162
21.8,2470,0.804,23100000,0.0163
21.9,2520,0.809,23500000,0.0164
21.9,2560,0.814,23900000,0.0165
22.0,2600,0.819,24300000,0.0166
22.1,2640,0.825,24700000,0.0167
22.1,2690,0.830,25100000,0.0168
22.2,2730,0.835,25500000,0.0169
22.2,2780,0.841,26000000,0.0170
22.3,2820,0.846,26400000,0.0171
22.4,2870,0.851,26800000,0.0172
22.4,2910,0.856,27200000,0.0173
22.5,2960,0.862,27700000,0.0174
22.6,3000,0.867,28100000,0.0176
22.6,3050,0.872,28500000,0.0177
22.7,3100,0.878,29000000,0.0178
22.8,3140,0.883,29400000,0.0179
22.8,3190,0.889,29800000,0.0180
22.9,3240,0.894,30300000,0.0181
23.0,3290,0.899,30700000,0.0182
23.0,3330,0.905,31200000,0.0183
23.1,3380,0.910,31600000,0.0184
23.2,3430,0.915,32000000,0.0185
23.2,3470,0.921,32500000,0.0186
23.3,3520,0.926,32900000,0.0187
23.3,3560,0.931,33300000,0.0189
23.4,3610,0.936,33800000,0.0190
23.5,3660,0.942,34200000,0.0191
23.5,3700,0.947,34600000,0.0192
23.6,3760,0.952,35100000,0.0193
23.7,3800,0.958,35600000,0.0194
23.7,3850,0.963,36000000,0.0195
23.8,3900,0.968,36500000,0.0196
23.9,3950,0.973,36900000,0.0197
23.9,4000,0.979,37400000,0.0198
24.0,4050,0.984,37800000,0.0199
24.1,4100,0.989,38300000,0.0200
24.1,4150,0.994,38800000,0.0201
24.2,4200,1.00,39300000,0.0202
24.2,4260,1.01,39800000,0.0204
24.3,4310,1.01,40300000,0.0205
24.4,4360,1.02,40800000,0.0206
24.4,4420,1.02,41300000,0.0207
24.5,4470,1.03,41800000,0.0208
24.6,4520,1.03,42300000,0.0209
24.6,4580,1.04,42800000,0.0210
24.7,4630,1.04,43300000,0.0211
24.8,4690,1.05,43900000,0.0212
24.8,4750,1.05,44400000,0.0213
24.9,4800,1.06,44900000,0.0214
25.0,4860,1.06,45400000,0.0215
25.0,4910,1.07,46000000,0.0216
25.1,4970,1.07,46400000,0.0217
25.1,5030,1.08,47000000,0.0219
25.2,5080,1.08,47500000,0.0220
25.3,5140,1.09,48100000,0.0221
25.3,5200,1.10,48600000,0.0222
25.4,5250,1.10,49100000,0.0223
25.5,5310,1.11,49700000,0.0224
25.5,5370,1.11,50200000,0.0225
25.6,5430,1.12,50800000,0.0226
25.7,5490,1.12,51300000,0.0227
25.7,5550,1.13,51900000,0.0228
25.8,5610,1.13,52400000,0.0229
25.9,5670,1.14,53000000,0.0230
25.9,5730,1.14,53600000,0.0231
26.0,5790,1.15,54100000,0.0233
26.1,5850,1.15,54700000,0.0234
26.1,5910,1.16,55300000,0.0235
26.2,5970,1.16,55800000,0.0236
26.2,6030,1.17,56400000,0.0237
26.3,6080,1.18,56900000,0.0238
26.4,6150,1.18,57500000,0.0239
26.4,6200,1.19,58000000,0.0240
26.5,6260,1.19,58600000,0.0241
26.6,6320,1.20,59100000,0.0242
26.6,6380,1.20,59600000,0.0243
26.7,6440,1.21,60200000,0.0244
26.8,6500,1.21,60800000,0.0245
26.8,6560,1.22,61400000,0.0247
26.9,6620,1.22,61900000,0.0248
27.0,6680,1.23,62400000,0.0249
27.0,6740,1.23,63000000,0.0250
27.1,6790,1.24,63500000,0.0251
27.1,6850,1.24,64100000,0.0252
27.2,6910,1.25,64600000,0.0253
27.3,6970,1.25,65200000,0.0254
27.3,7020,1.26,65700000,0.0255
27.4,7080,1.27,66200000,0.0256
27.5,7130,1.27,66700000,0.0257
27.5,7180,1.28,67200000,0.0258
27.6,7240,1.28,67700000,0.0259
27.7,7290,1.29,68200000,0.0260
27.7,7340,1.29,68600000,0.0262
27.8,7390,1.30,69100000,0.0263
27.9,7430,1.30,69500000,0.0264
27.9,7480,1.31,70000000,0.0265
28.0,7530,1.31,70400000,0.0266
28.0,7580,1.32,70900000,0.0267
28.1,7620,1.32,71300000,0.0268
28.2,7670,1.33,71700000,0.0269
28.2,7720,1.33,72200000,0.0270
28.3,7770,1.34,72600000,0.0271
28.4,7820,1.34,73100000,0.0272
28.4,7870,1.35,73600000,0.0273
28.5,7920,1.36,74100000,0.0274
28.6,7970,1.36,74500000,0.0275
28.6,8020,1.37,75000000,0.0277
28.7,8080,1.37,75600000,0.0278
28.8,8130,1.38,76000000,0.0279
28.8,8190,1.38,76600000,0.0280
28.9,8240,1.39,77100000,0.0281
29.0,8300,1.39,77600000,0.0282
29.0,8350,1.40,78100000,0.0283
29.1,8410,1.40,78600000,0.0284
29.1,8470,1.41,79200000,0.0285
29.2,8520,1.41,79700000,0.0286
29.3,8580,1.42,80300000,0.0287
29.3,8630,1.42,80800000,0.0288
29.4,8690,1.43,81300000,0.0290
29.5,8750,1.44,81900000,0.0291
29.5,8810,1.44,82400000,0.0292
29.6,8870,1.45,83000000,0.0293
29.7,8930,1.45,83500000,0.0294
29.7,8990,1.46,84100000,0.0295
29.8,9050,1.46,84700000,0.0296
29.9,9120,1.47,85300000,0.0297
29.9,9180,1.47,85900000,0.0298
30.0,9240,1.48,86400000,0.0299
30.0,9310,1.48,87000000,0.0300
30.1,9370,1.49,87600000,0.0301
30.2,9430,1.49,88200000,0.0302
30.2,9490,1.50,88800000,0.0303
30.3,9560,1.50,89400000,0.0304
30.4,9620,1.51,90000000,0.0306
30.4,9680,1.51,90600000,0.0307
30.5,9750,1.52,91200000,0.0308
30.6,9820,1.53,91800000,0.0309
30.6,9880,1.53,92400000,0.0310
30.7,9940,1.54,93000000,0.0311
30.8,10000,1.54,93600000,0.0312
30.8,10100,1.55,94200000,0.0313
30.9,10100,1.55,94800000,0.0314
30.9,10200,1.56,95400000,0.0315
31.0,10300,1.56,95900000,0.0316
31.1,10300,1.57,96500000,0.0317
31.1,10400,1.57,97000000,0.0319
31.2,10400,1.58,97600000,0.0320
31.3,10500,1.58,98100000,0.0321
31.3,10500,1.59,98700000,0.0322
31.4,10600,1.59,99200000,0.0323
31.5,10700,1.60,99700000,0.0324
31.5,10700,1.60,100000000,0.0325
31.6,10800,1.61,101000000,0.0326
31.7,10800,1.62,101000000,0.0327
31.7,10900,1.62,102000000,0.0328
31.8,10900,1.63,102000000,0.0329
31.8,11000,1.63,103000000,0.0330
31.9,11100,1.64,103000000,0.0331
32.0,11100,1.64,104000000,0.0332
32.0,11200,1.65,104000000,0.0334
32.1,11200,1.65,105000000,0.0335
32.2,11300,1.66,105000000,0.0336
32.2,11300,1.66,106000000,0.0337
32.3,11400,1.67,106000000,0.0338
32.4,11400,1.67,107000000,0.0339
32.4,11400,1.68,107000000,0.0340
32.5,11500,1.68,108000000,0.0341
32.6,11500,1.69,108000000,0.0342
32.6,11600,1.70,108000000,0.0343
32.7,11600,1.70,109000000,0.0344
32.8,11700,1.71,109000000,0.0345
32.8,11700,1.71,109000000,0.0346
32.9,11700,1.72,110000000,0.0348
32.9,11800,1.72,110000000,0.0349
33.0,11800,1.73,111000000,0.0350
33.1,11900,1.73,111000000,0.0351
33.1,11900,1.74,111000000,0.0352
33.2,11900,1.74,112000000,0.0353
33.3,12000,1.75,112000000,0.0354
33.3,12000,1.75,112000000,0.0355
33.4,12000,1.76,112000000,0.0356
33.5,12000,1.76,113000000,0.0357
33.5,12100,1.77,113000000,0.0358
33.6,12100,1.77,113000000,0.0359
33.7,12100,1.78,113000000,0.0360
33.7,12100,1.79,113000000,0.0362
33.8,12100,1.79,113000000,0.0363
33.8,12100,1.80,113000000,0.0364
33.9,12100,1.80,114000000,0.0365
34.0,12100,1.81,114000000,0.0366
34.0,12200,1.81,114000000,0.0367
34.1,12200,1.82,114000000,0.0368
34.2,12200,1.82,114000000,0.0369
34.2,12200,1.83,114000000,0.0370
34.3,12200,1.83,114000000,0.0371
34.4,12200,1.84,114000000,0.0372
34.4,12200,1.84,114000000,0.0373
34.5,12300,1.85,115000000,0.0374
34.6,12300,1.85,115000000,0.0375
34.6,12300,1.86,115000000,0.0377
34.7,12300,1.87,115000000,0.0378
34.7,12400,1.87,116000000,0.0379
34.8,12400,1.88,116000000,0.0380
34.9,12400,1.88,116000000,0.0381
34.9,12400,1.89,116000000,0.0382
35.0,12500,1.89,117000000,0.0383
35.1,12500,1.90,117000000,0.0384
35.1,12500,1.90,117000000,0.0385
35.2,12500,1.91,117000000,0.0386
35.3,12600,1.91,118000000,0.0387
35.3,12600,1.92,118000000,0.0388
35.4,12600,1.92,118000000,0.0389
35.5,12600,1.93,118000000,0.0391
35.5,12600,1.93,118000000,0.0392
35.6,12700,1.94,118000000,0.0393
35.7,12700,1.94,119000000,0.0394
35.7,12700,1.95,119000000,0.0395
35.8,12700,1.96,119000000,0.0396
35.8,12700,1.96,119000000,0.0397
35.9,12700,1.97,119000000,0.0398
36.0,12700,1.97,119000000,0.0399
36.0,12700,1.98,119000000,0.0400
36.1,12800,1.98,119000000,0.0401
36.2,12800,1.99,119000000,0.0402
36.2,12800,1.99,120000000,0.0403
36.3,12800,2.00,120000000,0.0405
36.4,12800,2.00,120000000,0.0406
36.4,12800,2.01,120000000,0.0407
36.5,12900,2.01,120000000,0.0408
36.6,12900,2.02,120000000,0.0409
36.6,12900,2.02,121000000,0.0410
36.7,12900,2.03,121000000,0.0411
36.7,13000,2.03,121000000,0.0412
36.8,13000,2.04,121000000,0.0413
36.9,13000,2.05,122000000,0.0414
36.9,13000,2.05,122000000,0.0415
37.0,13100,2.06,122000000,0.0416
37.1,13100,2.06,122000000,0.0417
37.1,13100,2.07,123000000,0.0418
37.2,13100,2.07,123000000,0.0420
37.3,13200,2.08,123000000,0.0421
37.3,13200,2.08,123000000,0.0422
37.4,13200,2.09,124000000,0.0423
37.5,13300,2.09,124000000,0.0424
37.5,13300,2.10,124000000,0.0425
37.6,13300,2.10,125000000,0.0426
37.6,13400,2.11,125000000,0.0427
37.7,13400,2.11,125000000,0.0428
37.8,13400,2.12,126000000,0.0429
37.8,13500,2.13,126000000,0.0430
37.9,13500,2.13,126000000,0.0431
38.0,13500,2.14,127000000,0.0432
38.0,13600,2.14,127000000,0.0434
38.1,13600,2.15,127000000,0.0435
38.2,13600,2.15,127000000,0.0436
38.2,13600,2.16,128000000,0.0437
38.3,13700,2.16,128000000,0.0438
38.4,13700,2.17,128000000,0.0439
38.4,13700,2.17,128000000,0.0440
38.5,13700,2.18,128000000,0.0441
38.6,13700,2.18,128000000,0.0442
38.6,13800,2.19,129000000,0.0443
38.7,13800,2.19,129000000,0.0444
38.7,13800,2.20,129000000,0.0445
38.8,13800,2.20,129000000,0.0446
38.9,13800,2.21,129000000,0.0448
38.9,13800,2.22,129000000,0.0449
39.0,13800,2.22,129000000,0.0450
39.1,13800,2.23,130000000,0.0451
39.1,13900,2.23,130000000,0.0452
39.2,13900,2.24,130000000,0.0453
39.3,13900,2.24,130000000,0.0454
39.3,13900,2.25,130000000,0.0455
39.4,13900,2.25,130000000,0.0456
39.5,13900,2.26,130000000,0.0457
39.5,13900,2.26,130000000,0.0458
39.6,14000,2.27,131000000,0.0459
39.6,14000,2.27,131000000,0.0460
39.7,14000,2.28,131000000,0.0461
39.8,14000,2.28,131000000,0.0463
39.8,14000,2.29,131000000,0.0464
39.9,14100,2.29,131000000,0.0465
40.0,14100,2.30,132000000,0.0466
40.0,14100,2.31,132000000,0.0467
40.1,14100,2.31,132000000,0.0468
40.2,14100,2.32,132000000,0.0469
40.2,14100,2.32,132000000,0.0470
40.3,14200,2.33,133000000,0.0471
40.4,14200,2.33,133000000,0.0472
40.4,14200,2.34,133000000,0.0473
40.5,14200,2.34,133000000,0.0474
40.5,14200,2.35,133000000,0.0475
40.6,14300,2.35,133000000,0.0477
40.7,14300,2.36,134000000,0.0478
40.7,14300,2.36,134000000,0.0479
40.8,14300,2.37,134000000,0.0480
40.9,14300,2.38,134000000,0.0481
40.9,14400,2.38,134000000,0.0482
41.0,14400,2.39,134000000,0.0483
41.1,14400,2.39,135000000,0.0484
41.1,14400,2.40,135000000,0.0485
41.2,14400,2.40,135000000,0.0486
41.3,14400,2.41,135000000,0.0487
41.3,14400,2.41,135000000,0.0488
41.4,14500,2.42,135000000,0.0489
41.4,14500,2.42,135000000,0.0491
41.5,14500,2.43,135000000,0.0492
41.6,14500,2.43,136000000,0.0493
41.6,14500,2.44,136000000,0.0494
41.7,14500,2.44,136000000,0.0495
41.8,14500,2.45,136000000,0.0496
41.8,14600,2.45,136000000,0.0497
41.9,14600,2.46,136000000,0.0498
42.0,14600,2.47,136000000,0.0499
42.0,14600,2.47,137000000,0.0500
42.1,14600,2.48,137000000,0.0501
42.2,14600,2.48,137000000,0.0502
42.2,14600,2.49,137000000,0.0503
42.3,14600,2.49,137000000,0.0504
42.4,14700,2.50,137000000,0.0506
42.4,14700,2.50,137000000,0.0507
42.5,14700,2.51,137000000,0.0508
42.5,14700,2.51,138000000,0.0509
42.6,14700,2.52,138000000,0.0510
42.7,14700,2.52,138000000,0.0511
42.7,14700,2.53,138000000,0.0512
42.8,14700,2.53,138000000,0.0513
42.9,14700,2.54,138000000,0.0514
42.9,14700,2.54,138000000,0.0515
43.0,14700,2.55,138000000,0.0516
43.1,14700,2.56,138000000,0.0517
43.1,14700,2.56,137000000,0.0519
43.2,14700,2.57,137000000,0.0520
43.3,14600,2.57,136000000,0.0521
43.3,14500,2.58,136000000,0.0522
43.4,14400,2.58,135000000,0.0523
43.4,14200,2.59,133000000,0.0524
43.5,14000,2.59,131000000,0.0525
43.6,13800,2.60,129000000,0.0526
43.6,13700,2.60,128000000,0.0527
43.7,13600,2.61,127000000,0.0528
43.8,13500,2.61,127000000,0.0529
43.8,13500,2.62,126000000,0.0530
43.9,13500,2.62,126000000,0.0531
44.0,13500,2.63,126000000,0.0532
44.0,13500,2.63,126000000,0.0533
44.1,13500,2.64,126000000,0.0535
44.2,13500,2.65,126000000,0.0536
44.2,13500,2.65,126000000,0.0537
44.3,13500,2.66,127000000,0.0538
44.3,13600,2.66,127000000,0.0539
44.4,13600,2.67,127000000,0.0540
44.5,13600,2.67,127000000,0.0541
44.5,13600,2.68,128000000,0.0542
44.6,13700,2.68,128000000,0.0543
44.7,13700,2.69,128000000,0.0544
44.7,13700,2.69,128000000,0.0545
44.8,13700,2.70,128000000,0.0546
44.9,13800,2.70,129000000,0.0548
44.9,13800,2.71,129000000,0.0549
45.0,13800,2.71,129000000,0.0550
45.1,13800,2.72,129000000,0.0551
45.1,13900,2.73,130000000,0.0552
45.2,13900,2.73,130000000,0.0553
45.3,13900,2.74,130000000,0.0554
45.3,13900,2.74,130000000,0.0555
45.4,13900,2.75,130000000,0.0556
45.4,13900,2.75,130000000,0.0557
45.5,13900,2.76,130000000,0.0558
45.6,14000,2.76,131000000,0.0559
45.6,14000,2.77,131000000,0.0560
45.7,14000,2.77,131000000,0.0561
45.8,14000,2.78,131000000,0.0563
45.8,14000,2.78,131000000,0.0564
45.9,14000,2.79,131000000,0.0565
46.0,14000,2.79,131000000,0.0566
46.0,14000,2.80,131000000,0.0567
46.1,14000,2.81,131000000,0.0568
46.2,14000,2.81,131000000,0.0569
46.2,14000,2.82,131000000,0.0570
46.3,14000,2.82,131000000,0.0571
46.3,14000,2.83,130000000,0.0572
46.4,13900,2.83,130000000,0.0573
46.5,13900,2.84,130000000,0.0574
46.5,13900,2.84,130000000,0.0575
46.6,13900,2.85,130000000,0.0576
46.7,13800,2.85,129000000,0.0578
46.7,13800,2.86,129000000,0.0579
46.8,13800,2.86,129000000,0.0580
46.9,13800,2.87,129000000,0.0581
46.9,13700,2.87,128000000,0.0582
47.0,13700,2.88,128000000,0.0583
47.1,13700,2.88,128000000,0.0584
47.1,13700,2.89,128000000,0.0585
47.2,13600,2.90,127000000,0.0586
47.2,13600,2.90,127000000,0.0587
47.3,13600,2.91,127000000,0.0588
47.4,13500,2.91,126000000,0.0589
47.4,13500,2.92,126000000,0.0591
47.5,13400,2.92,125000000,0.0592
47.6,13300,2.93,124000000,0.0593
47.6,13200,2.93,123000000,0.0594
47.7,13100,2.94,122000000,0.0595
47.8,12900,2.94,121000000,0.0596
47.8,12600,2.95,117000000,0.0597
47.9,11800,2.95,111000000,0.0598
48.0,9550,2.96,89300000,0.0599
48.0,9060,2.97,84700000,0.0600
48.1,8920,2.97,83400000,0.0601
48.2,8860,2.98,82900000,0.0602
48.2,8850,2.98,82800000,0.0604
48.3,8850,2.99,82800000,0.0605
48.3,8860,2.99,82900000,0.0606
48.4,8890,3.00,83100000,0.0607
48.5,8910,3.00,83400000,0.0608
48.5,8950,3.01,83700000,0.0609
48.6,8980,3.01,84000000,0.0610
48.7,9020,3.02,84400000,0.0611
48.7,9060,3.02,84700000,0.0612
48.8,9090,3.03,85000000,0.0613
48.9,9130,3.03,85400000,0.0614
48.9,9170,3.04,85800000,0.0615
49.0,9210,3.04,86200000,0.0616
49.1,9250,3.05,86500000,0.0617
49.1,9280,3.05,86800000,0.0618
49.2,9330,3.06,87200000,0.0619
49.2,9360,3.06,87500000,0.0621
49.3,9400,3.07,87900000,0.0622
49.4,9430,3.08,88200000,0.0623
49.4,9470,3.08,88600000,0.0624
49.5,9510,3.09,88900000,0.0625
49.6,9550,3.09,89300000,0.0626
49.6,9590,3.10,89700000,0.0627
49.7,9620,3.10,89900000,0.0628
49.8,9650,3.11,90300000,0.0629
49.8,9680,3.11,90600000,0.0630
49.9,9720,3.12,90900000,0.0631
50.0,9750,3.12,91200000,0.0632
50.0,9780,3.13,91500000,0.0633
50.1,9810,3.13,91800000,0.0635
50.1,9840,3.14,92000000,0.0636
50.2,9870,3.14,92300000,0.0637
50.3,9890,3.15,92500000,0.0638
50.3,9920,3.16,92800000,0.0639
50.4,9950,3.16,93000000,0.0640
50.5,9970,3.17,93200000,0.0641
50.5,10000,3.17,93500000,0.0642
50.6,10000,3.18,93700000,0.0643
50.7,10000,3.18,93900000,0.0644
50.7,10100,3.19,94200000,0.0645
50.8,10100,3.19,94400000,0.0646
50.9,10100,3.20,94700000,0.0647
50.9,10100,3.20,94900000,0.0648
51.0,10200,3.21,95100000,0.0650
51.1,10200,3.21,95400000,0.0651
51.1,10200,3.22,95600000,0.0652
51.2,10200,3.22,95800000,0.0653
51.2,10300,3.23,96000000,0.0654
51.3,10300,3.23,96300000,0.0655
51.4,10300,3.24,96500000,0.0656
51.4,10400,3.25,96800000,0.0657
51.5,10400,3.25,97100000,0.0658
51.6,10400,3.26,97300000,0.0659
51.6,10400,3.26,97700000,0.0660
51.7,10500,3.27,97900000,0.0661
51.8,10500,3.27,98300000,0.0662
51.8,10500,3.28,98600000,0.0663
51.9,10600,3.28,98900000,0.0665
52.0,10600,3.29,99200000,0.0666
52.0,10600,3.29,99600000,0.0667
52.1,10700,3.30,100000000,0.0668
52.1,10700,3.30,100000000,0.0669
52.2,10800,3.31,101000000,0.0670
52.3,10800,3.31,101000000,0.0671
52.3,10900,3.32,102000000,0.0672
52.4,10900,3.32,102000000,0.0673
52.5,10900,3.33,102000000,0.0674
52.5,11000,3.34,103000000,0.0675
52.6,11000,3.34,103000000,0.0676
52.7,11100,3.35,103000000,0.0678
52.7,11100,3.35,104000000,0.0679
52.8,11100,3.36,104000000,0.0680
52.9,11200,3.36,105000000,0.0681
52.9,11200,3.37,105000000,0.0682
53.0,11300,3.37,105000000,0.0683
53.0,11300,3.38,106000000,0.0684
53.1,11300,3.38,106000000,0.0685
53.2,11400,3.39,106000000,0.0686
53.2,11400,3.39,107000000,0.0687
53.3,11400,3.40,107000000,0.0688
53.4,11500,3.40,107000000,0.0689
53.4,11500,3.41,108000000,0.0690
53.5,11500,3.41,108000000,0.0691
53.6,11600,3.42,108000000,0.0693
53.6,11600,3.43,109000000,0.0694
53.7,11600,3.43,109000000,0.0695
53.8,11700,3.44,109000000,0.0696
53.8,11700,3.44,109000000,0.0697
53.9,11700,3.45,110000000,0.0698
53.9,11700,3.45,110000000,0.0699
54.0,11800,3.46,110000000,0.0700
54.1,11800,3.46,110000000,0.0701
54.1,11800,3.47,111000000,0.0702
54.2,11900,3.47,111000000,0.0703
54.3,11900,3.48,111000000,0.0704
54.3,11900,3.48,111000000,0.0705
54.4,11900,3.49,111000000,0.0706
54.5,11900,3.49,112000000,0.0708
54.5,11900,3.50,112000000,0.0709
54.6,12000,3.51,112000000,0.0710
54.7,12000,3.51,112000000,0.0711
54.7,12000,3.52,112000000,0.0712
54.8,12000,3.52,112000000,0.0713
54.9,12000,3.53,112000000,0.0714
54.9,12000,3.53,112000000,0.0715
55.0,12000,3.54,112000000,0.0716
55.0,12000,3.54,112000000,0.0717
55.1,12000,3.55,112000000,0.0718
55.2,12000,3.55,112000000,0.0719
55.2,12000,3.56,112000000,0.0720
55.3,12000,3.56,112000000,0.0722
55.4,12000,3.57,112000000,0.0723
55.4,12000,3.57,112000000,0.0724
55.5,12000,3.58,112000000,0.0725
55.6,12000,3.59,112000000,0.0726
55.6,12000,3.59,112000000,0.0727
55.7,12000,3.60,112000000,0.0728
55.8,12000,3.60,112000000,0.0729
55.8,12000,3.61,112000000,0.0730
55.9,11900,3.61,112000000,0.0731
55.9,11900,3.62,111000000,0.0732
56.0,11900,3.62,111000000,0.0733
56.1,11800,3.63,111000000,0.0734
56.1,11800,3.63,110000000,0.0735
56.2,11800,3.64,110000000,0.0737
56.3,11700,3.64,110000000,0.0738
56.3,11700,3.65,109000000,0.0739
56.4,11700,3.65,109000000,0.0740
56.5,11600,3.66,109000000,0.0741
56.5,11600,3.66,108000000,0.0742
56.6,11500,3.67,108000000,0.0743
56.7,11500,3.68,107000000,0.0744
56.7,11400,3.68,107000000,0.0745
56.8,11400,3.69,107000000,0.0746
56.8,11400,3.69,106000000,0.0747
56.9,11300,3.70,106000000,0.0748
57.0,11300,3.70,106000000,0.0749
57.0,11300,3.71,105000000,0.0751
57.1,11200,3.71,105000000,0.0752
57.2,11200,3.72,105000000,0.0753
57.2,11100,3.72,104000000,0.0754
57.3,11000,3.73,103000000,0.0755
57.4,10700,3.73,100000000,0.0756
57.4,10400,3.74,97500000,0.0757
57.5,10200,3.74,95900000,0.0758
57.6,10200,3.75,95200000,0.0759
57.6,10100,3.76,94800000,0.0760
57.7,10100,3.76,94700000,0.0761
57.8,10100,3.77,94800000,0.0762
57.8,10100,3.77,94900000,0.0763
57.9,10200,3.78,95200000,0.0765
57.9,10200,3.78,95500000,0.0766
58.0,10200,3.79,95800000,0.0767
58.1,10300,3.79,96100000,0.0768
58.1,10300,3.80,96500000,0.0769
58.2,10400,3.80,96900000,0.0770
58.3,10400,3.81,97300000,0.0771
58.3,10500,3.81,97800000,0.0772
58.4,10500,3.82,98200000,0.0773
58.5,10500,3.82,98600000,0.0774
58.5,10600,3.83,99100000,0.0775
58.6,10600,3.83,99500000,0.0776
58.7,10700,3.84,99900000,0.0777
58.7,10700,3.84,100000000,0.0778
58.8,10800,3.85,101000000,0.0780
58.8,10800,3.86,101000000,0.0781
58.9,10900,3.86,102000000,0.0782
59.0,10900,3.87,102000000,0.0783
59.0,10900,3.87,102000000,0.0784
59.1,11000,3.88,103000000,0.0785
59.2,11000,3.88,103000000,0.0786
59.2,11100,3.89,104000000,0.0787
59.3,11100,3.89,104000000,0.0788
59.4,11100,3.90,104000000,0.0789
59.4,11200,3.90,105000000,0.0790
59.5,11200,3.91,105000000,0.0791
59.6,11300,3.91,105000000,0.0792
59.6,11300,3.92,106000000,0.0794
59.7,11300,3.92,106000000,0.0795
59.7,11400,3.93,106000000,0.0796
59.8,11400,3.93,107000000,0.0797
59.9,11400,3.94,107000000,0.0798
59.9,11500,3.95,107000000,0.0799
60.0,11500,3.95,107000000,0.0800
60.1,11500,3.96,108000000,0.0801
60.1,11500,3.96,108000000,0.0802
60.2,11600,3.97,108000000,0.0803
60.3,11600,3.97,108000000,0.0804
60.3,11600,3.98,109000000,0.0805
60.4,11600,3.98,109000000,0.0806
60.5,11700,3.99,109000000,0.0808
60.5,11700,3.99,109000000,0.0809
60.6,11700,4.00,109000000,0.0810
60.7,11700,4.00,109000000,0.0811
60.7,11700,4.01,110000000,0.0812
60.8,11700,4.01,110000000,0.0813
60.8,11800,4.02,110000000,0.0814
60.9,11800,4.03,110000000,0.0815
61.0,11800,4.03,110000000,0.0816
61.0,11800,4.04,110000000,0.0817
61.1,11800,4.04,110000000,0.0818
61.2,11800,4.05,110000000,0.0819
61.2,11800,4.05,111000000,0.0820
61.3,11800,4.06,111000000,0.0821
61.4,11800,4.06,111000000,0.0823
61.4,11800,4.07,111000000,0.0824
61.5,11900,4.07,111000000,0.0825
61.6,11900,4.08,111000000,0.0826
61.6,11900,4.08,111000000,0.0827
61.7,11900,4.09,111000000,0.0828
61.7,11900,4.09,111000000,0.0829
61.8,11900,4.10,111000000,0.0830
61.9,11900,4.11,111000000,0.0831
61.9,11900,4.11,111000000,0.0832
62.0,11900,4.12,111000000,0.0833
62.1,11900,4.12,111000000,0.0834
62.1,11900,4.13,111000000,0.0835
62.2,11900,4.13,111000000,0.0837
62.3,11900,4.14,111000000,0.0838
62.3,11900,4.14,111000000,0.0839
62.4,11900,4.15,111000000,0.0840
62.5,11800,4.15,111000000,0.0841
62.5,11800,4.16,111000000,0.0842
62.6,11800,4.16,111000000,0.0843
62.6,11800,4.17,111000000,0.0844
62.7,11800,4.17,110000000,0.0845
62.8,11800,4.18,110000000,0.0846
62.8,11800,4.18,110000000,0.0847
62.9,11800,4.19,110000000,0.0848
63.0,11700,4.20,110000000,0.0849
63.0,11700,4.20,110000000,0.0850
63.1,11700,4.21,109000000,0.0852
63.2,11700,4.21,109000000,0.0853
63.2,11700,4.22,109000000,0.0854
63.3,11600,4.22,109000000,0.0855
63.4,11600,4.23,108000000,0.0856
63.4,11600,4.23,108000000,0.0857
63.5,11500,4.24,108000000,0.0858
63.5,11500,4.24,108000000,0.0859
63.6,11500,4.25,107000000,0.0860
63.7,11400,4.25,107000000,0.0861
63.7,11300,4.26,106000000,0.0862
63.8,11300,4.26,105000000,0.0863
63.9,11200,4.27,105000000,0.0864
63.9,11100,4.27,104000000,0.0866
64.0,10900,4.28,102000000,0.0867
64.1,10800,4.29,101000000,0.0868
64.1,10600,4.29,99300000,0.0869
64.2,10300,4.30,96600000,0.0870
64.3,9970,4.30,93200000,0.0871
64.3,9680,4.31,90500000,0.0872
64.4,9480,4.31,88700000,0.0873
64.5,9370,4.32,87600000,0.0874
64.5,9300,4.32,86900000,0.0875
64.6,9260,4.33,86600000,0.0876
64.6,9240,4.33,86400000,0.0877
64.7,9220,4.34,86300000,0.0878
64.8,9230,4.34,86300000,0.0880
64.8,9230,4.35,86400000,0.0881
64.9,9250,4.35,86500000,0.0882
65.0,9260,4.36,86600000,0.0883
65.0,9280,4.37,86800000,0.0884
65.1,9300,4.37,87000000,0.0885
65.2,9320,4.38,87100000,0.0886
65.2,9340,4.38,87400000,0.0887
65.3,9360,4.39,87500000,0.0888
65.4,9380,4.39,87700000,0.0889
65.4,9400,4.40,88000000,0.0890
65.5,9420,4.40,88100000,0.0891
65.5,9450,4.41,88400000,0.0892
65.6,9460,4.41,88500000,0.0893
65.7,9490,4.42,88700000,0.0895
65.7,9500,4.42,88900000,0.0896
65.8,9520,4.43,89100000,0.0897
65.9,9540,4.43,89300000,0.0898
65.9,9560,4.44,89400000,0.0899
66.0,9580,4.44,89600000,0.0900
66.1,9590,4.45,89700000,0.0901
66.1,9600,4.46,89800000,0.0902
66.2,9620,4.46,90000000,0.0903
66.3,9630,4.47,90000000,0.0904
66.3,9650,4.47,90200000,0.0905
66.4,9650,4.48,90300000,0.0906
66.4,9670,4.48,90400000,0.0907
66.5,9670,4.49,90500000,0.0908
66.6,9680,4.49,90500000,0.0910
66.6,9690,4.50,90600000,0.0911
66.7,9690,4.50,90600000,0.0912
66.8,9700,4.51,90700000,0.0913
66.8,9710,4.51,90800000,0.0914
66.9,9710,4.52,90800000,0.0915
67.0,9710,4.52,90900000,0.0916
67.0,9720,4.53,90900000,0.0917
67.1,9730,4.53,91000000,0.0918
67.2,9730,4.54,91000000,0.0919
67.2,9740,4.55,91100000,0.0920
67.3,9740,4.55,91100000,0.0921
67.4,9750,4.56,91200000,0.0922
67.4,9760,4.56,91300000,0.0923
67.5,9770,4.57,91400000,0.0925
67.5,9780,4.57,91500000,0.0926
67.6,9790,4.58,91600000,0.0927
67.7,9810,4.58,91700000,0.0928
67.7,9820,4.59,91800000,0.0929
67.8,9830,4.59,92000000,0.0930
67.9,9850,4.60,92100000,0.0931
67.9,9860,4.60,92200000,0.0932
68.0,9880,4.61,92400000,0.0933
68.1,9890,4.61,92500000,0.0934
68.1,9910,4.62,92700000,0.0935
68.2,9920,4.62,92800000,0.0936
68.3,9930,4.63,92900000,0.0937
68.3,9950,4.64,93100000,0.0939
68.4,9960,4.64,93200000,0.0940
68.4,9980,4.65,93300000,0.0941
68.5,9990,4.65,93400000,0.0942
68.6,10000,4.66,93600000,0.0943
68.6,10000,4.66,93700000,0.0944
68.7,10000,4.67,93900000,0.0945
68.8,10100,4.67,94100000,0.0946
68.8,10100,4.68,94300000,0.0947
68.9,10100,4.68,94500000,0.0948
69.0,10100,4.69,94600000,0.0949
69.0,10100,4.69,94800000,0.0950
69.1,10200,4.70,95100000,0.0951
69.2,10200,4.70,95200000,0.0953
69.2,10200,4.71,95500000,0.0954
69.3,10200,4.72,95700000,0.0955
69.3,10300,4.72,95900000,0.0956
69.4,10300,4.73,96100000,0.0957
69.5,10300,4.73,96400000,0.0958
69.5,10300,4.74,96600000,0.0959
69.6,10400,4.74,96800000,0.0960
69.7,10400,4.75,97100000,0.0961
69.7,10400,4.75,97300000,0.0962
69.8,10400,4.76,97500000,0.0963
69.9,10400,4.76,97700000,0.0964
69.9,10500,4.77,97800000,0.0965
70.0,10500,4.77,98100000,0.0967
70.1,10500,4.78,98200000,0.0968
70.1,10500,4.78,98400000,0.0969
70.2,10500,4.79,98600000,0.0970
70.3,10600,4.80,98700000,0.0971
70.3,10600,4.80,98800000,0.0972
70.4,10600,4.81,98900000,0.0973
70.4,10600,4.81,99100000,0.0974
70.5,10600,4.82,99200000,0.0975
70.6,10600,4.82,99400000,0.0976
70.6,10600,4.83,99500000,0.0977
70.7,10700,4.83,99600000,0.0978
70.8,10700,4.84,99800000,0.0979
70.8,10700,4.84,99900000,0.0980
70.9,10700,4.85,100000000,0.0982
71.0,10700,4.85,100000000,0.0983
71.0,10700,4.86,101000000,0.0984
71.1,10800,4.86,101000000,0.0985
71.2,10800,4.87,101000000,0.0986
71.2,10800,4.87,101000000,0.0987
71.3,10800,4.88,101000000,0.0988
71.3,10800,4.89,101000000,0.0989
71.4,10900,4.89,102000000,0.0990
71.5,10900,4.90,102000000,0.0991
71.5,10900,4.90,102000000,0.0992
71.6,10900,4.91,102000000,0.0993
71.7,10900,4.91,102000000,0.0994
71.7,10900,4.92,102000000,0.0995
71.8,11000,4.92,103000000,0.0997
71.9,11000,4.93,103000000,0.0998
71.9,11000,4.93,103000000,0.0999
72.0,11000,4.94,103000000,0.100
72.1,11000,4.94,103000000,0.100
72.1,11000,4.95,103000000,0.100
72.2,11000,4.95,103000000,0.100
72.2,11000,4.96,103000000,0.100
72.3,11000,4.96,103000000,0.101
72.4,11000,4.97,103000000,0.101
72.4,11000,4.98,103000000,0.101
72.5,11000,4.98,103000000,0.101
72.6,11000,4.99,103000000,0.101
72.6,11000,4.99,103000000,0.101
72.7,11000,5.00,103000000,0.101
72.8,11000,5.00,103000000,0.101
72.8,11000,5.01,103000000,0.101
72.9,11000,5.01,103000000,0.101
73.0,11000,5.02,103000000,0.102
73.0,11000,5.02,103000000,0.102
73.1,11000,5.03,103000000,0.102
73.1,11000,5.03,103000000,0.102
73.2,11000,5.04,103000000,0.102
73.3,11000,5.04,103000000,0.102
73.3,11000,5.05,103000000,0.102
73.4,11000,5.05,102000000,0.102
73.5,10900,5.06,102000000,0.102
73.5,10900,5.07,102000000,0.103
73.6,10900,5.07,102000000,0.103
73.7,10900,5.08,102000000,0.103
73.7,10900,5.08,102000000,0.103
73.8,10900,5.09,102000000,0.103
73.9,10800,5.09,101000000,0.103
73.9,10800,5.10,101000000,0.103
74.0,10800,5.10,101000000,0.103
74.1,10800,5.11,101000000,0.103
74.1,10700,5.11,100000000,0.104
74.2,10700,5.12,100000000,0.104
74.2,10700,5.12,99900000,0.104
74.3,10600,5.13,99600000,0.104
74.4,10600,5.13,99300000,0.104
74.4,10600,5.14,99100000,0.104
74.5,10600,5.15,98800000,0.104
74.6,10500,5.15,98600000,0.104
74.6,10500,5.16,98300000,0.104
74.7,10500,5.16,98100000,0.105
74.8,10500,5.17,97900000,0.105
74.8,10400,5.17,97700000,0.105
74.9,10400,5.18,97500000,0.105
75.0,10400,5.18,97300000,0.105
75.0,10400,5.19,97100000,0.105
75.1,10400,5.19,96900000,0.105
75.1,10300,5.20,96700000,0.105
75.2,10300,5.20,96600000,0.105
75.3,10300,5.21,96400000,0.105
75.3,10300,5.21,96200000,0.106
75.4,10300,5.22,95900000,0.106
75.5,10200,5.23,95700000,0.106
75.5,10200,5.23,95400000,0.106
75.6,10200,5.24,95100000,0.106
75.7,10100,5.24,94800000,0.106
75.7,10100,5.25,94500000,0.106
75.8,10100,5.25,94200000,0.106
75.9,10000,5.26,93800000,0.106
75.9,9980,5.26,93400000,0.107
76.0,9950,5.27,93000000,0.107
76.0,9900,5.27,92600000,0.107
76.1,9860,5.28,92200000,0.107
76.2,9820,5.28,91800000,0.107
76.2,9770,5.29,91400000,0.107
76.3,9710,5.29,90800000,0.107
76.4,9640,5.30,90200000,0.107
76.4,9560,5.30,89400000,0.107
76.5,9440,5.31,88300000,0.108
76.6,9260,5.32,86600000,0.108
76.6,8940,5.32,83600000,0.108
76.8,7980,5.33,74600000,0.108