File: data/DouglasFir/Superwood-IDW2-23 Jul, 2025.csv
Time (sec),Force (N),Position (mm),Stress (Pa),Strain (%)
2.73,24.6,0.0173,212000,0.0173
2.74,25.2,0.0200,217000,0.0200
2.76,25.8,0.0224,222000,0.0224
2.77,26.4,0.0249,227000,0.0249
2.79,26.8,0.0272,230000,0.0273
2.80,27.3,0.0297,235000,0.0298
2.82,28.0,0.0325,241000,0.0326
2.83,28.3,0.0349,243000,0.0350
2.85,28.7,0.0374,247000,0.0375
2.86,29.3,0.0398,252000,0.0399
2.88,30.0,0.0424,258000,0.0425
2.89,30.8,0.0450,265000,0.0451
2.91,31.7,0.0475,273000,0.0476
2.92,32.5,0.0499,280000,0.0500
2.94,33.5,0.0524,288000,0.0525
2.95,34.4,0.0548,296000,0.0549
2.97,35.4,0.0575,305000,0.0576
2.98,36.6,0.0599,315000,0.0600
3.00,37.6,0.0623,323000,0.0624
3.01,38.4,0.0648,331000,0.0649
3.03,39.4,0.0673,339000,0.0674
3.04,40.5,0.0699,348000,0.0700
3.06,41.6,0.0724,358000,0.0725
3.07,42.5,0.0748,366000,0.0749
3.09,43.5,0.0773,375000,0.0775
3.10,44.5,0.0798,383000,0.0800
3.12,45.4,0.0823,391000,0.0825
3.13,46.4,0.0850,400000,0.0852
3.15,47.4,0.0873,408000,0.0875
3.16,48.3,0.0898,416000,0.0900
3.18,49.4,0.0923,425000,0.0925
3.19,50.3,0.0948,433000,0.0950
3.21,51.4,0.0974,443000,0.0976
3.22,52.5,0.0999,452000,0.100
3.24,53.4,0.102,460000,0.103
3.25,54.3,0.105,467000,0.105
3.27,55.3,0.107,476000,0.108
3.28,56.4,0.110,486000,0.110
3.30,57.4,0.112,494000,0.113
3.31,58.4,0.115,502000,0.115
3.33,59.4,0.117,511000,0.117
3.34,60.3,0.120,519000,0.120
3.36,61.2,0.122,527000,0.122
3.37,62.2,0.125,535000,0.125
3.39,63.0,0.127,542000,0.127
3.40,63.9,0.130,549000,0.130
3.42,64.7,0.132,557000,0.133
3.43,65.9,0.135,567000,0.135
3.45,66.7,0.137,574000,0.138
3.46,67.6,0.140,582000,0.140
3.48,68.4,0.142,589000,0.142
3.49,69.3,0.145,596000,0.145
3.51,70.2,0.147,604000,0.148
3.52,71.0,0.150,611000,0.150
3.54,71.8,0.152,618000,0.152
3.55,72.6,0.155,624000,0.155
3.57,73.3,0.157,631000,0.157
3.58,74.4,0.160,640000,0.160
3.60,75.2,0.162,647000,0.163
3.61,75.9,0.165,653000,0.165
3.63,76.8,0.167,661000,0.167
3.64,77.5,0.170,667000,0.170
3.66,78.4,0.172,674000,0.173
3.67,79.1,0.175,680000,0.175
3.69,79.7,0.177,685000,0.177
3.70,80.3,0.180,691000,0.180
3.72,80.8,0.182,696000,0.182
3.73,81.7,0.185,703000,0.185
3.75,82.3,0.187,708000,0.188
3.76,82.7,0.190,712000,0.190
3.78,83.4,0.192,718000,0.192
3.79,84.1,0.195,724000,0.195
3.81,84.9,0.197,730000,0.197
3.82,85.8,0.200,738000,0.200
3.84,86.6,0.202,745000,0.202
3.85,87.3,0.205,751000,0.205
3.87,88.2,0.207,759000,0.207
3.88,88.9,0.210,765000,0.210
3.90,89.7,0.212,772000,0.213
3.91,90.3,0.214,777000,0.215
3.93,91.0,0.217,783000,0.217
3.94,91.8,0.219,790000,0.220
3.96,92.4,0.222,795000,0.222
3.97,92.9,0.225,799000,0.225
3.99,93.3,0.227,803000,0.227
4.00,93.6,0.229,805000,0.230
4.02,94.1,0.232,810000,0.232
4.03,94.7,0.234,815000,0.235
4.05,95.1,0.237,818000,0.237
4.06,95.4,0.239,821000,0.240
4.08,95.9,0.242,825000,0.242
4.09,96.5,0.244,830000,0.245
4.11,97.1,0.247,835000,0.247
4.12,97.5,0.249,839000,0.250
4.14,98.0,0.252,843000,0.252
4.15,98.3,0.254,846000,0.255
4.17,98.6,0.257,848000,0.257
4.18,99.1,0.259,853000,0.260
4.20,99.5,0.262,856000,0.262
4.21,100,0.264,861000,0.265
4.23,101,0.267,867000,0.267
4.24,101,0.269,871000,0.270
4.26,102,0.272,876000,0.272
4.27,103,0.274,882000,0.275
4.29,103,0.277,887000,0.277
4.30,104,0.279,894000,0.280
4.32,105,0.282,899000,0.282
4.33,106,0.284,909000,0.285
4.35,107,0.287,919000,0.287
4.36,108,0.289,929000,0.290
4.38,109,0.292,939000,0.292
4.39,110,0.294,949000,0.295
4.41,111,0.297,959000,0.297
4.42,113,0.299,971000,0.300
4.44,114,0.302,984000,0.303
4.45,116,0.304,995000,0.305
4.47,117,0.307,1010000,0.307
4.48,118,0.309,1020000,0.310
4.50,120,0.312,1030000,0.313
4.51,122,0.314,1050000,0.315
4.53,123,0.317,1060000,0.317
4.54,125,0.319,1070000,0.320
4.56,126,0.322,1080000,0.322
4.57,128,0.324,1100000,0.325
4.59,129,0.327,1110000,0.328
4.60,131,0.329,1130000,0.330
4.62,133,0.332,1140000,0.332
4.63,134,0.334,1160000,0.335
4.65,136,0.337,1170000,0.338
4.66,138,0.339,1190000,0.340
4.68,140,0.342,1210000,0.342
4.69,142,0.344,1220000,0.345
4.71,144,0.347,1240000,0.347
4.72,146,0.349,1260000,0.350
4.74,148,0.352,1270000,0.353
4.75,150,0.354,1290000,0.355
4.77,151,0.357,1300000,0.357
4.78,153,0.359,1320000,0.360
4.80,155,0.362,1340000,0.363
4.81,158,0.364,1360000,0.365
4.83,160,0.367,1370000,0.367
4.84,162,0.369,1390000,0.370
4.86,164,0.372,1410000,0.372
4.87,166,0.374,1430000,0.375
4.89,168,0.377,1450000,0.377
4.90,171,0.379,1470000,0.380
4.92,173,0.382,1490000,0.382
4.93,175,0.384,1510000,0.385
4.95,178,0.387,1530000,0.388
4.96,181,0.389,1550000,0.390
4.98,183,0.392,1580000,0.393
4.99,186,0.394,1600000,0.395
5.01,188,0.397,1620000,0.397
5.02,191,0.399,1640000,0.400
5.04,194,0.402,1670000,0.403
5.05,196,0.404,1690000,0.405
5.07,199,0.407,1710000,0.408
5.08,201,0.409,1730000,0.410
5.10,204,0.412,1760000,0.413
5.11,207,0.414,1780000,0.415
5.13,210,0.417,1800000,0.418
5.14,212,0.419,1830000,0.420
5.16,215,0.422,1850000,0.422
5.17,218,0.424,1870000,0.425
5.19,221,0.427,1900000,0.428
5.20,224,0.429,1920000,0.430
5.22,226,0.432,1950000,0.432
5.23,229,0.434,1970000,0.435
5.25,232,0.437,2000000,0.437
5.26,235,0.439,2020000,0.440
5.28,238,0.442,2050000,0.442
5.29,241,0.444,2070000,0.445
5.31,244,0.447,2100000,0.447
5.32,247,0.449,2120000,0.450
5.34,250,0.452,2150000,0.453
5.35,253,0.454,2180000,0.455
5.37,256,0.456,2200000,0.457
5.38,259,0.459,2230000,0.460
5.40,262,0.461,2260000,0.462
5.41,266,0.464,2290000,0.465
5.43,270,0.467,2320000,0.467
5.44,274,0.469,2360000,0.470
5.46,278,0.471,2390000,0.472
5.47,282,0.474,2430000,0.475
5.49,287,0.477,2470000,0.477
5.50,291,0.479,2510000,0.480
5.52,296,0.481,2540000,0.482
5.53,300,0.484,2580000,0.485
5.55,305,0.486,2620000,0.487
5.56,309,0.489,2660000,0.490
5.58,314,0.492,2700000,0.492
5.59,318,0.494,2740000,0.495
5.61,322,0.496,2770000,0.497
5.62,326,0.499,2810000,0.500
5.64,331,0.501,2850000,0.503
5.65,335,0.504,2880000,0.505
5.67,339,0.506,2920000,0.507
5.68,343,0.509,2950000,0.510
5.70,347,0.511,2990000,0.512
5.71,352,0.514,3030000,0.515
5.73,356,0.516,3060000,0.517
5.74,361,0.519,3100000,0.520
5.76,366,0.521,3150000,0.522
5.77,370,0.524,3180000,0.525
5.79,375,0.527,3230000,0.528
5.80,380,0.529,3270000,0.530
5.82,385,0.532,3310000,0.533
5.83,390,0.534,3360000,0.535
5.85,395,0.536,3400000,0.537
5.86,400,0.539,3440000,0.540
5.88,405,0.542,3490000,0.543
5.89,410,0.544,3530000,0.545
5.91,415,0.546,3570000,0.547
5.92,420,0.549,3610000,0.550
5.94,425,0.551,3660000,0.553
5.95,431,0.554,3710000,0.555
5.97,436,0.556,3750000,0.557
5.98,441,0.559,3800000,0.560
6.00,447,0.561,3840000,0.562
6.01,452,0.564,3890000,0.565
6.03,459,0.566,3950000,0.567
6.04,465,0.569,4000000,0.570
6.06,471,0.571,4050000,0.572
6.07,477,0.574,4100000,0.575
6.09,483,0.576,4150000,0.577
6.10,489,0.579,4210000,0.580
6.12,496,0.581,4270000,0.582
6.13,502,0.584,4320000,0.585
6.15,508,0.586,4370000,0.587
6.16,514,0.589,4420000,0.590
6.18,521,0.591,4480000,0.592
6.19,528,0.594,4540000,0.595
6.21,534,0.596,4590000,0.597
6.22,540,0.599,4640000,0.600
6.24,546,0.601,4700000,0.602
6.25,553,0.604,4760000,0.605
6.27,561,0.606,4820000,0.608
6.28,567,0.609,4880000,0.610
6.30,573,0.611,4930000,0.612
6.31,581,0.614,5000000,0.615
6.33,588,0.616,5060000,0.618
6.34,596,0.619,5130000,0.620
6.36,603,0.621,5190000,0.622
6.37,610,0.624,5250000,0.625
6.39,617,0.626,5310000,0.628
6.40,625,0.629,5380000,0.630
6.42,633,0.631,5450000,0.633
6.43,641,0.634,5510000,0.635
6.45,648,0.636,5570000,0.637
6.46,656,0.639,5640000,0.640
6.48,664,0.641,5720000,0.643
6.49,672,0.644,5780000,0.645
6.51,679,0.646,5850000,0.648
6.52,687,0.649,5910000,0.650
6.54,694,0.651,5970000,0.653
6.55,703,0.654,6050000,0.655
6.57,710,0.656,6110000,0.658
6.58,718,0.659,6180000,0.660
6.60,726,0.661,6240000,0.663
6.61,733,0.664,6310000,0.665
6.63,742,0.666,6390000,0.668
6.64,751,0.669,6460000,0.670
6.66,758,0.671,6530000,0.673
6.67,766,0.674,6590000,0.675
6.69,775,0.676,6660000,0.677
6.70,784,0.679,6750000,0.680
6.72,793,0.681,6820000,0.683
6.73,801,0.684,6890000,0.685
6.75,809,0.686,6960000,0.687
6.76,818,0.689,7040000,0.690
6.78,827,0.691,7120000,0.692
6.79,837,0.694,7200000,0.695
6.81,845,0.696,7270000,0.697
6.82,853,0.699,7340000,0.700
6.84,862,0.701,7420000,0.702
6.85,872,0.704,7500000,0.705
6.87,881,0.706,7580000,0.708
6.88,890,0.708,7660000,0.710
6.90,898,0.711,7720000,0.712
6.91,907,0.713,7800000,0.715
6.93,917,0.716,7890000,0.717
6.94,926,0.718,7970000,0.720
6.96,935,0.721,8040000,0.722
6.97,943,0.723,8110000,0.725
6.99,952,0.726,8190000,0.727
7.00,962,0.728,8270000,0.730
7.02,971,0.731,8360000,0.732
7.03,980,0.733,8430000,0.735
7.05,988,0.736,8500000,0.737
7.06,997,0.738,8580000,0.740
7.08,1010,0.741,8660000,0.742
7.09,1020,0.743,8740000,0.745
7.11,1020,0.746,8810000,0.747
7.12,1030,0.748,8880000,0.750
7.14,1040,0.751,8950000,0.752
7.15,1050,0.753,9030000,0.755
7.17,1060,0.756,9100000,0.757
7.18,1070,0.758,9170000,0.760
7.20,1070,0.761,9240000,0.762
7.21,1080,0.763,9310000,0.765
7.23,1090,0.766,9390000,0.767
7.24,1100,0.768,9470000,0.770
7.26,1110,0.771,9540000,0.772
7.27,1120,0.773,9620000,0.775
7.29,1130,0.776,9700000,0.777
7.30,1140,0.778,9770000,0.780
7.32,1150,0.781,9860000,0.782
7.33,1160,0.783,9940000,0.785
7.35,1160,0.786,10000000,0.787
7.36,1170,0.788,10100000,0.790
7.38,1180,0.791,10200000,0.792
7.39,1190,0.793,10300000,0.795
7.41,1200,0.796,10300000,0.797
7.42,1210,0.798,10400000,0.800
7.44,1220,0.801,10500000,0.802
7.45,1230,0.803,10600000,0.805
7.47,1240,0.806,10700000,0.808
7.48,1250,0.808,10800000,0.810
7.50,1260,0.811,10900000,0.812
7.51,1270,0.813,10900000,0.815
7.53,1280,0.816,11000000,0.817
7.54,1290,0.819,11100000,0.820
7.56,1300,0.821,11200000,0.823
7.57,1310,0.823,11300000,0.825
7.59,1320,0.826,11400000,0.827
7.60,1330,0.828,11500000,0.830
7.62,1340,0.831,11600000,0.832
7.63,1350,0.833,11600000,0.835
7.65,1360,0.836,11700000,0.837
7.66,1370,0.838,11800000,0.840
7.68,1380,0.841,11900000,0.842
7.69,1390,0.843,12000000,0.845
7.71,1400,0.846,12100000,0.847
7.72,1410,0.848,12200000,0.850
7.74,1420,0.851,12200000,0.852
7.75,1430,0.853,12300000,0.855
7.77,1440,0.856,12400000,0.857
7.78,1450,0.858,12500000,0.860
7.80,1460,0.861,12600000,0.862
7.81,1470,0.863,12700000,0.865
7.83,1480,0.866,12800000,0.867
7.84,1490,0.868,12800000,0.870
7.86,1500,0.871,12900000,0.872
7.87,1510,0.873,13000000,0.875
7.89,1520,0.876,13100000,0.877
7.90,1530,0.878,13200000,0.880
7.92,1540,0.881,13200000,0.883
7.93,1550,0.883,13300000,0.885
7.95,1560,0.886,13400000,0.887
7.96,1570,0.888,13500000,0.890
7.98,1570,0.891,13500000,0.892
7.99,1580,0.893,13600000,0.895
8.01,1590,0.896,13700000,0.897
8.02,1600,0.898,13800000,0.900
8.04,1610,0.901,13800000,0.902
8.05,1620,0.903,13900000,0.905
8.07,1630,0.906,14000000,0.908
8.08,1640,0.908,14100000,0.910
8.10,1640,0.911,14100000,0.913
8.11,1650,0.913,14200000,0.915
8.13,1660,0.916,14300000,0.917
8.14,1670,0.918,14300000,0.920
8.16,1680,0.921,14400000,0.923
8.17,1690,0.923,14500000,0.925
8.19,1690,0.926,14600000,0.928
8.20,1700,0.928,14600000,0.930
8.22,1710,0.931,14700000,0.933
8.23,1720,0.933,14800000,0.935
8.25,1730,0.936,14900000,0.938
8.26,1740,0.938,15000000,0.940
8.28,1750,0.941,15000000,0.942
8.29,1760,0.943,15100000,0.945
8.31,1770,0.946,15200000,0.947
8.32,1780,0.948,15300000,0.950
8.34,1780,0.950,15300000,0.952
8.35,1790,0.953,15400000,0.955
8.37,1800,0.955,15500000,0.957
8.38,1810,0.958,15600000,0.960
8.40,1820,0.960,15700000,0.962
8.41,1830,0.963,15800000,0.965
8.43,1840,0.965,15800000,0.967
8.44,1850,0.968,15900000,0.970
8.46,1860,0.970,16000000,0.972
8.47,1870,0.973,16100000,0.975
8.49,1880,0.975,16200000,0.977
8.50,1890,0.978,16300000,0.979
8.52,1910,0.980,16400000,0.982
8.53,1920,0.983,16500000,0.985
8.55,1930,0.985,16600000,0.987
8.56,1940,0.988,16700000,0.989
8.58,1950,0.990,16800000,0.992
8.59,1960,0.992,16900000,0.994
8.61,1970,0.995,17000000,0.997
8.62,1980,0.997,17100000,0.999
8.64,2000,1.00,17200000,1.00
8.65,2010,1.00,17300000,1.00
8.67,2020,1.01,17400000,1.01
8.68,2030,1.01,17500000,1.01
8.70,2050,1.01,17600000,1.01
8.71,2060,1.01,17700000,1.01
8.73,2070,1.01,17800000,1.02
8.74,2080,1.02,17900000,1.02
8.76,2090,1.02,18000000,1.02
8.77,2110,1.02,18100000,1.02
8.79,2120,1.03,18200000,1.03
8.80,2130,1.03,18400000,1.03
8.82,2150,1.03,18500000,1.03
8.83,2160,1.03,18600000,1.03
8.85,2170,1.04,18700000,1.04
8.86,2180,1.04,18800000,1.04
8.88,2200,1.04,18900000,1.04
8.89,2210,1.04,19000000,1.04
8.91,2220,1.05,19100000,1.05
8.92,2240,1.05,19200000,1.05
8.94,2250,1.05,19300000,1.05
8.95,2260,1.05,19500000,1.05
8.97,2270,1.06,19600000,1.06
8.98,2290,1.06,19700000,1.06
9.00,2300,1.06,19800000,1.06
9.01,2310,1.06,19900000,1.07
9.03,2330,1.07,20000000,1.07
9.04,2340,1.07,20100000,1.07
9.06,2350,1.07,20300000,1.07
9.07,2370,1.07,20400000,1.08
9.09,2380,1.08,20500000,1.08
9.10,2390,1.08,20600000,1.08
9.12,2410,1.08,20700000,1.08
9.13,2420,1.08,20800000,1.09
9.15,2440,1.09,21000000,1.09
9.16,2450,1.09,21100000,1.09
9.18,2460,1.09,21200000,1.09
9.19,2470,1.09,21300000,1.09
9.21,2490,1.10,21400000,1.10
9.22,2500,1.10,21500000,1.10
9.24,2520,1.10,21700000,1.10
9.25,2530,1.10,21800000,1.10
9.27,2540,1.11,21900000,1.11
9.28,2560,1.11,22000000,1.11
9.30,2570,1.11,22100000,1.11
9.31,2580,1.11,22200000,1.11
9.33,2600,1.12,22300000,1.12
9.34,2610,1.12,22400000,1.12
9.36,2620,1.12,22600000,1.12
9.37,2630,1.12,22700000,1.12
9.39,2650,1.13,22800000,1.13
9.40,2660,1.13,22900000,1.13
9.42,2670,1.13,23000000,1.13
9.43,2680,1.13,23100000,1.13
9.45,2700,1.14,23200000,1.14
9.46,2710,1.14,23300000,1.14
9.48,2720,1.14,23400000,1.14
9.49,2740,1.14,23500000,1.14
9.51,2750,1.15,23600000,1.15
9.52,2760,1.15,23800000,1.15
9.54,2780,1.15,23900000,1.15
9.55,2790,1.15,24000000,1.15
9.57,2800,1.16,24100000,1.16
9.58,2810,1.16,24200000,1.16
9.60,2830,1.16,24300000,1.16
9.61,2840,1.16,24400000,1.17
9.63,2850,1.17,24500000,1.17
9.64,2860,1.17,24600000,1.17
9.66,2870,1.17,24700000,1.17
9.67,2890,1.17,24800000,1.18
9.69,2900,1.18,24900000,1.18
9.70,2910,1.18,25000000,1.18
9.72,2920,1.18,25100000,1.18
9.73,2930,1.18,25200000,1.19
9.75,2950,1.19,25400000,1.19
9.76,2960,1.19,25500000,1.19
9.78,2970,1.19,25600000,1.19
9.79,2980,1.19,25700000,1.20
9.81,3000,1.20,25800000,1.20
9.82,3010,1.20,25900000,1.20
9.84,3020,1.20,26000000,1.20
9.85,3030,1.20,26100000,1.21
9.87,3040,1.21,26200000,1.21
9.88,3060,1.21,26300000,1.21
9.90,3070,1.21,26400000,1.21
9.91,3080,1.21,26500000,1.22
9.93,3090,1.22,26600000,1.22
9.94,3100,1.22,26700000,1.22
9.96,3120,1.22,26800000,1.22
9.97,3130,1.22,26900000,1.23
9.99,3140,1.23,27000000,1.23
10.0,3150,1.23,27100000,1.23
10.0,3170,1.23,27200000,1.23
10.0,3180,1.23,27300000,1.24
10.0,3190,1.24,27500000,1.24
10.1,3200,1.24,27600000,1.24
10.1,3210,1.24,27700000,1.24
10.1,3230,1.24,27800000,1.24
10.1,3240,1.25,27900000,1.25
10.1,3250,1.25,28000000,1.25
10.1,3260,1.25,28100000,1.25
10.2,3280,1.25,28200000,1.26
10.2,3290,1.25,28300000,1.26
10.2,3300,1.26,28400000,1.26
10.2,3320,1.26,28500000,1.26
10.2,3330,1.26,28600000,1.27
10.2,3340,1.27,28800000,1.27
10.2,3350,1.27,28900000,1.27
10.3,3370,1.27,29000000,1.27
10.3,3380,1.27,29100000,1.28
10.3,3390,1.28,29200000,1.28
10.3,3410,1.28,29300000,1.28
10.3,3420,1.28,29400000,1.28
10.3,3430,1.28,29500000,1.28
10.3,3440,1.29,29600000,1.29
10.4,3460,1.29,29800000,1.29
10.4,3470,1.29,29900000,1.29
10.4,3480,1.29,30000000,1.29
10.4,3490,1.29,30100000,1.30
10.4,3510,1.30,30200000,1.30
10.4,3520,1.30,30300000,1.30
10.5,3530,1.30,30400000,1.31
10.5,3550,1.30,30500000,1.31
10.5,3560,1.31,30600000,1.31
10.5,3570,1.31,30700000,1.31
10.5,3580,1.31,30800000,1.32
10.5,3600,1.31,30900000,1.32
10.5,3610,1.32,31000000,1.32
10.6,3620,1.32,31100000,1.32
10.6,3630,1.32,31300000,1.33
10.6,3650,1.33,31400000,1.33
10.6,3660,1.33,31500000,1.33
10.6,3670,1.33,31600000,1.33
10.6,3680,1.33,31700000,1.34
10.6,3690,1.33,31800000,1.34
10.7,3710,1.34,31900000,1.34
10.7,3720,1.34,32000000,1.34
10.7,3730,1.34,32100000,1.34
10.7,3740,1.34,32200000,1.35
10.7,3750,1.35,32300000,1.35
10.7,3770,1.35,32400000,1.35
10.8,3780,1.35,32500000,1.36
10.8,3790,1.35,32600000,1.36
10.8,3800,1.36,32700000,1.36
10.8,3820,1.36,32800000,1.36
10.8,3830,1.36,32900000,1.37
10.8,3840,1.36,33100000,1.37
10.8,3850,1.37,33200000,1.37
10.9,3870,1.37,33300000,1.37
10.9,3880,1.37,33400000,1.38
10.9,3890,1.37,33500000,1.38
10.9,3910,1.38,33600000,1.38
10.9,3920,1.38,33700000,1.38
10.9,3930,1.38,33800000,1.38
10.9,3940,1.38,33900000,1.39
11.0,3960,1.39,34100000,1.39
11.0,3970,1.39,34200000,1.39
11.0,3980,1.39,34300000,1.39
11.0,4000,1.39,34400000,1.40
11.0,4010,1.40,34500000,1.40
11.0,4020,1.40,34600000,1.40
11.1,4040,1.40,34700000,1.40
11.1,4050,1.40,34800000,1.41
11.1,4060,1.41,35000000,1.41
11.1,4080,1.41,35100000,1.41
11.1,4090,1.41,35200000,1.42
11.1,4100,1.41,35300000,1.42
11.1,4120,1.42,35400000,1.42
11.2,4130,1.42,35500000,1.42
11.2,4140,1.42,35600000,1.42
11.2,4160,1.42,35800000,1.43
11.2,4170,1.43,35900000,1.43
11.2,4180,1.43,36000000,1.43
11.2,4200,1.43,36100000,1.43
11.2,4210,1.43,36200000,1.44
11.3,4220,1.44,36300000,1.44
11.3,4240,1.44,36500000,1.44
11.3,4250,1.44,36600000,1.44
11.3,4260,1.44,36700000,1.45
11.3,4280,1.45,36800000,1.45
11.3,4290,1.45,36900000,1.45
11.4,4300,1.45,37000000,1.46
11.4,4320,1.45,37100000,1.46
11.4,4330,1.46,37300000,1.46
11.4,4340,1.46,37400000,1.46
11.4,4360,1.46,37500000,1.47
11.4,4370,1.46,37600000,1.47
11.4,4380,1.47,37700000,1.47
11.5,4400,1.47,37800000,1.47
11.5,4410,1.47,37900000,1.48
11.5,4420,1.47,38100000,1.48
11.5,4440,1.48,38200000,1.48
11.5,4450,1.48,38300000,1.48
11.5,4460,1.48,38400000,1.48
11.5,4470,1.48,38500000,1.49
11.6,4490,1.49,38600000,1.49
11.6,4500,1.49,38700000,1.49
11.6,4510,1.49,38800000,1.49
11.6,4520,1.49,38900000,1.50
11.6,4530,1.50,39000000,1.50
11.6,4550,1.50,39100000,1.50
11.7,4560,1.50,39200000,1.51
11.7,4570,1.50,39300000,1.51
11.7,4580,1.51,39400000,1.51
11.7,4600,1.51,39600000,1.51
11.7,4610,1.51,39700000,1.52
11.7,4620,1.51,39800000,1.52
11.7,4640,1.52,39900000,1.52
11.8,4650,1.52,40000000,1.52
11.8,4660,1.52,40100000,1.52
11.8,4670,1.52,40200000,1.53
11.8,4680,1.53,40300000,1.53
11.8,4700,1.53,40400000,1.53
11.8,4710,1.53,40500000,1.53
11.8,4720,1.53,40600000,1.54
11.9,4730,1.54,40700000,1.54
11.9,4740,1.54,40800000,1.54
11.9,4760,1.54,40900000,1.54
11.9,4770,1.54,41000000,1.55
11.9,4780,1.55,41100000,1.55
11.9,4790,1.55,41200000,1.55
12.0,4800,1.55,41300000,1.56
12.0,4810,1.55,41400000,1.56
12.0,4820,1.56,41500000,1.56
12.0,4830,1.56,41600000,1.56
12.0,4850,1.56,41700000,1.57
12.0,4860,1.56,41800000,1.57
12.0,4870,1.57,41900000,1.57
12.1,4880,1.57,42000000,1.57
12.1,4890,1.57,42100000,1.57
12.1,4900,1.57,42200000,1.58
12.1,4910,1.58,42300000,1.58
12.1,4920,1.58,42400000,1.58
12.1,4930,1.58,42500000,1.58
12.1,4940,1.58,42500000,1.59
12.2,4950,1.59,42600000,1.59
12.2,4970,1.59,42700000,1.59
12.2,4980,1.59,42800000,1.60
12.2,4990,1.59,42900000,1.60
12.2,4990,1.60,43000000,1.60
12.2,5000,1.60,43100000,1.60
12.3,5020,1.60,43200000,1.61
12.3,5020,1.60,43200000,1.61
12.3,5030,1.61,43300000,1.61
12.3,5040,1.61,43400000,1.61
12.3,5050,1.61,43400000,1.62
12.3,5060,1.61,43500000,1.62
12.3,5070,1.62,43600000,1.62
12.4,5080,1.62,43700000,1.62
12.4,5090,1.62,43800000,1.62
12.4,5090,1.62,43800000,1.63
12.4,5100,1.63,43900000,1.63
12.4,5110,1.63,44000000,1.63
12.4,5120,1.63,44000000,1.63
12.4,5130,1.63,44100000,1.64
12.5,5130,1.64,44200000,1.64
12.5,5140,1.64,44200000,1.64
12.5,5150,1.64,44300000,1.64
12.5,5160,1.64,44400000,1.65
12.5,5170,1.65,44400000,1.65
12.5,5170,1.65,44500000,1.65
12.6,5180,1.65,44600000,1.66
12.6,5190,1.65,44600000,1.66
12.6,5190,1.66,44700000,1.66
12.6,5200,1.66,44700000,1.66
12.6,5200,1.66,44800000,1.66
12.6,5210,1.66,44800000,1.67
12.6,5220,1.67,44900000,1.67
12.7,5220,1.67,44900000,1.67
12.7,5230,1.67,45000000,1.68
12.7,5230,1.67,45000000,1.68
12.7,5240,1.68,45100000,1.68
12.7,5240,1.68,45100000,1.68
12.7,5250,1.68,45100000,1.69
12.7,5250,1.68,45200000,1.69
12.8,5250,1.69,45200000,1.69
12.8,5260,1.69,45200000,1.69
12.8,5260,1.69,45300000,1.70
12.8,5270,1.69,45300000,1.70
12.8,5270,1.70,45300000,1.70
12.8,5270,1.70,45400000,1.70
12.9,5280,1.70,45400000,1.71
12.9,5280,1.70,45500000,1.71
12.9,5290,1.71,45500000,1.71
12.9,5290,1.71,45500000,1.71
12.9,5290,1.71,45500000,1.72
12.9,5300,1.71,45600000,1.72
12.9,5300,1.72,45600000,1.72
13.0,5300,1.72,45600000,1.72
13.0,5300,1.72,45600000,1.73
13.0,5310,1.72,45700000,1.73
13.0,5310,1.73,45700000,1.73
13.0,5320,1.73,45700000,1.73
13.0,5320,1.73,45800000,1.74
13.0,5320,1.73,45800000,1.74
13.1,5320,1.74,45800000,1.74
13.1,5330,1.74,45800000,1.74
13.1,5330,1.74,45900000,1.75
13.1,5340,1.74,45900000,1.75
13.1,5340,1.75,45900000,1.75
13.1,5340,1.75,46000000,1.75
13.2,5340,1.75,46000000,1.76
13.2,5350,1.75,46000000,1.76
13.2,5350,1.76,46000000,1.76
13.2,5350,1.76,46100000,1.76
13.2,5360,1.76,46100000,1.77
13.2,5360,1.76,46100000,1.77
13.2,5370,1.77,46200000,1.77
13.3,5370,1.77,46200000,1.77
13.3,5370,1.77,46200000,1.78
13.3,5370,1.77,46200000,1.78
13.3,5380,1.78,46300000,1.78
13.3,5380,1.78,46300000,1.78
13.3,5390,1.78,46400000,1.79
13.3,5390,1.78,46400000,1.79
13.4,5390,1.79,46400000,1.79
13.4,5400,1.79,46400000,1.79
13.4,5400,1.79,46500000,1.80
13.4,5410,1.79,46500000,1.80
13.4,5410,1.80,46500000,1.80
13.4,5410,1.80,46600000,1.80
13.5,5410,1.80,46600000,1.81
13.5,5420,1.80,46600000,1.81
13.5,5420,1.81,46700000,1.81
13.5,5430,1.81,46700000,1.81
13.5,5430,1.81,46700000,1.82
13.5,5430,1.81,46700000,1.82
13.5,5440,1.82,46800000,1.82
13.6,5440,1.82,46800000,1.82
13.6,5440,1.82,46800000,1.83
13.6,5450,1.82,46900000,1.83
13.6,5450,1.83,46900000,1.83
13.6,5450,1.83,46900000,1.83
13.6,5460,1.83,47000000,1.84
13.6,5460,1.83,47000000,1.84
13.7,5460,1.84,47000000,1.84
13.7,5460,1.84,47000000,1.84
13.7,5470,1.84,47100000,1.85
13.7,5470,1.84,47100000,1.85
13.7,5470,1.85,47100000,1.85
13.7,5480,1.85,47100000,1.85
13.8,5480,1.85,47100000,1.85
13.8,5480,1.85,47200000,1.86
13.8,5490,1.86,47200000,1.86
13.8,5490,1.86,47200000,1.86
13.8,5490,1.86,47300000,1.86
13.8,5490,1.86,47300000,1.87
13.8,5500,1.87,47300000,1.87
13.9,5500,1.87,47300000,1.87
13.9,5500,1.87,47400000,1.88
13.9,5510,1.87,47400000,1.88
13.9,5510,1.88,47400000,1.88
13.9,5510,1.88,47400000,1.88
13.9,5510,1.88,47400000,1.89
13.9,5520,1.88,47500000,1.89
14.0,5520,1.89,47500000,1.89
14.0,5520,1.89,47500000,1.89
14.0,5520,1.89,47500000,1.90
14.0,5530,1.89,47500000,1.90
14.0,5530,1.90,47600000,1.90
14.0,5530,1.90,47600000,1.90
14.1,5530,1.90,47600000,1.91
14.1,5530,1.90,47600000,1.91
14.1,5530,1.91,47600000,1.91
14.1,5540,1.91,47600000,1.91
14.1,5540,1.91,47700000,1.92
14.1,5540,1.91,47700000,1.92
14.1,5540,1.92,47700000,1.92
14.2,5540,1.92,47700000,1.92
14.2,5550,1.92,47700000,1.93
14.2,5550,1.92,47700000,1.93
14.2,5550,1.93,47800000,1.93
14.2,5550,1.93,47800000,1.93
14.2,5560,1.93,47800000,1.94
14.2,5560,1.93,47800000,1.94
14.3,5560,1.94,47800000,1.94
14.3,5560,1.94,47900000,1.94
14.3,5560,1.94,47900000,1.95
14.3,5570,1.94,47900000,1.95
14.3,5570,1.95,47900000,1.95
14.3,5570,1.95,47900000,1.95
14.4,5570,1.95,47900000,1.96
14.4,5570,1.95,48000000,1.96
14.4,5580,1.96,48000000,1.96
14.4,5580,1.96,48000000,1.96
14.4,5580,1.96,48000000,1.97
14.4,5580,1.96,48000000,1.97
14.4,5580,1.97,48000000,1.97
14.5,5580,1.97,48100000,1.97
14.5,5590,1.97,48100000,1.98
14.5,5590,1.97,48100000,1.98
14.5,5590,1.98,48100000,1.98
14.5,5590,1.98,48100000,1.98
14.5,5590,1.98,48100000,1.99
14.5,5590,1.98,48100000,1.99
14.6,5590,1.99,48100000,1.99
14.6,5600,1.99,48100000,1.99
14.6,5600,1.99,48200000,2.00
14.6,5600,1.99,48200000,2.00
14.6,5600,2.00,48200000,2.00
14.6,5600,2.00,48200000,2.00
14.7,5600,2.00,48200000,2.01
14.7,5600,2.00,48200000,2.01
14.7,5600,2.01,48200000,2.01
14.7,5610,2.01,48200000,2.01
14.7,5610,2.01,48200000,2.02
14.7,5610,2.01,48200000,2.02
14.7,5610,2.02,48200000,2.02
14.8,5610,2.02,48300000,2.02
14.8,5610,2.02,48300000,2.03
14.8,5610,2.02,48300000,2.03
14.8,5610,2.03,48300000,2.03
14.8,5610,2.03,48300000,2.03
14.8,5610,2.03,48300000,2.04
14.8,5610,2.03,48300000,2.04
14.9,5610,2.04,48300000,2.04
14.9,5610,2.04,48300000,2.04
14.9,5610,2.04,48300000,2.05
14.9,5610,2.04,48300000,2.05
14.9,5610,2.05,48300000,2.05
14.9,5610,2.05,48300000,2.05
15.0,5610,2.05,48300000,2.06
15.0,5610,2.05,48300000,2.06
15.0,5610,2.06,48300000,2.06
15.0,5620,2.06,48300000,2.06
15.0,5610,2.06,48300000,2.07
15.0,5610,2.06,48300000,2.07
15.0,5610,2.07,48300000,2.07
15.1,5610,2.07,48300000,2.07
15.1,5610,2.07,48300000,2.08
15.1,5610,2.07,48300000,2.08
15.1,5610,2.08,48300000,2.08
15.1,5610,2.08,48300000,2.08
15.1,5610,2.08,48300000,2.09
15.1,5610,2.08,48300000,2.09
15.2,5610,2.09,48300000,2.09
15.2,5610,2.09,48300000,2.09
15.2,5610,2.09,48200000,2.10
15.2,5610,2.09,48200000,2.10
15.2,5610,2.10,48200000,2.10
15.2,5600,2.10,48200000,2.10
15.3,5600,2.10,48200000,2.11
15.3,5600,2.10,48200000,2.11
15.3,5600,2.11,48200000,2.11
15.3,5600,2.11,48200000,2.11
15.3,5600,2.11,48200000,2.12
15.3,5600,2.11,48100000,2.12
15.3,5590,2.12,48100000,2.12
15.4,5590,2.12,48100000,2.12
15.4,5590,2.12,48100000,2.13
15.4,5590,2.12,48100000,2.13
15.4,5580,2.13,48000000,2.13
15.4,5580,2.13,48000000,2.13
15.4,5580,2.13,48000000,2.14
15.4,5580,2.13,48000000,2.14
15.5,5580,2.14,48000000,2.14
15.5,5570,2.14,48000000,2.14
15.5,5570,2.14,47900000,2.15
15.5,5570,2.14,47900000,2.15
15.5,5570,2.15,47900000,2.15
15.5,5560,2.15,47900000,2.15
15.6,5560,2.15,47800000,2.16
15.6,5560,2.15,47800000,2.16
15.6,5550,2.16,47800000,2.16
15.6,5550,2.16,47800000,2.16
15.6,5550,2.16,47800000,2.17
15.6,5540,2.16,47700000,2.17
15.6,5540,2.17,47700000,2.17
15.7,5540,2.17,47600000,2.17
15.7,5540,2.17,47600000,2.18
15.7,5530,2.17,47600000,2.18
15.7,5530,2.18,47600000,2.18
15.7,5520,2.18,47500000,2.18
15.7,5520,2.18,47500000,2.19
15.7,5520,2.18,47500000,2.19
15.8,5510,2.19,47400000,2.19
15.8,5510,2.19,47400000,2.19
15.8,5500,2.19,47300000,2.20
15.8,5500,2.19,47300000,2.20
15.8,5490,2.20,47300000,2.20
15.8,5490,2.20,47200000,2.20
15.9,5480,2.20,47200000,2.21
15.9,5480,2.20,47100000,2.21
15.9,5470,2.21,47100000,2.21
15.9,5470,2.21,47000000,2.21
15.9,5460,2.21,47000000,2.22
15.9,5450,2.21,46900000,2.22
15.9,5450,2.22,46900000,2.22
16.0,5440,2.22,46800000,2.22
16.0,5430,2.22,46700000,2.23
16.0,5430,2.22,46700000,2.23
16.0,5420,2.23,46600000,2.23
16.0,5410,2.23,46600000,2.23
16.0,5400,2.23,46500000,2.24
16.0,5400,2.23,46400000,2.24
16.1,5390,2.24,46400000,2.24
16.1,5380,2.24,46300000,2.24
16.1,5370,2.24,46200000,2.25
16.1,5360,2.24,46100000,2.25
16.1,5350,2.25,46100000,2.25
16.1,5350,2.25,46000000,2.25
16.2,5340,2.25,45900000,2.26
16.2,5330,2.25,45800000,2.26
16.2,5320,2.26,45700000,2.26
16.2,5310,2.26,45700000,2.26
16.2,5300,2.26,45600000,2.27
16.2,5290,2.26,45500000,2.27
16.2,5270,2.27,45400000,2.27
16.3,5260,2.27,45300000,2.27
16.3,5250,2.27,45200000,2.28
16.3,5240,2.27,45100000,2.28
16.3,5230,2.28,45000000,2.28
16.3,5220,2.28,44900000,2.28
16.3,5200,2.28,44800000,2.29
16.3,5190,2.28,44600000,2.29
16.4,5180,2.29,44500000,2.29
16.4,5160,2.29,44400000,2.29
16.4,5150,2.29,44300000,2.30
16.4,5140,2.29,44200000,2.30
16.4,5120,2.30,44100000,2.30
16.4,5110,2.30,44000000,2.30
16.5,5100,2.30,43800000,2.31
16.5,5080,2.30,43700000,2.31
16.5,5070,2.31,43600000,2.31
16.5,5050,2.31,43500000,2.31
16.5,5040,2.31,43400000,2.32
16.5,5030,2.31,43300000,2.32
16.5,5010,2.32,43100000,2.32
16.6,5000,2.32,43000000,2.32
16.6,4980,2.32,42900000,2.33
16.6,4970,2.32,42800000,2.33
16.6,4960,2.33,42700000,2.33
16.6,4940,2.33,42500000,2.33
16.6,4930,2.33,42400000,2.34
16.6,4910,2.33,42300000,2.34
16.7,4900,2.34,42200000,2.34
16.7,4890,2.34,42000000,2.34
16.7,4870,2.34,41900000,2.35
16.7,4850,2.34,41800000,2.35
16.7,4840,2.35,41600000,2.35
16.7,4830,2.35,41500000,2.35
16.8,4810,2.35,41400000,2.36
16.8,4790,2.35,41200000,2.36
16.8,4780,2.36,41100000,2.36
16.8,4760,2.36,41000000,2.36
16.8,4750,2.36,40900000,2.37
16.8,4730,2.36,40700000,2.37
16.8,4720,2.37,40600000,2.37
16.9,4700,2.37,40500000,2.37
16.9,4690,2.37,40300000,2.38
16.9,4670,2.37,40200000,2.38
16.9,4660,2.38,40100000,2.38
16.9,4640,2.38,39900000,2.38
16.9,4630,2.38,39800000,2.39
16.9,4610,2.38,39700000,2.39
17.0,4600,2.39,39600000,2.39
17.0,4590,2.39,39500000,2.39
17.0,4570,2.39,39300000,2.40
17.0,4560,2.39,39200000,2.40
17.0,4540,2.40,39100000,2.40
17.0,4530,2.40,39000000,2.40
17.1,4520,2.40,38900000,2.41
17.1,4500,2.40,38700000,2.41
17.1,4490,2.41,38600000,2.41
17.1,4480,2.41,38500000,2.41
17.1,4460,2.41,38400000,2.42
17.1,4450,2.41,38300000,2.42
17.1,4440,2.42,38200000,2.42
17.2,4420,2.42,38100000,2.42
17.2,4410,2.42,37900000,2.43
17.2,4400,2.42,37800000,2.43
17.2,4390,2.43,37700000,2.43
17.2,4370,2.43,37600000,2.43
17.2,4360,2.43,37500000,2.44
17.2,4350,2.43,37400000,2.44
17.3,4340,2.44,37300000,2.44
17.3,4320,2.44,37200000,2.44
17.3,4310,2.44,37100000,2.45
17.3,4300,2.44,37000000,2.45
17.3,4290,2.45,36900000,2.45
17.3,4280,2.45,36800000,2.45
17.4,4270,2.45,36800000,2.46
17.4,4260,2.45,36700000,2.46
17.4,4250,2.46,36600000,2.46
17.4,4240,2.46,36500000,2.46
17.4,4240,2.46,36500000,2.47
17.4,4230,2.46,36400000,2.47
17.4,4220,2.47,36300000,2.47
17.5,4210,2.47,36200000,2.47
17.5,4210,2.47,36200000,2.48
17.5,4200,2.47,36100000,2.48
17.5,4190,2.48,36100000,2.48
17.5,4190,2.48,36000000,2.48
17.5,4180,2.48,36000000,2.49
17.5,4170,2.48,35900000,2.49
17.6,4170,2.49,35900000,2.49
17.6,4160,2.49,35800000,2.49
17.6,4160,2.49,35800000,2.50
17.6,4150,2.49,35700000,2.50
17.6,4150,2.50,35700000,2.50
17.6,4140,2.50,35600000,2.50
17.7,4140,2.50,35600000,2.51
17.7,4130,2.50,35600000,2.51
17.7,4130,2.51,35500000,2.51
17.7,4130,2.51,35500000,2.51
17.7,4120,2.51,35500000,2.52
17.7,4120,2.51,35400000,2.52
17.7,4110,2.52,35400000,2.52
17.8,4110,2.52,35300000,2.52
17.8,4100,2.52,35300000,2.53
17.8,4100,2.52,35300000,2.53
17.8,4100,2.53,35200000,2.53
17.8,4090,2.53,35200000,2.53
17.8,4090,2.53,35200000,2.54
17.8,4080,2.53,35100000,2.54
17.9,4080,2.54,35100000,2.54
17.9,4070,2.54,35100000,2.54
17.9,4070,2.54,35000000,2.55
17.9,4060,2.54,35000000,2.55
17.9,4060,2.55,34900000,2.55
17.9,4060,2.55,34900000,2.55
18.0,4050,2.55,34900000,2.56
18.0,4050,2.55,34800000,2.56
18.0,4040,2.56,34800000,2.56
18.0,4040,2.56,34700000,2.56
18.0,4030,2.56,34700000,2.57
18.0,4030,2.56,34700000,2.57
18.0,4030,2.57,34600000,2.57
18.1,4020,2.57,34600000,2.57
18.1,4020,2.57,34600000,2.58
18.1,4010,2.57,34500000,2.58
18.1,4010,2.58,34500000,2.58
18.1,4010,2.58,34500000,2.58
18.1,4000,2.58,34400000,2.59
18.1,4000,2.58,34400000,2.59
18.2,3990,2.59,34400000,2.59
18.2,3990,2.59,34300000,2.59
18.2,3990,2.59,34300000,2.60
18.2,3980,2.59,34300000,2.60
18.2,3980,2.60,34200000,2.60
18.2,3970,2.60,34200000,2.60
18.3,3970,2.60,34200000,2.61
18.3,3970,2.60,34100000,2.61
18.3,3960,2.61,34100000,2.61
18.3,3960,2.61,34100000,2.61
18.3,3950,2.61,34000000,2.62
18.3,3950,2.61,34000000,2.62
18.3,3950,2.62,34000000,2.62
18.4,3940,2.62,33900000,2.62
18.4,3940,2.62,33900000,2.63
18.4,3940,2.62,33900000,2.63
18.4,3930,2.63,33800000,2.63
18.4,3930,2.63,33800000,2.63
18.4,3920,2.63,33800000,2.64
18.4,3920,2.63,33700000,2.64
18.5,3920,2.64,33700000,2.64
18.5,3910,2.64,33700000,2.64
18.5,3910,2.64,33700000,2.65
18.5,3910,2.64,33600000,2.65
18.5,3900,2.65,33600000,2.65
18.5,3900,2.65,33600000,2.65
18.6,3900,2.65,33500000,2.66
18.6,3900,2.65,33500000,2.66
18.6,3890,2.66,33500000,2.66
18.6,3890,2.66,33400000,2.66
18.6,3880,2.66,33400000,2.67
18.6,3880,2.66,33400000,2.67
18.6,3880,2.67,33400000,2.67
18.7,3880,2.67,33300000,2.67
18.7,3870,2.67,33300000,2.68
18.7,3870,2.67,33300000,2.68
18.7,3860,2.68,33300000,2.68
18.7,3860,2.68,33200000,2.68
18.7,3860,2.68,33200000,2.69
18.7,3860,2.68,33200000,2.69
18.8,3850,2.68,33100000,2.69
18.8,3850,2.69,33100000,2.69
18.8,3850,2.69,33100000,2.70
18.8,3840,2.69,33100000,2.70
18.8,3840,2.70,33100000,2.70
18.8,3840,2.70,33000000,2.70
18.9,3830,2.70,33000000,2.71
18.9,3830,2.70,33000000,2.71
18.9,3830,2.71,33000000,2.71
18.9,3830,2.71,32900000,2.71
18.9,3820,2.71,32900000,2.72
18.9,3820,2.71,32900000,2.72
18.9,3820,2.72,32800000,2.72
19.0,3810,2.72,32800000,2.72
19.0,3810,2.72,32800000,2.73
19.0,3810,2.72,32800000,2.73
19.0,3800,2.73,32700000,2.73
19.0,3800,2.73,32700000,2.73
19.0,3800,2.73,32700000,2.74
19.0,3800,2.73,32700000,2.74
19.1,3790,2.74,32600000,2.74
19.1,3790,2.74,32600000,2.74
19.1,3790,2.74,32600000,2.75
19.1,3790,2.74,32600000,2.75
19.1,3780,2.75,32500000,2.75
19.1,3780,2.75,32500000,2.75
19.2,3780,2.75,32500000,2.76
19.2,3770,2.75,32500000,2.76
19.2,3770,2.76,32400000,2.76
19.2,3770,2.76,32400000,2.76
19.2,3760,2.76,32400000,2.77
19.2,3760,2.76,32400000,2.77
19.2,3760,2.77,32300000,2.77
19.3,3760,2.77,32300000,2.77
19.3,3750,2.77,32300000,2.78
19.3,3750,2.77,32300000,2.78
19.3,3750,2.78,32200000,2.78
19.3,3740,2.78,32200000,2.78
19.3,3740,2.78,32200000,2.79
19.3,3740,2.78,32200000,2.79
19.4,3740,2.79,32100000,2.79
19.4,3730,2.79,32100000,2.79
19.4,3730,2.79,32100000,2.80
19.4,3730,2.79,32100000,2.80
19.4,3730,2.80,32100000,2.80
19.4,3720,2.80,32000000,2.80
19.5,3720,2.80,32000000,2.81
19.5,3720,2.80,32000000,2.81
19.5,3720,2.81,32000000,2.81
19.5,3710,2.81,31900000,2.81
19.5,3710,2.81,31900000,2.82
19.5,3710,2.81,31900000,2.82
19.5,3700,2.82,31900000,2.82
19.6,3700,2.82,31800000,2.82
19.6,3700,2.82,31800000,2.83
19.6,3690,2.82,31800000,2.83
19.6,3690,2.83,31700000,2.83
19.6,3680,2.83,31700000,2.83
19.6,3680,2.83,31700000,2.84
19.6,3680,2.83,31700000,2.84
19.7,3680,2.84,31600000,2.84
19.7,3670,2.84,31600000,2.84
19.7,3670,2.84,31600000,2.85
19.7,3670,2.84,31600000,2.85
19.7,3660,2.85,31500000,2.85
19.7,3660,2.85,31500000,2.85
19.8,3660,2.85,31500000,2.86
19.8,3650,2.85,31400000,2.86
19.8,3650,2.86,31400000,2.86
19.8,3650,2.86,31400000,2.86
19.8,3650,2.86,31400000,2.87
19.8,3640,2.86,31300000,2.87
19.8,3640,2.87,31300000,2.87
19.9,3640,2.87,31300000,2.87
19.9,3640,2.87,31300000,2.88
19.9,3630,2.87,31200000,2.88
19.9,3630,2.87,31200000,2.88
19.9,3630,2.88,31200000,2.88
19.9,3620,2.88,31200000,2.89
19.9,3620,2.88,31200000,2.89
20.0,3620,2.88,31100000,2.89
20.0,3610,2.89,31100000,2.89
20.0,3610,2.89,31100000,2.90
20.0,3610,2.89,31100000,2.90
20.0,3610,2.90,31000000,2.90
20.0,3600,2.90,31000000,2.90
20.1,3600,2.90,31000000,2.91
20.1,3600,2.90,31000000,2.91
20.1,3600,2.91,30900000,2.91
20.1,3590,2.91,30900000,2.91
20.1,3590,2.91,30900000,2.92
20.1,3580,2.91,30800000,2.92
20.1,3580,2.92,30800000,2.92
20.2,3580,2.92,30800000,2.92
20.2,3580,2.92,30800000,2.93
20.2,3570,2.92,30700000,2.93
20.2,3570,2.93,30700000,2.93
20.2,3560,2.93,30700000,2.93
20.2,3560,2.93,30600000,2.94
20.2,3560,2.93,30600000,2.94
20.3,3560,2.94,30600000,2.94
20.3,3550,2.94,30600000,2.94
20.3,3550,2.94,30500000,2.95
20.3,3550,2.94,30500000,2.95
20.3,3540,2.95,30500000,2.95
20.3,3540,2.95,30500000,2.95
20.4,3540,2.95,30400000,2.96
20.4,3530,2.95,30400000,2.96
20.4,3530,2.96,30400000,2.96
20.4,3530,2.96,30400000,2.96
20.4,3530,2.96,30300000,2.97
20.4,3520,2.96,30300000,2.97
20.4,3520,2.96,30300000,2.97
20.5,3520,2.97,30300000,2.97
20.5,3510,2.97,30200000,2.98
20.5,3510,2.97,30200000,2.98
20.5,3510,2.98,30200000,2.98
20.5,3510,2.98,30200000,2.98
20.5,3500,2.98,30100000,2.99
20.5,3500,2.98,30100000,2.99
20.6,3500,2.99,30100000,2.99
20.6,3490,2.99,30100000,2.99
20.6,3490,2.99,30000000,3.00
20.6,3490,2.99,30000000,3.00
20.6,3490,3.00,30000000,3.00
20.6,3490,3.00,30000000,3.00
20.7,3480,3.00,30000000,3.01
20.7,3480,3.00,29900000,3.01
20.7,3480,3.01,29900000,3.01
20.7,3470,3.01,29900000,3.01
20.7,3470,3.01,29900000,3.02
20.7,3470,3.01,29800000,3.02
20.7,3470,3.02,29800000,3.02
20.8,3460,3.02,29800000,3.02
20.8,3460,3.02,29800000,3.03
20.8,3460,3.02,29800000,3.03
20.8,3450,3.03,29700000,3.03
20.8,3450,3.03,29700000,3.03
20.8,3450,3.03,29700000,3.04
20.8,3450,3.03,29700000,3.04
20.9,3440,3.04,29600000,3.04
20.9,3440,3.04,29600000,3.04
20.9,3440,3.04,29600000,3.05
20.9,3440,3.04,29600000,3.05
20.9,3430,3.05,29500000,3.05
20.9,3430,3.05,29500000,3.05
21.0,3430,3.05,29500000,3.06
21.0,3420,3.05,29500000,3.06
21.0,3420,3.06,29400000,3.06
21.0,3420,3.06,29400000,3.06
21.0,3420,3.06,29400000,3.07
21.0,3410,3.06,29400000,3.07
21.0,3410,3.07,29300000,3.07
21.1,3410,3.07,29300000,3.07
21.1,3410,3.07,29300000,3.08
21.1,3400,3.07,29300000,3.08
21.1,3400,3.08,29300000,3.08
21.1,3400,3.08,29200000,3.08
21.1,3390,3.08,29200000,3.09
21.1,3390,3.08,29200000,3.09
21.2,3390,3.09,29200000,3.09
21.2,3390,3.09,29100000,3.09
21.2,3380,3.09,29100000,3.10
21.2,3380,3.09,29100000,3.10
21.2,3380,3.10,29100000,3.10
21.2,3380,3.10,29000000,3.10
21.3,3370,3.10,29000000,3.11
21.3,3370,3.10,29000000,3.11
21.3,3370,3.10,29000000,3.11
21.3,3360,3.11,28900000,3.11
21.3,3360,3.11,28900000,3.12
21.3,3360,3.11,28900000,3.12
21.3,3360,3.11,28900000,3.12
21.4,3350,3.12,28900000,3.12
21.4,3350,3.12,28800000,3.13
21.4,3350,3.12,28800000,3.13
21.4,3350,3.12,28800000,3.13
21.4,3340,3.13,28800000,3.13
21.4,3340,3.13,28700000,3.14
21.4,3340,3.13,28700000,3.14
21.5,3340,3.13,28700000,3.14
21.5,3330,3.14,28700000,3.14
21.5,3330,3.14,28600000,3.15
21.5,3330,3.14,28600000,3.15
21.5,3320,3.14,28600000,3.15
21.5,3320,3.15,28600000,3.15
21.6,3320,3.15,28600000,3.16
21.6,3320,3.15,28500000,3.16
21.6,3310,3.15,28500000,3.16
21.6,3310,3.16,28500000,3.16
21.6,3310,3.16,28500000,3.17
21.6,3310,3.16,28500000,3.17
21.6,3300,3.16,28400000,3.17
21.7,3300,3.17,28400000,3.17
21.7,3300,3.17,28400000,3.18
21.7,3290,3.17,28300000,3.18
21.7,3290,3.17,28300000,3.18
21.7,3290,3.18,28300000,3.18
21.7,3290,3.18,28300000,3.19
21.7,3280,3.18,28200000,3.19
21.8,3280,3.18,28200000,3.19
21.8,3280,3.19,28200000,3.19
21.8,3280,3.19,28200000,3.20
21.8,3270,3.19,28200000,3.20
21.8,3270,3.19,28100000,3.20
21.8,3270,3.20,28100000,3.20
21.9,3270,3.20,28100000,3.21
21.9,3260,3.20,28100000,3.21
21.9,3260,3.20,28000000,3.21
21.9,3260,3.21,28000000,3.21
21.9,3250,3.21,28000000,3.22
21.9,3250,3.21,28000000,3.22
21.9,3250,3.21,28000000,3.22
22.0,3250,3.22,27900000,3.22
22.0,3240,3.22,27900000,3.23
22.0,3240,3.22,27900000,3.23
22.0,3240,3.22,27900000,3.23
22.0,3240,3.23,27900000,3.23
22.0,3230,3.23,27800000,3.24
22.0,3230,3.23,27800000,3.24
22.1,3230,3.23,27800000,3.24
22.1,3230,3.24,27800000,3.24
22.1,3230,3.24,27700000,3.25
22.1,3220,3.24,27700000,3.25
22.1,3220,3.24,27700000,3.25
22.1,3220,3.25,27700000,3.25
22.2,3220,3.25,27700000,3.26
22.2,3210,3.25,27600000,3.26
22.2,3210,3.25,27600000,3.26
22.2,3210,3.26,27600000,3.26
22.2,3200,3.26,27600000,3.27
22.2,3200,3.26,27600000,3.27
22.2,3200,3.26,27500000,3.27
22.3,3200,3.27,27500000,3.27
22.3,3190,3.27,27500000,3.28
22.3,3190,3.27,27500000,3.28
22.3,3190,3.27,27500000,3.28
22.3,3190,3.28,27400000,3.28
22.3,3190,3.28,27400000,3.29
22.3,3180,3.28,27400000,3.29
22.4,3180,3.28,27400000,3.29
22.4,3180,3.29,27400000,3.29
22.4,3180,3.29,27300000,3.30
22.4,3170,3.29,27300000,3.30
22.4,3170,3.29,27300000,3.30
22.4,3170,3.30,27300000,3.30
22.5,3170,3.30,27200000,3.31
22.5,3160,3.30,27200000,3.31
22.5,3160,3.30,27200000,3.31
22.5,3160,3.31,27200000,3.31
22.5,3160,3.31,27200000,3.32
22.5,3160,3.31,27100000,3.32
22.5,3150,3.31,27100000,3.32
22.6,3150,3.32,27100000,3.32
22.6,3150,3.32,27100000,3.33
22.6,3150,3.32,27100000,3.33
22.6,3140,3.32,27100000,3.33
22.6,3140,3.33,27000000,3.33
22.6,3140,3.33,27000000,3.34
22.6,3140,3.33,27000000,3.34
22.7,3130,3.34,27000000,3.34
22.7,3130,3.34,26900000,3.34
22.7,3130,3.34,26900000,3.35
22.7,3130,3.34,26900000,3.35
22.7,3120,3.34,26900000,3.35
22.7,3120,3.35,26800000,3.35
22.8,3120,3.35,26800000,3.36
22.8,3120,3.35,26800000,3.36
22.8,3110,3.35,26800000,3.36
22.8,3110,3.36,26700000,3.36
22.8,3110,3.36,26700000,3.37
22.8,3100,3.36,26700000,3.37
22.8,3100,3.36,26700000,3.37
22.9,3100,3.37,26700000,3.37
22.9,3080,3.37,26500000,3.38
22.9,3080,3.37,26500000,3.38
22.9,3070,3.37,26400000,3.38
22.9,3070,3.38,26400000,3.38
22.9,3070,3.38,26400000,3.39
22.9,3060,3.38,26300000,3.39
23.0,3060,3.38,26300000,3.39
23.0,3060,3.39,26300000,3.39
23.0,3050,3.39,26300000,3.40
23.0,3050,3.39,26200000,3.40
23.0,3050,3.39,26200000,3.40
23.0,3050,3.40,26200000,3.40
23.1,3040,3.40,26200000,3.41
23.1,3040,3.40,26200000,3.41
23.1,3040,3.40,26100000,3.41
23.1,3040,3.41,26100000,3.41
23.1,3030,3.41,26100000,3.42
23.1,3030,3.41,26100000,3.42
23.1,3030,3.41,26100000,3.42
23.2,3030,3.42,26000000,3.42
23.2,3020,3.42,26000000,3.43
23.2,3020,3.42,26000000,3.43
23.2,3020,3.42,26000000,3.43
23.2,3020,3.43,26000000,3.43
23.2,3020,3.43,25900000,3.44
23.2,3010,3.43,25900000,3.44
23.3,3010,3.43,25900000,3.44
23.3,3010,3.44,25900000,3.44
23.3,3010,3.44,25900000,3.45
23.3,3000,3.44,25900000,3.45
23.3,3000,3.44,25800000,3.45
23.3,3000,3.45,25800000,3.45
23.4,3000,3.45,25800000,3.46
23.4,3000,3.45,25800000,3.46
23.4,2990,3.45,25800000,3.46
23.4,2990,3.46,25700000,3.46
23.4,2990,3.46,25700000,3.47
23.4,2990,3.46,25700000,3.47
23.4,2980,3.46,25700000,3.47
23.5,2980,3.47,25700000,3.47
23.5,2980,3.47,25600000,3.48
23.5,2980,3.47,25600000,3.48
23.5,2970,3.47,25600000,3.48
23.5,2970,3.48,25600000,3.48
23.5,2970,3.48,25600000,3.49
23.5,2970,3.48,25500000,3.49
23.6,2960,3.48,25500000,3.49
23.6,2960,3.49,25500000,3.49
23.6,2960,3.49,25500000,3.50
23.6,2960,3.49,25400000,3.50
23.6,2950,3.49,25400000,3.50
23.6,2950,3.50,25400000,3.50
23.7,2950,3.50,25400000,3.51
23.7,2950,3.50,25400000,3.51
23.7,2950,3.50,25400000,3.51
23.7,2940,3.51,25300000,3.51
23.7,2940,3.51,25300000,3.52
23.7,2940,3.51,25300000,3.52
23.7,2940,3.51,25300000,3.52
23.8,2930,3.52,25300000,3.52
23.8,2930,3.52,25200000,3.53
23.8,2930,3.52,25200000,3.53
23.8,2930,3.52,25200000,3.53
23.8,2930,3.53,25200000,3.53
23.8,2920,3.53,25200000,3.54
23.8,2920,3.53,25100000,3.54
23.9,2920,3.53,25100000,3.54
23.9,2920,3.54,25100000,3.54
23.9,2910,3.54,25100000,3.55
23.9,2910,3.54,25000000,3.55
23.9,2910,3.54,25000000,3.55
23.9,2910,3.55,25000000,3.55
24.0,2900,3.55,25000000,3.56
24.0,2900,3.55,25000000,3.56
24.0,2900,3.55,25000000,3.56
24.0,2860,3.56,24600000,3.56
24.0,2750,3.56,23700000,3.57
24.0,2730,3.56,23500000,3.57
24.0,2720,3.56,23400000,3.57
24.1,2700,3.57,23300000,3.57
2.86,29.0,0.0387,249000,0.0388
3.18,49.3,0.0920,424000,0.0922
3.50,69.5,0.145,598000,0.146
3.82,85.4,0.199,735000,0.199
4.14,97.9,0.252,843000,0.252
4.46,116,0.305,997000,0.305
4.78,153,0.358,1310000,0.359
5.10,204,0.412,1750000,0.412
5.42,267,0.465,2300000,0.466
5.74,359,0.518,3090000,0.519
6.06,470,0.571,4040000,0.572
6.38,612,0.624,5260000,0.626
6.70,780,0.678,6710000,0.679
7.02,971,0.731,8350000,0.732
7.34,1160,0.784,9960000,0.785
7.66,1370,0.837,11800000,0.839
7.98,1570,0.890,13500000,0.892
8.30,1760,0.944,15100000,0.946
8.62,1980,0.997,17000000,0.999
8.94,2250,1.05,19300000,1.05
9.26,2530,1.10,21800000,1.11
9.58,2810,1.16,24200000,1.16
9.90,3070,1.21,26400000,1.21
10.2,3330,1.26,28700000,1.27
10.5,3600,1.32,31000000,1.32
10.9,3870,1.37,33300000,1.37
11.2,4150,1.42,35700000,1.43
11.5,4430,1.48,38100000,1.48
11.8,4700,1.53,40400000,1.53
12.1,4940,1.58,42500000,1.59
12.5,5130,1.64,44100000,1.64
12.8,5260,1.69,45200000,1.69
13.1,5330,1.74,45900000,1.75
13.4,5410,1.80,46500000,1.80
13.7,5480,1.85,47100000,1.85
14.1,5530,1.90,47600000,1.91
14.4,5580,1.96,48000000,1.96
14.7,5610,2.01,48200000,2.01
15.0,5610,2.06,48300000,2.07
15.3,5590,2.12,48100000,2.12
15.7,5540,2.17,47600000,2.17
16.0,5430,2.22,46700000,2.23
16.3,5230,2.28,45000000,2.28
16.6,4940,2.33,42500000,2.33
16.9,4620,2.38,39800000,2.39
17.3,4340,2.44,37300000,2.44
17.6,4160,2.49,35800000,2.49
17.9,4070,2.54,35000000,2.55
18.2,3980,2.59,34200000,2.60
18.5,3900,2.65,33600000,2.65
18.9,3830,2.70,33000000,2.71
19.2,3770,2.75,32400000,2.76
19.5,3710,2.81,31900000,2.81
19.8,3640,2.86,31400000,2.87
20.1,3580,2.91,30800000,2.92
20.5,3520,2.97,30300000,2.97
20.8,3460,3.02,29800000,3.03
21.1,3400,3.07,29300000,3.08
21.4,3340,3.13,28800000,3.13
21.7,3280,3.18,28300000,3.19
22.1,3230,3.23,27800000,3.24
22.4,3180,3.29,27400000,3.29
22.7,3130,3.34,26900000,3.35
23.0,3050,3.39,26200000,3.40
23.3,3000,3.45,25800000,3.45
23.7,2950,3.50,25400000,3.51
24.0,2900,3.55,25000000,3.56
24.1,2700,3.57,23200000,3.58