File: data/DouglasFir/Superwood-IDW6-23 Jul, 2025.csv
Time (sec),Force (N),Position (mm),Stress (Pa),Strain (%)
2.29,30.6,0.0227,261000,0.0227
2.30,31.3,0.0253,268000,0.0254
2.32,32.1,0.0279,274000,0.0280
2.33,32.9,0.0307,281000,0.0308
2.35,33.7,0.0334,288000,0.0335
2.37,34.5,0.0359,294000,0.0360
2.38,35.3,0.0386,302000,0.0387
2.40,36.0,0.0412,308000,0.0413
2.41,36.5,0.0440,312000,0.0441
2.43,37.1,0.0466,317000,0.0467
2.44,37.7,0.0492,322000,0.0493
2.46,38.3,0.0519,327000,0.0520
2.48,39.1,0.0545,334000,0.0546
2.49,39.8,0.0574,340000,0.0575
2.51,40.6,0.0600,347000,0.0601
2.53,41.3,0.0626,353000,0.0627
2.54,42.0,0.0652,359000,0.0653
2.56,42.9,0.0679,367000,0.0680
2.57,43.9,0.0707,375000,0.0708
2.59,44.7,0.0732,382000,0.0733
2.61,45.2,0.0757,387000,0.0759
2.62,45.8,0.0785,391000,0.0787
2.64,46.7,0.0811,399000,0.0813
2.65,47.4,0.0839,405000,0.0841
2.67,48.1,0.0865,411000,0.0867
2.69,48.4,0.0890,414000,0.0892
2.70,49.0,0.0917,418000,0.0919
2.72,49.6,0.0944,424000,0.0946
2.73,50.1,0.0972,428000,0.0974
2.75,50.5,0.0998,432000,0.100
2.77,50.9,0.102,435000,0.103
2.78,51.3,0.105,439000,0.105
2.80,51.9,0.108,443000,0.108
2.81,52.3,0.111,447000,0.111
2.83,52.8,0.113,451000,0.113
2.85,53.5,0.116,457000,0.116
2.86,54.6,0.118,467000,0.119
2.88,56.0,0.121,478000,0.121
2.89,57.1,0.124,488000,0.124
2.91,58.0,0.126,495000,0.127
2.93,59.0,0.129,504000,0.129
2.94,60.1,0.132,514000,0.132
2.96,61.2,0.134,523000,0.135
2.97,62.3,0.137,532000,0.137
2.99,63.2,0.140,540000,0.140
3.01,64.4,0.142,550000,0.142
3.02,65.8,0.145,562000,0.145
3.04,67.1,0.148,574000,0.148
3.05,68.5,0.150,585000,0.151
3.07,69.8,0.153,596000,0.153
3.09,71.2,0.156,608000,0.156
3.10,73.0,0.158,623000,0.159
3.12,75.0,0.161,641000,0.161
3.13,76.8,0.164,656000,0.164
3.15,78.9,0.166,674000,0.167
3.17,81.1,0.169,693000,0.169
3.18,83.4,0.172,712000,0.172
3.20,85.6,0.174,732000,0.175
3.21,87.6,0.177,748000,0.177
3.23,89.8,0.180,767000,0.180
3.25,91.8,0.182,785000,0.183
3.26,94.1,0.185,804000,0.185
3.28,96.5,0.188,825000,0.188
3.29,98.7,0.190,843000,0.191
3.31,101,0.193,864000,0.193
3.33,103,0.196,884000,0.196
3.34,106,0.198,905000,0.199
3.36,108,0.201,926000,0.201
3.37,111,0.204,944000,0.204
3.39,113,0.206,968000,0.207
3.41,116,0.209,989000,0.209
3.42,118,0.212,1010000,0.212
3.44,121,0.214,1030000,0.215
3.45,123,0.217,1050000,0.217
3.47,126,0.220,1080000,0.220
3.49,129,0.222,1100000,0.223
3.50,132,0.225,1130000,0.225
3.52,135,0.228,1150000,0.228
3.53,138,0.230,1180000,0.231
3.55,141,0.233,1210000,0.233
3.57,145,0.236,1240000,0.236
3.58,149,0.238,1270000,0.239
3.60,152,0.241,1300000,0.241
3.61,156,0.243,1330000,0.244
3.63,160,0.246,1360000,0.247
3.65,163,0.249,1400000,0.249
3.66,167,0.252,1430000,0.252
3.68,171,0.254,1460000,0.255
3.69,175,0.257,1490000,0.257
3.71,179,0.260,1530000,0.260
3.73,183,0.262,1560000,0.263
3.74,187,0.265,1600000,0.265
3.76,191,0.268,1630000,0.268
3.77,195,0.270,1670000,0.271
3.79,200,0.273,1710000,0.273
3.81,205,0.275,1750000,0.276
3.82,209,0.278,1790000,0.279
3.84,214,0.281,1820000,0.281
3.85,218,0.284,1870000,0.284
3.87,224,0.286,1910000,0.287
3.89,229,0.289,1960000,0.289
3.90,234,0.292,2000000,0.292
3.92,239,0.294,2040000,0.295
3.93,245,0.297,2090000,0.297
3.95,250,0.300,2140000,0.300
3.97,256,0.302,2190000,0.303
3.98,262,0.305,2240000,0.305
4.00,268,0.307,2290000,0.308
4.01,274,0.310,2340000,0.311
4.03,280,0.313,2400000,0.314
4.05,286,0.315,2440000,0.316
4.06,291,0.318,2490000,0.319
4.08,297,0.321,2540000,0.321
4.09,303,0.324,2590000,0.324
4.11,309,0.326,2640000,0.327
4.13,314,0.329,2690000,0.329
4.14,319,0.331,2730000,0.332
4.16,325,0.334,2780000,0.335
4.17,331,0.337,2830000,0.337
4.19,338,0.339,2880000,0.340
4.21,343,0.342,2930000,0.343
4.22,349,0.345,2990000,0.345
4.24,356,0.347,3040000,0.348
4.25,364,0.350,3110000,0.351
4.27,371,0.353,3170000,0.353
4.29,379,0.355,3240000,0.356
4.30,386,0.358,3300000,0.359
4.32,394,0.361,3370000,0.361
4.33,402,0.363,3440000,0.364
4.35,411,0.366,3510000,0.367
4.37,419,0.368,3580000,0.369
4.38,427,0.371,3650000,0.372
4.40,436,0.374,3720000,0.375
4.41,445,0.377,3800000,0.377
4.43,454,0.379,3880000,0.380
4.45,462,0.382,3950000,0.382
4.46,472,0.384,4030000,0.385
4.48,482,0.387,4110000,0.388
4.49,492,0.390,4200000,0.390
4.51,502,0.392,4290000,0.393
4.53,512,0.395,4370000,0.396
4.54,522,0.398,4460000,0.398
4.56,533,0.400,4560000,0.401
4.57,544,0.403,4650000,0.404
4.59,555,0.406,4740000,0.407
4.61,566,0.408,4840000,0.409
4.62,577,0.411,4930000,0.412
4.64,590,0.414,5040000,0.415
4.65,601,0.416,5130000,0.417
4.67,612,0.419,5230000,0.420
4.68,623,0.422,5330000,0.422
4.70,635,0.424,5420000,0.425
4.72,648,0.427,5530000,0.428
4.73,659,0.430,5630000,0.430
4.75,670,0.432,5720000,0.433
4.76,683,0.435,5830000,0.436
4.78,694,0.438,5930000,0.439
4.80,708,0.440,6050000,0.441
4.81,719,0.443,6140000,0.444
4.83,731,0.446,6240000,0.446
4.85,743,0.448,6350000,0.449
4.86,756,0.451,6460000,0.452
4.88,770,0.454,6580000,0.455
4.89,782,0.456,6680000,0.457
4.91,795,0.459,6790000,0.460
4.93,807,0.462,6900000,0.463
4.94,820,0.464,7010000,0.465
4.96,834,0.467,7130000,0.468
4.97,846,0.470,7230000,0.470
4.99,859,0.472,7340000,0.473
5.01,872,0.475,7460000,0.476
5.02,887,0.478,7580000,0.479
5.04,900,0.480,7690000,0.481
5.05,912,0.483,7790000,0.484
5.07,926,0.486,7910000,0.487
5.09,939,0.488,8030000,0.489
5.10,954,0.491,8150000,0.492
5.12,967,0.494,8260000,0.495
5.13,980,0.496,8380000,0.497
5.15,993,0.499,8490000,0.500
5.17,1010,0.502,8610000,0.503
5.18,1020,0.504,8730000,0.505
5.20,1030,0.507,8840000,0.508
5.21,1050,0.509,8950000,0.511
5.23,1060,0.512,9070000,0.513
5.25,1080,0.515,9190000,0.516
5.26,1090,0.518,9310000,0.519
5.28,1100,0.520,9420000,0.521
5.29,1120,0.523,9540000,0.524
5.31,1130,0.526,9660000,0.527
5.33,1150,0.528,9790000,0.529
5.34,1160,0.531,9900000,0.532
5.36,1170,0.534,10000000,0.535
5.37,1190,0.536,10100000,0.537
5.39,1200,0.539,10300000,0.540
5.41,1220,0.542,10400000,0.543
5.42,1230,0.544,10500000,0.545
5.44,1240,0.547,10600000,0.548
5.45,1260,0.550,10700000,0.551
5.47,1270,0.552,10900000,0.554
5.49,1290,0.555,11000000,0.556
5.50,1300,0.558,11100000,0.559
5.52,1310,0.560,11200000,0.561
5.53,1330,0.563,11400000,0.564
5.55,1340,0.566,11500000,0.567
5.57,1360,0.568,11600000,0.569
5.58,1370,0.571,11700000,0.572
5.60,1390,0.574,11900000,0.575
5.61,1400,0.576,12000000,0.577
5.63,1420,0.579,12100000,0.580
5.65,1430,0.582,12200000,0.583
5.66,1450,0.584,12400000,0.585
5.68,1460,0.587,12500000,0.588
5.69,1480,0.590,12600000,0.591
5.71,1490,0.592,12800000,0.594
5.73,1510,0.595,12900000,0.596
5.74,1520,0.598,13000000,0.599
5.76,1540,0.600,13100000,0.602
5.77,1550,0.603,13300000,0.604
5.79,1570,0.606,13400000,0.607
5.81,1580,0.608,13500000,0.609
5.82,1590,0.611,13600000,0.612
5.84,1610,0.614,13800000,0.615
5.85,1620,0.616,13900000,0.618
5.87,1640,0.619,14000000,0.620
5.89,1650,0.621,14100000,0.623
5.90,1670,0.624,14200000,0.625
5.92,1680,0.627,14400000,0.628
5.93,1700,0.629,14500000,0.631
5.95,1710,0.632,14600000,0.633
5.97,1730,0.635,14700000,0.636
5.98,1740,0.637,14900000,0.639
6.00,1760,0.640,15000000,0.641
6.01,1770,0.643,15100000,0.644
6.03,1780,0.645,15200000,0.646
6.05,1800,0.648,15400000,0.649
6.06,1810,0.651,15500000,0.652
6.08,1830,0.653,15600000,0.655
6.09,1840,0.656,15700000,0.657
6.11,1860,0.659,15900000,0.660
6.13,1870,0.661,16000000,0.662
6.14,1890,0.664,16100000,0.665
6.16,1900,0.667,16200000,0.668
6.17,1920,0.669,16400000,0.670
6.19,1930,0.672,16500000,0.673
6.21,1940,0.674,16600000,0.676
6.22,1960,0.677,16700000,0.679
6.24,1980,0.680,16900000,0.681
6.25,1990,0.683,17000000,0.684
6.27,2000,0.685,17100000,0.686
6.29,2020,0.688,17200000,0.689
6.30,2030,0.691,17400000,0.692
6.32,2050,0.693,17500000,0.695
6.33,2060,0.696,17600000,0.697
6.35,2080,0.699,17700000,0.700
6.37,2090,0.702,17900000,0.703
6.38,2110,0.704,18000000,0.706
6.40,2120,0.707,18100000,0.708
6.41,2130,0.709,18200000,0.711
6.43,2150,0.712,18300000,0.714
6.45,2160,0.715,18500000,0.716
6.46,2180,0.718,18600000,0.719
6.48,2190,0.720,18700000,0.722
6.49,2200,0.723,18800000,0.724
6.51,2210,0.726,18900000,0.727
6.53,2230,0.728,19100000,0.730
6.54,2240,0.731,19200000,0.732
6.56,2260,0.734,19300000,0.735
6.57,2270,0.736,19400000,0.738
6.59,2280,0.739,19500000,0.740
6.61,2300,0.742,19600000,0.743
6.62,2310,0.744,19700000,0.746
6.64,2320,0.747,19800000,0.748
6.65,2330,0.750,19900000,0.751
6.67,2350,0.752,20000000,0.754
6.69,2360,0.755,20200000,0.757
6.70,2370,0.758,20300000,0.759
6.72,2390,0.760,20400000,0.762
6.73,2400,0.763,20500000,0.764
6.75,2410,0.766,20600000,0.767
6.77,2430,0.768,20700000,0.770
6.78,2440,0.771,20800000,0.772
6.80,2450,0.773,21000000,0.775
6.81,2470,0.776,21100000,0.778
6.83,2480,0.779,21200000,0.780
6.85,2490,0.781,21300000,0.783
6.86,2510,0.784,21400000,0.786
6.88,2520,0.787,21500000,0.788
6.89,2530,0.789,21600000,0.791
6.91,2550,0.792,21800000,0.794
6.93,2560,0.795,21900000,0.796
6.94,2570,0.797,22000000,0.799
6.96,2590,0.800,22100000,0.801
6.97,2600,0.803,22200000,0.804
6.99,2620,0.805,22300000,0.807
7.01,2630,0.808,22500000,0.810
7.02,2640,0.811,22600000,0.812
7.04,2650,0.813,22700000,0.815
7.05,2670,0.816,22800000,0.818
7.07,2680,0.819,22900000,0.820
7.09,2700,0.821,23000000,0.823
7.10,2710,0.824,23100000,0.826
7.12,2720,0.827,23300000,0.828
7.13,2740,0.829,23400000,0.831
7.15,2750,0.832,23500000,0.834
7.17,2760,0.834,23600000,0.836
7.18,2770,0.837,23700000,0.839
7.20,2790,0.840,23800000,0.842
7.21,2800,0.843,23900000,0.844
7.23,2820,0.845,24100000,0.847
7.25,2830,0.848,24200000,0.849
7.26,2840,0.851,24300000,0.852
7.28,2850,0.853,24400000,0.855
7.29,2870,0.856,24500000,0.858
7.31,2880,0.859,24600000,0.860
7.33,2890,0.861,24700000,0.863
7.34,2900,0.864,24800000,0.866
7.36,2920,0.867,24900000,0.868
7.37,2930,0.869,25100000,0.871
7.39,2940,0.872,25200000,0.874
7.41,2960,0.874,25300000,0.876
7.42,2970,0.877,25400000,0.879
7.44,2980,0.880,25500000,0.882
7.45,3000,0.883,25600000,0.884
7.47,3010,0.885,25700000,0.887
7.49,3020,0.888,25800000,0.889
7.50,3030,0.891,25900000,0.892
7.52,3050,0.893,26000000,0.895
7.53,3060,0.896,26200000,0.897
7.55,3070,0.898,26300000,0.900
7.57,3090,0.901,26400000,0.903
7.58,3100,0.904,26500000,0.906
7.60,3110,0.907,26600000,0.908
7.61,3120,0.909,26700000,0.911
7.63,3140,0.912,26800000,0.913
7.65,3150,0.914,26900000,0.916
7.66,3160,0.917,27000000,0.919
7.68,3180,0.920,27100000,0.922
7.69,3190,0.922,27200000,0.924
7.71,3200,0.925,27300000,0.927
7.73,3210,0.928,27500000,0.930
7.74,3230,0.930,27600000,0.932
7.76,3240,0.933,27700000,0.935
7.77,3250,0.936,27800000,0.937
7.79,3260,0.938,27900000,0.940
7.81,3280,0.941,28000000,0.943
7.82,3290,0.944,28100000,0.946
7.84,3300,0.946,28200000,0.948
7.85,3310,0.949,28300000,0.951
7.87,3330,0.952,28400000,0.954
7.89,3340,0.954,28500000,0.956
7.90,3350,0.957,28700000,0.959
7.92,3370,0.960,28800000,0.962
7.93,3380,0.962,28900000,0.964
7.95,3390,0.965,29000000,0.967
7.97,3400,0.968,29100000,0.970
7.98,3420,0.970,29200000,0.972
8.00,3430,0.973,29300000,0.975
8.01,3440,0.976,29400000,0.977
8.03,3450,0.978,29500000,0.980
8.05,3460,0.981,29600000,0.983
8.06,3480,0.984,29700000,0.986
8.08,3490,0.986,29800000,0.988
8.09,3500,0.989,29900000,0.991
8.11,3510,0.992,30000000,0.994
8.13,3530,0.994,30100000,0.996
8.14,3540,0.997,30200000,0.999
8.16,3550,1.00,30300000,1.00
8.17,3560,1.00,30400000,1.00
8.19,3570,1.01,30500000,1.01
8.21,3590,1.01,30700000,1.01
8.22,3600,1.01,30700000,1.01
8.24,3610,1.01,30900000,1.01
8.25,3620,1.02,31000000,1.02
8.27,3640,1.02,31100000,1.02
8.29,3650,1.02,31200000,1.02
8.30,3660,1.02,31300000,1.03
8.32,3680,1.03,31400000,1.03
8.33,3690,1.03,31500000,1.03
8.35,3700,1.03,31600000,1.03
8.37,3720,1.03,31800000,1.04
8.38,3730,1.04,31900000,1.04
8.40,3740,1.04,32000000,1.04
8.41,3750,1.04,32100000,1.04
8.43,3770,1.05,32200000,1.05
8.45,3780,1.05,32300000,1.05
8.46,3790,1.05,32400000,1.05
8.48,3810,1.05,32500000,1.06
8.49,3820,1.06,32600000,1.06
8.51,3830,1.06,32800000,1.06
8.53,3840,1.06,32900000,1.06
8.54,3860,1.06,33000000,1.07
8.56,3870,1.07,33100000,1.07
8.57,3880,1.07,33200000,1.07
8.59,3900,1.07,33300000,1.07
8.61,3910,1.07,33400000,1.08
8.62,3920,1.08,33500000,1.08
8.64,3940,1.08,33600000,1.08
8.65,3950,1.08,33700000,1.08
8.67,3960,1.09,33900000,1.09
8.69,3970,1.09,34000000,1.09
8.70,3990,1.09,34100000,1.09
8.72,4000,1.09,34200000,1.10
8.73,4010,1.10,34300000,1.10
8.75,4020,1.10,34400000,1.10
8.77,4040,1.10,34500000,1.10
8.78,4050,1.10,34600000,1.11
8.80,4060,1.11,34700000,1.11
8.81,4070,1.11,34800000,1.11
8.83,4080,1.11,34900000,1.11
8.85,4100,1.11,35000000,1.12
8.86,4110,1.12,35100000,1.12
8.88,4120,1.12,35200000,1.12
8.89,4130,1.12,35300000,1.12
8.91,4140,1.12,35400000,1.13
8.93,4160,1.13,35500000,1.13
8.94,4170,1.13,35600000,1.13
8.96,4180,1.13,35700000,1.14
8.97,4190,1.14,35800000,1.14
8.99,4200,1.14,35900000,1.14
9.01,4210,1.14,36000000,1.14
9.02,4220,1.14,36100000,1.15
9.04,4240,1.15,36200000,1.15
9.05,4250,1.15,36300000,1.15
9.07,4260,1.15,36400000,1.15
9.09,4270,1.15,36500000,1.16
9.10,4280,1.16,36600000,1.16
9.12,4290,1.16,36700000,1.16
9.13,4300,1.16,36800000,1.16
9.15,4310,1.16,36800000,1.17
9.16,4320,1.17,36900000,1.17
9.18,4330,1.17,37000000,1.17
9.20,4350,1.17,37100000,1.18
9.21,4360,1.18,37200000,1.18
9.23,4360,1.18,37300000,1.18
9.24,4380,1.18,37400000,1.18
9.26,4390,1.18,37500000,1.19
9.28,4400,1.19,37600000,1.19
9.29,4410,1.19,37700000,1.19
9.31,4420,1.19,37700000,1.19
9.32,4430,1.19,37800000,1.20
9.34,4440,1.20,37900000,1.20
9.36,4450,1.20,38000000,1.20
9.37,4460,1.20,38100000,1.20
9.39,4470,1.20,38200000,1.21
9.40,4480,1.21,38300000,1.21
9.42,4490,1.21,38300000,1.21
9.44,4500,1.21,38400000,1.22
9.45,4500,1.22,38500000,1.22
9.47,4510,1.22,38600000,1.22
9.49,4520,1.22,38600000,1.22
9.50,4530,1.22,38700000,1.23
9.52,4540,1.23,38800000,1.23
9.53,4550,1.23,38900000,1.23
9.55,4560,1.23,38900000,1.23
9.57,4570,1.23,39000000,1.24
9.58,4570,1.24,39100000,1.24
9.60,4580,1.24,39200000,1.24
9.61,4590,1.24,39200000,1.24
9.63,4600,1.24,39300000,1.25
9.65,4610,1.25,39400000,1.25
9.66,4610,1.25,39400000,1.25
9.68,4620,1.25,39500000,1.26
9.69,4630,1.26,39500000,1.26
9.71,4640,1.26,39600000,1.26
9.73,4640,1.26,39700000,1.26
9.74,4650,1.26,39700000,1.27
9.76,4660,1.27,39800000,1.27
9.77,4660,1.27,39900000,1.27
9.79,4670,1.27,39900000,1.27
9.81,4680,1.27,40000000,1.28
9.82,4690,1.28,40000000,1.28
9.84,4690,1.28,40100000,1.28
9.85,4700,1.28,40200000,1.28
9.87,4710,1.28,40200000,1.29
9.89,4710,1.29,40300000,1.29
9.90,4720,1.29,40300000,1.29
9.92,4720,1.29,40400000,1.30
9.93,4730,1.30,40400000,1.30
9.95,4740,1.30,40500000,1.30
9.97,4740,1.30,40500000,1.30
9.98,4750,1.30,40600000,1.31
10.0,4750,1.31,40600000,1.31
10.0,4760,1.31,40700000,1.31
10.0,4770,1.31,40700000,1.31
10.0,4770,1.31,40800000,1.32
10.1,4780,1.32,40800000,1.32
10.1,4780,1.32,40900000,1.32
10.1,4790,1.32,40900000,1.32
10.1,4790,1.32,41000000,1.33
10.1,4800,1.33,41000000,1.33
10.1,4800,1.33,41000000,1.33
10.2,4810,1.33,41100000,1.34
10.2,4810,1.34,41100000,1.34
10.2,4810,1.34,41100000,1.34
10.2,4820,1.34,41200000,1.34
10.2,4820,1.34,41200000,1.35
10.2,4830,1.35,41200000,1.35
10.3,4830,1.35,41300000,1.35
10.3,4830,1.35,41300000,1.35
10.3,4840,1.35,41300000,1.36
10.3,4840,1.36,41300000,1.36
10.3,4840,1.36,41400000,1.36
10.3,4850,1.36,41400000,1.36
10.3,4850,1.36,41400000,1.37
10.4,4850,1.37,41400000,1.37
10.4,4850,1.37,41500000,1.37
10.4,4860,1.37,41500000,1.38
10.4,4860,1.38,41500000,1.38
10.4,4860,1.38,41500000,1.38
10.4,4860,1.38,41500000,1.38
10.5,4860,1.38,41500000,1.39
10.5,4860,1.39,41600000,1.39
10.5,4870,1.39,41600000,1.39
10.5,4860,1.39,41600000,1.39
10.5,4870,1.39,41600000,1.40
10.5,4870,1.40,41600000,1.40
10.6,4870,1.40,41600000,1.40
10.6,4870,1.40,41600000,1.40
10.6,4870,1.40,41600000,1.41
10.6,4870,1.41,41600000,1.41
10.6,4870,1.41,41600000,1.41
10.6,4870,1.41,41600000,1.42
10.7,4870,1.42,41600000,1.42
10.7,4870,1.42,41600000,1.42
10.7,4870,1.42,41600000,1.42
10.7,4870,1.42,41600000,1.43
10.7,4870,1.43,41600000,1.43
10.7,4860,1.43,41600000,1.43
10.7,4860,1.43,41500000,1.43
10.8,4860,1.43,41500000,1.44
10.8,4860,1.44,41500000,1.44
10.8,4850,1.44,41500000,1.44
10.8,4850,1.44,41400000,1.44
10.8,4850,1.44,41400000,1.45
10.8,4840,1.45,41400000,1.45
10.9,4840,1.45,41400000,1.45
10.9,4840,1.45,41300000,1.46
10.9,4830,1.46,41300000,1.46
10.9,4830,1.46,41200000,1.46
10.9,4820,1.46,41200000,1.46
10.9,4820,1.46,41200000,1.47
11.0,4810,1.47,41100000,1.47
11.0,4800,1.47,41000000,1.47
11.0,4800,1.47,41000000,1.47
11.0,4790,1.47,41000000,1.48
11.0,4790,1.48,40900000,1.48
11.0,4780,1.48,40800000,1.48
11.1,4770,1.48,40800000,1.48
11.1,4760,1.48,40700000,1.49
11.1,4750,1.49,40600000,1.49
11.1,4750,1.49,40500000,1.49
11.1,4730,1.49,40500000,1.50
11.1,4720,1.50,40400000,1.50
11.1,4710,1.50,40300000,1.50
11.2,4710,1.50,40200000,1.50
11.2,4690,1.50,40100000,1.51
11.2,4680,1.51,40000000,1.51
11.2,4670,1.51,39900000,1.51
11.2,4660,1.51,39800000,1.51
11.2,4650,1.51,39800000,1.52
11.3,4640,1.52,39700000,1.52
11.3,4630,1.52,39600000,1.52
11.3,4620,1.52,39500000,1.52
11.3,4610,1.52,39400000,1.53
11.3,4600,1.53,39300000,1.53
11.3,4580,1.53,39200000,1.53
11.4,4570,1.53,39100000,1.54
11.4,4560,1.54,38900000,1.54
11.4,4550,1.54,38800000,1.54
11.4,4530,1.54,38700000,1.54
11.4,4520,1.54,38600000,1.55
11.4,4510,1.55,38500000,1.55
11.5,4500,1.55,38400000,1.55
11.5,4490,1.55,38300000,1.55
11.5,4470,1.55,38200000,1.56
11.5,4460,1.56,38100000,1.56
11.5,4450,1.56,38000000,1.56
11.5,4440,1.56,37900000,1.57
11.5,4430,1.56,37800000,1.57
11.6,4410,1.57,37700000,1.57
11.6,4400,1.57,37600000,1.57
11.6,4390,1.57,37500000,1.58
11.6,4380,1.58,37400000,1.58
11.6,4360,1.58,37300000,1.58
11.6,4350,1.58,37200000,1.58
11.7,4340,1.58,37100000,1.59
11.7,4330,1.59,37000000,1.59
11.7,4320,1.59,36900000,1.59
11.7,4310,1.59,36800000,1.59
11.7,4290,1.59,36700000,1.60
11.7,4280,1.60,36600000,1.60
11.8,4270,1.60,36500000,1.60
11.8,4260,1.60,36400000,1.61
11.8,4250,1.60,36300000,1.61
11.8,4240,1.61,36200000,1.61
11.8,4230,1.61,36100000,1.61
11.8,4220,1.61,36000000,1.62
11.9,4210,1.62,36000000,1.62
11.9,4200,1.62,35900000,1.62
11.9,4190,1.62,35800000,1.62
11.9,4170,1.62,35700000,1.63
11.9,4160,1.63,35600000,1.63
11.9,4160,1.63,35500000,1.63
11.9,4140,1.63,35400000,1.63
12.0,4130,1.63,35300000,1.64
12.0,4120,1.64,35200000,1.64
12.0,4110,1.64,35200000,1.64
12.0,4100,1.64,35100000,1.64
12.0,4090,1.64,35000000,1.65
12.0,4080,1.65,34900000,1.65
12.1,4070,1.65,34800000,1.65
12.1,4070,1.65,34700000,1.66
12.1,4060,1.65,34700000,1.66
12.1,4050,1.66,34600000,1.66
12.1,4040,1.66,34500000,1.66
12.1,4030,1.66,34400000,1.67
12.2,4020,1.67,34300000,1.67
12.2,4010,1.67,34300000,1.67
12.2,4000,1.67,34200000,1.67
12.2,3990,1.67,34100000,1.68
12.2,3980,1.68,34000000,1.68
12.2,3970,1.68,34000000,1.68
12.3,3970,1.68,33900000,1.68
12.3,3960,1.68,33800000,1.69
12.3,3950,1.69,33700000,1.69
12.3,3940,1.69,33700000,1.69
12.3,3930,1.69,33600000,1.70
12.3,3920,1.69,33500000,1.70
12.3,3920,1.70,33500000,1.70
12.4,3910,1.70,33400000,1.70
12.4,3900,1.70,33300000,1.71
12.4,3890,1.71,33300000,1.71
12.4,3890,1.71,33200000,1.71
12.4,3880,1.71,33100000,1.71
12.4,3870,1.71,33100000,1.72
12.5,3870,1.72,33000000,1.72
12.5,3860,1.72,33000000,1.72
12.5,3850,1.72,32900000,1.72
12.5,3850,1.72,32900000,1.73
12.5,3840,1.73,32800000,1.73
12.5,3840,1.73,32800000,1.73
12.6,3830,1.73,32700000,1.74
12.6,3830,1.73,32700000,1.74
12.6,3820,1.74,32600000,1.74
12.6,3820,1.74,32600000,1.74
12.6,3810,1.74,32600000,1.75
12.6,3810,1.75,32500000,1.75
12.7,3800,1.75,32500000,1.75
12.7,3800,1.75,32500000,1.75
12.7,3800,1.75,32400000,1.76
12.7,3790,1.76,32400000,1.76
12.7,3790,1.76,32400000,1.76
12.7,3780,1.76,32300000,1.77
12.7,3780,1.76,32300000,1.77
12.8,3780,1.77,32300000,1.77
12.8,3770,1.77,32200000,1.77
12.8,3770,1.77,32200000,1.78
12.8,3770,1.77,32200000,1.78
12.8,3760,1.78,32200000,1.78
12.8,3760,1.78,32100000,1.78
12.9,3760,1.78,32100000,1.79
12.9,3750,1.79,32100000,1.79
12.9,3750,1.79,32000000,1.79
12.9,3750,1.79,32000000,1.79
12.9,3740,1.79,32000000,1.80
12.9,3740,1.80,31900000,1.80
13.0,3730,1.80,31900000,1.80
13.0,3730,1.80,31900000,1.81
13.0,3730,1.80,31800000,1.81
13.0,3720,1.81,31800000,1.81
13.0,3720,1.81,31800000,1.81
13.0,3720,1.81,31800000,1.82
13.1,3710,1.81,31700000,1.82
13.1,3710,1.82,31700000,1.82
13.1,3710,1.82,31700000,1.82
13.1,3700,1.82,31600000,1.83
13.1,3700,1.83,31600000,1.83
13.1,3690,1.83,31600000,1.83
13.1,3690,1.83,31500000,1.83
13.2,3690,1.83,31500000,1.84
13.2,3680,1.84,31500000,1.84
13.2,3680,1.84,31400000,1.84
13.2,3680,1.84,31400000,1.84
13.2,3670,1.84,31400000,1.85
13.2,3670,1.85,31400000,1.85
13.3,3660,1.85,31300000,1.85
13.3,3660,1.85,31300000,1.86
13.3,3660,1.85,31300000,1.86
13.3,3650,1.86,31200000,1.86
13.3,3650,1.86,31200000,1.86
13.3,3650,1.86,31100000,1.87
13.4,3640,1.87,31100000,1.87
13.4,3640,1.87,31100000,1.87
13.4,3630,1.87,31100000,1.87
13.4,3630,1.87,31000000,1.88
13.4,3630,1.88,31000000,1.88
13.4,3620,1.88,31000000,1.88
13.5,3620,1.88,30900000,1.89
13.5,3610,1.88,30900000,1.89
13.5,3610,1.89,30800000,1.89
13.5,3600,1.89,30800000,1.89
13.5,3600,1.89,30800000,1.90
13.5,3600,1.90,30700000,1.90
13.5,3590,1.90,30700000,1.90
13.6,3590,1.90,30600000,1.90
13.6,3580,1.90,30600000,1.91
13.6,3580,1.91,30600000,1.91
13.6,3570,1.91,30500000,1.91
13.6,3570,1.91,30500000,1.91
13.6,3570,1.91,30500000,1.92
13.7,3560,1.92,30400000,1.92
13.7,3560,1.92,30400000,1.92
13.7,3550,1.92,30400000,1.93
13.7,3550,1.92,30300000,1.93
13.7,3540,1.93,30300000,1.93
13.7,3540,1.93,30300000,1.93
13.8,3540,1.93,30200000,1.94
13.8,3530,1.93,30200000,1.94
13.8,3530,1.94,30100000,1.94
13.8,3520,1.94,30100000,1.94
13.8,3520,1.94,30100000,1.95
13.8,3520,1.95,30000000,1.95
13.9,3510,1.95,30000000,1.95
13.9,3510,1.95,30000000,1.95
13.9,3500,1.95,29900000,1.96
13.9,3500,1.96,29900000,1.96
13.9,3490,1.96,29800000,1.96
13.9,3490,1.96,29800000,1.97
13.9,3480,1.96,29800000,1.97
14.0,3480,1.97,29700000,1.97
14.0,3460,1.97,29500000,1.97
14.0,3440,1.97,29400000,1.98
14.0,3420,1.97,29300000,1.98
14.0,3410,1.98,29200000,1.98
14.0,3400,1.98,29100000,1.98
14.1,3400,1.98,29000000,1.99
14.1,3390,1.99,29000000,1.99
14.1,3380,1.99,28900000,1.99
14.1,3370,1.99,28800000,1.99
14.1,3370,1.99,28800000,2.00
14.1,3360,2.00,28700000,2.00
14.2,3360,2.00,28700000,2.00
14.2,3350,2.00,28600000,2.01
14.2,3350,2.00,28600000,2.01
14.2,3340,2.01,28600000,2.01
14.2,3340,2.01,28500000,2.01
14.2,3330,2.01,28400000,2.02
14.3,3310,2.01,28300000,2.02
14.3,3300,2.02,28200000,2.02
14.3,3300,2.02,28200000,2.02
14.3,3290,2.02,28100000,2.03
14.3,3280,2.03,28000000,2.03
14.3,3280,2.03,28000000,2.03
14.3,3270,2.03,28000000,2.03
14.4,3270,2.03,27900000,2.04
14.4,3260,2.04,27900000,2.04
14.4,3260,2.04,27800000,2.04
14.4,3250,2.04,27800000,2.05
14.4,3250,2.04,27800000,2.05
14.4,3240,2.05,27700000,2.05
14.5,3240,2.05,27700000,2.05
14.5,3240,2.05,27600000,2.06
14.5,3230,2.05,27600000,2.06
14.5,3230,2.06,27600000,2.06
14.5,3230,2.06,27600000,2.06
14.5,3220,2.06,27500000,2.07
14.6,3220,2.07,27500000,2.07
14.6,3210,2.07,27500000,2.07
14.6,3210,2.07,27400000,2.07
14.6,3210,2.07,27400000,2.08
14.6,3200,2.08,27400000,2.08
14.6,3200,2.08,27300000,2.08
14.7,3200,2.08,27300000,2.09
14.7,3190,2.08,27300000,2.09
14.7,3190,2.09,27300000,2.09
14.7,3190,2.09,27200000,2.09
14.7,3180,2.09,27200000,2.10
14.7,3180,2.09,27200000,2.10
14.7,3180,2.10,27100000,2.10
14.8,3170,2.10,27100000,2.10
14.8,3170,2.10,27100000,2.11
14.8,3170,2.11,27100000,2.11
14.8,3160,2.11,27000000,2.11
14.8,3160,2.11,27000000,2.11
14.8,3160,2.11,27000000,2.12
14.9,3150,2.12,26900000,2.12
14.9,3150,2.12,26900000,2.12
14.9,3150,2.12,26900000,2.13
14.9,3140,2.12,26900000,2.13
14.9,3140,2.13,26800000,2.13
14.9,3140,2.13,26800000,2.13
15.0,3130,2.13,26800000,2.14
15.0,3130,2.13,26800000,2.14
15.0,3130,2.14,26700000,2.14
15.0,3120,2.14,26700000,2.14
15.0,3120,2.14,26700000,2.15
15.0,3120,2.15,26600000,2.15
15.1,3120,2.15,26600000,2.15
15.1,3110,2.15,26600000,2.15
15.1,3110,2.15,26600000,2.16
15.1,3110,2.16,26500000,2.16
15.1,3100,2.16,26500000,2.16
15.1,3100,2.16,26500000,2.17
15.1,3100,2.16,26500000,2.17
15.2,3090,2.17,26400000,2.17
15.2,3090,2.17,26400000,2.17
15.2,3090,2.17,26400000,2.18
15.2,3080,2.17,26300000,2.18
15.2,3080,2.18,26300000,2.18
15.2,3080,2.18,26300000,2.18
15.3,3070,2.18,26300000,2.19
15.3,3070,2.19,26200000,2.19
15.3,3070,2.19,26200000,2.19
15.3,3060,2.19,26200000,2.19
15.3,3060,2.19,26200000,2.20
15.3,3060,2.20,26100000,2.20
15.4,3060,2.20,26100000,2.20
15.4,3050,2.20,26100000,2.21
15.4,3050,2.20,26000000,2.21
15.4,3050,2.21,26000000,2.21
15.4,3040,2.21,26000000,2.21
15.4,3040,2.21,26000000,2.22
15.5,3040,2.21,25900000,2.22
15.5,3030,2.22,25900000,2.22
15.5,3030,2.22,25900000,2.22
15.5,3030,2.22,25900000,2.23
15.5,3020,2.23,25800000,2.23
15.5,3020,2.23,25800000,2.23
15.5,3020,2.23,25800000,2.23
15.6,3010,2.23,25800000,2.24
15.6,3010,2.24,25700000,2.24
15.6,3010,2.24,25700000,2.24
15.6,3010,2.24,25700000,2.25
15.6,3000,2.24,25700000,2.25
15.6,3000,2.25,25600000,2.25
15.7,3000,2.25,25600000,2.25
15.7,2990,2.25,25600000,2.26
15.7,2990,2.25,25500000,2.26
15.7,2990,2.26,25500000,2.26
15.7,2980,2.26,25500000,2.26
15.7,2980,2.26,25500000,2.27
15.8,2980,2.26,25400000,2.27
15.8,2970,2.27,25400000,2.27
15.8,2970,2.27,25400000,2.27
15.8,2970,2.27,25400000,2.28
15.8,2970,2.28,25300000,2.28
15.8,2960,2.28,25300000,2.28
15.9,2960,2.28,25300000,2.29
15.9,2960,2.28,25300000,2.29
15.9,2950,2.29,25200000,2.29
15.9,2950,2.29,25200000,2.29
15.9,2950,2.29,25200000,2.30
15.9,2940,2.29,25200000,2.30
15.9,2940,2.30,25100000,2.30
16.0,2940,2.30,25100000,2.30
16.0,2930,2.30,25100000,2.31
16.0,2930,2.30,25000000,2.31
16.0,2930,2.31,25000000,2.31
16.0,2930,2.31,25000000,2.31
16.0,2920,2.31,25000000,2.32
16.1,2920,2.32,25000000,2.32
16.1,2920,2.32,24900000,2.32
16.1,2910,2.32,24900000,2.33
16.1,2910,2.32,24900000,2.33
16.1,2910,2.33,24900000,2.33
16.1,2910,2.33,24800000,2.33
16.2,2900,2.33,24800000,2.34
16.2,2900,2.33,24800000,2.34
16.2,2900,2.34,24800000,2.34
16.2,2890,2.34,24700000,2.34
16.2,2890,2.34,24700000,2.35
16.2,2880,2.34,24600000,2.35
16.3,2860,2.35,24500000,2.35
16.3,2860,2.35,24400000,2.35
16.3,2860,2.35,24400000,2.36
16.3,2850,2.36,24400000,2.36
16.3,2850,2.36,24300000,2.36
16.3,2840,2.36,24300000,2.37
16.3,2840,2.36,24300000,2.37
16.4,2840,2.37,24200000,2.37
16.4,2830,2.37,24200000,2.37
16.4,2830,2.37,24200000,2.38
16.4,2830,2.37,24200000,2.38
16.4,2830,2.38,24100000,2.38
16.4,2820,2.38,24100000,2.38
16.5,2820,2.38,24100000,2.39
16.5,2820,2.38,24100000,2.39
16.5,2810,2.39,24000000,2.39
16.5,2810,2.39,24000000,2.39
16.5,2810,2.39,24000000,2.40
16.5,2800,2.40,24000000,2.40
16.6,2800,2.40,23900000,2.40
16.6,2800,2.40,23900000,2.41
16.6,2800,2.40,23900000,2.41
16.6,2790,2.41,23900000,2.41
16.6,2790,2.41,23900000,2.41
16.6,2790,2.41,23800000,2.42
16.7,2790,2.41,23800000,2.42
16.7,2780,2.42,23800000,2.42
16.7,2780,2.42,23800000,2.42
16.7,2780,2.42,23700000,2.43
16.7,2780,2.43,23700000,2.43
16.7,2770,2.43,23700000,2.43
16.7,2770,2.43,23700000,2.43
16.8,2770,2.43,23700000,2.44
16.8,2770,2.44,23600000,2.44
16.8,2760,2.44,23600000,2.44
16.8,2760,2.44,23600000,2.45
16.8,2760,2.44,23600000,2.45
16.8,2760,2.45,23600000,2.45
16.9,2750,2.45,23500000,2.45
16.9,2750,2.45,23500000,2.46
16.9,2750,2.45,23500000,2.46
16.9,2750,2.46,23500000,2.46
16.9,2740,2.46,23500000,2.46
16.9,2740,2.46,23400000,2.47
17.0,2740,2.46,23400000,2.47
17.0,2740,2.47,23400000,2.47
17.0,2740,2.47,23400000,2.47
17.0,2730,2.47,23400000,2.48
17.0,2730,2.48,23300000,2.48
17.0,2730,2.48,23300000,2.48
17.1,2730,2.48,23300000,2.49
17.1,2720,2.48,23300000,2.49
17.1,2720,2.49,23300000,2.49
17.1,2720,2.49,23200000,2.49
17.1,2720,2.49,23200000,2.50
17.1,2710,2.49,23200000,2.50
17.1,2710,2.50,23200000,2.50
17.2,2710,2.50,23200000,2.50
17.2,2710,2.50,23100000,2.51
17.2,2710,2.50,23100000,2.51
17.2,2700,2.51,23100000,2.51
17.2,2700,2.51,23000000,2.51
17.2,2690,2.51,23000000,2.52
17.3,2690,2.52,23000000,2.52
17.3,2680,2.52,22900000,2.52
17.3,2680,2.52,22900000,2.53
17.3,2680,2.52,22900000,2.53
17.3,2670,2.53,22800000,2.53
17.3,2670,2.53,22800000,2.53
17.4,2670,2.53,22800000,2.54
17.4,2670,2.53,22800000,2.54
17.4,2660,2.54,22800000,2.54
17.4,2660,2.54,22700000,2.54
17.4,2660,2.54,22700000,2.55
17.4,2660,2.54,22700000,2.55
17.5,2650,2.55,22700000,2.55
17.5,2650,2.55,22700000,2.55
17.5,2650,2.55,22600000,2.56
17.5,2650,2.56,22600000,2.56
17.5,2640,2.56,22600000,2.56
17.5,2640,2.56,22600000,2.57
17.5,2640,2.56,22600000,2.57
17.6,2640,2.57,22500000,2.57
17.6,2640,2.57,22500000,2.57
17.6,2630,2.57,22500000,2.58
17.6,2630,2.57,22500000,2.58
17.6,2630,2.58,22500000,2.58
17.6,2630,2.58,22500000,2.58
17.7,2630,2.58,22400000,2.59
17.7,2620,2.58,22400000,2.59
17.7,2620,2.59,22400000,2.59
17.7,2620,2.59,22400000,2.59
17.7,2620,2.59,22400000,2.60
17.7,2620,2.59,22300000,2.60
17.8,2610,2.60,22300000,2.60
17.8,2610,2.60,22300000,2.61
17.8,2610,2.60,22300000,2.61
17.8,2610,2.61,22300000,2.61
17.8,2600,2.61,22300000,2.61
17.8,2600,2.61,22200000,2.62
17.9,2600,2.61,22200000,2.62
17.9,2600,2.62,22200000,2.62
17.9,2600,2.62,22200000,2.62
17.9,2590,2.62,22200000,2.63
17.9,2590,2.62,22100000,2.63
17.9,2590,2.63,22100000,2.63
17.9,2590,2.63,22100000,2.63
18.0,2590,2.63,22100000,2.64
18.0,2580,2.63,22100000,2.64
18.0,2580,2.64,22100000,2.64
18.0,2580,2.64,22000000,2.65
18.0,2580,2.64,22000000,2.65
18.0,2570,2.65,22000000,2.65
18.1,2570,2.65,22000000,2.65
18.1,2570,2.65,22000000,2.66
18.1,2570,2.65,22000000,2.66
18.1,2570,2.66,21900000,2.66
18.1,2560,2.66,21900000,2.66
18.1,2560,2.66,21900000,2.67
18.2,2560,2.66,21900000,2.67
18.2,2560,2.67,21900000,2.67
18.2,2560,2.67,21800000,2.67
18.2,2550,2.67,21800000,2.68
18.2,2550,2.67,21800000,2.68
18.2,2550,2.68,21800000,2.68
18.3,2550,2.68,21800000,2.69
18.3,2550,2.68,21800000,2.69
18.3,2540,2.69,21700000,2.69
18.3,2540,2.69,21700000,2.69
18.3,2540,2.69,21700000,2.70
18.3,2540,2.69,21700000,2.70
18.3,2540,2.70,21700000,2.70
18.4,2530,2.70,21700000,2.70
18.4,2530,2.70,21600000,2.71
18.4,2530,2.70,21600000,2.71
18.4,2530,2.71,21600000,2.71
18.4,2530,2.71,21600000,2.71
18.4,2520,2.71,21600000,2.72
18.5,2520,2.71,21600000,2.72
18.5,2520,2.72,21500000,2.72
18.5,2520,2.72,21500000,2.73
18.5,2520,2.72,21500000,2.73
18.5,2510,2.73,21500000,2.73
18.5,2510,2.73,21500000,2.73
18.6,2510,2.73,21500000,2.74
18.6,2510,2.73,21400000,2.74
18.6,2510,2.74,21400000,2.74
18.6,2500,2.74,21400000,2.74
18.6,2500,2.74,21400000,2.75
18.6,2500,2.74,21400000,2.75
18.7,2500,2.75,21300000,2.75
18.7,2500,2.75,21300000,2.75
18.7,2490,2.75,21300000,2.76
18.7,2490,2.75,21300000,2.76
18.7,2490,2.76,21300000,2.76
18.7,2490,2.76,21300000,2.77
18.7,2490,2.76,21200000,2.77
18.8,2480,2.77,21200000,2.77
18.8,2480,2.77,21200000,2.77
18.8,2480,2.77,21200000,2.78
18.8,2480,2.77,21200000,2.78
18.8,2480,2.78,21200000,2.78
18.8,2470,2.78,21100000,2.78
18.9,2470,2.78,21100000,2.79
18.9,2470,2.78,21100000,2.79
18.9,2470,2.79,21100000,2.79
18.9,2470,2.79,21100000,2.79
18.9,2460,2.79,21100000,2.80
18.9,2460,2.79,21100000,2.80
19.0,2460,2.80,21000000,2.80
19.0,2460,2.80,21000000,2.81
19.0,2460,2.80,21000000,2.81
19.0,2460,2.81,21000000,2.81
19.0,2450,2.81,21000000,2.81
19.0,2450,2.81,21000000,2.82
19.1,2450,2.81,20900000,2.82
19.1,2450,2.82,20900000,2.82
19.1,2450,2.82,20900000,2.82
19.1,2450,2.82,20900000,2.83
19.1,2440,2.82,20900000,2.83
19.1,2440,2.83,20900000,2.83
19.1,2440,2.83,20800000,2.83
19.2,2430,2.83,20800000,2.84
19.2,2430,2.83,20800000,2.84
19.2,2430,2.84,20800000,2.84
19.2,2430,2.84,20700000,2.85
19.2,2420,2.84,20700000,2.85
19.2,2420,2.85,20700000,2.85
19.3,2420,2.85,20700000,2.85
19.3,2420,2.85,20600000,2.86
19.3,2410,2.85,20600000,2.86
19.3,2410,2.86,20600000,2.86
19.3,2410,2.86,20600000,2.86
19.3,2410,2.86,20600000,2.87
19.4,2410,2.86,20600000,2.87
19.4,2400,2.87,20500000,2.87
19.4,2400,2.87,20500000,2.87
19.4,2400,2.87,20500000,2.88
19.4,2400,2.87,20500000,2.88
19.4,2390,2.88,20500000,2.88
19.5,2390,2.88,20400000,2.89
19.5,2390,2.88,20400000,2.89
19.5,2390,2.89,20400000,2.89
19.5,2390,2.89,20400000,2.89
19.5,2370,2.89,20200000,2.90
19.5,2370,2.89,20200000,2.90
19.5,2360,2.90,20200000,2.90
19.6,2360,2.90,20200000,2.90
19.6,2360,2.90,20200000,2.91
19.6,2360,2.90,20100000,2.91
19.6,2360,2.91,20100000,2.91
19.6,2350,2.91,20100000,2.92
19.6,2350,2.91,20100000,2.92
19.7,2350,2.91,20100000,2.92
19.7,2350,2.92,20100000,2.92
19.7,2350,2.92,20000000,2.93
19.7,2340,2.92,20000000,2.93
19.7,2340,2.93,20000000,2.93
19.7,2340,2.93,20000000,2.93
19.8,2340,2.93,20000000,2.94
19.8,2340,2.93,20000000,2.94
19.8,2340,2.94,20000000,2.94
19.8,2330,2.94,19900000,2.94
19.8,2330,2.94,19900000,2.95
19.8,2330,2.94,19900000,2.95
19.9,2330,2.95,19900000,2.95
19.9,2330,2.95,19900000,2.95
19.9,2330,2.95,19900000,2.96
19.9,2320,2.95,19900000,2.96
19.9,2320,2.96,19800000,2.96
19.9,2320,2.96,19800000,2.97
19.9,2320,2.96,19800000,2.97
20.0,2320,2.96,19800000,2.97
20.0,2320,2.97,19800000,2.97
20.0,2310,2.97,19800000,2.98
20.0,2310,2.97,19800000,2.98
20.0,2310,2.98,19700000,2.98
20.0,2310,2.98,19700000,2.98
20.1,2310,2.98,19700000,2.99
20.1,2310,2.98,19700000,2.99
20.1,2310,2.99,19700000,2.99
20.1,2300,2.99,19700000,2.99
20.1,2300,2.99,19700000,3.00
20.1,2300,2.99,19700000,3.00
20.2,2300,3.00,19700000,3.00
20.2,2300,3.00,19600000,3.01
20.2,2300,3.00,19600000,3.01
20.2,2290,3.01,19600000,3.01
20.2,2290,3.01,19600000,3.01
20.2,2290,3.01,19600000,3.02
20.3,2290,3.01,19600000,3.02
20.3,2290,3.02,19500000,3.02
20.3,2290,3.02,19500000,3.02
20.3,2280,3.02,19500000,3.03
20.3,2280,3.02,19500000,3.03
20.3,2280,3.03,19500000,3.03
20.3,2280,3.03,19500000,3.03
20.4,2280,3.03,19500000,3.04
20.4,2280,3.03,19400000,3.04
20.4,2270,3.04,19400000,3.04
20.4,2270,3.04,19400000,3.05
20.4,2270,3.04,19400000,3.05
20.4,2270,3.04,19400000,3.05
20.5,2270,3.05,19400000,3.05
20.5,2270,3.05,19400000,3.06
20.5,2260,3.05,19300000,3.06
20.5,2260,3.06,19300000,3.06
20.5,2260,3.06,19300000,3.06
20.5,2260,3.06,19300000,3.07
20.6,2260,3.06,19300000,3.07
20.6,2260,3.07,19300000,3.07
20.6,2250,3.07,19300000,3.07
20.6,2250,3.07,19300000,3.08
20.6,2250,3.07,19200000,3.08
20.6,2250,3.08,19200000,3.08
20.7,2250,3.08,19200000,3.08
20.7,2250,3.08,19200000,3.09
20.7,2250,3.08,19200000,3.09
20.7,2240,3.09,19200000,3.09
20.7,2240,3.09,19200000,3.10
20.7,2240,3.09,19100000,3.10
20.7,2240,3.10,19100000,3.10
20.8,2240,3.10,19100000,3.10
20.8,2240,3.10,19100000,3.11
20.8,2240,3.10,19100000,3.11
20.8,2230,3.11,19100000,3.11
20.8,2230,3.11,19100000,3.11
20.8,2230,3.11,19100000,3.12
20.9,2230,3.11,19100000,3.12
20.9,2230,3.12,19000000,3.12
20.9,2230,3.12,19000000,3.13
20.9,2230,3.12,19000000,3.13
20.9,2220,3.12,19000000,3.13
20.9,2220,3.13,19000000,3.13
21.0,2220,3.13,19000000,3.14
21.0,2210,3.13,18800000,3.14
21.0,2200,3.14,18800000,3.14
21.0,2200,3.14,18800000,3.14
21.0,2200,3.14,18800000,3.15
21.0,2200,3.14,18800000,3.15
21.1,2200,3.15,18800000,3.15
21.1,2200,3.15,18800000,3.16
21.1,2190,3.15,18700000,3.16
21.1,2190,3.15,18700000,3.16
21.1,2190,3.16,18700000,3.16
21.1,2190,3.16,18700000,3.17
21.1,2180,3.16,18700000,3.17
21.2,2180,3.16,18600000,3.17
21.2,2180,3.17,18600000,3.17
21.2,2180,3.17,18600000,3.18
21.2,2180,3.17,18600000,3.18
21.2,2180,3.18,18600000,3.18
21.2,2170,3.18,18600000,3.18
21.3,2170,3.18,18600000,3.19
21.3,2170,3.18,18600000,3.19
21.3,2170,3.19,18500000,3.19
21.3,2170,3.19,18500000,3.19
21.3,2170,3.19,18500000,3.20
21.3,2170,3.19,18500000,3.20
21.4,2160,3.20,18500000,3.20
21.4,2160,3.20,18500000,3.21
21.4,2160,3.20,18500000,3.21
21.4,2160,3.20,18400000,3.21
21.4,2160,3.21,18400000,3.21
21.4,2160,3.21,18400000,3.22
21.5,2160,3.21,18400000,3.22
21.5,2150,3.22,18400000,3.22
21.5,2150,3.22,18300000,3.22
21.5,2130,3.22,18200000,3.23
21.5,2130,3.22,18200000,3.23
21.5,2130,3.23,18200000,3.23
21.5,2130,3.23,18200000,3.23
21.6,2130,3.23,18200000,3.24
21.6,2120,3.23,18100000,3.24
21.6,2120,3.24,18100000,3.24
21.6,2120,3.24,18100000,3.25
21.6,2120,3.24,18100000,3.25
21.6,2120,3.24,18100000,3.25
21.7,2120,3.25,18100000,3.25
21.7,2110,3.25,18100000,3.26
21.7,2110,3.25,18100000,3.26
21.7,2110,3.25,18000000,3.26
21.7,2110,3.26,18000000,3.26
21.7,2110,3.26,18000000,3.27
21.8,2110,3.26,18000000,3.27
21.8,2110,3.27,18000000,3.27
21.8,2100,3.27,18000000,3.27
21.8,2100,3.27,18000000,3.28
21.8,2100,3.27,18000000,3.28
21.8,2100,3.28,17900000,3.28
21.9,2100,3.28,17900000,3.29
21.9,2100,3.28,17900000,3.29
21.9,2100,3.28,17900000,3.29
21.9,2090,3.29,17900000,3.29
21.9,2090,3.29,17900000,3.30
21.9,2090,3.29,17900000,3.30
21.9,2090,3.29,17900000,3.30
22.0,2090,3.30,17800000,3.30
22.0,2090,3.30,17800000,3.31
22.0,2090,3.30,17800000,3.31
22.0,2080,3.31,17800000,3.31
22.0,2080,3.31,17800000,3.31
22.0,2080,3.31,17800000,3.32
22.1,2080,3.31,17800000,3.32
22.1,2080,3.32,17800000,3.32
22.1,2080,3.32,17800000,3.33
22.1,2080,3.32,17700000,3.33
22.1,2070,3.32,17700000,3.33
22.1,2070,3.33,17700000,3.33
22.2,2070,3.33,17700000,3.34
22.2,2070,3.33,17700000,3.34
22.2,1990,3.33,17000000,3.34
22.2,1840,3.34,15700000,3.34
22.2,1840,3.34,15700000,3.35
22.2,1840,3.34,15700000,3.35
22.3,1830,3.35,15700000,3.35
22.3,1830,3.35,15600000,3.36
22.3,1830,3.35,15600000,3.36
22.3,1830,3.35,15600000,3.36
22.3,1820,3.36,15600000,3.36
22.3,1820,3.36,15600000,3.37
22.3,1820,3.36,15600000,3.37
22.4,1820,3.36,15600000,3.37
22.4,1820,3.37,15500000,3.37
22.4,1820,3.37,15500000,3.38
22.4,1820,3.37,15500000,3.38
22.4,1820,3.37,15500000,3.38
22.4,1820,3.38,15500000,3.38
22.5,1820,3.38,15500000,3.39
22.5,1820,3.38,15500000,3.39
22.5,1820,3.39,15500000,3.39
22.5,1820,3.39,15500000,3.40
22.5,1820,3.39,15500000,3.40
22.5,1820,3.39,15500000,3.40
22.6,1820,3.40,15500000,3.40
22.6,1810,3.40,15500000,3.41
22.6,1810,3.40,15500000,3.41
22.6,1810,3.40,15500000,3.41
22.6,1810,3.41,15500000,3.41
22.6,1810,3.41,15500000,3.42
22.7,1810,3.41,15500000,3.42
22.7,1810,3.42,15500000,3.42
22.7,1810,3.42,15500000,3.42
22.7,1810,3.42,15500000,3.43
22.7,1810,3.42,15500000,3.43
22.7,1810,3.43,15500000,3.43
22.7,1810,3.43,15400000,3.44
22.8,1810,3.43,15400000,3.44
22.8,1810,3.43,15400000,3.44
22.8,1810,3.44,15400000,3.44
22.8,1810,3.44,15400000,3.45
22.8,1810,3.44,15400000,3.45
22.8,1810,3.44,15400000,3.45
22.9,1800,3.45,15400000,3.45
22.9,1800,3.45,15400000,3.46
22.9,1800,3.45,15400000,3.46
22.9,1800,3.45,15400000,3.46
22.9,1800,3.46,15400000,3.46
22.9,1800,3.46,15400000,3.47
23.0,1800,3.46,15400000,3.47
23.0,1800,3.47,15400000,3.47
23.0,1800,3.47,15400000,3.48
23.0,1800,3.47,15400000,3.48
23.0,1800,3.47,15400000,3.48
23.0,1800,3.48,15400000,3.48
23.1,1800,3.48,15400000,3.49
23.1,1800,3.48,15400000,3.49
23.1,1800,3.48,15400000,3.49
23.1,1800,3.49,15400000,3.49
23.1,1800,3.49,15400000,3.50
23.1,1800,3.49,15300000,3.50
23.1,1800,3.49,15300000,3.50
23.2,1790,3.50,15300000,3.50
23.2,1790,3.50,15300000,3.51
23.2,1790,3.50,15300000,3.51
23.2,1790,3.51,15300000,3.51
23.2,1790,3.51,15300000,3.52
23.2,1790,3.51,15300000,3.52
23.3,1790,3.51,15300000,3.52
23.3,1790,3.52,15300000,3.52
23.3,1790,3.52,15300000,3.53
23.3,1790,3.52,15300000,3.53
23.3,1790,3.52,15300000,3.53
23.3,1790,3.53,15300000,3.53
23.4,1790,3.53,15300000,3.54
23.4,1790,3.53,15300000,3.54
23.4,1790,3.53,15300000,3.54
23.4,1780,3.54,15200000,3.54
23.4,1780,3.54,15200000,3.55
23.4,1780,3.54,15200000,3.55
23.5,1780,3.55,15200000,3.55
23.5,1780,3.55,15200000,3.56
23.5,1780,3.55,15200000,3.56
23.5,1780,3.55,15200000,3.56
23.5,1780,3.56,15200000,3.56
23.5,1780,3.56,15200000,3.57
23.5,1780,3.56,15200000,3.57
23.6,1780,3.56,15200000,3.57
23.6,1780,3.57,15200000,3.57
23.6,1780,3.57,15200000,3.58
23.6,1770,3.57,15200000,3.58
23.6,1770,3.57,15200000,3.58
23.6,1770,3.58,15200000,3.58
23.7,1770,3.58,15100000,3.59
23.7,1770,3.58,15100000,3.59
23.7,1770,3.59,15100000,3.59
23.7,1770,3.59,15100000,3.60
23.7,1770,3.59,15100000,3.60
23.7,1770,3.59,15100000,3.60
23.8,1770,3.60,15100000,3.60
23.8,1770,3.60,15100000,3.61
23.8,1770,3.60,15100000,3.61
23.8,1770,3.60,15100000,3.61
23.8,1760,3.61,15100000,3.61
23.8,1760,3.61,15100000,3.62
23.9,1760,3.61,15100000,3.62
23.9,1760,3.61,15100000,3.62
23.9,1760,3.62,15000000,3.62
23.9,1760,3.62,15000000,3.63
23.9,1760,3.62,15000000,3.63
23.9,1760,3.63,15000000,3.63
23.9,1750,3.63,15000000,3.64
24.0,1750,3.63,14900000,3.64
24.0,1750,3.63,14900000,3.64
24.0,1740,3.64,14900000,3.64
24.0,1740,3.64,14900000,3.65
24.0,1740,3.64,14900000,3.65
24.0,1740,3.64,14900000,3.65
24.1,1740,3.65,14900000,3.65
24.1,1740,3.65,14900000,3.66
24.1,1740,3.65,14800000,3.66
24.1,1740,3.65,14800000,3.66
24.1,1740,3.66,14800000,3.66
24.1,1730,3.66,14800000,3.67
24.2,1730,3.66,14800000,3.67
24.2,1730,3.67,14800000,3.67
24.2,1730,3.67,14800000,3.68
24.2,1730,3.67,14800000,3.68
24.2,1730,3.67,14800000,3.68
24.2,1730,3.68,14800000,3.68
24.3,1730,3.68,14800000,3.69
24.3,1730,3.68,14800000,3.69
24.3,1730,3.68,14800000,3.69
24.3,1730,3.69,14800000,3.69
24.3,1730,3.69,14700000,3.70
24.3,1720,3.69,14700000,3.70
24.3,1720,3.69,14700000,3.70
24.4,1720,3.70,14700000,3.70
24.4,1720,3.70,14700000,3.71
24.4,1720,3.70,14700000,3.71
24.4,1720,3.71,14700000,3.71
24.4,1720,3.71,14700000,3.72
24.4,1720,3.71,14700000,3.72
24.5,1720,3.71,14700000,3.72
24.5,1720,3.72,14700000,3.72
24.5,1720,3.72,14700000,3.73
24.5,1720,3.72,14700000,3.73
24.5,1720,3.72,14700000,3.73
24.5,1720,3.73,14700000,3.73
24.6,1710,3.73,14700000,3.74
24.6,1710,3.73,14600000,3.74
24.6,1710,3.73,14600000,3.74
24.6,1710,3.74,14600000,3.74
24.6,1710,3.74,14600000,3.75
24.6,1710,3.74,14600000,3.75
24.7,1710,3.75,14600000,3.75
24.7,1710,3.75,14600000,3.76
24.7,1710,3.75,14600000,3.76
24.7,1710,3.75,14600000,3.76
24.7,1710,3.76,14600000,3.76
24.7,1710,3.76,14600000,3.77
24.7,1710,3.76,14600000,3.77
24.8,1700,3.76,14600000,3.77
2.49,39.5,0.0564,338000,0.0565
2.85,53.7,0.116,459000,0.116
3.21,86.8,0.176,742000,0.176
3.57,145,0.236,1240000,0.236
3.93,242,0.296,2070000,0.296
4.29,379,0.355,3240000,0.356
4.65,595,0.415,5090000,0.416
5.01,873,0.475,7460000,0.476
5.37,1180,0.535,10100000,0.536
5.73,1510,0.595,12900000,0.596
6.09,1840,0.655,15700000,0.656
6.44,2160,0.715,18500000,0.716
6.80,2460,0.775,21000000,0.776
7.16,2760,0.834,23600000,0.836
7.52,3050,0.894,26100000,0.896
7.88,3340,0.954,28500000,0.956
8.24,3620,1.01,30900000,1.02
8.60,3910,1.07,33400000,1.08
8.96,4190,1.13,35800000,1.14
9.32,4430,1.19,37800000,1.20
9.68,4620,1.25,39500000,1.26
10.0,4770,1.31,40800000,1.32
10.4,4860,1.37,41500000,1.38
10.8,4860,1.43,41500000,1.44
11.1,4730,1.49,40400000,1.50
11.5,4480,1.55,38200000,1.56
11.8,4220,1.61,36000000,1.62
12.2,3990,1.67,34100000,1.68
12.6,3830,1.73,32700000,1.74
12.9,3740,1.79,32000000,1.80
13.3,3660,1.85,31300000,1.86
13.6,3570,1.91,30500000,1.92
14.0,3430,1.97,29300000,1.98
14.4,3270,2.03,27900000,2.04
14.7,3180,2.09,27200000,2.10
15.1,3110,2.15,26600000,2.16
15.4,3040,2.21,26000000,2.22
15.8,2970,2.27,25400000,2.28
16.2,2900,2.33,24800000,2.34
16.5,2810,2.39,24000000,2.40
16.9,2750,2.45,23500000,2.46
17.2,2690,2.51,23000000,2.52
17.6,2630,2.57,22500000,2.58
18.0,2590,2.63,22100000,2.64
18.3,2540,2.69,21700000,2.70
18.7,2500,2.75,21300000,2.76
19.0,2450,2.81,21000000,2.82
19.4,2400,2.87,20500000,2.88
19.8,2340,2.93,20000000,2.94
20.1,2300,2.99,19700000,3.00
20.5,2270,3.05,19400000,3.06
20.8,2230,3.11,19100000,3.12
21.2,2180,3.17,18600000,3.18
21.6,2130,3.23,18200000,3.24
21.9,2090,3.29,17900000,3.30
22.3,1830,3.35,15600000,3.36
22.6,1810,3.41,15500000,3.42
23.0,1800,3.47,15400000,3.48
23.4,1790,3.53,15300000,3.54
23.7,1770,3.59,15100000,3.60
24.1,1740,3.65,14900000,3.66
24.4,1720,3.71,14700000,3.72
24.8,1700,3.76,14600000,3.77